Workbook

Sheet 1.한눈표(타입×품목)
A1: 그랜드 하얏트 인천 단위세대 기구물 — 1실당 개수 (2.상세 시트를 고치면 자동 반영)
A2: No | B2: 타입 | C2: 룸 | D2: 챠임벨 | E2: 키센서 DM | F2: BSP | G2: 거실 스위치 | H2: 회의실 스위치 | I2: 드레스룸 스위치 | J2: 화장실 스위치 | K2: 비상호출 | L2: 1실 합계 | M2: 실 수(입력) | N2: 총 개수 | O2: 상태
A3: 1 | B3: GOVERNOR SUITE (GS) | C3: - | D3: =SUMPRODUCT(('2.상세(수정)'!$A$2:$A$300=$B3)*('2.상세(수정)'!$B$2:$B$300=$C3)*('2.상세(수정)'!$D$2:$D$300=D$2)*'2.상세(수정)'!$E$2:$E$300) -> 1 | E3: =SUMPRODUCT(('2.상세(수정)'!$A$2:$A$300=$B3)*('2.상세(수정)'!$B$2:$B$300=$C3)*('2.상세(수정)'!$D$2:$D$300=E$2)*'2.상세(수정)'!$E$2:$E$300) -> 1 | F3: =SUMPRODUCT(('2.상세(수정)'!$A$2:$A$300=$B3)*('2.상세(수정)'!$B$2:$B$300=$C3)*('2.상세(수정)'!$D$2:$D$300=F$2)*'2.상세(수정)'!$E$2:$E$300) -> 1 | G3: =SUMPRODUCT(('2.상세(수정)'!$A$2:$A$300=$B3)*('2.상세(수정)'!$B$2:$B$300=$C3)*('2.상세(수정)'!$D$2:$D$300=G$2)*'2.상세(수정)'!$E$2:$E$300) -> 1 | H3: =SUMPRODUCT(('2.상세(수정)'!$A$2:$A$300=$B3)*('2.상세(수정)'!$B$2:$B$300=$C3)*('2.상세(수정)'!$D$2:$D$300=H$2)*'2.상세(수정)'!$E$2:$E$300) -> 0 | I3: =SUMPRODUCT(('2.상세(수정)'!$A$2:$A$300=$B3)*('2.상세(수정)'!$B$2:$B$300=$C3)*('2.상세(수정)'!$D$2:$D$300=I$2)*'2.상세(수정)'!$E$2:$E$300) -> 0 | J3: =SUMPRODUCT(('2.상세(수정)'!$A$2:$A$300=$B3)*('2.상세(수정)'!$B$2:$B$300=$C3)*('2.상세(수정)'!$D$2:$D$300=J$2)*'2.상세(수정)'!$E$2:$E$300) -> 1 | K3: =SUMPRODUCT(('2.상세(수정)'!$A$2:$A$300=$B3)*('2.상세(수정)'!$B$2:$B$300=$C3)*('2.상세(수정)'!$D$2:$D$300=K$2)*'2.상세(수정)'!$E$2:$E$300) -> 0 | L3: =SUM(D3:K3) -> 5 | N3: =L3*M3 -> 0 | O3: 확정(프로님 검토 v4)
A4: 2 | B4: 4~12F 타입(첫 도면) | C4: - | D4: =SUMPRODUCT(('2.상세(수정)'!$A$2:$A$300=$B4)*('2.상세(수정)'!$B$2:$B$300=$C4)*('2.상세(수정)'!$D$2:$D$300=D$2)*'2.상세(수정)'!$E$2:$E$300) -> 1 | E4: =SUMPRODUCT(('2.상세(수정)'!$A$2:$A$300=$B4)*('2.상세(수정)'!$B$2:$B$300=$C4)*('2.상세(수정)'!$D$2:$D$300=E$2)*'2.상세(수정)'!$E$2:$E$300) -> 1 | F4: =SUMPRODUCT(('2.상세(수정)'!$A$2:$A$300=$B4)*('2.상세(수정)'!$B$2:$B$300=$C4)*('2.상세(수정)'!$D$2:$D$300=F$2)*'2.상세(수정)'!$E$2:$E$300) -> 1 | G4: =SUMPRODUCT(('2.상세(수정)'!$A$2:$A$300=$B4)*('2.상세(수정)'!$B$2:$B$300=$C4)*('2.상세(수정)'!$D$2:$D$300=G$2)*'2.상세(수정)'!$E$2:$E$300) -> 0 | H4: =SUMPRODUCT(('2.상세(수정)'!$A$2:$A$300=$B4)*('2.상세(수정)'!$B$2:$B$300=$C4)*('2.상세(수정)'!$D$2:$D$300=H$2)*'2.상세(수정)'!$E$2:$E$300) -> 0 | I4: =SUMPRODUCT(('2.상세(수정)'!$A$2:$A$300=$B4)*('2.상세(수정)'!$B$2:$B$300=$C4)*('2.상세(수정)'!$D$2:$D$300=I$2)*'2.상세(수정)'!$E$2:$E$300) -> 1 | J4: =SUMPRODUCT(('2.상세(수정)'!$A$2:$A$300=$B4)*('2.상세(수정)'!$B$2:$B$300=$C4)*('2.상세(수정)'!$D$2:$D$300=J$2)*'2.상세(수정)'!$E$2:$E$300) -> 1 | K4: =SUMPRODUCT(('2.상세(수정)'!$A$2:$A$300=$B4)*('2.상세(수정)'!$B$2:$B$300=$C4)*('2.상세(수정)'!$D$2:$D$300=K$2)*'2.상세(수정)'!$E$2:$E$300) -> 0 | L4: =SUM(D4:K4) -> 5 | N4: =L4*M4 -> 0 | O4: 확정(프로님 검토 v4)
A5: 3 | B5: SUITE KING (K-3) 3~12F | C5: - | D5: =SUMPRODUCT(('2.상세(수정)'!$A$2:$A$300=$B5)*('2.상세(수정)'!$B$2:$B$300=$C5)*('2.상세(수정)'!$D$2:$D$300=D$2)*'2.상세(수정)'!$E$2:$E$300) -> 1 | E5: =SUMPRODUCT(('2.상세(수정)'!$A$2:$A$300=$B5)*('2.상세(수정)'!$B$2:$B$300=$C5)*('2.상세(수정)'!$D$2:$D$300=E$2)*'2.상세(수정)'!$E$2:$E$300) -> 1 | F5: =SUMPRODUCT(('2.상세(수정)'!$A$2:$A$300=$B5)*('2.상세(수정)'!$B$2:$B$300=$C5)*('2.상세(수정)'!$D$2:$D$300=F$2)*'2.상세(수정)'!$E$2:$E$300) -> 1 | G5: =SUMPRODUCT(('2.상세(수정)'!$A$2:$A$300=$B5)*('2.상세(수정)'!$B$2:$B$300=$C5)*('2.상세(수정)'!$D$2:$D$300=G$2)*'2.상세(수정)'!$E$2:$E$300) -> 0 | H5: =SUMPRODUCT(('2.상세(수정)'!$A$2:$A$300=$B5)*('2.상세(수정)'!$B$2:$B$300=$C5)*('2.상세(수정)'!$D$2:$D$300=H$2)*'2.상세(수정)'!$E$2:$E$300) -> 0 | I5: =SUMPRODUCT(('2.상세(수정)'!$A$2:$A$300=$B5)*('2.상세(수정)'!$B$2:$B$300=$C5)*('2.상세(수정)'!$D$2:$D$300=I$2)*'2.상세(수정)'!$E$2:$E$300) -> 1 | J5: =SUMPRODUCT(('2.상세(수정)'!$A$2:$A$300=$B5)*('2.상세(수정)'!$B$2:$B$300=$C5)*('2.상세(수정)'!$D$2:$D$300=J$2)*'2.상세(수정)'!$E$2:$E$300) -> 1 | K5: =SUMPRODUCT(('2.상세(수정)'!$A$2:$A$300=$B5)*('2.상세(수정)'!$B$2:$B$300=$C5)*('2.상세(수정)'!$D$2:$D$300=K$2)*'2.상세(수정)'!$E$2:$E$300) -> 0 | L5: =SUM(D5:K5) -> 5 | N5: =L5*M5 -> 0 | O5: 미검토
A6: 4 | B6: AMBASSADOR SUITE (AS) — 커넥팅 | C6: 룸1 = 좌측 침실 + 거실 | D6: =SUMPRODUCT(('2.상세(수정)'!$A$2:$A$300=$B6)*('2.상세(수정)'!$B$2:$B$300=$C6)*('2.상세(수정)'!$D$2:$D$300=D$2)*'2.상세(수정)'!$E$2:$E$300) -> 1 | E6: =SUMPRODUCT(('2.상세(수정)'!$A$2:$A$300=$B6)*('2.상세(수정)'!$B$2:$B$300=$C6)*('2.상세(수정)'!$D$2:$D$300=E$2)*'2.상세(수정)'!$E$2:$E$300) -> 1 | F6: =SUMPRODUCT(('2.상세(수정)'!$A$2:$A$300=$B6)*('2.상세(수정)'!$B$2:$B$300=$C6)*('2.상세(수정)'!$D$2:$D$300=F$2)*'2.상세(수정)'!$E$2:$E$300) -> 1 | G6: =SUMPRODUCT(('2.상세(수정)'!$A$2:$A$300=$B6)*('2.상세(수정)'!$B$2:$B$300=$C6)*('2.상세(수정)'!$D$2:$D$300=G$2)*'2.상세(수정)'!$E$2:$E$300) -> 1 | H6: =SUMPRODUCT(('2.상세(수정)'!$A$2:$A$300=$B6)*('2.상세(수정)'!$B$2:$B$300=$C6)*('2.상세(수정)'!$D$2:$D$300=H$2)*'2.상세(수정)'!$E$2:$E$300) -> 0 | I6: =SUMPRODUCT(('2.상세(수정)'!$A$2:$A$300=$B6)*('2.상세(수정)'!$B$2:$B$300=$C6)*('2.상세(수정)'!$D$2:$D$300=I$2)*'2.상세(수정)'!$E$2:$E$300) -> 1 | J6: =SUMPRODUCT(('2.상세(수정)'!$A$2:$A$300=$B6)*('2.상세(수정)'!$B$2:$B$300=$C6)*('2.상세(수정)'!$D$2:$D$300=J$2)*'2.상세(수정)'!$E$2:$E$300) -> 1 | K6: =SUMPRODUCT(('2.상세(수정)'!$A$2:$A$300=$B6)*('2.상세(수정)'!$B$2:$B$300=$C6)*('2.상세(수정)'!$D$2:$D$300=K$2)*'2.상세(수정)'!$E$2:$E$300) -> 0 | L6: =SUM(D6:K6) -> 6 | N6: =L6*M6 -> 0 | O6: 확정(프로님 검토 v4)
A7: 4 | B7: AMBASSADOR SUITE (AS) — 커넥팅 | C7: 룸2 = 우측 침실 | D7: =SUMPRODUCT(('2.상세(수정)'!$A$2:$A$300=$B7)*('2.상세(수정)'!$B$2:$B$300=$C7)*('2.상세(수정)'!$D$2:$D$300=D$2)*'2.상세(수정)'!$E$2:$E$300) -> 1 | E7: =SUMPRODUCT(('2.상세(수정)'!$A$2:$A$300=$B7)*('2.상세(수정)'!$B$2:$B$300=$C7)*('2.상세(수정)'!$D$2:$D$300=E$2)*'2.상세(수정)'!$E$2:$E$300) -> 1 | F7: =SUMPRODUCT(('2.상세(수정)'!$A$2:$A$300=$B7)*('2.상세(수정)'!$B$2:$B$300=$C7)*('2.상세(수정)'!$D$2:$D$300=F$2)*'2.상세(수정)'!$E$2:$E$300) -> 1 | G7: =SUMPRODUCT(('2.상세(수정)'!$A$2:$A$300=$B7)*('2.상세(수정)'!$B$2:$B$300=$C7)*('2.상세(수정)'!$D$2:$D$300=G$2)*'2.상세(수정)'!$E$2:$E$300) -> 0 | H7: =SUMPRODUCT(('2.상세(수정)'!$A$2:$A$300=$B7)*('2.상세(수정)'!$B$2:$B$300=$C7)*('2.상세(수정)'!$D$2:$D$300=H$2)*'2.상세(수정)'!$E$2:$E$300) -> 0 | I7: =SUMPRODUCT(('2.상세(수정)'!$A$2:$A$300=$B7)*('2.상세(수정)'!$B$2:$B$300=$C7)*('2.상세(수정)'!$D$2:$D$300=I$2)*'2.상세(수정)'!$E$2:$E$300) -> 0 | J7: =SUMPRODUCT(('2.상세(수정)'!$A$2:$A$300=$B7)*('2.상세(수정)'!$B$2:$B$300=$C7)*('2.상세(수정)'!$D$2:$D$300=J$2)*'2.상세(수정)'!$E$2:$E$300) -> 1 | K7: =SUMPRODUCT(('2.상세(수정)'!$A$2:$A$300=$B7)*('2.상세(수정)'!$B$2:$B$300=$C7)*('2.상세(수정)'!$D$2:$D$300=K$2)*'2.상세(수정)'!$E$2:$E$300) -> 0 | L7: =SUM(D7:K7) -> 4 | N7: =L7*M7 -> 0 | O7: 확정(프로님 검토 v4)
A8: 5 | B8: MANAGER'S SUITE (GM) | C8: - | D8: =SUMPRODUCT(('2.상세(수정)'!$A$2:$A$300=$B8)*('2.상세(수정)'!$B$2:$B$300=$C8)*('2.상세(수정)'!$D$2:$D$300=D$2)*'2.상세(수정)'!$E$2:$E$300) -> 1 | E8: =SUMPRODUCT(('2.상세(수정)'!$A$2:$A$300=$B8)*('2.상세(수정)'!$B$2:$B$300=$C8)*('2.상세(수정)'!$D$2:$D$300=E$2)*'2.상세(수정)'!$E$2:$E$300) -> 1 | F8: =SUMPRODUCT(('2.상세(수정)'!$A$2:$A$300=$B8)*('2.상세(수정)'!$B$2:$B$300=$C8)*('2.상세(수정)'!$D$2:$D$300=F$2)*'2.상세(수정)'!$E$2:$E$300) -> 2 | G8: =SUMPRODUCT(('2.상세(수정)'!$A$2:$A$300=$B8)*('2.상세(수정)'!$B$2:$B$300=$C8)*('2.상세(수정)'!$D$2:$D$300=G$2)*'2.상세(수정)'!$E$2:$E$300) -> 1 | H8: =SUMPRODUCT(('2.상세(수정)'!$A$2:$A$300=$B8)*('2.상세(수정)'!$B$2:$B$300=$C8)*('2.상세(수정)'!$D$2:$D$300=H$2)*'2.상세(수정)'!$E$2:$E$300) -> 0 | I8: =SUMPRODUCT(('2.상세(수정)'!$A$2:$A$300=$B8)*('2.상세(수정)'!$B$2:$B$300=$C8)*('2.상세(수정)'!$D$2:$D$300=I$2)*'2.상세(수정)'!$E$2:$E$300) -> 2 | J8: =SUMPRODUCT(('2.상세(수정)'!$A$2:$A$300=$B8)*('2.상세(수정)'!$B$2:$B$300=$C8)*('2.상세(수정)'!$D$2:$D$300=J$2)*'2.상세(수정)'!$E$2:$E$300) -> 2 | K8: =SUMPRODUCT(('2.상세(수정)'!$A$2:$A$300=$B8)*('2.상세(수정)'!$B$2:$B$300=$C8)*('2.상세(수정)'!$D$2:$D$300=K$2)*'2.상세(수정)'!$E$2:$E$300) -> 0 | L8: =SUM(D8:K8) -> 9 | N8: =L8*M8 -> 0 | O8: 확정(프로님 검토 v2)
A9: 6 | B9: OWNER'S SUITE (OS) | C9: - | D9: =SUMPRODUCT(('2.상세(수정)'!$A$2:$A$300=$B9)*('2.상세(수정)'!$B$2:$B$300=$C9)*('2.상세(수정)'!$D$2:$D$300=D$2)*'2.상세(수정)'!$E$2:$E$300) -> 1 | E9: =SUMPRODUCT(('2.상세(수정)'!$A$2:$A$300=$B9)*('2.상세(수정)'!$B$2:$B$300=$C9)*('2.상세(수정)'!$D$2:$D$300=E$2)*'2.상세(수정)'!$E$2:$E$300) -> 1 | F9: =SUMPRODUCT(('2.상세(수정)'!$A$2:$A$300=$B9)*('2.상세(수정)'!$B$2:$B$300=$C9)*('2.상세(수정)'!$D$2:$D$300=F$2)*'2.상세(수정)'!$E$2:$E$300) -> 1 | G9: =SUMPRODUCT(('2.상세(수정)'!$A$2:$A$300=$B9)*('2.상세(수정)'!$B$2:$B$300=$C9)*('2.상세(수정)'!$D$2:$D$300=G$2)*'2.상세(수정)'!$E$2:$E$300) -> 2 | H9: =SUMPRODUCT(('2.상세(수정)'!$A$2:$A$300=$B9)*('2.상세(수정)'!$B$2:$B$300=$C9)*('2.상세(수정)'!$D$2:$D$300=H$2)*'2.상세(수정)'!$E$2:$E$300) -> 0 | I9: =SUMPRODUCT(('2.상세(수정)'!$A$2:$A$300=$B9)*('2.상세(수정)'!$B$2:$B$300=$C9)*('2.상세(수정)'!$D$2:$D$300=I$2)*'2.상세(수정)'!$E$2:$E$300) -> 1 | J9: =SUMPRODUCT(('2.상세(수정)'!$A$2:$A$300=$B9)*('2.상세(수정)'!$B$2:$B$300=$C9)*('2.상세(수정)'!$D$2:$D$300=J$2)*'2.상세(수정)'!$E$2:$E$300) -> 2 | K9: =SUMPRODUCT(('2.상세(수정)'!$A$2:$A$300=$B9)*('2.상세(수정)'!$B$2:$B$300=$C9)*('2.상세(수정)'!$D$2:$D$300=K$2)*'2.상세(수정)'!$E$2:$E$300) -> 0 | L9: =SUM(D9:K9) -> 8 | N9: =L9*M9 -> 0 | O9: 미검토
A10: 7 | B10: PRESIDENTIAL SUITE (PS) | C10: - | D10: =SUMPRODUCT(('2.상세(수정)'!$A$2:$A$300=$B10)*('2.상세(수정)'!$B$2:$B$300=$C10)*('2.상세(수정)'!$D$2:$D$300=D$2)*'2.상세(수정)'!$E$2:$E$300) -> 1 | E10: =SUMPRODUCT(('2.상세(수정)'!$A$2:$A$300=$B10)*('2.상세(수정)'!$B$2:$B$300=$C10)*('2.상세(수정)'!$D$2:$D$300=E$2)*'2.상세(수정)'!$E$2:$E$300) -> 1 | F10: =SUMPRODUCT(('2.상세(수정)'!$A$2:$A$300=$B10)*('2.상세(수정)'!$B$2:$B$300=$C10)*('2.상세(수정)'!$D$2:$D$300=F$2)*'2.상세(수정)'!$E$2:$E$300) -> 2 | G10: =SUMPRODUCT(('2.상세(수정)'!$A$2:$A$300=$B10)*('2.상세(수정)'!$B$2:$B$300=$C10)*('2.상세(수정)'!$D$2:$D$300=G$2)*'2.상세(수정)'!$E$2:$E$300) -> 3 | H10: =SUMPRODUCT(('2.상세(수정)'!$A$2:$A$300=$B10)*('2.상세(수정)'!$B$2:$B$300=$C10)*('2.상세(수정)'!$D$2:$D$300=H$2)*'2.상세(수정)'!$E$2:$E$300) -> 0 | I10: =SUMPRODUCT(('2.상세(수정)'!$A$2:$A$300=$B10)*('2.상세(수정)'!$B$2:$B$300=$C10)*('2.상세(수정)'!$D$2:$D$300=I$2)*'2.상세(수정)'!$E$2:$E$300) -> 2 | J10: =SUMPRODUCT(('2.상세(수정)'!$A$2:$A$300=$B10)*('2.상세(수정)'!$B$2:$B$300=$C10)*('2.상세(수정)'!$D$2:$D$300=J$2)*'2.상세(수정)'!$E$2:$E$300) -> 4 | K10: =SUMPRODUCT(('2.상세(수정)'!$A$2:$A$300=$B10)*('2.상세(수정)'!$B$2:$B$300=$C10)*('2.상세(수정)'!$D$2:$D$300=K$2)*'2.상세(수정)'!$E$2:$E$300) -> 0 | L10: =SUM(D10:K10) -> 13 | N10: =L10*M10 -> 0 | O10: 미검토
A11: 8 | B11: HOSPITALITY SUITE-1 (HS-1) | C11: - | D11: =SUMPRODUCT(('2.상세(수정)'!$A$2:$A$300=$B11)*('2.상세(수정)'!$B$2:$B$300=$C11)*('2.상세(수정)'!$D$2:$D$300=D$2)*'2.상세(수정)'!$E$2:$E$300) -> 1 | E11: =SUMPRODUCT(('2.상세(수정)'!$A$2:$A$300=$B11)*('2.상세(수정)'!$B$2:$B$300=$C11)*('2.상세(수정)'!$D$2:$D$300=E$2)*'2.상세(수정)'!$E$2:$E$300) -> 1 | F11: =SUMPRODUCT(('2.상세(수정)'!$A$2:$A$300=$B11)*('2.상세(수정)'!$B$2:$B$300=$C11)*('2.상세(수정)'!$D$2:$D$300=F$2)*'2.상세(수정)'!$E$2:$E$300) -> 0 | G11: =SUMPRODUCT(('2.상세(수정)'!$A$2:$A$300=$B11)*('2.상세(수정)'!$B$2:$B$300=$C11)*('2.상세(수정)'!$D$2:$D$300=G$2)*'2.상세(수정)'!$E$2:$E$300) -> 0 | H11: =SUMPRODUCT(('2.상세(수정)'!$A$2:$A$300=$B11)*('2.상세(수정)'!$B$2:$B$300=$C11)*('2.상세(수정)'!$D$2:$D$300=H$2)*'2.상세(수정)'!$E$2:$E$300) -> 1 | I11: =SUMPRODUCT(('2.상세(수정)'!$A$2:$A$300=$B11)*('2.상세(수정)'!$B$2:$B$300=$C11)*('2.상세(수정)'!$D$2:$D$300=I$2)*'2.상세(수정)'!$E$2:$E$300) -> 1 | J11: =SUMPRODUCT(('2.상세(수정)'!$A$2:$A$300=$B11)*('2.상세(수정)'!$B$2:$B$300=$C11)*('2.상세(수정)'!$D$2:$D$300=J$2)*'2.상세(수정)'!$E$2:$E$300) -> 1 | K11: =SUMPRODUCT(('2.상세(수정)'!$A$2:$A$300=$B11)*('2.상세(수정)'!$B$2:$B$300=$C11)*('2.상세(수정)'!$D$2:$D$300=K$2)*'2.상세(수정)'!$E$2:$E$300) -> 0 | L11: =SUM(D11:K11) -> 5 | N11: =L11*M11 -> 0 | O11: 미검토
A12: 9 | B12: HOSPITALITY SUITE-3 (HS-3) | C12: - | D12: =SUMPRODUCT(('2.상세(수정)'!$A$2:$A$300=$B12)*('2.상세(수정)'!$B$2:$B$300=$C12)*('2.상세(수정)'!$D$2:$D$300=D$2)*'2.상세(수정)'!$E$2:$E$300) -> 1 | E12: =SUMPRODUCT(('2.상세(수정)'!$A$2:$A$300=$B12)*('2.상세(수정)'!$B$2:$B$300=$C12)*('2.상세(수정)'!$D$2:$D$300=E$2)*'2.상세(수정)'!$E$2:$E$300) -> 1 | F12: =SUMPRODUCT(('2.상세(수정)'!$A$2:$A$300=$B12)*('2.상세(수정)'!$B$2:$B$300=$C12)*('2.상세(수정)'!$D$2:$D$300=F$2)*'2.상세(수정)'!$E$2:$E$300) -> 0 | G12: =SUMPRODUCT(('2.상세(수정)'!$A$2:$A$300=$B12)*('2.상세(수정)'!$B$2:$B$300=$C12)*('2.상세(수정)'!$D$2:$D$300=G$2)*'2.상세(수정)'!$E$2:$E$300) -> 0 | H12: =SUMPRODUCT(('2.상세(수정)'!$A$2:$A$300=$B12)*('2.상세(수정)'!$B$2:$B$300=$C12)*('2.상세(수정)'!$D$2:$D$300=H$2)*'2.상세(수정)'!$E$2:$E$300) -> 1 | I12: =SUMPRODUCT(('2.상세(수정)'!$A$2:$A$300=$B12)*('2.상세(수정)'!$B$2:$B$300=$C12)*('2.상세(수정)'!$D$2:$D$300=I$2)*'2.상세(수정)'!$E$2:$E$300) -> 0 | J12: =SUMPRODUCT(('2.상세(수정)'!$A$2:$A$300=$B12)*('2.상세(수정)'!$B$2:$B$300=$C12)*('2.상세(수정)'!$D$2:$D$300=J$2)*'2.상세(수정)'!$E$2:$E$300) -> 1 | K12: =SUMPRODUCT(('2.상세(수정)'!$A$2:$A$300=$B12)*('2.상세(수정)'!$B$2:$B$300=$C12)*('2.상세(수정)'!$D$2:$D$300=K$2)*'2.상세(수정)'!$E$2:$E$300) -> 0 | L12: =SUM(D12:K12) -> 4 | N12: =L12*M12 -> 0 | O12: 미검토
A13: 10 | B13: HOSPITALITY SUITE-5 (HS-5) | C13: - | D13: =SUMPRODUCT(('2.상세(수정)'!$A$2:$A$300=$B13)*('2.상세(수정)'!$B$2:$B$300=$C13)*('2.상세(수정)'!$D$2:$D$300=D$2)*'2.상세(수정)'!$E$2:$E$300) -> 1 | E13: =SUMPRODUCT(('2.상세(수정)'!$A$2:$A$300=$B13)*('2.상세(수정)'!$B$2:$B$300=$C13)*('2.상세(수정)'!$D$2:$D$300=E$2)*'2.상세(수정)'!$E$2:$E$300) -> 1 | F13: =SUMPRODUCT(('2.상세(수정)'!$A$2:$A$300=$B13)*('2.상세(수정)'!$B$2:$B$300=$C13)*('2.상세(수정)'!$D$2:$D$300=F$2)*'2.상세(수정)'!$E$2:$E$300) -> 0 | G13: =SUMPRODUCT(('2.상세(수정)'!$A$2:$A$300=$B13)*('2.상세(수정)'!$B$2:$B$300=$C13)*('2.상세(수정)'!$D$2:$D$300=G$2)*'2.상세(수정)'!$E$2:$E$300) -> 1 | H13: =SUMPRODUCT(('2.상세(수정)'!$A$2:$A$300=$B13)*('2.상세(수정)'!$B$2:$B$300=$C13)*('2.상세(수정)'!$D$2:$D$300=H$2)*'2.상세(수정)'!$E$2:$E$300) -> 1 | I13: =SUMPRODUCT(('2.상세(수정)'!$A$2:$A$300=$B13)*('2.상세(수정)'!$B$2:$B$300=$C13)*('2.상세(수정)'!$D$2:$D$300=I$2)*'2.상세(수정)'!$E$2:$E$300) -> 0 | J13: =SUMPRODUCT(('2.상세(수정)'!$A$2:$A$300=$B13)*('2.상세(수정)'!$B$2:$B$300=$C13)*('2.상세(수정)'!$D$2:$D$300=J$2)*'2.상세(수정)'!$E$2:$E$300) -> 1 | K13: =SUMPRODUCT(('2.상세(수정)'!$A$2:$A$300=$B13)*('2.상세(수정)'!$B$2:$B$300=$C13)*('2.상세(수정)'!$D$2:$D$300=K$2)*'2.상세(수정)'!$E$2:$E$300) -> 0 | L13: =SUM(D13:K13) -> 5 | N13: =L13*M13 -> 0 | O13: 미검토
A14: 11 | B14: HANDICAP (DD-2) 3~12F 주거약자실 | C14: - | D14: =SUMPRODUCT(('2.상세(수정)'!$A$2:$A$300=$B14)*('2.상세(수정)'!$B$2:$B$300=$C14)*('2.상세(수정)'!$D$2:$D$300=D$2)*'2.상세(수정)'!$E$2:$E$300) -> 1 | E14: =SUMPRODUCT(('2.상세(수정)'!$A$2:$A$300=$B14)*('2.상세(수정)'!$B$2:$B$300=$C14)*('2.상세(수정)'!$D$2:$D$300=E$2)*'2.상세(수정)'!$E$2:$E$300) -> 1 | F14: =SUMPRODUCT(('2.상세(수정)'!$A$2:$A$300=$B14)*('2.상세(수정)'!$B$2:$B$300=$C14)*('2.상세(수정)'!$D$2:$D$300=F$2)*'2.상세(수정)'!$E$2:$E$300) -> 1 | G14: =SUMPRODUCT(('2.상세(수정)'!$A$2:$A$300=$B14)*('2.상세(수정)'!$B$2:$B$300=$C14)*('2.상세(수정)'!$D$2:$D$300=G$2)*'2.상세(수정)'!$E$2:$E$300) -> 0 | H14: =SUMPRODUCT(('2.상세(수정)'!$A$2:$A$300=$B14)*('2.상세(수정)'!$B$2:$B$300=$C14)*('2.상세(수정)'!$D$2:$D$300=H$2)*'2.상세(수정)'!$E$2:$E$300) -> 0 | I14: =SUMPRODUCT(('2.상세(수정)'!$A$2:$A$300=$B14)*('2.상세(수정)'!$B$2:$B$300=$C14)*('2.상세(수정)'!$D$2:$D$300=I$2)*'2.상세(수정)'!$E$2:$E$300) -> 1 | J14: =SUMPRODUCT(('2.상세(수정)'!$A$2:$A$300=$B14)*('2.상세(수정)'!$B$2:$B$300=$C14)*('2.상세(수정)'!$D$2:$D$300=J$2)*'2.상세(수정)'!$E$2:$E$300) -> 1 | K14: =SUMPRODUCT(('2.상세(수정)'!$A$2:$A$300=$B14)*('2.상세(수정)'!$B$2:$B$300=$C14)*('2.상세(수정)'!$D$2:$D$300=K$2)*'2.상세(수정)'!$E$2:$E$300) -> 1 | L14: =SUM(D14:K14) -> 6 | N14: =L14*M14 -> 0 | O14: 미검토
... A16: 12 | B16: KING & DD TYPE — 2실 | C16: 하 = DD | D16: =SUMPRODUCT(('2.상세(수정)'!$A$2:$A$300=$B16)*('2.상세(수정)'!$B$2:$B$300=$C16)*('2.상세(수정)'!$D$2:$D$300=D$2)*'2.상세(수정)'!$E$2:$E$300) -> 1 | E16: =SUMPRODUCT(('2.상세(수정)'!$A$2:$A$300=$B16)*('2.상세(수정)'!$B$2:$B$300=$C16)*('2.상세(수정)'!$D$2:$D$300=E$2)*'2.상세(수정)'!$E$2:$E$300) -> 1 | F16: =SUMPRODUCT(('2.상세(수정)'!$A$2:$A$300=$B16)*('2.상세(수정)'!$B$2:$B$300=$C16)*('2.상세(수정)'!$D$2:$D$300=F$2)*'2.상세(수정)'!$E$2:$E$300) -> 1 | G16: =SUMPRODUCT(('2.상세(수정)'!$A$2:$A$300=$B16)*('2.상세(수정)'!$B$2:$B$300=$C16)*('2.상세(수정)'!$D$2:$D$300=G$2)*'2.상세(수정)'!$E$2:$E$300) -> 0 | H16: =SUMPRODUCT(('2.상세(수정)'!$A$2:$A$300=$B16)*('2.상세(수정)'!$B$2:$B$300=$C16)*('2.상세(수정)'!$D$2:$D$300=H$2)*'2.상세(수정)'!$E$2:$E$300) -> 0 | I16: =SUMPRODUCT(('2.상세(수정)'!$A$2:$A$300=$B16)*('2.상세(수정)'!$B$2:$B$300=$C16)*('2.상세(수정)'!$D$2:$D$300=I$2)*'2.상세(수정)'!$E$2:$E$300) -> 1 | J16: =SUMPRODUCT(('2.상세(수정)'!$A$2:$A$300=$B16)*('2.상세(수정)'!$B$2:$B$300=$C16)*('2.상세(수정)'!$D$2:$D$300=J$2)*'2.상세(수정)'!$E$2:$E$300) -> 1 | K16: =SUMPRODUCT(('2.상세(수정)'!$A$2:$A$300=$B16)*('2.상세(수정)'!$B$2:$B$300=$C16)*('2.상세(수정)'!$D$2:$D$300=K$2)*'2.상세(수정)'!$E$2:$E$300) -> 0 | L16: =SUM(D16:K16) -> 5 | N16: =L16*M16 -> 0 | O16: 미검토
B17: 합계 (실 수 넣으면 총 개수 자동) | D17: =SUMPRODUCT(D3:D16,$M$3:$M16) -> 0 | E17: =SUMPRODUCT(E3:E16,$M$3:$M16) -> 0 | F17: =SUMPRODUCT(F3:F16,$M$3:$M16) -> 0 | G17: =SUMPRODUCT(G3:G16,$M$3:$M16) -> 0 | H17: =SUMPRODUCT(H3:H16,$M$3:$M16) -> 0 | I17: =SUMPRODUCT(I3:I16,$M$3:$M16) -> 0 | J17: =SUMPRODUCT(J3:J16,$M$3:$M16) -> 0 | K17: =SUMPRODUCT(K3:K16,$M$3:$M16) -> 0 | L17: =SUM(L3:L16) -> 85 | N17: =SUM(N3:N16) -> 0
B18: ※ 합계행 품목칸 = 품목별 총 개수(1실 개수 × 실 수). 중앙장비(PC 1, FIP 층당 1)는 층별 실 수 확정 후 추가.

Sheet 2.상세(수정)
A1: 타입 | B1: 룸 | C1: 번호 | D1: 품목 | E1: 수량 | F1: 위치 | G1: 상태 | H1: 비고(프로님 수정칸)
A2: ■ 01. GOVERNOR SUITE (GS) [확정(프로님 검토 v4)]
A3: GOVERNOR SUITE (GS) | B3: - | C3: 1 | D3: 챠임벨 | E3: 1 | F3: 출입문 복도 쪽 | G3: 확정(프로님 검토 v4)
A4: GOVERNOR SUITE (GS) | B4: - | C4: 2 | D4: 키센서 DM | E4: 1 | F4: 출입문 안쪽 | G4: 확정(프로님 검토 v4)
A5: GOVERNOR SUITE (GS) | B5: - | C5: 3 | D5: BSP | E5: 1 | F5: 침대 옆 | G5: 확정(프로님 검토 v4)
A6: GOVERNOR SUITE (GS) | B6: - | C6: 4 | D6: 거실 스위치 | E6: 1 | F6: 거실 들어가는 문 옆 | G6: 확정(프로님 검토 v4)
A7: GOVERNOR SUITE (GS) | B7: - | C7: 5 | D7: 화장실 스위치 | E7: 1 | F7: 욕실 문 옆 | G7: 확정(프로님 검토 v4)
A8: ■ 02. 4~12F 타입(첫 도면) [확정(프로님 검토 v4)]
A9: 4~12F 타입(첫 도면) | B9: - | C9: 1 | D9: 챠임벨 | E9: 1 | F9: 출입문 복도 쪽 | G9: 확정(프로님 검토 v4)
A10: 4~12F 타입(첫 도면) | B10: - | C10: 2 | D10: 키센서 DM | E10: 1 | F10: 출입문 안쪽 | G10: 확정(프로님 검토 v4)
A11: 4~12F 타입(첫 도면) | B11: - | C11: 3 | D11: BSP | E11: 1 | F11: 침대 옆 | G11: 확정(프로님 검토 v4)
A12: 4~12F 타입(첫 도면) | B12: - | C12: 4 | D12: 드레스룸 스위치 | E12: 1 | F12: 출입문과 욕실 사이 옷장 통로 | G12: 확정(프로님 검토 v4)
A13: 4~12F 타입(첫 도면) | B13: - | C13: 5 | D13: 화장실 스위치 | E13: 1 | F13: 욕실 문 옆 벽, 손잡이 쪽 | G13: 확정(프로님 검토 v4)
A14: ■ 03. SUITE KING (K-3) 3~12F [미검토]
A15: SUITE KING (K-3) 3~12F | B15: - | C15: 1 | D15: 챠임벨 | E15: 1 | F15: 우측 하단 출입문 복도 쪽 | G15: 미검토
A16: SUITE KING (K-3) 3~12F | B16: - | C16: 2 | D16: 키센서 DM | E16: 1 | F16: 출입문 안쪽 | G16: 미검토
A17: SUITE KING (K-3) 3~12F | B17: - | C17: 3 | D17: BSP | E17: 1 | F17: 침대 옆 | G17: 미검토
A18: SUITE KING (K-3) 3~12F | B18: - | C18: 4 | D18: 드레스룸 스위치 | E18: 1 | F18: 상단 옷장(CB 옆) | G18: 미검토
A19: SUITE KING (K-3) 3~12F | B19: - | C19: 5 | D19: 화장실 스위치 | E19: 1 | F19: 욕실 문 옆 벽 | G19: 미검토
A20: ■ 04. AMBASSADOR SUITE (AS) — 커넥팅 [확정(프로님 검토 v4)]
A21: AMBASSADOR SUITE (AS) — 커넥팅 | B21: 룸1 = 좌측 침실 + 거실 | C21: 1 | D21: 챠임벨 | E21: 1 | F21: 중앙 하단 출입문 복도 쪽 | G21: 확정(프로님 검토 v4)
A22: AMBASSADOR SUITE (AS) — 커넥팅 | B22: 룸1 = 좌측 침실 + 거실 | C22: 2 | D22: 키센서 DM | E22: 1 | F22: 출입문 안쪽 | G22: 확정(프로님 검토 v4)
A23: AMBASSADOR SUITE (AS) — 커넥팅 | B23: 룸1 = 좌측 침실 + 거실 | C23: 3 | D23: BSP | E23: 1 | F23: 킹 침대 옆 | G23: 확정(프로님 검토 v4)
A24: AMBASSADOR SUITE (AS) — 커넥팅 | B24: 룸1 = 좌측 침실 + 거실 | C24: 4 | D24: 거실 스위치 | E24: 1 | F24: 현관에서 거실 들어가는 입구 옆 벽 | G24: 확정(프로님 검토 v4)
A25: AMBASSADOR SUITE (AS) — 커넥팅 | B25: 룸1 = 좌측 침실 + 거실 | C25: 5 | D25: 화장실 스위치 | E25: 1 | F25: 욕실 문 옆 벽 | G25: 확정(프로님 검토 v4)
A26: AMBASSADOR SUITE (AS) — 커넥팅 | B26: 룸1 = 좌측 침실 + 거실 | C26: 6 | D26: 드레스룸 스위치 | E26: 1 | F26: 침실과 욕실 사이 옷장 통로 | G26: 확정(프로님 검토 v4)
A27: AMBASSADOR SUITE (AS) — 커넥팅 | B27: 룸2 = 우측 침실 | C27: 1 | D27: 챠임벨 | E27: 1 | F27: 우측 하단 출입문 복도 쪽 | G27: 확정(프로님 검토 v4)
A28: AMBASSADOR SUITE (AS) — 커넥팅 | B28: 룸2 = 우측 침실 | C28: 2 | D28: 키센서 DM | E28: 1 | F28: 출입문 안쪽 | G28: 확정(프로님 검토 v4)
A29: AMBASSADOR SUITE (AS) — 커넥팅 | B29: 룸2 = 우측 침실 | C29: 3 | D29: BSP | E29: 1 | F29: 트윈 침대 옆 | G29: 확정(프로님 검토 v4)
A30: AMBASSADOR SUITE (AS) — 커넥팅 | B30: 룸2 = 우측 침실 | C30: 4 | D30: 화장실 스위치 | E30: 1 | F30: 욕실 문 옆 벽 (현관은 통로라 스위치 없음) | G30: 확정(프로님 검토 v4)
A31: ■ 05. MANAGER'S SUITE (GM) [확정(프로님 검토 v2)]
A32: MANAGER'S SUITE (GM) | B32: - | C32: 1 | D32: 챠임벨 | E32: 1 | F32: 좌측 상단 출입문 복도 쪽 | G32: 확정(프로님 검토 v2)
A33: MANAGER'S SUITE (GM) | B33: - | C33: 2 | D33: 키센서 DM | E33: 1 | F33: 출입문 안쪽 | G33: 확정(프로님 검토 v2)
A34: MANAGER'S SUITE (GM) | B34: - | C34: 3 | D34: BSP | E34: 2 | F34: 좌 침실 침대 옆 / 우 침실 침대 옆 | G34: 확정(프로님 검토 v2)
A35: MANAGER'S SUITE (GM) | B35: - | C35: 4 | D35: 거실 스위치 | E35: 1 | F35: 현관 복도에서 거실 들어가는 입구 옆 벽 | G35: 확정(프로님 검토 v2)
A36: MANAGER'S SUITE (GM) | B36: - | C36: 5 | D36: 화장실 스위치 | E36: 2 | F36: 좌 욕실 문 옆 벽 / 우 욕실 문 옆 벽 | G36: 확정(프로님 검토 v2)
A37: MANAGER'S SUITE (GM) | B37: - | C37: 6 | D37: 드레스룸 스위치 | E37: 2 | F37: 출입문 옆 드레스룸(옷걸이) / 우 침실 드레스룸 | G37: 확정(프로님 검토 v2)
A38: ■ 06. OWNER'S SUITE (OS) [미검토]
A39: OWNER'S SUITE (OS) | B39: - | C39: 1 | D39: 챠임벨 | E39: 1 | F39: 좌측 하단 출입문 복도 쪽 | G39: 미검토
A40: OWNER'S SUITE (OS) | B40: - | C40: 2 | D40: 키센서 DM | E40: 1 | F40: 출입문 안쪽 | G40: 미검토
...

Sheet 3.정정 기준(프로님 확정)
A1: 항목 | B1: 기준 (2026-10-07)
A2: 번호 체계 | B2: 1 챠임벨 / 2 키센서 DM / 3 BSP / 4 거실·회의실 스위치(없으면 드레스룸이 4) / 5 화장실 스위치 / 6 드레스룸 스위치(거실 있을 때) / 비상호출은 맨 끝. 같은 품목이 여러 개면 같은 번호 반복.
A3: MMO | B3: 이 현장은 MMO 삭제(데스크·화장대 구분 어려움). 다른 현장은 책상 있으면 MMO 1 규칙 유지.
A4: BSP 내장 | B4: 온도조절기·L·디밍·커튼스위치는 BSP 안에 내장. 침실만 있는 타입은 별도 없음.
A5: 거실 스위치 | B5: 별도 거실이 있을 때만 거실 입구 옆 벽에 1개(온도+L+디밍+커튼). 회의실도 같은 구성.
A6: 화장실 스위치 | B6: 화장실 들어가는 문 옆 벽, 손잡이 쪽(경첩 반대), 문 바깥. 공간 한가운데 찍지 않는다.
A7: 드레스룸 | B7: 옷걸이 기호가 있는 옷장방이면 스위치 1. 옷걸이 없이 지나가는 통로형 현관은 스위치 없음.
A8: 비상호출 | B8: 주거약자실(장애인실)만 욕실 1. 일반실 없음.
A9: 미니바·수납 | B9: 거실과 한 공간인 미니바 콘솔·붙박이 옷장은 기구물 없음.
A10: 커넥팅룸 | B10: 룸1·룸2로 나눠 표를 따로 만든다. 같이 팔 때는 합산.
A11: 책상 판독 | B11: 창가에 의자 1 + 작은 탁자 = 책상. 양면 긴 장(TV장·콘솔)·화장대는 책상 아님. (이 현장은 MMO 삭제라 참고만)
A12: 산출 방식 | B12: 한 타입씩 그림+표 한 장으로 내고 프로님 확인 후 다음 타입. 한꺼번에 내지 않는다.

Sheet 9.자가진단·변경이력
A1: 날짜 | B1: 버전 | C1: 내용
A2: 2026-10-07 | B2: v1 | C2: 12타입 번호판·표 최초 생성. 파일을 열면 자가진단 시트가 먼저 떠서 타입이 안 보였음.
A3: 2026-10-07 | B3: v2 | C3: 한눈표(타입×품목)를 첫 장으로. 이름에 ~ 가 든 타입(4~12F, K-3, DD-2)이 SUMIFS에서 0으로 잡히던 문제를 SUMPRODUCT로 바꿔 해결. 상세 시트에 타입별 구분 줄 추가. 한눈표는 상세를 자동 집계. 수량 값은 v1과 같음.
A4: 2026-10-07 | B4: - | C4: ④ 미검토 8타입 위치는 Claude 판독. OS 회의·식당실, PS 다이닝·라이브러리 거실 스위치, KING&DD BSP 자리는 확신 낮음.
A5: 2026-10-07 | B5: - | C5: 저장: 드라이브 _컴퓨터로 옮길 것/46.그랜드하얏트인천_3.단위세대배치 → PC 「3.단위세 대배치 해봄」으로 옮길 것.
