Workbook

Sheet 사용법
A1: 시트 3번 「영업판」 v1 (2026-09-27) — 산군 + 설계사 영업 전용
A3: ■ 프로님 손은 1번 : 매주 월요일 산군 엑셀을 받아 「1.산군_붙여넣기」 탭 A1 칸을 누르고 통째로 붙여넣기(전체 덮어쓰기).
A4: → 2.현장 · 3.설계사 · 5.이번주_갈곳 · 7.문안 · 6.본전계산 이 저절로 바뀝니다.
A5: ■ 처음 한 번만 : 「설정」 탭 B4~B15 에 산군 엑셀 1행의 열 이름을 똑같이 적기(지금은 짐작값). 「0.자가진단」 1번이 「통과」 면 끝.
A6: ■ 다녀오시면 : 「4.방문기록」 에 한 줄(날짜·설계사무소·결과). 결과를 「관심 없음」 으로 고르면 그 사무소는 갈 곳 목록에서 빠집니다.
A7: ■ 담당자·전화를 알게 되면 : 「설계사_메모」 에 한 줄. 3·5·7번 탭에 저절로 붙습니다.
A8: ■ 전화·메일 문안 : 「7.문안」 B3 에서 설계사무소를 고르면 전화 첫마디·문자·메일 제목·본문이 채워집니다. 복사해서 쓰시면 됩니다.
A9: ■ 노란 칸 = 프로님 입력칸 / 초록 칸 = 자동(건드리지 않음).
A10: ■ 누구를 만나나 : 산군 공사단계가 허가·설계 단계 → 설계사무소(객실관리를 설계에 넣게) / 착공 이후 → 시공사 / 마감·준공 → 늦음.
A11: ■ 예시 줄 : [예시] 가 붙은 줄은 동작을 보여 드리려고 넣은 가짜입니다. 산군 엑셀을 붙여넣으면 자동으로 사라집니다(방문기록 예시 1줄은 직접 지우기).
A12: ■ 이 시트는 회의록·견적·공정·수금과 섞지 않습니다. 기존 레이더·도구 47번과도 따로입니다(계획서 9절).
A13: ■ 바꿀 때는 덮어쓰지 않고 새 판(v2)으로 냅니다. 변경 이력은 「0.자가진단」 아래에 있습니다.

Sheet 0.자가진단
A1: 자가진단 — 전부 「통과」 면 정상 (v1)
A3: 번호 | B3: 검사 | C3: 값 | D3: 판정
A4: 1 | B4: 산군 열 이름 12개 중 찾은 수 | C4: =COUNT(설정!C4:C15) | D4: =IF(C4=12,"통과",IF(AND(설정!C4<>"",설정!C5<>"",설정!C9<>""),"통과(일부 열 없음 — 설정 확인)","실패 — 설정 B4~B15"))
A5: 2 | B5: 붙여넣은 줄 수(1행 제외) | C5: =MAX(COUNTA('1.산군_붙여넣기'!A:A)-1,0) | D5: =IF(C5<=1000,"통과","실패 — 1000줄 넘음, 아래는 안 읽힘")
A6: 3 | B6: 읽은 현장 줄 | C6: =COUNTIF('2.현장'!O2:O1001,TRUE) | D6: =IF(C6=C5,"통과","확인 — 빈 줄·제목줄 섞임")
A7: 4 | B7: 중복 뺀 현장 | C7: =COUNTIF('2.현장'!Q2:Q1001,TRUE) | D7: ="참고"
A8: 5 | B8: 대상(용도·면적 맞음) | C8: =COUNTIF('2.현장'!T2:T1001,TRUE) | D8: ="참고"
A9: 6 | B9: 설계사행 + 시공사행 + 늦음 = 대상 | C9: =COUNTIF('2.현장'!U2:U1001,"설계사")+COUNTIF('2.현장'!U2:U1001,"시공사")+COUNTIF('2.현장'!U2:U1001,"늦음") | D9: =IF(C9=C8,"통과","실패 — 설정 단계 행선지 확인")
A10: 7 | B10: 설계사무소 수 = 번호 최댓값 | C10: =COUNTIF('3.설계사'!B4:B303,"?*") | D10: =IF(C10=MAX('2.현장'!W2:W1001),IF(C10<300,"통과","실패 — 300곳 넘음"),"실패")
A11: 8 | B11: 설계사 이름 빈 대상 현장 | C11: =COUNTIFS('2.현장'!T2:T1001,TRUE,'2.현장'!V2:V1001,"") | D11: =IF(C11=0,"통과","확인 — 산군에 설계사 없는 현장(2.현장 필터)")
A12: 9 | B12: 방문기록 중 목록에 없는 사무소 | C12: =SUM('4.방문기록'!J3:J502) | D12: =IF(C12=0,"통과","확인 — 이름이 3.설계사와 다름(드롭다운으로 고르기)")
A13: 10 | B13: 예시 줄 남음 | C13: =COUNTIF('1.산군_붙여넣기'!B:B,"[예시]*")+COUNTIF('4.방문기록'!B:B,"[예시]*") | D13: =IF(C13=0,"통과","알림 — [예시] 줄이 있음. 산군 붙여넣기 후 방문기록 예시 줄 지우기")
A16: 변경 이력
A17: 날짜 | B17: 판 | C17: 내용 | D17: 이전 값
A18: 2026-09-27 | B18: v1 | C18: 최초 작성 — 11개 탭(사용법·0~7·설정·설계사_메모). 계획서 v1 구조 그대로. | D18: 없음

Sheet 1.산군_붙여넣기
A1: 현장주소 | B1: 건물명 | C1: 연면적 | D1: 주용도 | E1: 허가구분 | F1: 공사단계 | G1: 허가일 | H1: 착공일 | I1: 건축주 | J1: 설계사 | K1: 시공사 | L1: 감리
A2: 서울특별시 중구 예시동 1 | B2: [예시]가나호텔 | C2: 12,500 | D2: 숙박시설(관광호텔) | E2: 신축 | F2: 건축허가 | G2: 2026-08-12 | I2: [예시]가나개발 | J2: [예시]가나건축사사무소
A3: 서울특별시 강남구 예시동 2 | B3: [예시]다라호텔 | C3: 8400 | D3: 숙박시설 | E3: 신축 | F3: 착공 | G3: 2026-03-02 | H3: 2026-07-01 | I3: [예시]다라산업 | J3: (주)[예시]가나건축사사무소 | K3: [예시]마바건설 | L3: [예시]감리
A4: 강원특별자치도 양양군 예시리 3 | B4: [예시]사아리조트 | C4: 31,000 | D4: 숙박시설(콘도) | E4: 신축 | F4: 설계 | G4: 2026-09-01 | I4: [예시]사아레저 | J4: [예시]사아종합건축사사무소
A5: 경기도 이천시 예시동 4 | B5: [예시]자차기숙사 | C5: 22000 | D5: 교육연구시설(기숙사) | E5: 신축 | F5: 건축허가 | G5: 2026-07-20 | I5: [예시]자차 | J5: [예시]카타건축
A6: 경기도 성남시 예시동 5 | B6: [예시]파하오피스 | C6: 40000 | D6: 업무시설 | E6: 신축 | F6: 건축허가 | G6: 2026-06-01 | I6: [예시]파하 | J6: [예시]가나건축사사무소
A7: 부산광역시 해운대구 예시동 6 | B7: [예시]거너호텔 | C7: 900 | D7: 숙박시설 | E7: 신축 | F7: 건축허가 | G7: 2026-05-01 | I7: [예시]거너 | J7: [예시]거너건축
A8: 서울특별시 중구 예시동 1 | B8: [예시]가나호텔 | C8: 12,500 | D8: 숙박시설(관광호텔) | E8: 신축 | F8: 건축허가 | G8: 2026-08-12 | I8: [예시]가나개발 | J8: [예시]가나건축사사무소

Sheet 5.이번주_갈곳
A1: ="이번 주 찾아갈 설계사무소 "&COUNT('3.설계사'!R4:R303)&"곳 · 지역: "&IF(설정!B21="","전국",설정!B21)&" · 기준일 "&TEXT(설정!B24,"yyyy-mm-dd")
A2: 순서 : ①7일 안 약속 ②설계단계 현장이 많고 안 가본 곳 ③오래 안 간 곳. 관심 없음·최근 방문(재방문 간격 안)은 빠짐. 지역은 설정 B21.
A3: 순위 | B3: 설계사무소 | C3: 왜 가야 하나 | D3: 대표 현장 | E3: 지역 | F3: 최대 연면적 | G3: 담당자 | H3: 전화 | I3: 전화 첫마디(복사) | J3: _행
A4: =IF(J4="","",1) | B4: =IF(J4="","",INDEX('3.설계사'!$B$4:$B$303,J4)) | C4: =IF(J4="","",IF(INDEX('3.설계사'!$Q$4:$Q$303,J4)>=100,"약속 "&TEXT(INDEX('3.설계사'!$N$4:$N$303,J4),"m/d")&" · ",IF(INDEX('3.설계사'!$L$4:$L$303,J4)="","아직 안 가봄 · ","마지막 방문 "&INDEX('3.설계사'!$M$4:$M$303,J4)&"일 전 · "))&"설계단계 "&INDEX('3.설계사'!$D$4:$D$303,J4)&"건"&IF(INDEX('3.설계사'!$E$4:$E$303,J4)>0," · 시공단계 "&INDEX('3.설계사'!$E$4:$E$303,J4)&"건","")) | D4: =IF(J4="","",INDEX('3.설계사'!$H$4:$H$303,J4)) | E4: =IF(J4="","",INDEX('3.설계사'!$I$4:$I$303,J4)) | F4: =IF(J4="","",INDEX('3.설계사'!$F$4:$F$303,J4)) | G4: =IF(J4="","",INDEX('3.설계사'!$J$4:$J$303,J4)) | H4: =IF(J4="","",INDEX('3.설계사'!$K$4:$K$303,J4)) | I4: =IF(J4="","","한국마이크로닉 배성윤 차장입니다. "&INDEX('3.설계사'!$H$4:$H$303,J4)&" 설계 진행하고 계신 걸로 알고 연락드렸습니다. 호텔 객실관리(키센서·온도조절기·조명 제어) 도면과 특기시방서를 무상으로 지원해 드리고 있어서, 이번 주에 10분만 찾아뵈어도 될까요?") | J4: =IFERROR(MATCH(1,'3.설계사'!$R$4:$R$303,0),"")
A5: =IF(J5="","",2) | B5: =IF(J5="","",INDEX('3.설계사'!$B$4:$B$303,J5)) | C5: =IF(J5="","",IF(INDEX('3.설계사'!$Q$4:$Q$303,J5)>=100,"약속 "&TEXT(INDEX('3.설계사'!$N$4:$N$303,J5),"m/d")&" · ",IF(INDEX('3.설계사'!$L$4:$L$303,J5)="","아직 안 가봄 · ","마지막 방문 "&INDEX('3.설계사'!$M$4:$M$303,J5)&"일 전 · "))&"설계단계 "&INDEX('3.설계사'!$D$4:$D$303,J5)&"건"&IF(INDEX('3.설계사'!$E$4:$E$303,J5)>0," · 시공단계 "&INDEX('3.설계사'!$E$4:$E$303,J5)&"건","")) | D5: =IF(J5="","",INDEX('3.설계사'!$H$4:$H$303,J5)) | E5: =IF(J5="","",INDEX('3.설계사'!$I$4:$I$303,J5)) | F5: =IF(J5="","",INDEX('3.설계사'!$F$4:$F$303,J5)) | G5: =IF(J5="","",INDEX('3.설계사'!$J$4:$J$303,J5)) | H5: =IF(J5="","",INDEX('3.설계사'!$K$4:$K$303,J5)) | I5: =IF(J5="","","한국마이크로닉 배성윤 차장입니다. "&INDEX('3.설계사'!$H$4:$H$303,J5)&" 설계 진행하고 계신 걸로 알고 연락드렸습니다. 호텔 객실관리(키센서·온도조절기·조명 제어) 도면과 특기시방서를 무상으로 지원해 드리고 있어서, 이번 주에 10분만 찾아뵈어도 될까요?") | J5: =IFERROR(MATCH(2,'3.설계사'!$R$4:$R$303,0),"")
A6: =IF(J6="","",3) | B6: =IF(J6="","",INDEX('3.설계사'!$B$4:$B$303,J6)) | C6: =IF(J6="","",IF(INDEX('3.설계사'!$Q$4:$Q$303,J6)>=100,"약속 "&TEXT(INDEX('3.설계사'!$N$4:$N$303,J6),"m/d")&" · ",IF(INDEX('3.설계사'!$L$4:$L$303,J6)="","아직 안 가봄 · ","마지막 방문 "&INDEX('3.설계사'!$M$4:$M$303,J6)&"일 전 · "))&"설계단계 "&INDEX('3.설계사'!$D$4:$D$303,J6)&"건"&IF(INDEX('3.설계사'!$E$4:$E$303,J6)>0," · 시공단계 "&INDEX('3.설계사'!$E$4:$E$303,J6)&"건","")) | D6: =IF(J6="","",INDEX('3.설계사'!$H$4:$H$303,J6)) | E6: =IF(J6="","",INDEX('3.설계사'!$I$4:$I$303,J6)) | F6: =IF(J6="","",INDEX('3.설계사'!$F$4:$F$303,J6)) | G6: =IF(J6="","",INDEX('3.설계사'!$J$4:$J$303,J6)) | H6: =IF(J6="","",INDEX('3.설계사'!$K$4:$K$303,J6)) | I6: =IF(J6="","","한국마이크로닉 배성윤 차장입니다. "&INDEX('3.설계사'!$H$4:$H$303,J6)&" 설계 진행하고 계신 걸로 알고 연락드렸습니다. 호텔 객실관리(키센서·온도조절기·조명 제어) 도면과 특기시방서를 무상으로 지원해 드리고 있어서, 이번 주에 10분만 찾아뵈어도 될까요?") | J6: =IFERROR(MATCH(3,'3.설계사'!$R$4:$R$303,0),"")
A7: =IF(J7="","",4) | B7: =IF(J7="","",INDEX('3.설계사'!$B$4:$B$303,J7)) | C7: =IF(J7="","",IF(INDEX('3.설계사'!$Q$4:$Q$303,J7)>=100,"약속 "&TEXT(INDEX('3.설계사'!$N$4:$N$303,J7),"m/d")&" · ",IF(INDEX('3.설계사'!$L$4:$L$303,J7)="","아직 안 가봄 · ","마지막 방문 "&INDEX('3.설계사'!$M$4:$M$303,J7)&"일 전 · "))&"설계단계 "&INDEX('3.설계사'!$D$4:$D$303,J7)&"건"&IF(INDEX('3.설계사'!$E$4:$E$303,J7)>0," · 시공단계 "&INDEX('3.설계사'!$E$4:$E$303,J7)&"건","")) | D7: =IF(J7="","",INDEX('3.설계사'!$H$4:$H$303,J7)) | E7: =IF(J7="","",INDEX('3.설계사'!$I$4:$I$303,J7)) | F7: =IF(J7="","",INDEX('3.설계사'!$F$4:$F$303,J7)) | G7: =IF(J7="","",INDEX('3.설계사'!$J$4:$J$303,J7)) | H7: =IF(J7="","",INDEX('3.설계사'!$K$4:$K$303,J7)) | I7: =IF(J7="","","한국마이크로닉 배성윤 차장입니다. "&INDEX('3.설계사'!$H$4:$H$303,J7)&" 설계 진행하고 계신 걸로 알고 연락드렸습니다. 호텔 객실관리(키센서·온도조절기·조명 제어) 도면과 특기시방서를 무상으로 지원해 드리고 있어서, 이번 주에 10분만 찾아뵈어도 될까요?") | J7: =IFERROR(MATCH(4,'3.설계사'!$R$4:$R$303,0),"")
A8: =IF(J8="","",5) | B8: =IF(J8="","",INDEX('3.설계사'!$B$4:$B$303,J8)) | C8: =IF(J8="","",IF(INDEX('3.설계사'!$Q$4:$Q$303,J8)>=100,"약속 "&TEXT(INDEX('3.설계사'!$N$4:$N$303,J8),"m/d")&" · ",IF(INDEX('3.설계사'!$L$4:$L$303,J8)="","아직 안 가봄 · ","마지막 방문 "&INDEX('3.설계사'!$M$4:$M$303,J8)&"일 전 · "))&"설계단계 "&INDEX('3.설계사'!$D$4:$D$303,J8)&"건"&IF(INDEX('3.설계사'!$E$4:$E$303,J8)>0," · 시공단계 "&INDEX('3.설계사'!$E$4:$E$303,J8)&"건","")) | D8: =IF(J8="","",INDEX('3.설계사'!$H$4:$H$303,J8)) | E8: =IF(J8="","",INDEX('3.설계사'!$I$4:$I$303,J8)) | F8: =IF(J8="","",INDEX('3.설계사'!$F$4:$F$303,J8)) | G8: =IF(J8="","",INDEX('3.설계사'!$J$4:$J$303,J8)) | H8: =IF(J8="","",INDEX('3.설계사'!$K$4:$K$303,J8)) | I8: =IF(J8="","","한국마이크로닉 배성윤 차장입니다. "&INDEX('3.설계사'!$H$4:$H$303,J8)&" 설계 진행하고 계신 걸로 알고 연락드렸습니다. 호텔 객실관리(키센서·온도조절기·조명 제어) 도면과 특기시방서를 무상으로 지원해 드리고 있어서, 이번 주에 10분만 찾아뵈어도 될까요?") | J8: =IFERROR(MATCH(5,'3.설계사'!$R$4:$R$303,0),"")
A9: =IF(J9="","",6) | B9: =IF(J9="","",INDEX('3.설계사'!$B$4:$B$303,J9)) | C9: =IF(J9="","",IF(INDEX('3.설계사'!$Q$4:$Q$303,J9)>=100,"약속 "&TEXT(INDEX('3.설계사'!$N$4:$N$303,J9),"m/d")&" · ",IF(INDEX('3.설계사'!$L$4:$L$303,J9)="","아직 안 가봄 · ","마지막 방문 "&INDEX('3.설계사'!$M$4:$M$303,J9)&"일 전 · "))&"설계단계 "&INDEX('3.설계사'!$D$4:$D$303,J9)&"건"&IF(INDEX('3.설계사'!$E$4:$E$303,J9)>0," · 시공단계 "&INDEX('3.설계사'!$E$4:$E$303,J9)&"건","")) | D9: =IF(J9="","",INDEX('3.설계사'!$H$4:$H$303,J9)) | E9: =IF(J9="","",INDEX('3.설계사'!$I$4:$I$303,J9)) | F9: =IF(J9="","",INDEX('3.설계사'!$F$4:$F$303,J9)) | G9: =IF(J9="","",INDEX('3.설계사'!$J$4:$J$303,J9)) | H9: =IF(J9="","",INDEX('3.설계사'!$K$4:$K$303,J9)) | I9: =IF(J9="","","한국마이크로닉 배성윤 차장입니다. "&INDEX('3.설계사'!$H$4:$H$303,J9)&" 설계 진행하고 계신 걸로 알고 연락드렸습니다. 호텔 객실관리(키센서·온도조절기·조명 제어) 도면과 특기시방서를 무상으로 지원해 드리고 있어서, 이번 주에 10분만 찾아뵈어도 될까요?") | J9: =IFERROR(MATCH(6,'3.설계사'!$R$4:$R$303,0),"")
A10: =IF(J10="","",7) | B10: =IF(J10="","",INDEX('3.설계사'!$B$4:$B$303,J10)) | C10: =IF(J10="","",IF(INDEX('3.설계사'!$Q$4:$Q$303,J10)>=100,"약속 "&TEXT(INDEX('3.설계사'!$N$4:$N$303,J10),"m/d")&" · ",IF(INDEX('3.설계사'!$L$4:$L$303,J10)="","아직 안 가봄 · ","마지막 방문 "&INDEX('3.설계사'!$M$4:$M$303,J10)&"일 전 · "))&"설계단계 "&INDEX('3.설계사'!$D$4:$D$303,J10)&"건"&IF(INDEX('3.설계사'!$E$4:$E$303,J10)>0," · 시공단계 "&INDEX('3.설계사'!$E$4:$E$303,J10)&"건","")) | D10: =IF(J10="","",INDEX('3.설계사'!$H$4:$H$303,J10)) | E10: =IF(J10="","",INDEX('3.설계사'!$I$4:$I$303,J10)) | F10: =IF(J10="","",INDEX('3.설계사'!$F$4:$F$303,J10)) | G10: =IF(J10="","",INDEX('3.설계사'!$J$4:$J$303,J10)) | H10: =IF(J10="","",INDEX('3.설계사'!$K$4:$K$303,J10)) | I10: =IF(J10="","","한국마이크로닉 배성윤 차장입니다. "&INDEX('3.설계사'!$H$4:$H$303,J10)&" 설계 진행하고 계신 걸로 알고 연락드렸습니다. 호텔 객실관리(키센서·온도조절기·조명 제어) 도면과 특기시방서를 무상으로 지원해 드리고 있어서, 이번 주에 10분만 찾아뵈어도 될까요?") | J10: =IFERROR(MATCH(7,'3.설계사'!$R$4:$R$303,0),"")
A11: =IF(J11="","",8) | B11: =IF(J11="","",INDEX('3.설계사'!$B$4:$B$303,J11)) | C11: =IF(J11="","",IF(INDEX('3.설계사'!$Q$4:$Q$303,J11)>=100,"약속 "&TEXT(INDEX('3.설계사'!$N$4:$N$303,J11),"m/d")&" · ",IF(INDEX('3.설계사'!$L$4:$L$303,J11)="","아직 안 가봄 · ","마지막 방문 "&INDEX('3.설계사'!$M$4:$M$303,J11)&"일 전 · "))&"설계단계 "&INDEX('3.설계사'!$D$4:$D$303,J11)&"건"&IF(INDEX('3.설계사'!$E$4:$E$303,J11)>0," · 시공단계 "&INDEX('3.설계사'!$E$4:$E$303,J11)&"건","")) | D11: =IF(J11="","",INDEX('3.설계사'!$H$4:$H$303,J11)) | E11: =IF(J11="","",INDEX('3.설계사'!$I$4:$I$303,J11)) | F11: =IF(J11="","",INDEX('3.설계사'!$F$4:$F$303,J11)) | G11: =IF(J11="","",INDEX('3.설계사'!$J$4:$J$303,J11)) | H11: =IF(J11="","",INDEX('3.설계사'!$K$4:$K$303,J11)) | I11: =IF(J11="","","한국마이크로닉 배성윤 차장입니다. "&INDEX('3.설계사'!$H$4:$H$303,J11)&" 설계 진행하고 계신 걸로 알고 연락드렸습니다. 호텔 객실관리(키센서·온도조절기·조명 제어) 도면과 특기시방서를 무상으로 지원해 드리고 있어서, 이번 주에 10분만 찾아뵈어도 될까요?") | J11: =IFERROR(MATCH(8,'3.설계사'!$R$4:$R$303,0),"")
A12: =IF(J12="","",9) | B12: =IF(J12="","",INDEX('3.설계사'!$B$4:$B$303,J12)) | C12: =IF(J12="","",IF(INDEX('3.설계사'!$Q$4:$Q$303,J12)>=100,"약속 "&TEXT(INDEX('3.설계사'!$N$4:$N$303,J12),"m/d")&" · ",IF(INDEX('3.설계사'!$L$4:$L$303,J12)="","아직 안 가봄 · ","마지막 방문 "&INDEX('3.설계사'!$M$4:$M$303,J12)&"일 전 · "))&"설계단계 "&INDEX('3.설계사'!$D$4:$D$303,J12)&"건"&IF(INDEX('3.설계사'!$E$4:$E$303,J12)>0," · 시공단계 "&INDEX('3.설계사'!$E$4:$E$303,J12)&"건","")) | D12: =IF(J12="","",INDEX('3.설계사'!$H$4:$H$303,J12)) | E12: =IF(J12="","",INDEX('3.설계사'!$I$4:$I$303,J12)) | F12: =IF(J12="","",INDEX('3.설계사'!$F$4:$F$303,J12)) | G12: =IF(J12="","",INDEX('3.설계사'!$J$4:$J$303,J12)) | H12: =IF(J12="","",INDEX('3.설계사'!$K$4:$K$303,J12)) | I12: =IF(J12="","","한국마이크로닉 배성윤 차장입니다. "&INDEX('3.설계사'!$H$4:$H$303,J12)&" 설계 진행하고 계신 걸로 알고 연락드렸습니다. 호텔 객실관리(키센서·온도조절기·조명 제어) 도면과 특기시방서를 무상으로 지원해 드리고 있어서, 이번 주에 10분만 찾아뵈어도 될까요?") | J12: =IFERROR(MATCH(9,'3.설계사'!$R$4:$R$303,0),"")
A13: =IF(J13="","",10) | B13: =IF(J13="","",INDEX('3.설계사'!$B$4:$B$303,J13)) | C13: =IF(J13="","",IF(INDEX('3.설계사'!$Q$4:$Q$303,J13)>=100,"약속 "&TEXT(INDEX('3.설계사'!$N$4:$N$303,J13),"m/d")&" · ",IF(INDEX('3.설계사'!$L$4:$L$303,J13)="","아직 안 가봄 · ","마지막 방문 "&INDEX('3.설계사'!$M$4:$M$303,J13)&"일 전 · "))&"설계단계 "&INDEX('3.설계사'!$D$4:$D$303,J13)&"건"&IF(INDEX('3.설계사'!$E$4:$E$303,J13)>0," · 시공단계 "&INDEX('3.설계사'!$E$4:$E$303,J13)&"건","")) | D13: =IF(J13="","",INDEX('3.설계사'!$H$4:$H$303,J13)) | E13: =IF(J13="","",INDEX('3.설계사'!$I$4:$I$303,J13)) | F13: =IF(J13="","",INDEX('3.설계사'!$F$4:$F$303,J13)) | G13: =IF(J13="","",INDEX('3.설계사'!$J$4:$J$303,J13)) | H13: =IF(J13="","",INDEX('3.설계사'!$K$4:$K$303,J13)) | I13: =IF(J13="","","한국마이크로닉 배성윤 차장입니다. "&INDEX('3.설계사'!$H$4:$H$303,J13)&" 설계 진행하고 계신 걸로 알고 연락드렸습니다. 호텔 객실관리(키센서·온도조절기·조명 제어) 도면과 특기시방서를 무상으로 지원해 드리고 있어서, 이번 주에 10분만 찾아뵈어도 될까요?") | J13: =IFERROR(MATCH(10,'3.설계사'!$R$4:$R$303,0),"")
A14: =IF(J14="","",11) | B14: =IF(J14="","",INDEX('3.설계사'!$B$4:$B$303,J14)) | C14: =IF(J14="","",IF(INDEX('3.설계사'!$Q$4:$Q$303,J14)>=100,"약속 "&TEXT(INDEX('3.설계사'!$N$4:$N$303,J14),"m/d")&" · ",IF(INDEX('3.설계사'!$L$4:$L$303,J14)="","아직 안 가봄 · ","마지막 방문 "&INDEX('3.설계사'!$M$4:$M$303,J14)&"일 전 · "))&"설계단계 "&INDEX('3.설계사'!$D$4:$D$303,J14)&"건"&IF(INDEX('3.설계사'!$E$4:$E$303,J14)>0," · 시공단계 "&INDEX('3.설계사'!$E$4:$E$303,J14)&"건","")) | D14: =IF(J14="","",INDEX('3.설계사'!$H$4:$H$303,J14)) | E14: =IF(J14="","",INDEX('3.설계사'!$I$4:$I$303,J14)) | F14: =IF(J14="","",INDEX('3.설계사'!$F$4:$F$303,J14)) | G14: =IF(J14="","",INDEX('3.설계사'!$J$4:$J$303,J14)) | H14: =IF(J14="","",INDEX('3.설계사'!$K$4:$K$303,J14)) | I14: =IF(J14="","","한국마이크로닉 배성윤 차장입니다. "&INDEX('3.설계사'!$H$4:$H$303,J14)&" 설계 진행하고 계신 걸로 알고 연락드렸습니다. 호텔 객실관리(키센서·온도조절기·조명 제어) 도면과 특기시방서를 무상으로 지원해 드리고 있어서, 이번 주에 10분만 찾아뵈어도 될까요?") | J14: =IFERROR(MATCH(11,'3.설계사'!$R$4:$R$303,0),"")
A15: =IF(J15="","",12) | B15: =IF(J15="","",INDEX('3.설계사'!$B$4:$B$303,J15)) | C15: =IF(J15="","",IF(INDEX('3.설계사'!$Q$4:$Q$303,J15)>=100,"약속 "&TEXT(INDEX('3.설계사'!$N$4:$N$303,J15),"m/d")&" · ",IF(INDEX('3.설계사'!$L$4:$L$303,J15)="","아직 안 가봄 · ","마지막 방문 "&INDEX('3.설계사'!$M$4:$M$303,J15)&"일 전 · "))&"설계단계 "&INDEX('3.설계사'!$D$4:$D$303,J15)&"건"&IF(INDEX('3.설계사'!$E$4:$E$303,J15)>0," · 시공단계 "&INDEX('3.설계사'!$E$4:$E$303,J15)&"건","")) | D15: =IF(J15="","",INDEX('3.설계사'!$H$4:$H$303,J15)) | E15: =IF(J15="","",INDEX('3.설계사'!$I$4:$I$303,J15)) | F15: =IF(J15="","",INDEX('3.설계사'!$F$4:$F$303,J15)) | G15: =IF(J15="","",INDEX('3.설계사'!$J$4:$J$303,J15)) | H15: =IF(J15="","",INDEX('3.설계사'!$K$4:$K$303,J15)) | I15: =IF(J15="","","한국마이크로닉 배성윤 차장입니다. "&INDEX('3.설계사'!$H$4:$H$303,J15)&" 설계 진행하고 계신 걸로 알고 연락드렸습니다. 호텔 객실관리(키센서·온도조절기·조명 제어) 도면과 특기시방서를 무상으로 지원해 드리고 있어서, 이번 주에 10분만 찾아뵈어도 될까요?") | J15: =IFERROR(MATCH(12,'3.설계사'!$R$4:$R$303,0),"")
A16: =IF(J16="","",13) | B16: =IF(J16="","",INDEX('3.설계사'!$B$4:$B$303,J16)) | C16: =IF(J16="","",IF(INDEX('3.설계사'!$Q$4:$Q$303,J16)>=100,"약속 "&TEXT(INDEX('3.설계사'!$N$4:$N$303,J16),"m/d")&" · ",IF(INDEX('3.설계사'!$L$4:$L$303,J16)="","아직 안 가봄 · ","마지막 방문 "&INDEX('3.설계사'!$M$4:$M$303,J16)&"일 전 · "))&"설계단계 "&INDEX('3.설계사'!$D$4:$D$303,J16)&"건"&IF(INDEX('3.설계사'!$E$4:$E$303,J16)>0," · 시공단계 "&INDEX('3.설계사'!$E$4:$E$303,J16)&"건","")) | D16: =IF(J16="","",INDEX('3.설계사'!$H$4:$H$303,J16)) | E16: =IF(J16="","",INDEX('3.설계사'!$I$4:$I$303,J16)) | F16: =IF(J16="","",INDEX('3.설계사'!$F$4:$F$303,J16)) | G16: =IF(J16="","",INDEX('3.설계사'!$J$4:$J$303,J16)) | H16: =IF(J16="","",INDEX('3.설계사'!$K$4:$K$303,J16)) | I16: =IF(J16="","","한국마이크로닉 배성윤 차장입니다. "&INDEX('3.설계사'!$H$4:$H$303,J16)&" 설계 진행하고 계신 걸로 알고 연락드렸습니다. 호텔 객실관리(키센서·온도조절기·조명 제어) 도면과 특기시방서를 무상으로 지원해 드리고 있어서, 이번 주에 10분만 찾아뵈어도 될까요?") | J16: =IFERROR(MATCH(13,'3.설계사'!$R$4:$R$303,0),"")
A17: =IF(J17="","",14) | B17: =IF(J17="","",INDEX('3.설계사'!$B$4:$B$303,J17)) | C17: =IF(J17="","",IF(INDEX('3.설계사'!$Q$4:$Q$303,J17)>=100,"약속 "&TEXT(INDEX('3.설계사'!$N$4:$N$303,J17),"m/d")&" · ",IF(INDEX('3.설계사'!$L$4:$L$303,J17)="","아직 안 가봄 · ","마지막 방문 "&INDEX('3.설계사'!$M$4:$M$303,J17)&"일 전 · "))&"설계단계 "&INDEX('3.설계사'!$D$4:$D$303,J17)&"건"&IF(INDEX('3.설계사'!$E$4:$E$303,J17)>0," · 시공단계 "&INDEX('3.설계사'!$E$4:$E$303,J17)&"건","")) | D17: =IF(J17="","",INDEX('3.설계사'!$H$4:$H$303,J17)) | E17: =IF(J17="","",INDEX('3.설계사'!$I$4:$I$303,J17)) | F17: =IF(J17="","",INDEX('3.설계사'!$F$4:$F$303,J17)) | G17: =IF(J17="","",INDEX('3.설계사'!$J$4:$J$303,J17)) | H17: =IF(J17="","",INDEX('3.설계사'!$K$4:$K$303,J17)) | I17: =IF(J17="","","한국마이크로닉 배성윤 차장입니다. "&INDEX('3.설계사'!$H$4:$H$303,J17)&" 설계 진행하고 계신 걸로 알고 연락드렸습니다. 호텔 객실관리(키센서·온도조절기·조명 제어) 도면과 특기시방서를 무상으로 지원해 드리고 있어서, 이번 주에 10분만 찾아뵈어도 될까요?") | J17: =IFERROR(MATCH(14,'3.설계사'!$R$4:$R$303,0),"")
A18: =IF(J18="","",15) | B18: =IF(J18="","",INDEX('3.설계사'!$B$4:$B$303,J18)) | C18: =IF(J18="","",IF(INDEX('3.설계사'!$Q$4:$Q$303,J18)>=100,"약속 "&TEXT(INDEX('3.설계사'!$N$4:$N$303,J18),"m/d")&" · ",IF(INDEX('3.설계사'!$L$4:$L$303,J18)="","아직 안 가봄 · ","마지막 방문 "&INDEX('3.설계사'!$M$4:$M$303,J18)&"일 전 · "))&"설계단계 "&INDEX('3.설계사'!$D$4:$D$303,J18)&"건"&IF(INDEX('3.설계사'!$E$4:$E$303,J18)>0," · 시공단계 "&INDEX('3.설계사'!$E$4:$E$303,J18)&"건","")) | D18: =IF(J18="","",INDEX('3.설계사'!$H$4:$H$303,J18)) | E18: =IF(J18="","",INDEX('3.설계사'!$I$4:$I$303,J18)) | F18: =IF(J18="","",INDEX('3.설계사'!$F$4:$F$303,J18)) | G18: =IF(J18="","",INDEX('3.설계사'!$J$4:$J$303,J18)) | H18: =IF(J18="","",INDEX('3.설계사'!$K$4:$K$303,J18)) | I18: =IF(J18="","","한국마이크로닉 배성윤 차장입니다. "&INDEX('3.설계사'!$H$4:$H$303,J18)&" 설계 진행하고 계신 걸로 알고 연락드렸습니다. 호텔 객실관리(키센서·온도조절기·조명 제어) 도면과 특기시방서를 무상으로 지원해 드리고 있어서, 이번 주에 10분만 찾아뵈어도 될까요?") | J18: =IFERROR(MATCH(15,'3.설계사'!$R$4:$R$303,0),"")
A19: =IF(J19="","",16) | B19: =IF(J19="","",INDEX('3.설계사'!$B$4:$B$303,J19)) | C19: =IF(J19="","",IF(INDEX('3.설계사'!$Q$4:$Q$303,J19)>=100,"약속 "&TEXT(INDEX('3.설계사'!$N$4:$N$303,J19),"m/d")&" · ",IF(INDEX('3.설계사'!$L$4:$L$303,J19)="","아직 안 가봄 · ","마지막 방문 "&INDEX('3.설계사'!$M$4:$M$303,J19)&"일 전 · "))&"설계단계 "&INDEX('3.설계사'!$D$4:$D$303,J19)&"건"&IF(INDEX('3.설계사'!$E$4:$E$303,J19)>0," · 시공단계 "&INDEX('3.설계사'!$E$4:$E$303,J19)&"건","")) | D19: =IF(J19="","",INDEX('3.설계사'!$H$4:$H$303,J19)) | E19: =IF(J19="","",INDEX('3.설계사'!$I$4:$I$303,J19)) | F19: =IF(J19="","",INDEX('3.설계사'!$F$4:$F$303,J19)) | G19: =IF(J19="","",INDEX('3.설계사'!$J$4:$J$303,J19)) | H19: =IF(J19="","",INDEX('3.설계사'!$K$4:$K$303,J19)) | I19: =IF(J19="","","한국마이크로닉 배성윤 차장입니다. "&INDEX('3.설계사'!$H$4:$H$303,J19)&" 설계 진행하고 계신 걸로 알고 연락드렸습니다. 호텔 객실관리(키센서·온도조절기·조명 제어) 도면과 특기시방서를 무상으로 지원해 드리고 있어서, 이번 주에 10분만 찾아뵈어도 될까요?") | J19: =IFERROR(MATCH(16,'3.설계사'!$R$4:$R$303,0),"")
A20: =IF(J20="","",17) | B20: =IF(J20="","",INDEX('3.설계사'!$B$4:$B$303,J20)) | C20: =IF(J20="","",IF(INDEX('3.설계사'!$Q$4:$Q$303,J20)>=100,"약속 "&TEXT(INDEX('3.설계사'!$N$4:$N$303,J20),"m/d")&" · ",IF(INDEX('3.설계사'!$L$4:$L$303,J20)="","아직 안 가봄 · ","마지막 방문 "&INDEX('3.설계사'!$M$4:$M$303,J20)&"일 전 · "))&"설계단계 "&INDEX('3.설계사'!$D$4:$D$303,J20)&"건"&IF(INDEX('3.설계사'!$E$4:$E$303,J20)>0," · 시공단계 "&INDEX('3.설계사'!$E$4:$E$303,J20)&"건","")) | D20: =IF(J20="","",INDEX('3.설계사'!$H$4:$H$303,J20)) | E20: =IF(J20="","",INDEX('3.설계사'!$I$4:$I$303,J20)) | F20: =IF(J20="","",INDEX('3.설계사'!$F$4:$F$303,J20)) | G20: =IF(J20="","",INDEX('3.설계사'!$J$4:$J$303,J20)) | H20: =IF(J20="","",INDEX('3.설계사'!$K$4:$K$303,J20)) | I20: =IF(J20="","","한국마이크로닉 배성윤 차장입니다. "&INDEX('3.설계사'!$H$4:$H$303,J20)&" 설계 진행하고 계신 걸로 알고 연락드렸습니다. 호텔 객실관리(키센서·온도조절기·조명 제어) 도면과 특기시방서를 무상으로 지원해 드리고 있어서, 이번 주에 10분만 찾아뵈어도 될까요?") | J20: =IFERROR(MATCH(17,'3.설계사'!$R$4:$R$303,0),"")
A21: =IF(J21="","",18) | B21: =IF(J21="","",INDEX('3.설계사'!$B$4:$B$303,J21)) | C21: =IF(J21="","",IF(INDEX('3.설계사'!$Q$4:$Q$303,J21)>=100,"약속 "&TEXT(INDEX('3.설계사'!$N$4:$N$303,J21),"m/d")&" · ",IF(INDEX('3.설계사'!$L$4:$L$303,J21)="","아직 안 가봄 · ","마지막 방문 "&INDEX('3.설계사'!$M$4:$M$303,J21)&"일 전 · "))&"설계단계 "&INDEX('3.설계사'!$D$4:$D$303,J21)&"건"&IF(INDEX('3.설계사'!$E$4:$E$303,J21)>0," · 시공단계 "&INDEX('3.설계사'!$E$4:$E$303,J21)&"건","")) | D21: =IF(J21="","",INDEX('3.설계사'!$H$4:$H$303,J21)) | E21: =IF(J21="","",INDEX('3.설계사'!$I$4:$I$303,J21)) | F21: =IF(J21="","",INDEX('3.설계사'!$F$4:$F$303,J21)) | G21: =IF(J21="","",INDEX('3.설계사'!$J$4:$J$303,J21)) | H21: =IF(J21="","",INDEX('3.설계사'!$K$4:$K$303,J21)) | I21: =IF(J21="","","한국마이크로닉 배성윤 차장입니다. "&INDEX('3.설계사'!$H$4:$H$303,J21)&" 설계 진행하고 계신 걸로 알고 연락드렸습니다. 호텔 객실관리(키센서·온도조절기·조명 제어) 도면과 특기시방서를 무상으로 지원해 드리고 있어서, 이번 주에 10분만 찾아뵈어도 될까요?") | J21: =IFERROR(MATCH(18,'3.설계사'!$R$4:$R$303,0),"")
A22: =IF(J22="","",19) | B22: =IF(J22="","",INDEX('3.설계사'!$B$4:$B$303,J22)) | C22: =IF(J22="","",IF(INDEX('3.설계사'!$Q$4:$Q$303,J22)>=100,"약속 "&TEXT(INDEX('3.설계사'!$N$4:$N$303,J22),"m/d")&" · ",IF(INDEX('3.설계사'!$L$4:$L$303,J22)="","아직 안 가봄 · ","마지막 방문 "&INDEX('3.설계사'!$M$4:$M$303,J22)&"일 전 · "))&"설계단계 "&INDEX('3.설계사'!$D$4:$D$303,J22)&"건"&IF(INDEX('3.설계사'!$E$4:$E$303,J22)>0," · 시공단계 "&INDEX('3.설계사'!$E$4:$E$303,J22)&"건","")) | D22: =IF(J22="","",INDEX('3.설계사'!$H$4:$H$303,J22)) | E22: =IF(J22="","",INDEX('3.설계사'!$I$4:$I$303,J22)) | F22: =IF(J22="","",INDEX('3.설계사'!$F$4:$F$303,J22)) | G22: =IF(J22="","",INDEX('3.설계사'!$J$4:$J$303,J22)) | H22: =IF(J22="","",INDEX('3.설계사'!$K$4:$K$303,J22)) | I22: =IF(J22="","","한국마이크로닉 배성윤 차장입니다. "&INDEX('3.설계사'!$H$4:$H$303,J22)&" 설계 진행하고 계신 걸로 알고 연락드렸습니다. 호텔 객실관리(키센서·온도조절기·조명 제어) 도면과 특기시방서를 무상으로 지원해 드리고 있어서, 이번 주에 10분만 찾아뵈어도 될까요?") | J22: =IFERROR(MATCH(19,'3.설계사'!$R$4:$R$303,0),"")
A23: =IF(J23="","",20) | B23: =IF(J23="","",INDEX('3.설계사'!$B$4:$B$303,J23)) | C23: =IF(J23="","",IF(INDEX('3.설계사'!$Q$4:$Q$303,J23)>=100,"약속 "&TEXT(INDEX('3.설계사'!$N$4:$N$303,J23),"m/d")&" · ",IF(INDEX('3.설계사'!$L$4:$L$303,J23)="","아직 안 가봄 · ","마지막 방문 "&INDEX('3.설계사'!$M$4:$M$303,J23)&"일 전 · "))&"설계단계 "&INDEX('3.설계사'!$D$4:$D$303,J23)&"건"&IF(INDEX('3.설계사'!$E$4:$E$303,J23)>0," · 시공단계 "&INDEX('3.설계사'!$E$4:$E$303,J23)&"건","")) | D23: =IF(J23="","",INDEX('3.설계사'!$H$4:$H$303,J23)) | E23: =IF(J23="","",INDEX('3.설계사'!$I$4:$I$303,J23)) | F23: =IF(J23="","",INDEX('3.설계사'!$F$4:$F$303,J23)) | G23: =IF(J23="","",INDEX('3.설계사'!$J$4:$J$303,J23)) | H23: =IF(J23="","",INDEX('3.설계사'!$K$4:$K$303,J23)) | I23: =IF(J23="","","한국마이크로닉 배성윤 차장입니다. "&INDEX('3.설계사'!$H$4:$H$303,J23)&" 설계 진행하고 계신 걸로 알고 연락드렸습니다. 호텔 객실관리(키센서·온도조절기·조명 제어) 도면과 특기시방서를 무상으로 지원해 드리고 있어서, 이번 주에 10분만 찾아뵈어도 될까요?") | J23: =IFERROR(MATCH(20,'3.설계사'!$R$4:$R$303,0),"")
A24: =IF(J24="","",21) | B24: =IF(J24="","",INDEX('3.설계사'!$B$4:$B$303,J24)) | C24: =IF(J24="","",IF(INDEX('3.설계사'!$Q$4:$Q$303,J24)>=100,"약속 "&TEXT(INDEX('3.설계사'!$N$4:$N$303,J24),"m/d")&" · ",IF(INDEX('3.설계사'!$L$4:$L$303,J24)="","아직 안 가봄 · ","마지막 방문 "&INDEX('3.설계사'!$M$4:$M$303,J24)&"일 전 · "))&"설계단계 "&INDEX('3.설계사'!$D$4:$D$303,J24)&"건"&IF(INDEX('3.설계사'!$E$4:$E$303,J24)>0," · 시공단계 "&INDEX('3.설계사'!$E$4:$E$303,J24)&"건","")) | D24: =IF(J24="","",INDEX('3.설계사'!$H$4:$H$303,J24)) | E24: =IF(J24="","",INDEX('3.설계사'!$I$4:$I$303,J24)) | F24: =IF(J24="","",INDEX('3.설계사'!$F$4:$F$303,J24)) | G24: =IF(J24="","",INDEX('3.설계사'!$J$4:$J$303,J24)) | H24: =IF(J24="","",INDEX('3.설계사'!$K$4:$K$303,J24)) | I24: =IF(J24="","","한국마이크로닉 배성윤 차장입니다. "&INDEX('3.설계사'!$H$4:$H$303,J24)&" 설계 진행하고 계신 걸로 알고 연락드렸습니다. 호텔 객실관리(키센서·온도조절기·조명 제어) 도면과 특기시방서를 무상으로 지원해 드리고 있어서, 이번 주에 10분만 찾아뵈어도 될까요?") | J24: =IFERROR(MATCH(21,'3.설계사'!$R$4:$R$303,0),"")
A25: =IF(J25="","",22) | B25: =IF(J25="","",INDEX('3.설계사'!$B$4:$B$303,J25)) | C25: =IF(J25="","",IF(INDEX('3.설계사'!$Q$4:$Q$303,J25)>=100,"약속 "&TEXT(INDEX('3.설계사'!$N$4:$N$303,J25),"m/d")&" · ",IF(INDEX('3.설계사'!$L$4:$L$303,J25)="","아직 안 가봄 · ","마지막 방문 "&INDEX('3.설계사'!$M$4:$M$303,J25)&"일 전 · "))&"설계단계 "&INDEX('3.설계사'!$D$4:$D$303,J25)&"건"&IF(INDEX('3.설계사'!$E$4:$E$303,J25)>0," · 시공단계 "&INDEX('3.설계사'!$E$4:$E$303,J25)&"건","")) | D25: =IF(J25="","",INDEX('3.설계사'!$H$4:$H$303,J25)) | E25: =IF(J25="","",INDEX('3.설계사'!$I$4:$I$303,J25)) | F25: =IF(J25="","",INDEX('3.설계사'!$F$4:$F$303,J25)) | G25: =IF(J25="","",INDEX('3.설계사'!$J$4:$J$303,J25)) | H25: =IF(J25="","",INDEX('3.설계사'!$K$4:$K$303,J25)) | I25: =IF(J25="","","한국마이크로닉 배성윤 차장입니다. "&INDEX('3.설계사'!$H$4:$H$303,J25)&" 설계 진행하고 계신 걸로 알고 연락드렸습니다. 호텔 객실관리(키센서·온도조절기·조명 제어) 도면과 특기시방서를 무상으로 지원해 드리고 있어서, 이번 주에 10분만 찾아뵈어도 될까요?") | J25: =IFERROR(MATCH(22,'3.설계사'!$R$4:$R$303,0),"")
A26: =IF(J26="","",23) | B26: =IF(J26="","",INDEX('3.설계사'!$B$4:$B$303,J26)) | C26: =IF(J26="","",IF(INDEX('3.설계사'!$Q$4:$Q$303,J26)>=100,"약속 "&TEXT(INDEX('3.설계사'!$N$4:$N$303,J26),"m/d")&" · ",IF(INDEX('3.설계사'!$L$4:$L$303,J26)="","아직 안 가봄 · ","마지막 방문 "&INDEX('3.설계사'!$M$4:$M$303,J26)&"일 전 · "))&"설계단계 "&INDEX('3.설계사'!$D$4:$D$303,J26)&"건"&IF(INDEX('3.설계사'!$E$4:$E$303,J26)>0," · 시공단계 "&INDEX('3.설계사'!$E$4:$E$303,J26)&"건","")) | D26: =IF(J26="","",INDEX('3.설계사'!$H$4:$H$303,J26)) | E26: =IF(J26="","",INDEX('3.설계사'!$I$4:$I$303,J26)) | F26: =IF(J26="","",INDEX('3.설계사'!$F$4:$F$303,J26)) | G26: =IF(J26="","",INDEX('3.설계사'!$J$4:$J$303,J26)) | H26: =IF(J26="","",INDEX('3.설계사'!$K$4:$K$303,J26)) | I26: =IF(J26="","","한국마이크로닉 배성윤 차장입니다. "&INDEX('3.설계사'!$H$4:$H$303,J26)&" 설계 진행하고 계신 걸로 알고 연락드렸습니다. 호텔 객실관리(키센서·온도조절기·조명 제어) 도면과 특기시방서를 무상으로 지원해 드리고 있어서, 이번 주에 10분만 찾아뵈어도 될까요?") | J26: =IFERROR(MATCH(23,'3.설계사'!$R$4:$R$303,0),"")
A27: =IF(J27="","",24) | B27: =IF(J27="","",INDEX('3.설계사'!$B$4:$B$303,J27)) | C27: =IF(J27="","",IF(INDEX('3.설계사'!$Q$4:$Q$303,J27)>=100,"약속 "&TEXT(INDEX('3.설계사'!$N$4:$N$303,J27),"m/d")&" · ",IF(INDEX('3.설계사'!$L$4:$L$303,J27)="","아직 안 가봄 · ","마지막 방문 "&INDEX('3.설계사'!$M$4:$M$303,J27)&"일 전 · "))&"설계단계 "&INDEX('3.설계사'!$D$4:$D$303,J27)&"건"&IF(INDEX('3.설계사'!$E$4:$E$303,J27)>0," · 시공단계 "&INDEX('3.설계사'!$E$4:$E$303,J27)&"건","")) | D27: =IF(J27="","",INDEX('3.설계사'!$H$4:$H$303,J27)) | E27: =IF(J27="","",INDEX('3.설계사'!$I$4:$I$303,J27)) | F27: =IF(J27="","",INDEX('3.설계사'!$F$4:$F$303,J27)) | G27: =IF(J27="","",INDEX('3.설계사'!$J$4:$J$303,J27)) | H27: =IF(J27="","",INDEX('3.설계사'!$K$4:$K$303,J27)) | I27: =IF(J27="","","한국마이크로닉 배성윤 차장입니다. "&INDEX('3.설계사'!$H$4:$H$303,J27)&" 설계 진행하고 계신 걸로 알고 연락드렸습니다. 호텔 객실관리(키센서·온도조절기·조명 제어) 도면과 특기시방서를 무상으로 지원해 드리고 있어서, 이번 주에 10분만 찾아뵈어도 될까요?") | J27: =IFERROR(MATCH(24,'3.설계사'!$R$4:$R$303,0),"")
A28: =IF(J28="","",25) | B28: =IF(J28="","",INDEX('3.설계사'!$B$4:$B$303,J28)) | C28: =IF(J28="","",IF(INDEX('3.설계사'!$Q$4:$Q$303,J28)>=100,"약속 "&TEXT(INDEX('3.설계사'!$N$4:$N$303,J28),"m/d")&" · ",IF(INDEX('3.설계사'!$L$4:$L$303,J28)="","아직 안 가봄 · ","마지막 방문 "&INDEX('3.설계사'!$M$4:$M$303,J28)&"일 전 · "))&"설계단계 "&INDEX('3.설계사'!$D$4:$D$303,J28)&"건"&IF(INDEX('3.설계사'!$E$4:$E$303,J28)>0," · 시공단계 "&INDEX('3.설계사'!$E$4:$E$303,J28)&"건","")) | D28: =IF(J28="","",INDEX('3.설계사'!$H$4:$H$303,J28)) | E28: =IF(J28="","",INDEX('3.설계사'!$I$4:$I$303,J28)) | F28: =IF(J28="","",INDEX('3.설계사'!$F$4:$F$303,J28)) | G28: =IF(J28="","",INDEX('3.설계사'!$J$4:$J$303,J28)) | H28: =IF(J28="","",INDEX('3.설계사'!$K$4:$K$303,J28)) | I28: =IF(J28="","","한국마이크로닉 배성윤 차장입니다. "&INDEX('3.설계사'!$H$4:$H$303,J28)&" 설계 진행하고 계신 걸로 알고 연락드렸습니다. 호텔 객실관리(키센서·온도조절기·조명 제어) 도면과 특기시방서를 무상으로 지원해 드리고 있어서, 이번 주에 10분만 찾아뵈어도 될까요?") | J28: =IFERROR(MATCH(25,'3.설계사'!$R$4:$R$303,0),"")
A29: =IF(J29="","",26) | B29: =IF(J29="","",INDEX('3.설계사'!$B$4:$B$303,J29)) | C29: =IF(J29="","",IF(INDEX('3.설계사'!$Q$4:$Q$303,J29)>=100,"약속 "&TEXT(INDEX('3.설계사'!$N$4:$N$303,J29),"m/d")&" · ",IF(INDEX('3.설계사'!$L$4:$L$303,J29)="","아직 안 가봄 · ","마지막 방문 "&INDEX('3.설계사'!$M$4:$M$303,J29)&"일 전 · "))&"설계단계 "&INDEX('3.설계사'!$D$4:$D$303,J29)&"건"&IF(INDEX('3.설계사'!$E$4:$E$303,J29)>0," · 시공단계 "&INDEX('3.설계사'!$E$4:$E$303,J29)&"건","")) | D29: =IF(J29="","",INDEX('3.설계사'!$H$4:$H$303,J29)) | E29: =IF(J29="","",INDEX('3.설계사'!$I$4:$I$303,J29)) | F29: =IF(J29="","",INDEX('3.설계사'!$F$4:$F$303,J29)) | G29: =IF(J29="","",INDEX('3.설계사'!$J$4:$J$303,J29)) | H29: =IF(J29="","",INDEX('3.설계사'!$K$4:$K$303,J29)) | I29: =IF(J29="","","한국마이크로닉 배성윤 차장입니다. "&INDEX('3.설계사'!$H$4:$H$303,J29)&" 설계 진행하고 계신 걸로 알고 연락드렸습니다. 호텔 객실관리(키센서·온도조절기·조명 제어) 도면과 특기시방서를 무상으로 지원해 드리고 있어서, 이번 주에 10분만 찾아뵈어도 될까요?") | J29: =IFERROR(MATCH(26,'3.설계사'!$R$4:$R$303,0),"")
A30: =IF(J30="","",27) | B30: =IF(J30="","",INDEX('3.설계사'!$B$4:$B$303,J30)) | C30: =IF(J30="","",IF(INDEX('3.설계사'!$Q$4:$Q$303,J30)>=100,"약속 "&TEXT(INDEX('3.설계사'!$N$4:$N$303,J30),"m/d")&" · ",IF(INDEX('3.설계사'!$L$4:$L$303,J30)="","아직 안 가봄 · ","마지막 방문 "&INDEX('3.설계사'!$M$4:$M$303,J30)&"일 전 · "))&"설계단계 "&INDEX('3.설계사'!$D$4:$D$303,J30)&"건"&IF(INDEX('3.설계사'!$E$4:$E$303,J30)>0," · 시공단계 "&INDEX('3.설계사'!$E$4:$E$303,J30)&"건","")) | D30: =IF(J30="","",INDEX('3.설계사'!$H$4:$H$303,J30)) | E30: =IF(J30="","",INDEX('3.설계사'!$I$4:$I$303,J30)) | F30: =IF(J30="","",INDEX('3.설계사'!$F$4:$F$303,J30)) | G30: =IF(J30="","",INDEX('3.설계사'!$J$4:$J$303,J30)) | H30: =IF(J30="","",INDEX('3.설계사'!$K$4:$K$303,J30)) | I30: =IF(J30="","","한국마이크로닉 배성윤 차장입니다. "&INDEX('3.설계사'!$H$4:$H$303,J30)&" 설계 진행하고 계신 걸로 알고 연락드렸습니다. 호텔 객실관리(키센서·온도조절기·조명 제어) 도면과 특기시방서를 무상으로 지원해 드리고 있어서, 이번 주에 10분만 찾아뵈어도 될까요?") | J30: =IFERROR(MATCH(27,'3.설계사'!$R$4:$R$303,0),"")
A31: =IF(J31="","",28) | B31: =IF(J31="","",INDEX('3.설계사'!$B$4:$B$303,J31)) | C31: =IF(J31="","",IF(INDEX('3.설계사'!$Q$4:$Q$303,J31)>=100,"약속 "&TEXT(INDEX('3.설계사'!$N$4:$N$303,J31),"m/d")&" · ",IF(INDEX('3.설계사'!$L$4:$L$303,J31)="","아직 안 가봄 · ","마지막 방문 "&INDEX('3.설계사'!$M$4:$M$303,J31)&"일 전 · "))&"설계단계 "&INDEX('3.설계사'!$D$4:$D$303,J31)&"건"&IF(INDEX('3.설계사'!$E$4:$E$303,J31)>0," · 시공단계 "&INDEX('3.설계사'!$E$4:$E$303,J31)&"건","")) | D31: =IF(J31="","",INDEX('3.설계사'!$H$4:$H$303,J31)) | E31: =IF(J31="","",INDEX('3.설계사'!$I$4:$I$303,J31)) | F31: =IF(J31="","",INDEX('3.설계사'!$F$4:$F$303,J31)) | G31: =IF(J31="","",INDEX('3.설계사'!$J$4:$J$303,J31)) | H31: =IF(J31="","",INDEX('3.설계사'!$K$4:$K$303,J31)) | I31: =IF(J31="","","한국마이크로닉 배성윤 차장입니다. "&INDEX('3.설계사'!$H$4:$H$303,J31)&" 설계 진행하고 계신 걸로 알고 연락드렸습니다. 호텔 객실관리(키센서·온도조절기·조명 제어) 도면과 특기시방서를 무상으로 지원해 드리고 있어서, 이번 주에 10분만 찾아뵈어도 될까요?") | J31: =IFERROR(MATCH(28,'3.설계사'!$R$4:$R$303,0),"")
A32: =IF(J32="","",29) | B32: =IF(J32="","",INDEX('3.설계사'!$B$4:$B$303,J32)) | C32: =IF(J32="","",IF(INDEX('3.설계사'!$Q$4:$Q$303,J32)>=100,"약속 "&TEXT(INDEX('3.설계사'!$N$4:$N$303,J32),"m/d")&" · ",IF(INDEX('3.설계사'!$L$4:$L$303,J32)="","아직 안 가봄 · ","마지막 방문 "&INDEX('3.설계사'!$M$4:$M$303,J32)&"일 전 · "))&"설계단계 "&INDEX('3.설계사'!$D$4:$D$303,J32)&"건"&IF(INDEX('3.설계사'!$E$4:$E$303,J32)>0," · 시공단계 "&INDEX('3.설계사'!$E$4:$E$303,J32)&"건","")) | D32: =IF(J32="","",INDEX('3.설계사'!$H$4:$H$303,J32)) | E32: =IF(J32="","",INDEX('3.설계사'!$I$4:$I$303,J32)) | F32: =IF(J32="","",INDEX('3.설계사'!$F$4:$F$303,J32)) | G32: =IF(J32="","",INDEX('3.설계사'!$J$4:$J$303,J32)) | H32: =IF(J32="","",INDEX('3.설계사'!$K$4:$K$303,J32)) | I32: =IF(J32="","","한국마이크로닉 배성윤 차장입니다. "&INDEX('3.설계사'!$H$4:$H$303,J32)&" 설계 진행하고 계신 걸로 알고 연락드렸습니다. 호텔 객실관리(키센서·온도조절기·조명 제어) 도면과 특기시방서를 무상으로 지원해 드리고 있어서, 이번 주에 10분만 찾아뵈어도 될까요?") | J32: =IFERROR(MATCH(29,'3.설계사'!$R$4:$R$303,0),"")
A33: =IF(J33="","",30) | B33: =IF(J33="","",INDEX('3.설계사'!$B$4:$B$303,J33)) | C33: =IF(J33="","",IF(INDEX('3.설계사'!$Q$4:$Q$303,J33)>=100,"약속 "&TEXT(INDEX('3.설계사'!$N$4:$N$303,J33),"m/d")&" · ",IF(INDEX('3.설계사'!$L$4:$L$303,J33)="","아직 안 가봄 · ","마지막 방문 "&INDEX('3.설계사'!$M$4:$M$303,J33)&"일 전 · "))&"설계단계 "&INDEX('3.설계사'!$D$4:$D$303,J33)&"건"&IF(INDEX('3.설계사'!$E$4:$E$303,J33)>0," · 시공단계 "&INDEX('3.설계사'!$E$4:$E$303,J33)&"건","")) | D33: =IF(J33="","",INDEX('3.설계사'!$H$4:$H$303,J33)) | E33: =IF(J33="","",INDEX('3.설계사'!$I$4:$I$303,J33)) | F33: =IF(J33="","",INDEX('3.설계사'!$F$4:$F$303,J33)) | G33: =IF(J33="","",INDEX('3.설계사'!$J$4:$J$303,J33)) | H33: =IF(J33="","",INDEX('3.설계사'!$K$4:$K$303,J33)) | I33: =IF(J33="","","한국마이크로닉 배성윤 차장입니다. "&INDEX('3.설계사'!$H$4:$H$303,J33)&" 설계 진행하고 계신 걸로 알고 연락드렸습니다. 호텔 객실관리(키센서·온도조절기·조명 제어) 도면과 특기시방서를 무상으로 지원해 드리고 있어서, 이번 주에 10분만 찾아뵈어도 될까요?") | J33: =IFERROR(MATCH(30,'3.설계사'!$R$4:$R$303,0),"")

Sheet 3.설계사
A1: 설계사무소별 모음 (자동) — 산군 대상 현장을 설계사무소 이름으로 묶음
A2: ="설계사무소 "&COUNTIF(B4:B303,"?*")&"곳 · 대상 현장 "&COUNTIF('2.현장'!T2:T1001,TRUE)&"건"
A3: 번호 | B3: 설계사무소 | C3: 대상 현장 | D3: 설계단계 | E3: 시공단계 | F3: 최대 연면적 | G3: 최근 허가일 | H3: 대표 현장 | I3: 지역 | J3: 담당자 | K3: 전화 | L3: 마지막 방문 | M3: 경과일 | N3: 다음 약속 | O3: 최근 결과 | P3: 상태 | Q3: 우선점수 | R3: 순위
A4: =IF(B4="","",1) | B4: =IFERROR(INDEX('2.현장'!$V$2:$V$1001,MATCH(1,'2.현장'!$W$2:$W$1001,0)),"") | C4: =IF(B4="","",COUNTIFS('2.현장'!$V$2:$V$1001,B4,'2.현장'!$T$2:$T$1001,TRUE)) | D4: =IF(B4="","",COUNTIFS('2.현장'!$V$2:$V$1001,B4,'2.현장'!$U$2:$U$1001,"설계사")) | E4: =IF(B4="","",COUNTIFS('2.현장'!$V$2:$V$1001,B4,'2.현장'!$U$2:$U$1001,"시공사")) | F4: =IF(B4="","",_xlfn.MAXIFS('2.현장'!$D$2:$D$1001,'2.현장'!$V$2:$V$1001,B4,'2.현장'!$T$2:$T$1001,TRUE)) | G4: =IF(B4="","",IF(_xlfn.MAXIFS('2.현장'!$L$2:$L$1001,'2.현장'!$V$2:$V$1001,B4,'2.현장'!$T$2:$T$1001,TRUE)=0,"",_xlfn.MAXIFS('2.현장'!$L$2:$L$1001,'2.현장'!$V$2:$V$1001,B4,'2.현장'!$T$2:$T$1001,TRUE))) | H4: =IF(B4="","",IFERROR(INDEX('2.현장'!$C$2:$C$1001,IFERROR(MATCH(B4&"|설계사",'2.현장'!$Z$2:$Z$1001,0),IFERROR(MATCH(B4&"|시공사",'2.현장'!$Z$2:$Z$1001,0),MATCH(B4&"|늦음",'2.현장'!$Z$2:$Z$1001,0)))),"")) | I4: =IF(B4="","",IFERROR(INDEX('2.현장'!$N$2:$N$1001,IFERROR(MATCH(B4&"|설계사",'2.현장'!$Z$2:$Z$1001,0),IFERROR(MATCH(B4&"|시공사",'2.현장'!$Z$2:$Z$1001,0),MATCH(B4&"|늦음",'2.현장'!$Z$2:$Z$1001,0)))),"")) | J4: =IF(B4="","",IFERROR(VLOOKUP(B4,설계사_메모!$A$3:$G$302,2,FALSE)&"","")) | K4: =IF(B4="","",IFERROR(VLOOKUP(B4,설계사_메모!$A$3:$G$302,4,FALSE)&"","")) | L4: =IF(B4="","",IF(COUNTIF('4.방문기록'!$B$3:$B$502,B4)=0,"",_xlfn.MAXIFS('4.방문기록'!$A$3:$A$502,'4.방문기록'!$B$3:$B$502,B4))) | M4: =IF(L4="","",설정!$B$24-L4) | N4: =IF(B4="","",IF(_xlfn.MAXIFS('4.방문기록'!$F$3:$F$502,'4.방문기록'!$B$3:$B$502,B4)=0,"",_xlfn.MAXIFS('4.방문기록'!$F$3:$F$502,'4.방문기록'!$B$3:$B$502,B4))) | O4: =IF(L4="","",IFERROR(INDEX('4.방문기록'!$H$3:$H$502,MATCH(B4&"|"&(L4*1),'4.방문기록'!$I$3:$I$502,0))&"","")) | P4: =IF(B4="","",IF(O4="관심 없음","제외",IF(L4="","안 가봄",IF(M4>=설정!$B$20,M4&"일 지남","최근 방문")))) | Q4: =IF(B4="","",IF(P4="제외","",IF(AND(설정!$B$21<>"",I4<>설정!$B$21),"",IF(AND(N4<>"",N4>N(L4),N4<=설정!$B$24+7),100+7-(N4-설정!$B$24),IF(AND(D4>0,OR(P4="안 가봄",RIGHT(P4,2)="지남")),D4*10+IF(L4="",30,MIN(M4,60)/2)+MIN(N(F4)/1000,20),""))))) | R4: =IF(Q4="","",COUNTIF(Q$4:Q$303,">"&Q4)+COUNTIF(Q$4:Q4,Q4))
A5: =IF(B5="","",2) | B5: =IFERROR(INDEX('2.현장'!$V$2:$V$1001,MATCH(2,'2.현장'!$W$2:$W$1001,0)),"") | C5: =IF(B5="","",COUNTIFS('2.현장'!$V$2:$V$1001,B5,'2.현장'!$T$2:$T$1001,TRUE)) | D5: =IF(B5="","",COUNTIFS('2.현장'!$V$2:$V$1001,B5,'2.현장'!$U$2:$U$1001,"설계사")) | E5: =IF(B5="","",COUNTIFS('2.현장'!$V$2:$V$1001,B5,'2.현장'!$U$2:$U$1001,"시공사")) | F5: =IF(B5="","",_xlfn.MAXIFS('2.현장'!$D$2:$D$1001,'2.현장'!$V$2:$V$1001,B5,'2.현장'!$T$2:$T$1001,TRUE)) | G5: =IF(B5="","",IF(_xlfn.MAXIFS('2.현장'!$L$2:$L$1001,'2.현장'!$V$2:$V$1001,B5,'2.현장'!$T$2:$T$1001,TRUE)=0,"",_xlfn.MAXIFS('2.현장'!$L$2:$L$1001,'2.현장'!$V$2:$V$1001,B5,'2.현장'!$T$2:$T$1001,TRUE))) | H5: =IF(B5="","",IFERROR(INDEX('2.현장'!$C$2:$C$1001,IFERROR(MATCH(B5&"|설계사",'2.현장'!$Z$2:$Z$1001,0),IFERROR(MATCH(B5&"|시공사",'2.현장'!$Z$2:$Z$1001,0),MATCH(B5&"|늦음",'2.현장'!$Z$2:$Z$1001,0)))),"")) | I5: =IF(B5="","",IFERROR(INDEX('2.현장'!$N$2:$N$1001,IFERROR(MATCH(B5&"|설계사",'2.현장'!$Z$2:$Z$1001,0),IFERROR(MATCH(B5&"|시공사",'2.현장'!$Z$2:$Z$1001,0),MATCH(B5&"|늦음",'2.현장'!$Z$2:$Z$1001,0)))),"")) | J5: =IF(B5="","",IFERROR(VLOOKUP(B5,설계사_메모!$A$3:$G$302,2,FALSE)&"","")) | K5: =IF(B5="","",IFERROR(VLOOKUP(B5,설계사_메모!$A$3:$G$302,4,FALSE)&"","")) | L5: =IF(B5="","",IF(COUNTIF('4.방문기록'!$B$3:$B$502,B5)=0,"",_xlfn.MAXIFS('4.방문기록'!$A$3:$A$502,'4.방문기록'!$B$3:$B$502,B5))) | M5: =IF(L5="","",설정!$B$24-L5) | N5: =IF(B5="","",IF(_xlfn.MAXIFS('4.방문기록'!$F$3:$F$502,'4.방문기록'!$B$3:$B$502,B5)=0,"",_xlfn.MAXIFS('4.방문기록'!$F$3:$F$502,'4.방문기록'!$B$3:$B$502,B5))) | O5: =IF(L5="","",IFERROR(INDEX('4.방문기록'!$H$3:$H$502,MATCH(B5&"|"&(L5*1),'4.방문기록'!$I$3:$I$502,0))&"","")) | P5: =IF(B5="","",IF(O5="관심 없음","제외",IF(L5="","안 가봄",IF(M5>=설정!$B$20,M5&"일 지남","최근 방문")))) | Q5: =IF(B5="","",IF(P5="제외","",IF(AND(설정!$B$21<>"",I5<>설정!$B$21),"",IF(AND(N5<>"",N5>N(L5),N5<=설정!$B$24+7),100+7-(N5-설정!$B$24),IF(AND(D5>0,OR(P5="안 가봄",RIGHT(P5,2)="지남")),D5*10+IF(L5="",30,MIN(M5,60)/2)+MIN(N(F5)/1000,20),""))))) | R5: =IF(Q5="","",COUNTIF(Q$4:Q$303,">"&Q5)+COUNTIF(Q$4:Q5,Q5))
A6: =IF(B6="","",3) | B6: =IFERROR(INDEX('2.현장'!$V$2:$V$1001,MATCH(3,'2.현장'!$W$2:$W$1001,0)),"") | C6: =IF(B6="","",COUNTIFS('2.현장'!$V$2:$V$1001,B6,'2.현장'!$T$2:$T$1001,TRUE)) | D6: =IF(B6="","",COUNTIFS('2.현장'!$V$2:$V$1001,B6,'2.현장'!$U$2:$U$1001,"설계사")) | E6: =IF(B6="","",COUNTIFS('2.현장'!$V$2:$V$1001,B6,'2.현장'!$U$2:$U$1001,"시공사")) | F6: =IF(B6="","",_xlfn.MAXIFS('2.현장'!$D$2:$D$1001,'2.현장'!$V$2:$V$1001,B6,'2.현장'!$T$2:$T$1001,TRUE)) | G6: =IF(B6="","",IF(_xlfn.MAXIFS('2.현장'!$L$2:$L$1001,'2.현장'!$V$2:$V$1001,B6,'2.현장'!$T$2:$T$1001,TRUE)=0,"",_xlfn.MAXIFS('2.현장'!$L$2:$L$1001,'2.현장'!$V$2:$V$1001,B6,'2.현장'!$T$2:$T$1001,TRUE))) | H6: =IF(B6="","",IFERROR(INDEX('2.현장'!$C$2:$C$1001,IFERROR(MATCH(B6&"|설계사",'2.현장'!$Z$2:$Z$1001,0),IFERROR(MATCH(B6&"|시공사",'2.현장'!$Z$2:$Z$1001,0),MATCH(B6&"|늦음",'2.현장'!$Z$2:$Z$1001,0)))),"")) | I6: =IF(B6="","",IFERROR(INDEX('2.현장'!$N$2:$N$1001,IFERROR(MATCH(B6&"|설계사",'2.현장'!$Z$2:$Z$1001,0),IFERROR(MATCH(B6&"|시공사",'2.현장'!$Z$2:$Z$1001,0),MATCH(B6&"|늦음",'2.현장'!$Z$2:$Z$1001,0)))),"")) | J6: =IF(B6="","",IFERROR(VLOOKUP(B6,설계사_메모!$A$3:$G$302,2,FALSE)&"","")) | K6: =IF(B6="","",IFERROR(VLOOKUP(B6,설계사_메모!$A$3:$G$302,4,FALSE)&"","")) | L6: =IF(B6="","",IF(COUNTIF('4.방문기록'!$B$3:$B$502,B6)=0,"",_xlfn.MAXIFS('4.방문기록'!$A$3:$A$502,'4.방문기록'!$B$3:$B$502,B6))) | M6: =IF(L6="","",설정!$B$24-L6) | N6: =IF(B6="","",IF(_xlfn.MAXIFS('4.방문기록'!$F$3:$F$502,'4.방문기록'!$B$3:$B$502,B6)=0,"",_xlfn.MAXIFS('4.방문기록'!$F$3:$F$502,'4.방문기록'!$B$3:$B$502,B6))) | O6: =IF(L6="","",IFERROR(INDEX('4.방문기록'!$H$3:$H$502,MATCH(B6&"|"&(L6*1),'4.방문기록'!$I$3:$I$502,0))&"","")) | P6: =IF(B6="","",IF(O6="관심 없음","제외",IF(L6="","안 가봄",IF(M6>=설정!$B$20,M6&"일 지남","최근 방문")))) | Q6: =IF(B6="","",IF(P6="제외","",IF(AND(설정!$B$21<>"",I6<>설정!$B$21),"",IF(AND(N6<>"",N6>N(L6),N6<=설정!$B$24+7),100+7-(N6-설정!$B$24),IF(AND(D6>0,OR(P6="안 가봄",RIGHT(P6,2)="지남")),D6*10+IF(L6="",30,MIN(M6,60)/2)+MIN(N(F6)/1000,20),""))))) | R6: =IF(Q6="","",COUNTIF(Q$4:Q$303,">"&Q6)+COUNTIF(Q$4:Q6,Q6))
A7: =IF(B7="","",4) | B7: =IFERROR(INDEX('2.현장'!$V$2:$V$1001,MATCH(4,'2.현장'!$W$2:$W$1001,0)),"") | C7: =IF(B7="","",COUNTIFS('2.현장'!$V$2:$V$1001,B7,'2.현장'!$T$2:$T$1001,TRUE)) | D7: =IF(B7="","",COUNTIFS('2.현장'!$V$2:$V$1001,B7,'2.현장'!$U$2:$U$1001,"설계사")) | E7: =IF(B7="","",COUNTIFS('2.현장'!$V$2:$V$1001,B7,'2.현장'!$U$2:$U$1001,"시공사")) | F7: =IF(B7="","",_xlfn.MAXIFS('2.현장'!$D$2:$D$1001,'2.현장'!$V$2:$V$1001,B7,'2.현장'!$T$2:$T$1001,TRUE)) | G7: =IF(B7="","",IF(_xlfn.MAXIFS('2.현장'!$L$2:$L$1001,'2.현장'!$V$2:$V$1001,B7,'2.현장'!$T$2:$T$1001,TRUE)=0,"",_xlfn.MAXIFS('2.현장'!$L$2:$L$1001,'2.현장'!$V$2:$V$1001,B7,'2.현장'!$T$2:$T$1001,TRUE))) | H7: =IF(B7="","",IFERROR(INDEX('2.현장'!$C$2:$C$1001,IFERROR(MATCH(B7&"|설계사",'2.현장'!$Z$2:$Z$1001,0),IFERROR(MATCH(B7&"|시공사",'2.현장'!$Z$2:$Z$1001,0),MATCH(B7&"|늦음",'2.현장'!$Z$2:$Z$1001,0)))),"")) | I7: =IF(B7="","",IFERROR(INDEX('2.현장'!$N$2:$N$1001,IFERROR(MATCH(B7&"|설계사",'2.현장'!$Z$2:$Z$1001,0),IFERROR(MATCH(B7&"|시공사",'2.현장'!$Z$2:$Z$1001,0),MATCH(B7&"|늦음",'2.현장'!$Z$2:$Z$1001,0)))),"")) | J7: =IF(B7="","",IFERROR(VLOOKUP(B7,설계사_메모!$A$3:$G$302,2,FALSE)&"","")) | K7: =IF(B7="","",IFERROR(VLOOKUP(B7,설계사_메모!$A$3:$G$302,4,FALSE)&"","")) | L7: =IF(B7="","",IF(COUNTIF('4.방문기록'!$B$3:$B$502,B7)=0,"",_xlfn.MAXIFS('4.방문기록'!$A$3:$A$502,'4.방문기록'!$B$3:$B$502,B7))) | M7: =IF(L7="","",설정!$B$24-L7) | N7: =IF(B7="","",IF(_xlfn.MAXIFS('4.방문기록'!$F$3:$F$502,'4.방문기록'!$B$3:$B$502,B7)=0,"",_xlfn.MAXIFS('4.방문기록'!$F$3:$F$502,'4.방문기록'!$B$3:$B$502,B7))) | O7: =IF(L7="","",IFERROR(INDEX('4.방문기록'!$H$3:$H$502,MATCH(B7&"|"&(L7*1),'4.방문기록'!$I$3:$I$502,0))&"","")) | P7: =IF(B7="","",IF(O7="관심 없음","제외",IF(L7="","안 가봄",IF(M7>=설정!$B$20,M7&"일 지남","최근 방문")))) | Q7: =IF(B7="","",IF(P7="제외","",IF(AND(설정!$B$21<>"",I7<>설정!$B$21),"",IF(AND(N7<>"",N7>N(L7),N7<=설정!$B$24+7),100+7-(N7-설정!$B$24),IF(AND(D7>0,OR(P7="안 가봄",RIGHT(P7,2)="지남")),D7*10+IF(L7="",30,MIN(M7,60)/2)+MIN(N(F7)/1000,20),""))))) | R7: =IF(Q7="","",COUNTIF(Q$4:Q$303,">"&Q7)+COUNTIF(Q$4:Q7,Q7))
A8: =IF(B8="","",5) | B8: =IFERROR(INDEX('2.현장'!$V$2:$V$1001,MATCH(5,'2.현장'!$W$2:$W$1001,0)),"") | C8: =IF(B8="","",COUNTIFS('2.현장'!$V$2:$V$1001,B8,'2.현장'!$T$2:$T$1001,TRUE)) | D8: =IF(B8="","",COUNTIFS('2.현장'!$V$2:$V$1001,B8,'2.현장'!$U$2:$U$1001,"설계사")) | E8: =IF(B8="","",COUNTIFS('2.현장'!$V$2:$V$1001,B8,'2.현장'!$U$2:$U$1001,"시공사")) | F8: =IF(B8="","",_xlfn.MAXIFS('2.현장'!$D$2:$D$1001,'2.현장'!$V$2:$V$1001,B8,'2.현장'!$T$2:$T$1001,TRUE)) | G8: =IF(B8="","",IF(_xlfn.MAXIFS('2.현장'!$L$2:$L$1001,'2.현장'!$V$2:$V$1001,B8,'2.현장'!$T$2:$T$1001,TRUE)=0,"",_xlfn.MAXIFS('2.현장'!$L$2:$L$1001,'2.현장'!$V$2:$V$1001,B8,'2.현장'!$T$2:$T$1001,TRUE))) | H8: =IF(B8="","",IFERROR(INDEX('2.현장'!$C$2:$C$1001,IFERROR(MATCH(B8&"|설계사",'2.현장'!$Z$2:$Z$1001,0),IFERROR(MATCH(B8&"|시공사",'2.현장'!$Z$2:$Z$1001,0),MATCH(B8&"|늦음",'2.현장'!$Z$2:$Z$1001,0)))),"")) | I8: =IF(B8="","",IFERROR(INDEX('2.현장'!$N$2:$N$1001,IFERROR(MATCH(B8&"|설계사",'2.현장'!$Z$2:$Z$1001,0),IFERROR(MATCH(B8&"|시공사",'2.현장'!$Z$2:$Z$1001,0),MATCH(B8&"|늦음",'2.현장'!$Z$2:$Z$1001,0)))),"")) | J8: =IF(B8="","",IFERROR(VLOOKUP(B8,설계사_메모!$A$3:$G$302,2,FALSE)&"","")) | K8: =IF(B8="","",IFERROR(VLOOKUP(B8,설계사_메모!$A$3:$G$302,4,FALSE)&"","")) | L8: =IF(B8="","",IF(COUNTIF('4.방문기록'!$B$3:$B$502,B8)=0,"",_xlfn.MAXIFS('4.방문기록'!$A$3:$A$502,'4.방문기록'!$B$3:$B$502,B8))) | M8: =IF(L8="","",설정!$B$24-L8) | N8: =IF(B8="","",IF(_xlfn.MAXIFS('4.방문기록'!$F$3:$F$502,'4.방문기록'!$B$3:$B$502,B8)=0,"",_xlfn.MAXIFS('4.방문기록'!$F$3:$F$502,'4.방문기록'!$B$3:$B$502,B8))) | O8: =IF(L8="","",IFERROR(INDEX('4.방문기록'!$H$3:$H$502,MATCH(B8&"|"&(L8*1),'4.방문기록'!$I$3:$I$502,0))&"","")) | P8: =IF(B8="","",IF(O8="관심 없음","제외",IF(L8="","안 가봄",IF(M8>=설정!$B$20,M8&"일 지남","최근 방문")))) | Q8: =IF(B8="","",IF(P8="제외","",IF(AND(설정!$B$21<>"",I8<>설정!$B$21),"",IF(AND(N8<>"",N8>N(L8),N8<=설정!$B$24+7),100+7-(N8-설정!$B$24),IF(AND(D8>0,OR(P8="안 가봄",RIGHT(P8,2)="지남")),D8*10+IF(L8="",30,MIN(M8,60)/2)+MIN(N(F8)/1000,20),""))))) | R8: =IF(Q8="","",COUNTIF(Q$4:Q$303,">"&Q8)+COUNTIF(Q$4:Q8,Q8))
A9: =IF(B9="","",6) | B9: =IFERROR(INDEX('2.현장'!$V$2:$V$1001,MATCH(6,'2.현장'!$W$2:$W$1001,0)),"") | C9: =IF(B9="","",COUNTIFS('2.현장'!$V$2:$V$1001,B9,'2.현장'!$T$2:$T$1001,TRUE)) | D9: =IF(B9="","",COUNTIFS('2.현장'!$V$2:$V$1001,B9,'2.현장'!$U$2:$U$1001,"설계사")) | E9: =IF(B9="","",COUNTIFS('2.현장'!$V$2:$V$1001,B9,'2.현장'!$U$2:$U$1001,"시공사")) | F9: =IF(B9="","",_xlfn.MAXIFS('2.현장'!$D$2:$D$1001,'2.현장'!$V$2:$V$1001,B9,'2.현장'!$T$2:$T$1001,TRUE)) | G9: =IF(B9="","",IF(_xlfn.MAXIFS('2.현장'!$L$2:$L$1001,'2.현장'!$V$2:$V$1001,B9,'2.현장'!$T$2:$T$1001,TRUE)=0,"",_xlfn.MAXIFS('2.현장'!$L$2:$L$1001,'2.현장'!$V$2:$V$1001,B9,'2.현장'!$T$2:$T$1001,TRUE))) | H9: =IF(B9="","",IFERROR(INDEX('2.현장'!$C$2:$C$1001,IFERROR(MATCH(B9&"|설계사",'2.현장'!$Z$2:$Z$1001,0),IFERROR(MATCH(B9&"|시공사",'2.현장'!$Z$2:$Z$1001,0),MATCH(B9&"|늦음",'2.현장'!$Z$2:$Z$1001,0)))),"")) | I9: =IF(B9="","",IFERROR(INDEX('2.현장'!$N$2:$N$1001,IFERROR(MATCH(B9&"|설계사",'2.현장'!$Z$2:$Z$1001,0),IFERROR(MATCH(B9&"|시공사",'2.현장'!$Z$2:$Z$1001,0),MATCH(B9&"|늦음",'2.현장'!$Z$2:$Z$1001,0)))),"")) | J9: =IF(B9="","",IFERROR(VLOOKUP(B9,설계사_메모!$A$3:$G$302,2,FALSE)&"","")) | K9: =IF(B9="","",IFERROR(VLOOKUP(B9,설계사_메모!$A$3:$G$302,4,FALSE)&"","")) | L9: =IF(B9="","",IF(COUNTIF('4.방문기록'!$B$3:$B$502,B9)=0,"",_xlfn.MAXIFS('4.방문기록'!$A$3:$A$502,'4.방문기록'!$B$3:$B$502,B9))) | M9: =IF(L9="","",설정!$B$24-L9) | N9: =IF(B9="","",IF(_xlfn.MAXIFS('4.방문기록'!$F$3:$F$502,'4.방문기록'!$B$3:$B$502,B9)=0,"",_xlfn.MAXIFS('4.방문기록'!$F$3:$F$502,'4.방문기록'!$B$3:$B$502,B9))) | O9: =IF(L9="","",IFERROR(INDEX('4.방문기록'!$H$3:$H$502,MATCH(B9&"|"&(L9*1),'4.방문기록'!$I$3:$I$502,0))&"","")) | P9: =IF(B9="","",IF(O9="관심 없음","제외",IF(L9="","안 가봄",IF(M9>=설정!$B$20,M9&"일 지남","최근 방문")))) | Q9: =IF(B9="","",IF(P9="제외","",IF(AND(설정!$B$21<>"",I9<>설정!$B$21),"",IF(AND(N9<>"",N9>N(L9),N9<=설정!$B$24+7),100+7-(N9-설정!$B$24),IF(AND(D9>0,OR(P9="안 가봄",RIGHT(P9,2)="지남")),D9*10+IF(L9="",30,MIN(M9,60)/2)+MIN(N(F9)/1000,20),""))))) | R9: =IF(Q9="","",COUNTIF(Q$4:Q$303,">"&Q9)+COUNTIF(Q$4:Q9,Q9))
A10: =IF(B10="","",7) | B10: =IFERROR(INDEX('2.현장'!$V$2:$V$1001,MATCH(7,'2.현장'!$W$2:$W$1001,0)),"") | C10: =IF(B10="","",COUNTIFS('2.현장'!$V$2:$V$1001,B10,'2.현장'!$T$2:$T$1001,TRUE)) | D10: =IF(B10="","",COUNTIFS('2.현장'!$V$2:$V$1001,B10,'2.현장'!$U$2:$U$1001,"설계사")) | E10: =IF(B10="","",COUNTIFS('2.현장'!$V$2:$V$1001,B10,'2.현장'!$U$2:$U$1001,"시공사")) | F10: =IF(B10="","",_xlfn.MAXIFS('2.현장'!$D$2:$D$1001,'2.현장'!$V$2:$V$1001,B10,'2.현장'!$T$2:$T$1001,TRUE)) | G10: =IF(B10="","",IF(_xlfn.MAXIFS('2.현장'!$L$2:$L$1001,'2.현장'!$V$2:$V$1001,B10,'2.현장'!$T$2:$T$1001,TRUE)=0,"",_xlfn.MAXIFS('2.현장'!$L$2:$L$1001,'2.현장'!$V$2:$V$1001,B10,'2.현장'!$T$2:$T$1001,TRUE))) | H10: =IF(B10="","",IFERROR(INDEX('2.현장'!$C$2:$C$1001,IFERROR(MATCH(B10&"|설계사",'2.현장'!$Z$2:$Z$1001,0),IFERROR(MATCH(B10&"|시공사",'2.현장'!$Z$2:$Z$1001,0),MATCH(B10&"|늦음",'2.현장'!$Z$2:$Z$1001,0)))),"")) | I10: =IF(B10="","",IFERROR(INDEX('2.현장'!$N$2:$N$1001,IFERROR(MATCH(B10&"|설계사",'2.현장'!$Z$2:$Z$1001,0),IFERROR(MATCH(B10&"|시공사",'2.현장'!$Z$2:$Z$1001,0),MATCH(B10&"|늦음",'2.현장'!$Z$2:$Z$1001,0)))),"")) | J10: =IF(B10="","",IFERROR(VLOOKUP(B10,설계사_메모!$A$3:$G$302,2,FALSE)&"","")) | K10: =IF(B10="","",IFERROR(VLOOKUP(B10,설계사_메모!$A$3:$G$302,4,FALSE)&"","")) | L10: =IF(B10="","",IF(COUNTIF('4.방문기록'!$B$3:$B$502,B10)=0,"",_xlfn.MAXIFS('4.방문기록'!$A$3:$A$502,'4.방문기록'!$B$3:$B$502,B10))) | M10: =IF(L10="","",설정!$B$24-L10) | N10: =IF(B10="","",IF(_xlfn.MAXIFS('4.방문기록'!$F$3:$F$502,'4.방문기록'!$B$3:$B$502,B10)=0,"",_xlfn.MAXIFS('4.방문기록'!$F$3:$F$502,'4.방문기록'!$B$3:$B$502,B10))) | O10: =IF(L10="","",IFERROR(INDEX('4.방문기록'!$H$3:$H$502,MATCH(B10&"|"&(L10*1),'4.방문기록'!$I$3:$I$502,0))&"","")) | P10: =IF(B10="","",IF(O10="관심 없음","제외",IF(L10="","안 가봄",IF(M10>=설정!$B$20,M10&"일 지남","최근 방문")))) | Q10: =IF(B10="","",IF(P10="제외","",IF(AND(설정!$B$21<>"",I10<>설정!$B$21),"",IF(AND(N10<>"",N10>N(L10),N10<=설정!$B$24+7),100+7-(N10-설정!$B$24),IF(AND(D10>0,OR(P10="안 가봄",RIGHT(P10,2)="지남")),D10*10+IF(L10="",30,MIN(M10,60)/2)+MIN(N(F10)/1000,20),""))))) | R10: =IF(Q10="","",COUNTIF(Q$4:Q$303,">"&Q10)+COUNTIF(Q$4:Q10,Q10))
A11: =IF(B11="","",8) | B11: =IFERROR(INDEX('2.현장'!$V$2:$V$1001,MATCH(8,'2.현장'!$W$2:$W$1001,0)),"") | C11: =IF(B11="","",COUNTIFS('2.현장'!$V$2:$V$1001,B11,'2.현장'!$T$2:$T$1001,TRUE)) | D11: =IF(B11="","",COUNTIFS('2.현장'!$V$2:$V$1001,B11,'2.현장'!$U$2:$U$1001,"설계사")) | E11: =IF(B11="","",COUNTIFS('2.현장'!$V$2:$V$1001,B11,'2.현장'!$U$2:$U$1001,"시공사")) | F11: =IF(B11="","",_xlfn.MAXIFS('2.현장'!$D$2:$D$1001,'2.현장'!$V$2:$V$1001,B11,'2.현장'!$T$2:$T$1001,TRUE)) | G11: =IF(B11="","",IF(_xlfn.MAXIFS('2.현장'!$L$2:$L$1001,'2.현장'!$V$2:$V$1001,B11,'2.현장'!$T$2:$T$1001,TRUE)=0,"",_xlfn.MAXIFS('2.현장'!$L$2:$L$1001,'2.현장'!$V$2:$V$1001,B11,'2.현장'!$T$2:$T$1001,TRUE))) | H11: =IF(B11="","",IFERROR(INDEX('2.현장'!$C$2:$C$1001,IFERROR(MATCH(B11&"|설계사",'2.현장'!$Z$2:$Z$1001,0),IFERROR(MATCH(B11&"|시공사",'2.현장'!$Z$2:$Z$1001,0),MATCH(B11&"|늦음",'2.현장'!$Z$2:$Z$1001,0)))),"")) | I11: =IF(B11="","",IFERROR(INDEX('2.현장'!$N$2:$N$1001,IFERROR(MATCH(B11&"|설계사",'2.현장'!$Z$2:$Z$1001,0),IFERROR(MATCH(B11&"|시공사",'2.현장'!$Z$2:$Z$1001,0),MATCH(B11&"|늦음",'2.현장'!$Z$2:$Z$1001,0)))),"")) | J11: =IF(B11="","",IFERROR(VLOOKUP(B11,설계사_메모!$A$3:$G$302,2,FALSE)&"","")) | K11: =IF(B11="","",IFERROR(VLOOKUP(B11,설계사_메모!$A$3:$G$302,4,FALSE)&"","")) | L11: =IF(B11="","",IF(COUNTIF('4.방문기록'!$B$3:$B$502,B11)=0,"",_xlfn.MAXIFS('4.방문기록'!$A$3:$A$502,'4.방문기록'!$B$3:$B$502,B11))) | M11: =IF(L11="","",설정!$B$24-L11) | N11: =IF(B11="","",IF(_xlfn.MAXIFS('4.방문기록'!$F$3:$F$502,'4.방문기록'!$B$3:$B$502,B11)=0,"",_xlfn.MAXIFS('4.방문기록'!$F$3:$F$502,'4.방문기록'!$B$3:$B$502,B11))) | O11: =IF(L11="","",IFERROR(INDEX('4.방문기록'!$H$3:$H$502,MATCH(B11&"|"&(L11*1),'4.방문기록'!$I$3:$I$502,0))&"","")) | P11: =IF(B11="","",IF(O11="관심 없음","제외",IF(L11="","안 가봄",IF(M11>=설정!$B$20,M11&"일 지남","최근 방문")))) | Q11: =IF(B11="","",IF(P11="제외","",IF(AND(설정!$B$21<>"",I11<>설정!$B$21),"",IF(AND(N11<>"",N11>N(L11),N11<=설정!$B$24+7),100+7-(N11-설정!$B$24),IF(AND(D11>0,OR(P11="안 가봄",RIGHT(P11,2)="지남")),D11*10+IF(L11="",30,MIN(M11,60)/2)+MIN(N(F11)/1000,20),""))))) | R11: =IF(Q11="","",COUNTIF(Q$4:Q$303,">"&Q11)+COUNTIF(Q$4:Q11,Q11))
A12: =IF(B12="","",9) | B12: =IFERROR(INDEX('2.현장'!$V$2:$V$1001,MATCH(9,'2.현장'!$W$2:$W$1001,0)),"") | C12: =IF(B12="","",COUNTIFS('2.현장'!$V$2:$V$1001,B12,'2.현장'!$T$2:$T$1001,TRUE)) | D12: =IF(B12="","",COUNTIFS('2.현장'!$V$2:$V$1001,B12,'2.현장'!$U$2:$U$1001,"설계사")) | E12: =IF(B12="","",COUNTIFS('2.현장'!$V$2:$V$1001,B12,'2.현장'!$U$2:$U$1001,"시공사")) | F12: =IF(B12="","",_xlfn.MAXIFS('2.현장'!$D$2:$D$1001,'2.현장'!$V$2:$V$1001,B12,'2.현장'!$T$2:$T$1001,TRUE)) | G12: =IF(B12="","",IF(_xlfn.MAXIFS('2.현장'!$L$2:$L$1001,'2.현장'!$V$2:$V$1001,B12,'2.현장'!$T$2:$T$1001,TRUE)=0,"",_xlfn.MAXIFS('2.현장'!$L$2:$L$1001,'2.현장'!$V$2:$V$1001,B12,'2.현장'!$T$2:$T$1001,TRUE))) | H12: =IF(B12="","",IFERROR(INDEX('2.현장'!$C$2:$C$1001,IFERROR(MATCH(B12&"|설계사",'2.현장'!$Z$2:$Z$1001,0),IFERROR(MATCH(B12&"|시공사",'2.현장'!$Z$2:$Z$1001,0),MATCH(B12&"|늦음",'2.현장'!$Z$2:$Z$1001,0)))),"")) | I12: =IF(B12="","",IFERROR(INDEX('2.현장'!$N$2:$N$1001,IFERROR(MATCH(B12&"|설계사",'2.현장'!$Z$2:$Z$1001,0),IFERROR(MATCH(B12&"|시공사",'2.현장'!$Z$2:$Z$1001,0),MATCH(B12&"|늦음",'2.현장'!$Z$2:$Z$1001,0)))),"")) | J12: =IF(B12="","",IFERROR(VLOOKUP(B12,설계사_메모!$A$3:$G$302,2,FALSE)&"","")) | K12: =IF(B12="","",IFERROR(VLOOKUP(B12,설계사_메모!$A$3:$G$302,4,FALSE)&"","")) | L12: =IF(B12="","",IF(COUNTIF('4.방문기록'!$B$3:$B$502,B12)=0,"",_xlfn.MAXIFS('4.방문기록'!$A$3:$A$502,'4.방문기록'!$B$3:$B$502,B12))) | M12: =IF(L12="","",설정!$B$24-L12) | N12: =IF(B12="","",IF(_xlfn.MAXIFS('4.방문기록'!$F$3:$F$502,'4.방문기록'!$B$3:$B$502,B12)=0,"",_xlfn.MAXIFS('4.방문기록'!$F$3:$F$502,'4.방문기록'!$B$3:$B$502,B12))) | O12: =IF(L12="","",IFERROR(INDEX('4.방문기록'!$H$3:$H$502,MATCH(B12&"|"&(L12*1),'4.방문기록'!$I$3:$I$502,0))&"","")) | P12: =IF(B12="","",IF(O12="관심 없음","제외",IF(L12="","안 가봄",IF(M12>=설정!$B$20,M12&"일 지남","최근 방문")))) | Q12: =IF(B12="","",IF(P12="제외","",IF(AND(설정!$B$21<>"",I12<>설정!$B$21),"",IF(AND(N12<>"",N12>N(L12),N12<=설정!$B$24+7),100+7-(N12-설정!$B$24),IF(AND(D12>0,OR(P12="안 가봄",RIGHT(P12,2)="지남")),D12*10+IF(L12="",30,MIN(M12,60)/2)+MIN(N(F12)/1000,20),""))))) | R12: =IF(Q12="","",COUNTIF(Q$4:Q$303,">"&Q12)+COUNTIF(Q$4:Q12,Q12))
A13: =IF(B13="","",10) | B13: =IFERROR(INDEX('2.현장'!$V$2:$V$1001,MATCH(10,'2.현장'!$W$2:$W$1001,0)),"") | C13: =IF(B13="","",COUNTIFS('2.현장'!$V$2:$V$1001,B13,'2.현장'!$T$2:$T$1001,TRUE)) | D13: =IF(B13="","",COUNTIFS('2.현장'!$V$2:$V$1001,B13,'2.현장'!$U$2:$U$1001,"설계사")) | E13: =IF(B13="","",COUNTIFS('2.현장'!$V$2:$V$1001,B13,'2.현장'!$U$2:$U$1001,"시공사")) | F13: =IF(B13="","",_xlfn.MAXIFS('2.현장'!$D$2:$D$1001,'2.현장'!$V$2:$V$1001,B13,'2.현장'!$T$2:$T$1001,TRUE)) | G13: =IF(B13="","",IF(_xlfn.MAXIFS('2.현장'!$L$2:$L$1001,'2.현장'!$V$2:$V$1001,B13,'2.현장'!$T$2:$T$1001,TRUE)=0,"",_xlfn.MAXIFS('2.현장'!$L$2:$L$1001,'2.현장'!$V$2:$V$1001,B13,'2.현장'!$T$2:$T$1001,TRUE))) | H13: =IF(B13="","",IFERROR(INDEX('2.현장'!$C$2:$C$1001,IFERROR(MATCH(B13&"|설계사",'2.현장'!$Z$2:$Z$1001,0),IFERROR(MATCH(B13&"|시공사",'2.현장'!$Z$2:$Z$1001,0),MATCH(B13&"|늦음",'2.현장'!$Z$2:$Z$1001,0)))),"")) | I13: =IF(B13="","",IFERROR(INDEX('2.현장'!$N$2:$N$1001,IFERROR(MATCH(B13&"|설계사",'2.현장'!$Z$2:$Z$1001,0),IFERROR(MATCH(B13&"|시공사",'2.현장'!$Z$2:$Z$1001,0),MATCH(B13&"|늦음",'2.현장'!$Z$2:$Z$1001,0)))),"")) | J13: =IF(B13="","",IFERROR(VLOOKUP(B13,설계사_메모!$A$3:$G$302,2,FALSE)&"","")) | K13: =IF(B13="","",IFERROR(VLOOKUP(B13,설계사_메모!$A$3:$G$302,4,FALSE)&"","")) | L13: =IF(B13="","",IF(COUNTIF('4.방문기록'!$B$3:$B$502,B13)=0,"",_xlfn.MAXIFS('4.방문기록'!$A$3:$A$502,'4.방문기록'!$B$3:$B$502,B13))) | M13: =IF(L13="","",설정!$B$24-L13) | N13: =IF(B13="","",IF(_xlfn.MAXIFS('4.방문기록'!$F$3:$F$502,'4.방문기록'!$B$3:$B$502,B13)=0,"",_xlfn.MAXIFS('4.방문기록'!$F$3:$F$502,'4.방문기록'!$B$3:$B$502,B13))) | O13: =IF(L13="","",IFERROR(INDEX('4.방문기록'!$H$3:$H$502,MATCH(B13&"|"&(L13*1),'4.방문기록'!$I$3:$I$502,0))&"","")) | P13: =IF(B13="","",IF(O13="관심 없음","제외",IF(L13="","안 가봄",IF(M13>=설정!$B$20,M13&"일 지남","최근 방문")))) | Q13: =IF(B13="","",IF(P13="제외","",IF(AND(설정!$B$21<>"",I13<>설정!$B$21),"",IF(AND(N13<>"",N13>N(L13),N13<=설정!$B$24+7),100+7-(N13-설정!$B$24),IF(AND(D13>0,OR(P13="안 가봄",RIGHT(P13,2)="지남")),D13*10+IF(L13="",30,MIN(M13,60)/2)+MIN(N(F13)/1000,20),""))))) | R13: =IF(Q13="","",COUNTIF(Q$4:Q$303,">"&Q13)+COUNTIF(Q$4:Q13,Q13))
A14: =IF(B14="","",11) | B14: =IFERROR(INDEX('2.현장'!$V$2:$V$1001,MATCH(11,'2.현장'!$W$2:$W$1001,0)),"") | C14: =IF(B14="","",COUNTIFS('2.현장'!$V$2:$V$1001,B14,'2.현장'!$T$2:$T$1001,TRUE)) | D14: =IF(B14="","",COUNTIFS('2.현장'!$V$2:$V$1001,B14,'2.현장'!$U$2:$U$1001,"설계사")) | E14: =IF(B14="","",COUNTIFS('2.현장'!$V$2:$V$1001,B14,'2.현장'!$U$2:$U$1001,"시공사")) | F14: =IF(B14="","",_xlfn.MAXIFS('2.현장'!$D$2:$D$1001,'2.현장'!$V$2:$V$1001,B14,'2.현장'!$T$2:$T$1001,TRUE)) | G14: =IF(B14="","",IF(_xlfn.MAXIFS('2.현장'!$L$2:$L$1001,'2.현장'!$V$2:$V$1001,B14,'2.현장'!$T$2:$T$1001,TRUE)=0,"",_xlfn.MAXIFS('2.현장'!$L$2:$L$1001,'2.현장'!$V$2:$V$1001,B14,'2.현장'!$T$2:$T$1001,TRUE))) | H14: =IF(B14="","",IFERROR(INDEX('2.현장'!$C$2:$C$1001,IFERROR(MATCH(B14&"|설계사",'2.현장'!$Z$2:$Z$1001,0),IFERROR(MATCH(B14&"|시공사",'2.현장'!$Z$2:$Z$1001,0),MATCH(B14&"|늦음",'2.현장'!$Z$2:$Z$1001,0)))),"")) | I14: =IF(B14="","",IFERROR(INDEX('2.현장'!$N$2:$N$1001,IFERROR(MATCH(B14&"|설계사",'2.현장'!$Z$2:$Z$1001,0),IFERROR(MATCH(B14&"|시공사",'2.현장'!$Z$2:$Z$1001,0),MATCH(B14&"|늦음",'2.현장'!$Z$2:$Z$1001,0)))),"")) | J14: =IF(B14="","",IFERROR(VLOOKUP(B14,설계사_메모!$A$3:$G$302,2,FALSE)&"","")) | K14: =IF(B14="","",IFERROR(VLOOKUP(B14,설계사_메모!$A$3:$G$302,4,FALSE)&"","")) | L14: =IF(B14="","",IF(COUNTIF('4.방문기록'!$B$3:$B$502,B14)=0,"",_xlfn.MAXIFS('4.방문기록'!$A$3:$A$502,'4.방문기록'!$B$3:$B$502,B14))) | M14: =IF(L14="","",설정!$B$24-L14) | N14: =IF(B14="","",IF(_xlfn.MAXIFS('4.방문기록'!$F$3:$F$502,'4.방문기록'!$B$3:$B$502,B14)=0,"",_xlfn.MAXIFS('4.방문기록'!$F$3:$F$502,'4.방문기록'!$B$3:$B$502,B14))) | O14: =IF(L14="","",IFERROR(INDEX('4.방문기록'!$H$3:$H$502,MATCH(B14&"|"&(L14*1),'4.방문기록'!$I$3:$I$502,0))&"","")) | P14: =IF(B14="","",IF(O14="관심 없음","제외",IF(L14="","안 가봄",IF(M14>=설정!$B$20,M14&"일 지남","최근 방문")))) | Q14: =IF(B14="","",IF(P14="제외","",IF(AND(설정!$B$21<>"",I14<>설정!$B$21),"",IF(AND(N14<>"",N14>N(L14),N14<=설정!$B$24+7),100+7-(N14-설정!$B$24),IF(AND(D14>0,OR(P14="안 가봄",RIGHT(P14,2)="지남")),D14*10+IF(L14="",30,MIN(M14,60)/2)+MIN(N(F14)/1000,20),""))))) | R14: =IF(Q14="","",COUNTIF(Q$4:Q$303,">"&Q14)+COUNTIF(Q$4:Q14,Q14))
A15: =IF(B15="","",12) | B15: =IFERROR(INDEX('2.현장'!$V$2:$V$1001,MATCH(12,'2.현장'!$W$2:$W$1001,0)),"") | C15: =IF(B15="","",COUNTIFS('2.현장'!$V$2:$V$1001,B15,'2.현장'!$T$2:$T$1001,TRUE)) | D15: =IF(B15="","",COUNTIFS('2.현장'!$V$2:$V$1001,B15,'2.현장'!$U$2:$U$1001,"설계사")) | E15: =IF(B15="","",COUNTIFS('2.현장'!$V$2:$V$1001,B15,'2.현장'!$U$2:$U$1001,"시공사")) | F15: =IF(B15="","",_xlfn.MAXIFS('2.현장'!$D$2:$D$1001,'2.현장'!$V$2:$V$1001,B15,'2.현장'!$T$2:$T$1001,TRUE)) | G15: =IF(B15="","",IF(_xlfn.MAXIFS('2.현장'!$L$2:$L$1001,'2.현장'!$V$2:$V$1001,B15,'2.현장'!$T$2:$T$1001,TRUE)=0,"",_xlfn.MAXIFS('2.현장'!$L$2:$L$1001,'2.현장'!$V$2:$V$1001,B15,'2.현장'!$T$2:$T$1001,TRUE))) | H15: =IF(B15="","",IFERROR(INDEX('2.현장'!$C$2:$C$1001,IFERROR(MATCH(B15&"|설계사",'2.현장'!$Z$2:$Z$1001,0),IFERROR(MATCH(B15&"|시공사",'2.현장'!$Z$2:$Z$1001,0),MATCH(B15&"|늦음",'2.현장'!$Z$2:$Z$1001,0)))),"")) | I15: =IF(B15="","",IFERROR(INDEX('2.현장'!$N$2:$N$1001,IFERROR(MATCH(B15&"|설계사",'2.현장'!$Z$2:$Z$1001,0),IFERROR(MATCH(B15&"|시공사",'2.현장'!$Z$2:$Z$1001,0),MATCH(B15&"|늦음",'2.현장'!$Z$2:$Z$1001,0)))),"")) | J15: =IF(B15="","",IFERROR(VLOOKUP(B15,설계사_메모!$A$3:$G$302,2,FALSE)&"","")) | K15: =IF(B15="","",IFERROR(VLOOKUP(B15,설계사_메모!$A$3:$G$302,4,FALSE)&"","")) | L15: =IF(B15="","",IF(COUNTIF('4.방문기록'!$B$3:$B$502,B15)=0,"",_xlfn.MAXIFS('4.방문기록'!$A$3:$A$502,'4.방문기록'!$B$3:$B$502,B15))) | M15: =IF(L15="","",설정!$B$24-L15) | N15: =IF(B15="","",IF(_xlfn.MAXIFS('4.방문기록'!$F$3:$F$502,'4.방문기록'!$B$3:$B$502,B15)=0,"",_xlfn.MAXIFS('4.방문기록'!$F$3:$F$502,'4.방문기록'!$B$3:$B$502,B15))) | O15: =IF(L15="","",IFERROR(INDEX('4.방문기록'!$H$3:$H$502,MATCH(B15&"|"&(L15*1),'4.방문기록'!$I$3:$I$502,0))&"","")) | P15: =IF(B15="","",IF(O15="관심 없음","제외",IF(L15="","안 가봄",IF(M15>=설정!$B$20,M15&"일 지남","최근 방문")))) | Q15: =IF(B15="","",IF(P15="제외","",IF(AND(설정!$B$21<>"",I15<>설정!$B$21),"",IF(AND(N15<>"",N15>N(L15),N15<=설정!$B$24+7),100+7-(N15-설정!$B$24),IF(AND(D15>0,OR(P15="안 가봄",RIGHT(P15,2)="지남")),D15*10+IF(L15="",30,MIN(M15,60)/2)+MIN(N(F15)/1000,20),""))))) | R15: =IF(Q15="","",COUNTIF(Q$4:Q$303,">"&Q15)+COUNTIF(Q$4:Q15,Q15))
A16: =IF(B16="","",13) | B16: =IFERROR(INDEX('2.현장'!$V$2:$V$1001,MATCH(13,'2.현장'!$W$2:$W$1001,0)),"") | C16: =IF(B16="","",COUNTIFS('2.현장'!$V$2:$V$1001,B16,'2.현장'!$T$2:$T$1001,TRUE)) | D16: =IF(B16="","",COUNTIFS('2.현장'!$V$2:$V$1001,B16,'2.현장'!$U$2:$U$1001,"설계사")) | E16: =IF(B16="","",COUNTIFS('2.현장'!$V$2:$V$1001,B16,'2.현장'!$U$2:$U$1001,"시공사")) | F16: =IF(B16="","",_xlfn.MAXIFS('2.현장'!$D$2:$D$1001,'2.현장'!$V$2:$V$1001,B16,'2.현장'!$T$2:$T$1001,TRUE)) | G16: =IF(B16="","",IF(_xlfn.MAXIFS('2.현장'!$L$2:$L$1001,'2.현장'!$V$2:$V$1001,B16,'2.현장'!$T$2:$T$1001,TRUE)=0,"",_xlfn.MAXIFS('2.현장'!$L$2:$L$1001,'2.현장'!$V$2:$V$1001,B16,'2.현장'!$T$2:$T$1001,TRUE))) | H16: =IF(B16="","",IFERROR(INDEX('2.현장'!$C$2:$C$1001,IFERROR(MATCH(B16&"|설계사",'2.현장'!$Z$2:$Z$1001,0),IFERROR(MATCH(B16&"|시공사",'2.현장'!$Z$2:$Z$1001,0),MATCH(B16&"|늦음",'2.현장'!$Z$2:$Z$1001,0)))),"")) | I16: =IF(B16="","",IFERROR(INDEX('2.현장'!$N$2:$N$1001,IFERROR(MATCH(B16&"|설계사",'2.현장'!$Z$2:$Z$1001,0),IFERROR(MATCH(B16&"|시공사",'2.현장'!$Z$2:$Z$1001,0),MATCH(B16&"|늦음",'2.현장'!$Z$2:$Z$1001,0)))),"")) | J16: =IF(B16="","",IFERROR(VLOOKUP(B16,설계사_메모!$A$3:$G$302,2,FALSE)&"","")) | K16: =IF(B16="","",IFERROR(VLOOKUP(B16,설계사_메모!$A$3:$G$302,4,FALSE)&"","")) | L16: =IF(B16="","",IF(COUNTIF('4.방문기록'!$B$3:$B$502,B16)=0,"",_xlfn.MAXIFS('4.방문기록'!$A$3:$A$502,'4.방문기록'!$B$3:$B$502,B16))) | M16: =IF(L16="","",설정!$B$24-L16) | N16: =IF(B16="","",IF(_xlfn.MAXIFS('4.방문기록'!$F$3:$F$502,'4.방문기록'!$B$3:$B$502,B16)=0,"",_xlfn.MAXIFS('4.방문기록'!$F$3:$F$502,'4.방문기록'!$B$3:$B$502,B16))) | O16: =IF(L16="","",IFERROR(INDEX('4.방문기록'!$H$3:$H$502,MATCH(B16&"|"&(L16*1),'4.방문기록'!$I$3:$I$502,0))&"","")) | P16: =IF(B16="","",IF(O16="관심 없음","제외",IF(L16="","안 가봄",IF(M16>=설정!$B$20,M16&"일 지남","최근 방문")))) | Q16: =IF(B16="","",IF(P16="제외","",IF(AND(설정!$B$21<>"",I16<>설정!$B$21),"",IF(AND(N16<>"",N16>N(L16),N16<=설정!$B$24+7),100+7-(N16-설정!$B$24),IF(AND(D16>0,OR(P16="안 가봄",RIGHT(P16,2)="지남")),D16*10+IF(L16="",30,MIN(M16,60)/2)+MIN(N(F16)/1000,20),""))))) | R16: =IF(Q16="","",COUNTIF(Q$4:Q$303,">"&Q16)+COUNTIF(Q$4:Q16,Q16))
A17: =IF(B17="","",14) | B17: =IFERROR(INDEX('2.현장'!$V$2:$V$1001,MATCH(14,'2.현장'!$W$2:$W$1001,0)),"") | C17: =IF(B17="","",COUNTIFS('2.현장'!$V$2:$V$1001,B17,'2.현장'!$T$2:$T$1001,TRUE)) | D17: =IF(B17="","",COUNTIFS('2.현장'!$V$2:$V$1001,B17,'2.현장'!$U$2:$U$1001,"설계사")) | E17: =IF(B17="","",COUNTIFS('2.현장'!$V$2:$V$1001,B17,'2.현장'!$U$2:$U$1001,"시공사")) | F17: =IF(B17="","",_xlfn.MAXIFS('2.현장'!$D$2:$D$1001,'2.현장'!$V$2:$V$1001,B17,'2.현장'!$T$2:$T$1001,TRUE)) | G17: =IF(B17="","",IF(_xlfn.MAXIFS('2.현장'!$L$2:$L$1001,'2.현장'!$V$2:$V$1001,B17,'2.현장'!$T$2:$T$1001,TRUE)=0,"",_xlfn.MAXIFS('2.현장'!$L$2:$L$1001,'2.현장'!$V$2:$V$1001,B17,'2.현장'!$T$2:$T$1001,TRUE))) | H17: =IF(B17="","",IFERROR(INDEX('2.현장'!$C$2:$C$1001,IFERROR(MATCH(B17&"|설계사",'2.현장'!$Z$2:$Z$1001,0),IFERROR(MATCH(B17&"|시공사",'2.현장'!$Z$2:$Z$1001,0),MATCH(B17&"|늦음",'2.현장'!$Z$2:$Z$1001,0)))),"")) | I17: =IF(B17="","",IFERROR(INDEX('2.현장'!$N$2:$N$1001,IFERROR(MATCH(B17&"|설계사",'2.현장'!$Z$2:$Z$1001,0),IFERROR(MATCH(B17&"|시공사",'2.현장'!$Z$2:$Z$1001,0),MATCH(B17&"|늦음",'2.현장'!$Z$2:$Z$1001,0)))),"")) | J17: =IF(B17="","",IFERROR(VLOOKUP(B17,설계사_메모!$A$3:$G$302,2,FALSE)&"","")) | K17: =IF(B17="","",IFERROR(VLOOKUP(B17,설계사_메모!$A$3:$G$302,4,FALSE)&"","")) | L17: =IF(B17="","",IF(COUNTIF('4.방문기록'!$B$3:$B$502,B17)=0,"",_xlfn.MAXIFS('4.방문기록'!$A$3:$A$502,'4.방문기록'!$B$3:$B$502,B17))) | M17: =IF(L17="","",설정!$B$24-L17) | N17: =IF(B17="","",IF(_xlfn.MAXIFS('4.방문기록'!$F$3:$F$502,'4.방문기록'!$B$3:$B$502,B17)=0,"",_xlfn.MAXIFS('4.방문기록'!$F$3:$F$502,'4.방문기록'!$B$3:$B$502,B17))) | O17: =IF(L17="","",IFERROR(INDEX('4.방문기록'!$H$3:$H$502,MATCH(B17&"|"&(L17*1),'4.방문기록'!$I$3:$I$502,0))&"","")) | P17: =IF(B17="","",IF(O17="관심 없음","제외",IF(L17="","안 가봄",IF(M17>=설정!$B$20,M17&"일 지남","최근 방문")))) | Q17: =IF(B17="","",IF(P17="제외","",IF(AND(설정!$B$21<>"",I17<>설정!$B$21),"",IF(AND(N17<>"",N17>N(L17),N17<=설정!$B$24+7),100+7-(N17-설정!$B$24),IF(AND(D17>0,OR(P17="안 가봄",RIGHT(P17,2)="지남")),D17*10+IF(L17="",30,MIN(M17,60)/2)+MIN(N(F17)/1000,20),""))))) | R17: =IF(Q17="","",COUNTIF(Q$4:Q$303,">"&Q17)+COUNTIF(Q$4:Q17,Q17))
