Workbook

Sheet 사용법
A1: 시트 3번 「영업판」 v3(구글판) (2026-09-27) — 산군 + 설계사 영업 전용 · 구글시트에서 바로 계산
A3: ■ 이 파일은 구글시트 전용입니다(열마다 수식 한 칸이 전체를 계산). 폰 구글시트 앱에서도 그대로 보고 고칠 수 있습니다.
A4: ■ 프로님 손은 1번 : 매주 월요일 산군 엑셀을 받아 「1.산군_붙여넣기」 탭 A1 칸을 누르고 통째로 붙여넣기(전체 덮어쓰기). 여러 조건으로 받으면 아래로 이어 붙여도 됩니다(같은 주소+현장명은 아래 줄이 이김).
A5: → 2.현장(★△✕) · 3.설계사 · 3b.시공사 · 5.이번주_갈곳 · 7.문안 · 6.본전계산 이 저절로 바뀝니다.
A6: ■ 5.이번주_갈곳 의 「지도」 를 누르면 네이버 지도, 「검색」 을 누르면 사무소 이름+전화 네이버 검색이 열립니다. 「확인할 것」 칸에 이 줄에서 아직 못 믿는 정보가 적혀 있습니다.
A7: ■ 처음 한 번만 : 「설정」 탭 B4~B15 에 산군 엑셀 1행의 열 이름을 똑같이 적기. 지금은 9/14 산군 화면 캡처의 열 이름입니다. 「0.자가진단」 1번이 「통과」 면 끝.
A8: ■ 지금 1번 탭의 11줄 = 2026-09-14 산군 캡처 실제 자료(드라이브 산군/산군_관심현장 v1). 설계사 이름 2곳은 캡처에서 잘려 「…」 로 끝납니다.
A9: ■ 다녀오시면 : 「4.방문기록」 에 한 줄(날짜·업체·결과). 「관심 없음」 이면 갈 곳 목록에서 빠집니다.
A10: ■ 담당자·전화 : 「업체_메모」 에 한 줄. 확신도 칸을 「확정」 으로 바꾸시면 5번 「확인할 것」 에서 빠집니다.
A11: ■ 현장 뉴스 : 「현장_조사」 탭. 객실 수는 확신도가 「확정」 일 때만 7.문안 메일에 들어갑니다(추정 숫자가 대외로 안 나가게).
A12: ■ 판정 : ✕ = 용도 아님 또는 연면적 미달 / △ = 허가→착공 표류 또는 ★ 기준 미만 / ★ = 나머지. 기준·점수 가중치는 설정 탭 노란 칸.
A13: ■ 초록 칸(자동)은 지우거나 덮어쓰지 마십시오. 한 칸 수식이 아래 줄까지 채웁니다. 지웠으면 「0.자가진단」 이 실패로 알려 줍니다 → 판 기록에서 되돌리기.
A14: ■ 이 시트는 회의록·견적·공정·수금과 섞지 않습니다. 기존 레이더·도구 47번과도 따로입니다.

Sheet 0.자가진단
A1: 자가진단 — 전부 「통과」 면 정상 (v3(구글판))
A3: 번호 | B3: 검사 | C3: 값 | D3: 판정
A4: 1 | B4: 필수 열 6개(주소·현장명·연면적·용도·설계사·단계) 중 찾은 수 | C4: =N(설정!$C$4<>"")+N(설정!$C$5<>"")+N(설정!$C$6<>"")+N(설정!$C$7<>"")+N(설정!$C$9<>"")+N(설정!$C$13<>"") | D4: =IF(C4=6,"통과","실패 — 설정 B4~B15 를 산군 엑셀 1행과 맞추기")
A5: 2 | B5: 붙여넣은 줄 수(1행 제외) | C5: =MAX(COUNTA('1.산군_붙여넣기'!B:B)-1,0) | D5: =IF(C5<=1000,"통과","실패 — 1000줄 넘음, 아래는 안 읽힘")
A6: 3 | B6: 읽은 현장 줄 | C6: =COUNTIF('2.현장'!$O$2:$O$1001,TRUE) | D6: =IF(C6=C5,"통과","확인 — 빈 줄·제목줄 섞임")
A7: 4 | B7: 중복 뺀 현장 | C7: =COUNTIF('2.현장'!$Q$2:$Q$1001,TRUE) | D7: ="참고"
A8: 5 | B8: ★ + △ + ✕ = 중복 뺀 현장 | C8: =COUNTIF('2.현장'!$AA$2:$AA$1001,"★")+COUNTIF('2.현장'!$AA$2:$AA$1001,"△")+COUNTIF('2.현장'!$AA$2:$AA$1001,"✕") | D8: =IF(C8=C7,"통과","실패")
A9: 6 | B9: 대상(용도·면적 맞음) = ★ + △ | C9: =COUNTIF('2.현장'!$T$2:$T$1001,TRUE) | D9: =IF(C9=COUNTIF('2.현장'!$AA$2:$AA$1001,"★")+COUNTIF('2.현장'!$AA$2:$AA$1001,"△"),"통과","실패")
A10: 7 | B10: 설계사행 + 시공사행 + 늦음 = 대상 | C10: =COUNTIF('2.현장'!$U$2:$U$1001,"설계사")+COUNTIF('2.현장'!$U$2:$U$1001,"시공사")+COUNTIF('2.현장'!$U$2:$U$1001,"늦음") | D10: =IF(C10=C9,"통과","실패 — 설정 단계 행선지 확인")
A11: 8 | B11: 설계사무소 수(목록) = 대상 현장의 설계사 이름 수 | C11: =COUNTIF('3.설계사'!$B$4:$B$303,"?*") | D11: =IF(C11=IFERROR(COUNTA(UNIQUE(FILTER('2.현장'!$V$2:$V$1001,'2.현장'!$T$2:$T$1001=TRUE,'2.현장'!$V$2:$V$1001<>""))),0),IF(C11<300,"통과","실패 — 300곳 넘음"),"실패")
A12: 9 | B12: 시공사 수(목록) = 대상 현장의 시공사 이름 수 | C12: =COUNTIF('3b.시공사'!$B$4:$B$203,"?*") | D12: =IF(C12=IFERROR(COUNTA(UNIQUE(FILTER('2.현장'!$AC$2:$AC$1001,'2.현장'!$T$2:$T$1001=TRUE,'2.현장'!$AC$2:$AC$1001<>""))),0),IF(C12<200,"통과","실패 — 200곳 넘음"),"실패")
A13: 10 | B13: 설계사 이름 빈 대상 현장 | C13: =COUNTIFS('2.현장'!$T$2:$T$1001,TRUE,'2.현장'!$V$2:$V$1001,"") | D13: =IF(C13=0,"통과","확인 — 산군에 설계사 없는 현장(2.현장 필터)")
A14: 11 | B14: 방문기록 중 목록에 없는 업체 | C14: =SUM('4.방문기록'!$J$3:$J$502) | D14: =IF(C14=0,"통과","확인 — 이름이 3·3b번 탭과 다름")
A15: 12 | B15: 점수 가중치 빈칸 | C15: =COUNTBLANK(설정!B31:B39) | D15: =IF(C15=0,"통과","실패 — 설정 가중치 칸을 채우기")
A16: 13 | B16: 잘린 이름(…) 남음 | C16: =COUNTIF('2.현장'!$G$2:$G$1001,"*…*") | D16: =IF(C16=0,"통과","알림 — 캡처에서 잘린 설계사 이름. 엑셀 다운로드로 바꾸면 사라짐")
A17: 14 | B17: 자동 수식 칸 살아 있음(2.현장·3번·3b번) | C17: =SUMPRODUCT(--ISFORMULA('2.현장'!B2:AD2))+ISFORMULA('3.설계사'!B4)+ISFORMULA('3.설계사'!T4)+ISFORMULA('3b.시공사'!B4) | D17: =IF(C17>=27,"통과","실패 — 초록 수식 칸이 지워짐. 판 기록에서 되돌리기")
A20: 변경 이력
A21: 날짜 | B21: 판 | C21: 내용 | D21: 이전 값
A22: 2026-09-27 | B22: v1 | C22: 최초 작성 — 엑셀판 11개 탭, [예시] 가짜 7줄 | D22: 없음
A23: 2026-09-27 | B23: v2 | C23: 엑셀판 — 9/14 산군 캡처 11줄, ★△✕, 가중치 입력칸, 3b.시공사·현장_조사·업체_메모 | D23: v1
A24: 2026-09-27 | B24: v3(구글판) | C24: B: 계산 방식 → 구글시트 배열 수식(MAP·UNIQUE·SORT). 드라이브에 바로 쓰는 구글시트로 올림. 탭·열·규칙·숫자는 v2 와 같음 | D24: 엑셀판 줄마다 수식(v2)
A25: 2026-09-27 | B25: v3(구글판) | C25: A: 5.이번주_갈곳 에 지도·검색 링크, 「확인할 것」 칸 / 3.설계사 에 대표 주소·전화 확신도 / 자가진단 14번(수식 칸 살아 있음) | D25: —

Sheet 5.이번주_갈곳
A1: ="이번 주 찾아갈 설계사무소 "&COUNTA(FILTER('3.설계사'!$T$4:$T$303,'3.설계사'!$T$4:$T$303<>""))&"곳 · 지역: "&IF(설정!$B$21="","전국",설정!$B$21)&" · 기준일 "&TEXT(설정!$B$24,"yyyy-mm-dd")
A2: 순서 : ①7일 안 약속 ②현장점수(설계단계>최근 착공>오래된 착공, ★ 가산)+안 가본 곳 ③오래 안 간 곳. 「지도」·「검색」 을 누르면 네이버가 열립니다. 「확인할 것」 = 아직 못 믿는 정보.
A3: 순위 | B3: 설계사무소 | C3: 왜 가야 하나 | D3: 대표 현장 | E3: 지역 | F3: 최대 연면적 | G3: 객실 수(조사) | H3: 담당자 | I3: 전화 | J3: 지도 | K3: 검색 | L3: 확인할 것 | M3: 전화 첫마디(복사) | N3: _행
A4: =IF(B4="","",ROW()-3) | B4: =IFERROR(ARRAY_CONSTRAIN(SORT(FILTER({'3.설계사'!$B$4:$B$303,'3.설계사'!$T$4:$T$303,'3.설계사'!$A$4:$A$303},'3.설계사'!$T$4:$T$303<>""),2,FALSE,3,TRUE),30,1),"") | C4: =IF(B4="","",INDEX('3.설계사'!$W$4:$W$303,N4)) | D4: =IF(B4="","",INDEX('3.설계사'!$K$4:$K$303,N4)) | E4: =IF(B4="","",INDEX('3.설계사'!$L$4:$L$303,N4)) | F4: =IF(B4="","",INDEX('3.설계사'!$H$4:$H$303,N4)) | G4: =IF(B4="","",INDEX('3.설계사'!$AB$4:$AB$303,N4)) | H4: =IF(B4="","",INDEX('3.설계사'!$M$4:$M$303,N4)) | I4: =IF(B4="","",INDEX('3.설계사'!$N$4:$N$303,N4)) | J4: =IF(B4="","",HYPERLINK(INDEX('3.설계사'!$Z$4:$Z$303,N4),"지도")) | K4: =IF(B4="","",HYPERLINK(INDEX('3.설계사'!$AA$4:$AA$303,N4),"검색")) | L4: =IF(B4="","",INDEX('3.설계사'!$X$4:$X$303,N4)) | M4: =IF(B4="","",INDEX('3.설계사'!$Y$4:$Y$303,N4)) | N4: =IF(B4="","",MATCH(B4,'3.설계사'!$B$4:$B$303,0))
A5: =IF(B5="","",ROW()-3) | C5: =IF(B5="","",INDEX('3.설계사'!$W$4:$W$303,N5)) | D5: =IF(B5="","",INDEX('3.설계사'!$K$4:$K$303,N5)) | E5: =IF(B5="","",INDEX('3.설계사'!$L$4:$L$303,N5)) | F5: =IF(B5="","",INDEX('3.설계사'!$H$4:$H$303,N5)) | G5: =IF(B5="","",INDEX('3.설계사'!$AB$4:$AB$303,N5)) | H5: =IF(B5="","",INDEX('3.설계사'!$M$4:$M$303,N5)) | I5: =IF(B5="","",INDEX('3.설계사'!$N$4:$N$303,N5)) | J5: =IF(B5="","",HYPERLINK(INDEX('3.설계사'!$Z$4:$Z$303,N5),"지도")) | K5: =IF(B5="","",HYPERLINK(INDEX('3.설계사'!$AA$4:$AA$303,N5),"검색")) | L5: =IF(B5="","",INDEX('3.설계사'!$X$4:$X$303,N5)) | M5: =IF(B5="","",INDEX('3.설계사'!$Y$4:$Y$303,N5)) | N5: =IF(B5="","",MATCH(B5,'3.설계사'!$B$4:$B$303,0))
A6: =IF(B6="","",ROW()-3) | C6: =IF(B6="","",INDEX('3.설계사'!$W$4:$W$303,N6)) | D6: =IF(B6="","",INDEX('3.설계사'!$K$4:$K$303,N6)) | E6: =IF(B6="","",INDEX('3.설계사'!$L$4:$L$303,N6)) | F6: =IF(B6="","",INDEX('3.설계사'!$H$4:$H$303,N6)) | G6: =IF(B6="","",INDEX('3.설계사'!$AB$4:$AB$303,N6)) | H6: =IF(B6="","",INDEX('3.설계사'!$M$4:$M$303,N6)) | I6: =IF(B6="","",INDEX('3.설계사'!$N$4:$N$303,N6)) | J6: =IF(B6="","",HYPERLINK(INDEX('3.설계사'!$Z$4:$Z$303,N6),"지도")) | K6: =IF(B6="","",HYPERLINK(INDEX('3.설계사'!$AA$4:$AA$303,N6),"검색")) | L6: =IF(B6="","",INDEX('3.설계사'!$X$4:$X$303,N6)) | M6: =IF(B6="","",INDEX('3.설계사'!$Y$4:$Y$303,N6)) | N6: =IF(B6="","",MATCH(B6,'3.설계사'!$B$4:$B$303,0))
A7: =IF(B7="","",ROW()-3) | C7: =IF(B7="","",INDEX('3.설계사'!$W$4:$W$303,N7)) | D7: =IF(B7="","",INDEX('3.설계사'!$K$4:$K$303,N7)) | E7: =IF(B7="","",INDEX('3.설계사'!$L$4:$L$303,N7)) | F7: =IF(B7="","",INDEX('3.설계사'!$H$4:$H$303,N7)) | G7: =IF(B7="","",INDEX('3.설계사'!$AB$4:$AB$303,N7)) | H7: =IF(B7="","",INDEX('3.설계사'!$M$4:$M$303,N7)) | I7: =IF(B7="","",INDEX('3.설계사'!$N$4:$N$303,N7)) | J7: =IF(B7="","",HYPERLINK(INDEX('3.설계사'!$Z$4:$Z$303,N7),"지도")) | K7: =IF(B7="","",HYPERLINK(INDEX('3.설계사'!$AA$4:$AA$303,N7),"검색")) | L7: =IF(B7="","",INDEX('3.설계사'!$X$4:$X$303,N7)) | M7: =IF(B7="","",INDEX('3.설계사'!$Y$4:$Y$303,N7)) | N7: =IF(B7="","",MATCH(B7,'3.설계사'!$B$4:$B$303,0))
A8: =IF(B8="","",ROW()-3) | C8: =IF(B8="","",INDEX('3.설계사'!$W$4:$W$303,N8)) | D8: =IF(B8="","",INDEX('3.설계사'!$K$4:$K$303,N8)) | E8: =IF(B8="","",INDEX('3.설계사'!$L$4:$L$303,N8)) | F8: =IF(B8="","",INDEX('3.설계사'!$H$4:$H$303,N8)) | G8: =IF(B8="","",INDEX('3.설계사'!$AB$4:$AB$303,N8)) | H8: =IF(B8="","",INDEX('3.설계사'!$M$4:$M$303,N8)) | I8: =IF(B8="","",INDEX('3.설계사'!$N$4:$N$303,N8)) | J8: =IF(B8="","",HYPERLINK(INDEX('3.설계사'!$Z$4:$Z$303,N8),"지도")) | K8: =IF(B8="","",HYPERLINK(INDEX('3.설계사'!$AA$4:$AA$303,N8),"검색")) | L8: =IF(B8="","",INDEX('3.설계사'!$X$4:$X$303,N8)) | M8: =IF(B8="","",INDEX('3.설계사'!$Y$4:$Y$303,N8)) | N8: =IF(B8="","",MATCH(B8,'3.설계사'!$B$4:$B$303,0))
A9: =IF(B9="","",ROW()-3) | C9: =IF(B9="","",INDEX('3.설계사'!$W$4:$W$303,N9)) | D9: =IF(B9="","",INDEX('3.설계사'!$K$4:$K$303,N9)) | E9: =IF(B9="","",INDEX('3.설계사'!$L$4:$L$303,N9)) | F9: =IF(B9="","",INDEX('3.설계사'!$H$4:$H$303,N9)) | G9: =IF(B9="","",INDEX('3.설계사'!$AB$4:$AB$303,N9)) | H9: =IF(B9="","",INDEX('3.설계사'!$M$4:$M$303,N9)) | I9: =IF(B9="","",INDEX('3.설계사'!$N$4:$N$303,N9)) | J9: =IF(B9="","",HYPERLINK(INDEX('3.설계사'!$Z$4:$Z$303,N9),"지도")) | K9: =IF(B9="","",HYPERLINK(INDEX('3.설계사'!$AA$4:$AA$303,N9),"검색")) | L9: =IF(B9="","",INDEX('3.설계사'!$X$4:$X$303,N9)) | M9: =IF(B9="","",INDEX('3.설계사'!$Y$4:$Y$303,N9)) | N9: =IF(B9="","",MATCH(B9,'3.설계사'!$B$4:$B$303,0))
A10: =IF(B10="","",ROW()-3) | C10: =IF(B10="","",INDEX('3.설계사'!$W$4:$W$303,N10)) | D10: =IF(B10="","",INDEX('3.설계사'!$K$4:$K$303,N10)) | E10: =IF(B10="","",INDEX('3.설계사'!$L$4:$L$303,N10)) | F10: =IF(B10="","",INDEX('3.설계사'!$H$4:$H$303,N10)) | G10: =IF(B10="","",INDEX('3.설계사'!$AB$4:$AB$303,N10)) | H10: =IF(B10="","",INDEX('3.설계사'!$M$4:$M$303,N10)) | I10: =IF(B10="","",INDEX('3.설계사'!$N$4:$N$303,N10)) | J10: =IF(B10="","",HYPERLINK(INDEX('3.설계사'!$Z$4:$Z$303,N10),"지도")) | K10: =IF(B10="","",HYPERLINK(INDEX('3.설계사'!$AA$4:$AA$303,N10),"검색")) | L10: =IF(B10="","",INDEX('3.설계사'!$X$4:$X$303,N10)) | M10: =IF(B10="","",INDEX('3.설계사'!$Y$4:$Y$303,N10)) | N10: =IF(B10="","",MATCH(B10,'3.설계사'!$B$4:$B$303,0))
A11: =IF(B11="","",ROW()-3) | C11: =IF(B11="","",INDEX('3.설계사'!$W$4:$W$303,N11)) | D11: =IF(B11="","",INDEX('3.설계사'!$K$4:$K$303,N11)) | E11: =IF(B11="","",INDEX('3.설계사'!$L$4:$L$303,N11)) | F11: =IF(B11="","",INDEX('3.설계사'!$H$4:$H$303,N11)) | G11: =IF(B11="","",INDEX('3.설계사'!$AB$4:$AB$303,N11)) | H11: =IF(B11="","",INDEX('3.설계사'!$M$4:$M$303,N11)) | I11: =IF(B11="","",INDEX('3.설계사'!$N$4:$N$303,N11)) | J11: =IF(B11="","",HYPERLINK(INDEX('3.설계사'!$Z$4:$Z$303,N11),"지도")) | K11: =IF(B11="","",HYPERLINK(INDEX('3.설계사'!$AA$4:$AA$303,N11),"검색")) | L11: =IF(B11="","",INDEX('3.설계사'!$X$4:$X$303,N11)) | M11: =IF(B11="","",INDEX('3.설계사'!$Y$4:$Y$303,N11)) | N11: =IF(B11="","",MATCH(B11,'3.설계사'!$B$4:$B$303,0))
A12: =IF(B12="","",ROW()-3) | C12: =IF(B12="","",INDEX('3.설계사'!$W$4:$W$303,N12)) | D12: =IF(B12="","",INDEX('3.설계사'!$K$4:$K$303,N12)) | E12: =IF(B12="","",INDEX('3.설계사'!$L$4:$L$303,N12)) | F12: =IF(B12="","",INDEX('3.설계사'!$H$4:$H$303,N12)) | G12: =IF(B12="","",INDEX('3.설계사'!$AB$4:$AB$303,N12)) | H12: =IF(B12="","",INDEX('3.설계사'!$M$4:$M$303,N12)) | I12: =IF(B12="","",INDEX('3.설계사'!$N$4:$N$303,N12)) | J12: =IF(B12="","",HYPERLINK(INDEX('3.설계사'!$Z$4:$Z$303,N12),"지도")) | K12: =IF(B12="","",HYPERLINK(INDEX('3.설계사'!$AA$4:$AA$303,N12),"검색")) | L12: =IF(B12="","",INDEX('3.설계사'!$X$4:$X$303,N12)) | M12: =IF(B12="","",INDEX('3.설계사'!$Y$4:$Y$303,N12)) | N12: =IF(B12="","",MATCH(B12,'3.설계사'!$B$4:$B$303,0))
A13: =IF(B13="","",ROW()-3) | C13: =IF(B13="","",INDEX('3.설계사'!$W$4:$W$303,N13)) | D13: =IF(B13="","",INDEX('3.설계사'!$K$4:$K$303,N13)) | E13: =IF(B13="","",INDEX('3.설계사'!$L$4:$L$303,N13)) | F13: =IF(B13="","",INDEX('3.설계사'!$H$4:$H$303,N13)) | G13: =IF(B13="","",INDEX('3.설계사'!$AB$4:$AB$303,N13)) | H13: =IF(B13="","",INDEX('3.설계사'!$M$4:$M$303,N13)) | I13: =IF(B13="","",INDEX('3.설계사'!$N$4:$N$303,N13)) | J13: =IF(B13="","",HYPERLINK(INDEX('3.설계사'!$Z$4:$Z$303,N13),"지도")) | K13: =IF(B13="","",HYPERLINK(INDEX('3.설계사'!$AA$4:$AA$303,N13),"검색")) | L13: =IF(B13="","",INDEX('3.설계사'!$X$4:$X$303,N13)) | M13: =IF(B13="","",INDEX('3.설계사'!$Y$4:$Y$303,N13)) | N13: =IF(B13="","",MATCH(B13,'3.설계사'!$B$4:$B$303,0))
A14: =IF(B14="","",ROW()-3) | C14: =IF(B14="","",INDEX('3.설계사'!$W$4:$W$303,N14)) | D14: =IF(B14="","",INDEX('3.설계사'!$K$4:$K$303,N14)) | E14: =IF(B14="","",INDEX('3.설계사'!$L$4:$L$303,N14)) | F14: =IF(B14="","",INDEX('3.설계사'!$H$4:$H$303,N14)) | G14: =IF(B14="","",INDEX('3.설계사'!$AB$4:$AB$303,N14)) | H14: =IF(B14="","",INDEX('3.설계사'!$M$4:$M$303,N14)) | I14: =IF(B14="","",INDEX('3.설계사'!$N$4:$N$303,N14)) | J14: =IF(B14="","",HYPERLINK(INDEX('3.설계사'!$Z$4:$Z$303,N14),"지도")) | K14: =IF(B14="","",HYPERLINK(INDEX('3.설계사'!$AA$4:$AA$303,N14),"검색")) | L14: =IF(B14="","",INDEX('3.설계사'!$X$4:$X$303,N14)) | M14: =IF(B14="","",INDEX('3.설계사'!$Y$4:$Y$303,N14)) | N14: =IF(B14="","",MATCH(B14,'3.설계사'!$B$4:$B$303,0))
A15: =IF(B15="","",ROW()-3) | C15: =IF(B15="","",INDEX('3.설계사'!$W$4:$W$303,N15)) | D15: =IF(B15="","",INDEX('3.설계사'!$K$4:$K$303,N15)) | E15: =IF(B15="","",INDEX('3.설계사'!$L$4:$L$303,N15)) | F15: =IF(B15="","",INDEX('3.설계사'!$H$4:$H$303,N15)) | G15: =IF(B15="","",INDEX('3.설계사'!$AB$4:$AB$303,N15)) | H15: =IF(B15="","",INDEX('3.설계사'!$M$4:$M$303,N15)) | I15: =IF(B15="","",INDEX('3.설계사'!$N$4:$N$303,N15)) | J15: =IF(B15="","",HYPERLINK(INDEX('3.설계사'!$Z$4:$Z$303,N15),"지도")) | K15: =IF(B15="","",HYPERLINK(INDEX('3.설계사'!$AA$4:$AA$303,N15),"검색")) | L15: =IF(B15="","",INDEX('3.설계사'!$X$4:$X$303,N15)) | M15: =IF(B15="","",INDEX('3.설계사'!$Y$4:$Y$303,N15)) | N15: =IF(B15="","",MATCH(B15,'3.설계사'!$B$4:$B$303,0))
A16: =IF(B16="","",ROW()-3) | C16: =IF(B16="","",INDEX('3.설계사'!$W$4:$W$303,N16)) | D16: =IF(B16="","",INDEX('3.설계사'!$K$4:$K$303,N16)) | E16: =IF(B16="","",INDEX('3.설계사'!$L$4:$L$303,N16)) | F16: =IF(B16="","",INDEX('3.설계사'!$H$4:$H$303,N16)) | G16: =IF(B16="","",INDEX('3.설계사'!$AB$4:$AB$303,N16)) | H16: =IF(B16="","",INDEX('3.설계사'!$M$4:$M$303,N16)) | I16: =IF(B16="","",INDEX('3.설계사'!$N$4:$N$303,N16)) | J16: =IF(B16="","",HYPERLINK(INDEX('3.설계사'!$Z$4:$Z$303,N16),"지도")) | K16: =IF(B16="","",HYPERLINK(INDEX('3.설계사'!$AA$4:$AA$303,N16),"검색")) | L16: =IF(B16="","",INDEX('3.설계사'!$X$4:$X$303,N16)) | M16: =IF(B16="","",INDEX('3.설계사'!$Y$4:$Y$303,N16)) | N16: =IF(B16="","",MATCH(B16,'3.설계사'!$B$4:$B$303,0))
... A33: =IF(B33="","",ROW()-3) | C33: =IF(B33="","",INDEX('3.설계사'!$W$4:$W$303,N33)) | D33: =IF(B33="","",INDEX('3.설계사'!$K$4:$K$303,N33)) | E33: =IF(B33="","",INDEX('3.설계사'!$L$4:$L$303,N33)) | F33: =IF(B33="","",INDEX('3.설계사'!$H$4:$H$303,N33)) | G33: =IF(B33="","",INDEX('3.설계사'!$AB$4:$AB$303,N33)) | H33: =IF(B33="","",INDEX('3.설계사'!$M$4:$M$303,N33)) | I33: =IF(B33="","",INDEX('3.설계사'!$N$4:$N$303,N33)) | J33: =IF(B33="","",HYPERLINK(INDEX('3.설계사'!$Z$4:$Z$303,N33),"지도")) | K33: =IF(B33="","",HYPERLINK(INDEX('3.설계사'!$AA$4:$AA$303,N33),"검색")) | L33: =IF(B33="","",INDEX('3.설계사'!$X$4:$X$303,N33)) | M33: =IF(B33="","",INDEX('3.설계사'!$Y$4:$Y$303,N33)) | N33: =IF(B33="","",MATCH(B33,'3.설계사'!$B$4:$B$303,0))

Sheet 1.산군_붙여넣기
A1: No | B1: 현장명 | C1: 소재지 | D1: 공종 | E1: 단계 | F1: 날짜1(추정:허가일) | G1: 날짜2(추정:착공일) | H1: 건축설계 | I1: 열J(미확인) | J1: 용도 | K1: 구분 | L1: 연면적㎡ | M1: 구조
A2: 1 | B2: 길상면 선두리 976-7 생활숙박시설 | C2: 인천광역시 강화군 길상면 선두리 976-7 | D2: 건축 | E2: 착공 | F2: 2026-06-23 | G2: 2026-07-02 | J2: 숙박시설 | K2: 신축 | L2: 460 | M2: 경량철골구조
A3: 2 | B3: 범방동 1898-7 생활숙박시설 | C3: 부산광역시 강서구 범방동 1898-7번지 | D3: 건축 | E3: 착공 | F3: 2022-04-15 | G3: 2025-10-31 | J3: 숙박시설 | K3: 신축 | L3: 22409
A4: 3 | B4: 대소면 성본리 115-5 숙박시설 | C4: 충청북도 음성군 대소면 성본리 산115-5 | D4: 건축 | E4: 착공 | F4: 2023-09-14 | G4: 2026-09-14 | H4: 태건축사사무소 | J4: 숙박시설 | K4: 신축 | L4: 2596 | M4: 철근콘크리트구조
A5: 4 | B5: 조양동 1558-3 생활숙박시설 | C5: 강원특별자치도 속초시 조양동 1558-3번지 | D5: 건축 | E5: 착공 | F5: 2023-09-27 | G5: 2026-09-14 | H5: (주)파인드건축사사무소 | J5: 숙박시설 | K5: 신축 | L5: 14868 | M5: 철근콘크리트구조
A6: 5 | B6: 명동2가 95-1 생활숙박시설 신축공사 | C6: 서울특별시 중구 남대문로 64 (명동2가) | D6: 건축 | E6: 착공 | F6: 2023-08-18 | G6: 2026-08-17 | H6: (주)야촌건축사사무소 | I6: (주)시경개발 | J6: 숙박시설 | K6: 신축 | L6: 6095 | M6: 철근콘크리트구조
A7: 6 | B7: 부산시 중구 남포동3가 생활형숙박시설 | C7: 부산광역시 중구 남포길 16 (남포동3가) | D7: 건축 | E7: 착공 | F7: 2023-07-31 | G7: 2026-07-31 | H7: (주)상지이앤에이건축… | I7: (주)평광이앤씨 | J7: 숙박시설 | K7: 신축 | L7: 14453 | M7: 철근콘크리트구조
A8: 7 | B8: 와룡동 37 관광숙박시설 | C8: 서울특별시 종로구 와룡동 37번지 | D8: 건축 | E8: 착공 | F8: 2026-04-01 | G8: 2026-07-30 | H8: 오파드건축연구소 | J8: 숙박시설 | K8: 신축 | L8: 301 | M8: 철근콘크리트구조
A9: 8 | B9: 경서동 경서3구역 11블록 2로트 숙박시설 | C9: 인천광역시 서구 경서동 블록 | D9: 건축 | E9: 착공 | F9: 2022-07-20 | G9: 2026-07-23 | H9: 건축사무소 고강 | J9: 숙박시설 | K9: 신축 | L9: 1995 | M9: 철근콘크리트구조
A10: 9 | B10: 종로5가 193-17,3번지 관광숙박시설 | C10: 서울특별시 종로구 종로 228 (종로5가) | D10: 건축 | E10: 착공 | F10: 2026-01-29 | G10: 2026-07-15 | H10: (주)아이디어키텍… | I10: 태재연구재단 | J10: 숙박시설 | K10: 신축 | L10: 4482 | M10: 철근콘크리트구조
A11: 10 | B11: 부전동 숙박시설 | C11: 부산광역시 부산진구 중앙대로680번가길 | D11: 건축 | E11: 착공 | F11: 2025-10-20 | G11: 2026-07-06 | H11: 이진건축사사무소 | J11: 숙박시설 | K11: 신축 | L11: 2000 | M11: 철근콘크리트구조
A12: 11 | B12: 서면 중방대리 106 일반숙박시설 | C12: 강원특별자치도 홍천군 서면 고두개길 112 | D12: 건축 | E12: 착공 | F12: 2024-08-08 | G12: 2026-06-30 | H12: (주)세움건축사사무소 | J12: 숙박시설 | K12: 신축 | L12: 97 | M12: 일반목구조

Sheet 3.설계사
A1: 설계사무소별 모음 (자동) — 산군 대상 현장을 설계사무소 이름으로 묶음
A2: ="설계사무소 "&COUNTIF(B4:B303,"?*")&"곳 · 대상 현장 "&COUNTIF('2.현장'!$T$2:$T$1001,TRUE)&"건 · ★ "&COUNTIF('2.현장'!$AA$2:$AA$1001,"★")&"건"
A3: 번호 | B3: 설계사무소 | C3: 대상 현장 | D3: 설계단계 | E3: 시공단계 | F3: ★ 수 | G3: 현장점수 | H3: 최대 연면적 | I3: 최근 허가일 | J3: 최근 착공일 | K3: 대표 현장 | L3: 지역 | M3: 담당자 | N3: 전화 | O3: 마지막 방문 | P3: 경과일 | Q3: 다음 약속 | R3: 최근 결과 | S3: 상태 | T3: 우선점수 | U3: 대표 주소 | V3: 전화 확신도 | W3: 왜 가야 하나 | X3: 확인할 것 | Y3: 전화 첫마디 | Z3: 지도 주소 | AA3: 검색 주소 | AB3: 객실 수(조사)
A4: =MAP(B4:B303,SEQUENCE(300),LAMBDA(x_n,x_i,IF(x_n="","",x_i))) | B4: =IFERROR(UNIQUE(FILTER('2.현장'!$V$2:$V$1001,'2.현장'!$T$2:$T$1001=TRUE,'2.현장'!$V$2:$V$1001<>"")),"") | C4: =MAP(B4:B303,LAMBDA(x_n,IF(x_n="","",COUNTIFS('2.현장'!$V$2:$V$1001,x_n,'2.현장'!$T$2:$T$1001,TRUE)))) | D4: =MAP(B4:B303,LAMBDA(x_n,IF(x_n="","",COUNTIFS('2.현장'!$V$2:$V$1001,x_n,'2.현장'!$U$2:$U$1001,"설계사")))) | E4: =MAP(B4:B303,LAMBDA(x_n,IF(x_n="","",COUNTIFS('2.현장'!$V$2:$V$1001,x_n,'2.현장'!$U$2:$U$1001,"시공사")))) | F4: =MAP(B4:B303,LAMBDA(x_n,IF(x_n="","",COUNTIFS('2.현장'!$V$2:$V$1001,x_n,'2.현장'!$T$2:$T$1001,TRUE,'2.현장'!$AA$2:$AA$1001,"★")))) | G4: =MAP(B4:B303,LAMBDA(x_n,IF(x_n="","",SUMIFS('2.현장'!$AB$2:$AB$1001,'2.현장'!$V$2:$V$1001,x_n,'2.현장'!$T$2:$T$1001,TRUE)))) | H4: =MAP(B4:B303,LAMBDA(x_n,IF(x_n="","",MAXIFS('2.현장'!$D$2:$D$1001,'2.현장'!$V$2:$V$1001,x_n,'2.현장'!$T$2:$T$1001,TRUE)))) | I4: =MAP(B4:B303,LAMBDA(x_n,IF(x_n="","",IF(MAXIFS('2.현장'!$L$2:$L$1001,'2.현장'!$V$2:$V$1001,x_n,'2.현장'!$T$2:$T$1001,TRUE)=0,"",MAXIFS('2.현장'!$L$2:$L$1001,'2.현장'!$V$2:$V$1001,x_n,'2.현장'!$T$2:$T$1001,TRUE))))) | J4: =MAP(B4:B303,LAMBDA(x_n,IF(x_n="","",IF(MAXIFS('2.현장'!$M$2:$M$1001,'2.현장'!$V$2:$V$1001,x_n,'2.현장'!$T$2:$T$1001,TRUE)=0,"",MAXIFS('2.현장'!$M$2:$M$1001,'2.현장'!$V$2:$V$1001,x_n,'2.현장'!$T$2:$T$1001,TRUE))))) | K4: =MAP(B4:B303,LAMBDA(x_n,IF(x_n="","",IFERROR(INDEX('2.현장'!$C$2:$C$1001,IFERROR(MATCH(x_n&"|설계사",'2.현장'!$Z$2:$Z$1001,0),IFERROR(MATCH(x_n&"|시공사",'2.현장'!$Z$2:$Z$1001,0),MATCH(x_n&"|늦음",'2.현장'!$Z$2:$Z$1001,0)))),"")))) | L4: =MAP(B4:B303,LAMBDA(x_n,IF(x_n="","",IFERROR(INDEX('2.현장'!$N$2:$N$1001,IFERROR(MATCH(x_n&"|설계사",'2.현장'!$Z$2:$Z$1001,0),IFERROR(MATCH(x_n&"|시공사",'2.현장'!$Z$2:$Z$1001,0),MATCH(x_n&"|늦음",'2.현장'!$Z$2:$Z$1001,0)))),"")))) | M4: =MAP(B4:B303,LAMBDA(x_n,IF(x_n="","",IFERROR(VLOOKUP(x_n,업체_메모!$A$3:$I$302,2,FALSE)&"","")))) | N4: =MAP(B4:B303,LAMBDA(x_n,IF(x_n="","",IFERROR(VLOOKUP(x_n,업체_메모!$A$3:$I$302,4,FALSE)&"","")))) | O4: =MAP(B4:B303,LAMBDA(x_n,IF(x_n="","",IF(COUNTIF('4.방문기록'!$B$3:$B$502,x_n)=0,"",MAXIFS('4.방문기록'!$A$3:$A$502,'4.방문기록'!$B$3:$B$502,x_n))))) | P4: =MAP(O4:O303,LAMBDA(x_o,IF(x_o="","",설정!$B$24-x_o))) | Q4: =MAP(B4:B303,LAMBDA(x_n,IF(x_n="","",IF(MAXIFS('4.방문기록'!$F$3:$F$502,'4.방문기록'!$B$3:$B$502,x_n)=0,"",MAXIFS('4.방문기록'!$F$3:$F$502,'4.방문기록'!$B$3:$B$502,x_n))))) | R4: =MAP(B4:B303,O4:O303,LAMBDA(x_n,x_o,IF(x_o="","",IFERROR(INDEX('4.방문기록'!$H$3:$H$502,MATCH(x_n&"|"&(x_o*1),'4.방문기록'!$I$3:$I$502,0))&"","")))) | S4: =MAP(B4:B303,O4:O303,P4:P303,R4:R303,LAMBDA(x_n,x_o,x_p,x_rr,IF(x_n="","",IF(x_rr="관심 없음","제외",IF(x_o="","안 가봄",IF(x_p>=설정!$B$20,x_p&"일 지남","최근 방문")))))) | T4: =MAP(B4:B303,S4:S303,L4:L303,Q4:Q303,O4:O303,P4:P303,G4:G303,H4:H303,LAMBDA(x_n,x_s,x_l,x_q,x_o,x_p,x_g,x_h,IF(x_n="","",IF(x_s="제외","",IF(AND(설정!$B$21<>"",x_l<>설정!$B$21),"",IF(AND(x_q<>"",x_q>N(x_o),x_q<=설정!$B$24+7),설정!$B$39+7-(x_q-설정!$B$24),IF(AND(x_g>0,OR(x_s="안 가봄",RIGHT(x_s,2)="지남")),x_g+IF(x_o="",설정!$B$36,MIN(x_p,60)*설정!$B$37)+MIN(N(x_h)/1000*설정!$B$38,20),""))))))) | U4: =MAP(B4:B303,LAMBDA(x_n,IF(x_n="","",IFERROR(INDEX('2.현장'!$B$2:$B$1001,IFERROR(MATCH(x_n&"|설계사",'2.현장'!$Z$2:$Z$1001,0),IFERROR(MATCH(x_n&"|시공사",'2.현장'!$Z$2:$Z$1001,0),MATCH(x_n&"|늦음",'2.현장'!$Z$2:$Z$1001,0)))),"")))) | V4: =MAP(B4:B303,LAMBDA(x_n,IF(x_n="","",IFERROR(VLOOKUP(x_n,업체_메모!$A$3:$I$302,8,FALSE)&"","")))) | W4: =MAP(B4:B303,T4:T303,Q4:Q303,O4:O303,P4:P303,D4:D303,E4:E303,F4:F303,LAMBDA(x_n,x_t,x_q,x_o,x_p,x_d,x_e,x_f,IF(x_n="","",IF(N(x_t)>=설정!$B$39,"약속 "&TEXT(x_q,"m/d")&" · ",IF(x_o="","아직 안 가봄 · ","마지막 방문 "&x_p&"일 전 · "))&IF(x_d>0,"설계단계 "&x_d&"건 ","")&IF(x_e>0,"착공 "&x_e&"건 ","")&IF(x_f>0,"★"&x_f,"")))) | X4: =MAP(B4:B303,N4:N303,V4:V303,AB4:AB303,LAMBDA(x_n,x_ph,x_cf,x_rm,IF(x_n="","",REGEXREPLACE(TRIM(IF(ISNUMBER(SEARCH("…",x_n)),"이름 잘림(산군 상세에서 전체 이름) · ","")&IF(x_ph="","전화 없음(검색) · ",IF(x_cf<>"확정","전화 "&x_cf&" · ",""))&IF(x_rm="","객실 수 미확인 · ",IF(ISNUMBER(SEARCH("(",x_rm)),"객실 수 추정 · ",""))&IF(COUNTIFS('2.현장'!$V$2:$V$1001,x_n,'2.현장'!$T$2:$T$1001,TRUE,'2.현장'!$H$2:$H$1001,"")>0,"시공사 미상","")),"\s*·\s*$","")))) | Y4: =MAP(B4:B303,K4:K303,D4:D303,LAMBDA(x_n,x_k,x_d,IF(x_n="","","한국마이크로닉 배성윤 차장입니다. "&x_k&IF(x_d>0," 설계 진행하고 계신"," 설계하신")&" 걸로 알고 연락드렸습니다. 호텔 객실관리(키센서·온도조절기·조명 제어) 도면과 특기시방서를 무상으로 지원해 드리고 있어서, 이번 주에 10분만 찾아뵈어도 될까요?"))) | Z4: =MAP(B4:B303,U4:U303,LAMBDA(x_n,x_u,IF(x_n="","","https://map.naver.com/p/search/"&ENCODEURL(x_u)))) | AA4: =MAP(B4:B303,L4:L303,LAMBDA(x_n,x_l,IF(x_n="","","https://search.naver.com/search.naver?query="&ENCODEURL(SUBSTITUTE(x_n,"…","")&" "&x_l&" 전화")))) | AB4: =MAP(B4:B303,K4:K303,LAMBDA(x_n,x_k,IF(x_n="","",IFERROR(IF(VLOOKUP(x_k,현장_조사!$A$3:$J$202,5,FALSE)&""="","",VLOOKUP(x_k,현장_조사!$A$3:$J$202,5,FALSE)&IF(VLOOKUP(x_k,현장_조사!$A$3:$J$202,8,FALSE)="확정",""," ("&VLOOKUP(x_k,현장_조사!$A$3:$J$202,8,FALSE)&")")),""))))

Sheet 3b.시공사
A1: 시공사(또는 발주처)별 모음 (자동) — 착공 현장 영업용. 산군 캡처의 「열J」 가 시공사인지 발주처인지는 미확인
A2: ="시공사 "&COUNTIF(B4:B203,"?*")&"곳"
A3: 번호 | B3: 시공사 | C3: 대상 현장 | D3: ★ 수 | E3: 최대 연면적 | F3: 최근 착공일 | G3: 대표 현장 | H3: 지역 | I3: 설계사(같은 현장) | J3: 담당자 | K3: 전화 | L3: 마지막 방문 | M3: 경과일 | N3: 최근 결과 | O3: 상태
A4: =MAP(B4:B203,SEQUENCE(200),LAMBDA(x_n,x_i,IF(x_n="","",x_i))) | B4: =IFERROR(UNIQUE(FILTER('2.현장'!$AC$2:$AC$1001,'2.현장'!$T$2:$T$1001=TRUE,'2.현장'!$AC$2:$AC$1001<>"")),"") | C4: =MAP(B4:B203,LAMBDA(x_n,IF(x_n="","",COUNTIFS('2.현장'!$AC$2:$AC$1001,x_n,'2.현장'!$T$2:$T$1001,TRUE)))) | D4: =MAP(B4:B203,LAMBDA(x_n,IF(x_n="","",COUNTIFS('2.현장'!$AC$2:$AC$1001,x_n,'2.현장'!$T$2:$T$1001,TRUE,'2.현장'!$AA$2:$AA$1001,"★")))) | E4: =MAP(B4:B203,LAMBDA(x_n,IF(x_n="","",MAXIFS('2.현장'!$D$2:$D$1001,'2.현장'!$AC$2:$AC$1001,x_n,'2.현장'!$T$2:$T$1001,TRUE)))) | F4: =MAP(B4:B203,LAMBDA(x_n,IF(x_n="","",IF(MAXIFS('2.현장'!$M$2:$M$1001,'2.현장'!$AC$2:$AC$1001,x_n,'2.현장'!$T$2:$T$1001,TRUE)=0,"",MAXIFS('2.현장'!$M$2:$M$1001,'2.현장'!$AC$2:$AC$1001,x_n,'2.현장'!$T$2:$T$1001,TRUE))))) | G4: =MAP(B4:B203,LAMBDA(x_n,IF(x_n="","",IFERROR(INDEX('2.현장'!$C$2:$C$1001,MATCH(1,('2.현장'!$AC$2:$AC$1001=x_n)*('2.현장'!$T$2:$T$1001=TRUE),0)),"")))) | H4: =MAP(B4:B203,LAMBDA(x_n,IF(x_n="","",IFERROR(INDEX('2.현장'!$N$2:$N$1001,MATCH(1,('2.현장'!$AC$2:$AC$1001=x_n)*('2.현장'!$T$2:$T$1001=TRUE),0)),"")))) | I4: =MAP(B4:B203,LAMBDA(x_n,IF(x_n="","",IFERROR(INDEX('2.현장'!$G$2:$G$1001,MATCH(1,('2.현장'!$AC$2:$AC$1001=x_n)*('2.현장'!$T$2:$T$1001=TRUE),0)),"")))) | J4: =MAP(B4:B203,LAMBDA(x_n,IF(x_n="","",IFERROR(VLOOKUP(x_n,업체_메모!$A$3:$I$302,2,FALSE)&"","")))) | K4: =MAP(B4:B203,LAMBDA(x_n,IF(x_n="","",IFERROR(VLOOKUP(x_n,업체_메모!$A$3:$I$302,4,FALSE)&"","")))) | L4: =MAP(B4:B203,LAMBDA(x_n,IF(x_n="","",IF(COUNTIF('4.방문기록'!$B$3:$B$502,x_n)=0,"",MAXIFS('4.방문기록'!$A$3:$A$502,'4.방문기록'!$B$3:$B$502,x_n))))) | M4: =MAP(L4:L203,LAMBDA(x_o,IF(x_o="","",설정!$B$24-x_o))) | N4: =MAP(B4:B203,L4:L203,LAMBDA(x_n,x_o,IF(x_o="","",IFERROR(INDEX('4.방문기록'!$H$3:$H$502,MATCH(x_n&"|"&(x_o*1),'4.방문기록'!$I$3:$I$502,0))&"","")))) | O4: =MAP(B4:B203,L4:L203,M4:M203,N4:N203,LAMBDA(x_n,x_o,x_p,x_rr,IF(x_n="","",IF(x_rr="관심 없음","제외",IF(x_o="","안 가봄",IF(x_p>=설정!$B$20,x_p&"일 지남","최근 방문"))))))

Sheet 4.방문기록
A1: 방문·통화 기록 — 다녀오시면 한 줄 (날짜·업체·결과만 넣어도 됩니다). 설계사·시공사 모두
A2: 날짜 | B2: 업체(설계사·시공사) | C2: 관련 현장 | D2: 만난 사람 | E2: 들은 것 | F2: 다음 약속일 | G2: 다음 할 것 | H2: 결과 | I2: 키(자동) | J2: 목록에없음(자동)
I3: =MAP(A3:A502,B3:B502,LAMBDA(x_a,x_b,IF(x_a="","",x_b&"|"&(x_a*1)))) | J3: =MAP(B3:B502,LAMBDA(x_b,IF(x_b="",0,IF(COUNTIF('3.설계사'!$B$4:$B$303,x_b)+COUNTIF('3b.시공사'!$B$4:$B$203,x_b)=0,1,0))))

Sheet 7.문안
A1: 보낼 문안 — B3 에서 업체를 고르면 채워집니다(비우면 5번 1순위). [ ] 칸만 고쳐서 복사
A3: 업체 고르기
A5: 쓰는 이름 | B5: =IF(B3<>"",B3,IFERROR('5.이번주_갈곳'!B4&"",""))
A6: 대표 현장 | B6: =IFERROR(INDEX('3.설계사'!$K$4:$K$303,MATCH(B5,'3.설계사'!$B$4:$B$303,0))&"",IFERROR(INDEX('3b.시공사'!$G$4:$G$203,MATCH(B5,'3b.시공사'!$B$4:$B$203,0))&"","[현장명]"))
A7: 담당자 | B7: =IF(IFERROR(VLOOKUP(B5,업체_메모!$A$3:$I$302,2,FALSE)&"","")="","[담당자]",IFERROR(VLOOKUP(B5,업체_메모!$A$3:$I$302,2,FALSE)&"",""))
A8: 객실 수 | B8: =IFERROR(IF(AND(VLOOKUP(B6,현장_조사!$A$3:$J$202,5,FALSE)&""<>"",VLOOKUP(B6,현장_조사!$A$3:$J$202,8,FALSE)="확정"),VLOOKUP(B6,현장_조사!$A$3:$J$202,5,FALSE)&"","[객실 수]"),"[객실 수]") | C8: 현장_조사 확신도가 「확정」 일 때만 자동으로 넣음(추정 숫자가 대외 메일로 나가지 않게)
A9: 전화(업체) | B9: =IF(IFERROR(VLOOKUP(B5,업체_메모!$A$3:$I$302,4,FALSE)&"","")="","[업체 전화]",IFERROR(VLOOKUP(B5,업체_메모!$A$3:$I$302,4,FALSE)&"",""))
A11: 전화 첫마디 | B11: ="한국마이크로닉 배성윤 차장입니다. "&B6&" 설계하신 걸로 알고 연락드렸습니다. 호텔 객실관리(키센서·온도조절기·조명 제어) 도면과 특기시방서를 무상으로 지원해 드리고 있어서, [날짜]에 10분만 찾아뵈어도 될까요?"
A12: 문자(짧게) | B12: ="[한국마이크로닉 배성윤 차장] "&B7&"님, "&B6&" 객실관리시스템 설계(도면·특기시방서)를 무상 지원해 드립니다. [날짜] 잠시 찾아뵈어도 될지 여쭙습니다. [내 전화]"
A13: 메일 제목 | B13: =B6&" 객실관리시스템 설계 지원 안내 — 한국마이크로닉(주)"
A14: 메일 본문 | B14: =B5&" "&B7&"님께"&CHAR(10)&CHAR(10)&"한국마이크로닉(주) 배성윤 차장입니다."&CHAR(10)&"진행 중이신 "&B6&"("&B8&"실)의 객실관리시스템(RCU·CB함·키센서·온도조절기·조명스위치) 설계를 무상으로 지원해 드립니다."&CHAR(10)&CHAR(10)&"- 단위세대 평면도를 주시면 성급 기준으로 기구물 배치와 예상 수량표를 드립니다."&CHAR(10)&"- 특기시방서(한글 파일)를 현장에 맞춰 드립니다."&CHAR(10)&"- 전기설계업체용 설계 요청서도 함께 드립니다."&CHAR(10)&CHAR(10)&"[날짜] 중 편하신 시간에 찾아뵙겠습니다."&CHAR(10)&CHAR(10)&"한국마이크로닉(주) 배성윤 드림 / [내 전화]"
A15: 방문 후 감사 문자 | B15: ="[한국마이크로닉 배성윤] 오늘 시간 내주셔서 감사합니다. 말씀하신 "&B6&" 자료는 [날짜]까지 보내 드리겠습니다."

Sheet 업체_메모
A1: 업체 담당자 메모 — 설계사·시공사 모두. 이름은 3번·3b번 탭 글자와 똑같이
A2: 업체명(시트 표기) | B2: 담당자 | C2: 직함 | D2: 전화 | E2: 이메일 | F2: 주소·지역 | G2: 메모 | H2: 확신도 | I2: 출처 | J2: ← 노란 칸 대신 2행 아래 아무 줄에나 입력
A3: 상지이앤에이건축… | D3: 051-247-0208 (또는 051-461-4114 — 확인 필요) | F3: 부산 중구 자갈치로 42 513호(남포동5가, 신동아빌딩) | G3: 정식 이름 추정: (주)상지이앤에이건축사사무소(2003 부산 설립, 상지엔지니어링건축사사무소 계열). 홈페이지 sangji21c.co.kr. 번호 2개가 갈려 방문 전 확인 | H3: 추정 | I3: saramin.co.kr 기업정보 / jobplanet.co.kr/companies/90750 / busan.com 2024-04-06 기사
A4: 아이디어키텍… | F4: 서울 용산구 한강대로48길 7, 2층 | G4: 정식 이름 추정: (주)아이디아키텍츠건축사사무소(idarchi.kr). 종로5가 16층 관광숙박 4,482㎡ 와 연결된 자료 있음(주택폴리오). 태재연구재단 관계 미확인 | H4: 추정 | I4: jootek.com/folio/1005037 / idarchi.kr
A5: 이진건축사사무소 | F5: 부산 부산진구 서면문화로 27 유원골든타워 1515호(부전동) | G5: 현장(부전동)과 같은 동네 | H5: 추정 | I5: bizno.net 검색 결과
A6: 오파드건축연구소 | B6: 오문석(대표) | C6: 대표 | D6: 070-8600-0463 | F6: 서울 도봉구 우이천로38마길 7-5 1층(쌍문동) | G6: 현장 301㎡로 ✕(면적 미달) — 갈 곳 목록엔 안 나옴. 산군 등록명 「오파드건축사사무소」 | H6: 추정 | I6: a-platform.co.kr archigroup / bizno.net/article/1191622328
A7: 세움건축사사무소 | F7: 강원 홍천군 홍천읍 희망리 91-4 | G7: 현장 97㎡로 ✕. 주택·근생·창고 위주. 동명 사무소 많음 | H7: 추정 | I7: jootek.com/folio/1020726
A8: 태건축사사무소 | G8: 검색으로 못 찾음. 비슷한 이름(고양 태종합건축사사무소 등)은 음성 현장과 연결 근거 없음 → 산군 설계사 상세 화면 또는 대한건축사협회 회원찾기(kira.or.kr) | H8: 미확인 | I8: taearchitects.com / taadg.com (다른 사무소 가능성 높음)
A9: 파인드건축사사무소 | G9: 검색으로 못 찾음 → 산군 설계사 상세 화면 또는 kira.or.kr 회원찾기 | H9: 미확인
A10: 야촌건축사사무소 | G10: 검색으로 못 찾음. 비슷한 이름 (주)예촌건축(yeachon.com)은 같은 곳 근거 없음 | H10: 미확인 | I10: yeachon.com
A11: 건축사무소고강 | G11: 검색으로 못 찾음 → kira.or.kr 회원찾기 | H11: 미확인

Sheet 현장_조사
A1: 현장 조사노트 — 웹검색 결과(출처 포함). 현장명은 2.현장의 현장명과 똑같이. 확신도 : 확정 / 추정 / 미확인
A2: 현장명(산군 표기) | B2: 사업명·브랜드 | C2: 발주처(시행) | D2: 시공사 | E2: 객실 수 | F2: 준공 예정 | G2: 최신 상황 | H2: 확신도 | I2: 출처 | J2: 조사일
A3: 범방동 1898-7 생활숙박시설 | B3: 부산 범방동 생활형숙박시설 신축공사(적산 자료명) | C3: 미확인 | D3: 미확인 | E3: 460 | F3: 미확인 | G3: 자료상 지번 1898-1, 연면적 약 22,470㎡·지하2~지상27층 — 산군 값과 거의 같으나 지번 불일치 | H3: 추정 | I3: thinkzon.com/share_biz/1161340 (검색 요약만) | J3: 2026-09-27
A4: 대소면 성본리 115-5 숙박시설 | C4: 미확인 | D4: 미확인 | F4: 미확인 | G4: 성본산단 배후 개발 중이라는 것만 확인. 현장 자체 기사 없음 | H4: 미확인 | I4: biz.heraldcorp.com/article/10867296 | J4: 2026-09-27
A5: 조양동 1558-3 생활숙박시설 | C5: 미확인 | D5: 미확인 | F5: 미확인 | G5: 조양동 다른 생숙(1464-5 한라 724실, 하워드존슨 1111-1, 리슈빌S 1452)은 번지가 달라 별건 | H5: 미확인 | I5: etoday.co.kr/news/view/1645764 외 | J5: 2026-09-27
A6: 명동2가 95-1 생활숙박시설 신축공사 | C6: 미확인(시경개발 역할 미확인) | D6: 미확인 | F6: 미확인 | G6: 이 주소 생숙 기사 없음. 명동2가 89 호텔(75실)은 별건 | H6: 미확인 | I6: etoday.co.kr/news/view/1687748 | J6: 2026-09-27
A7: 부산시 중구 남포동3가 생활형숙박시설 | B7: 후보: 와이컬렉션 바이 남포 | C7: 미확인(평광이앤씨 역할 미확인) | D7: 미확인 | E7: 276 | F7: 미확인 | G7: 지하2~지상27층, 운영사 ㈜지냄(야놀자 투자), 분양 홍보 중. 번지 일치 미확인 | H7: 추정 | I7: enetnews.co.kr/news/articleView.html?idxno=54525 / theviewers.co.kr 4228259 | J7: 2026-09-27
A8: 경서동 경서3구역 11블록 2로트 숙박시설 | C8: 미확인 | D8: 미확인 | F8: 미확인 | G8: 경서3구역 보람그룹 5성급 호텔 MOU(2024.2)는 규모가 달라 별건 가능성 높음 | H8: 미확인 | I8: joongboo.com 363725457 / 1gan.co.kr 236208 | J8: 2026-09-27
A9: 종로5가 193-17,3번지 관광숙박시설 | C9: 미확인(태재연구재단 역할 미확인) | D9: 미확인 | F9: 미확인 | G9: 16층 관광숙박 4,482㎡ — 설계 (주)아이디아키텍츠 연결 자료. 종로5가 138-4 호텔(360실)은 무산된 다른 부지 | H9: 미확인 | I9: jootek.com/folio/1005037 / etoday.co.kr/news/view/876222 | J9: 2026-09-27
A10: 부전동 숙박시설 | C10: 미확인 | D10: 미확인 | F10: 미확인 | G10: 기존 모텔 정보만 나옴 | H10: 미확인 | J10: 2026-09-27

Sheet 2.현장
A1: 원본행 | B1: 주소 | C1: 현장명 | D1: 연면적(㎡) | E1: 주용도 | F1: 허가구분 | G1: 설계사 | H1: 시공사 | I1: 감리 | J1: 건축주 | K1: 공사단계 | L1: 허가일 | M1: 착공일 | N1: 시·도 | O1: 유효 | P1: 키 | Q1: 최신 | R1: 용도맞음 | S1: 면적맞음 | T1: 대상 | U1: 누구를 만나나 | V1: 설계사(정리) | W1: (안 씀) | X1: 허가일원문 | Y1: 착공일원문 | Z1: 대상키 | AA1: 판정 | AB1: 현장점수 | AC1: 시공사(정리) | AD1: 연면적원문
A2: =SEQUENCE(1000,1,2) | B2: =IF(설정!$C$4="","",ARRAYFORMULA(IFERROR(INDEX('1.산군_붙여넣기'!$A$2:$AZ$1001,0,설정!$C$4)&"",""))) | C2: =IF(설정!$C$5="","",ARRAYFORMULA(IFERROR(INDEX('1.산군_붙여넣기'!$A$2:$AZ$1001,0,설정!$C$5)&"",""))) | D2: =MAP($AD$2:$AD$1001,LAMBDA(x_a,IFERROR(VALUE(SUBSTITUTE(SUBSTITUTE(SUBSTITUTE(x_a,",",""),"㎡",""),"m2","")),""))) | E2: =IF(설정!$C$7="","",ARRAYFORMULA(IFERROR(INDEX('1.산군_붙여넣기'!$A$2:$AZ$1001,0,설정!$C$7)&"",""))) | F2: =IF(설정!$C$8="","",ARRAYFORMULA(IFERROR(INDEX('1.산군_붙여넣기'!$A$2:$AZ$1001,0,설정!$C$8)&"",""))) | G2: =IF(설정!$C$9="","",ARRAYFORMULA(IFERROR(INDEX('1.산군_붙여넣기'!$A$2:$AZ$1001,0,설정!$C$9)&"",""))) | H2: =IF(설정!$C$10="","",ARRAYFORMULA(IFERROR(INDEX('1.산군_붙여넣기'!$A$2:$AZ$1001,0,설정!$C$10)&"",""))) | I2: =IF(설정!$C$11="","",ARRAYFORMULA(IFERROR(INDEX('1.산군_붙여넣기'!$A$2:$AZ$1001,0,설정!$C$11)&"",""))) | J2: =IF(설정!$C$12="","",ARRAYFORMULA(IFERROR(INDEX('1.산군_붙여넣기'!$A$2:$AZ$1001,0,설정!$C$12)&"",""))) | K2: =IF(설정!$C$13="","",ARRAYFORMULA(IFERROR(INDEX('1.산군_붙여넣기'!$A$2:$AZ$1001,0,설정!$C$13)&"",""))) | L2: =MAP($X$2:$X$1001,LAMBDA(x_t,IF(x_t="","",IF(AND(LEN(x_t)=8,ISNUMBER(x_t*1)),DATE(LEFT(x_t,4),MID(x_t,5,2),RIGHT(x_t,2)),IFERROR(DATEVALUE(SUBSTITUTE(SUBSTITUTE(x_t,".","-"),"/","-")),IFERROR(x_t*1,"")))))) | M2: =MAP($Y$2:$Y$1001,LAMBDA(x_t,IF(x_t="","",IF(AND(LEN(x_t)=8,ISNUMBER(x_t*1)),DATE(LEFT(x_t,4),MID(x_t,5,2),RIGHT(x_t,2)),IFERROR(DATEVALUE(SUBSTITUTE(SUBSTITUTE(x_t,".","-"),"/","-")),IFERROR(x_t*1,"")))))) | N2: =MAP($B$2:$B$1001,LAMBDA(x_b,IFERROR(LEFT(x_b,FIND(" ",x_b)-1),x_b))) | O2: =MAP($B$2:$B$1001,$C$2:$C$1001,LAMBDA(x_b,x_cc,AND(x_b<>"",x_b<>설정!$B$4,x_cc<>설정!$B$5))) | P2: =MAP($B$2:$B$1001,$C$2:$C$1001,$O$2:$O$1001,LAMBDA(x_b,x_cc,x_o,IF(x_o,x_b&"|"&x_cc,""))) | Q2: =MAP($P$2:$P$1001,$A$2:$A$1001,LAMBDA(x_k,x_rw,IF(x_k="",FALSE,SUMPRODUCT(($P$2:$P$1001=x_k)*($A$2:$A$1001>x_rw))=0))) | R2: =MAP($E$2:$E$1001,$C$2:$C$1001,LAMBDA(x_e,x_cc,SUMPRODUCT((설정!$A$42:$A$51<>"")*ISNUMBER(SEARCH(설정!$A$42:$A$51,x_e&" "&x_cc)))>0)) | S2: =MAP($D$2:$D$1001,LAMBDA(x_d,OR(x_d="",x_d>=설정!$B$19))) | T2: =MAP($Q$2:$Q$1001,$R$2:$R$1001,$S$2:$S$1001,LAMBDA(x_q,x_u,x_s,AND(x_q,x_u,x_s))) | U2: =MAP($T$2:$T$1001,$K$2:$K$1001,$M$2:$M$1001,LAMBDA(x_g,x_k,x_m,IF(NOT(x_g),"",LET(x_hit,IFERROR(INDEX(FILTER(설정!$B$54:$B$61,(설정!$A$54:$A$61<>"")*ISNUMBER(SEARCH(설정!$A$54:$A$61,x_k))),1),""),IF(x_hit<>"",x_hit,IF(x_m="","설계사","시공사")))))) | V2: =MAP($G$2:$G$1001,LAMBDA(x_n,SUBSTITUTE(SUBSTITUTE(SUBSTITUTE(SUBSTITUTE(x_n,"(주)",""),"㈜",""),"주식회사","")," ",""))) | X2: =IF(설정!$C$14="","",ARRAYFORMULA(IFERROR(INDEX('1.산군_붙여넣기'!$A$2:$AZ$1001,0,설정!$C$14)&"",""))) | Y2: =IF(설정!$C$15="","",ARRAYFORMULA(IFERROR(INDEX('1.산군_붙여넣기'!$A$2:$AZ$1001,0,설정!$C$15)&"",""))) | Z2: =MAP($T$2:$T$1001,$V$2:$V$1001,$U$2:$U$1001,LAMBDA(x_g,x_v,x_w,IF(x_g,x_v&"|"&x_w,""))) | AA2: =MAP($Q$2:$Q$1001,$R$2:$R$1001,$S$2:$S$1001,$D$2:$D$1001,$L$2:$L$1001,$M$2:$M$1001,LAMBDA(x_q,x_u,x_s,x_d,x_l,x_m,IF(NOT(x_q),"",IF(NOT(AND(x_u,x_s)),"✕",IF(OR(AND(x_l<>"",x_m<>"",N(x_m)-N(x_l)>설정!$B$27),AND(x_l<>"",x_m="",설정!$B$24-N(x_l)>설정!$B$27),AND(x_d<>"",N(x_d)<설정!$B$26)),"△","★"))))) | AB2: =MAP($T$2:$T$1001,$U$2:$U$1001,$M$2:$M$1001,$AA$2:$AA$1001,LAMBDA(x_g,x_w,x_m,x_j,IF(NOT(x_g),"",IF(x_w="설계사",설정!$B$31,IF(x_w="시공사",IF(OR(x_m="",설정!$B$24-N(x_m)<=설정!$B$28*30.4),설정!$B$32,설정!$B$33),설정!$B$34))+IF(x_j="★",설정!$B$35,0)))) | AC2: =MAP($H$2:$H$1001,LAMBDA(x_n,SUBSTITUTE(SUBSTITUTE(SUBSTITUTE(SUBSTITUTE(x_n,"(주)",""),"㈜",""),"주식회사","")," ",""))) | AD2: =IF(설정!$C$6="","",ARRAYFORMULA(IFERROR(INDEX('1.산군_붙여넣기'!$A$2:$AZ$1001,0,설정!$C$6)&"","")))

Sheet 6.본전계산
A1: 산군 본전 계산 — 기준 숫자는 프로님이 넣으십시오(노란 칸)
A3: 항목 | B3: 값 | C3: 메모
A4: 산군 사용 시작일 | B4: =IF(설정!$B$23="","",설정!$B$23) | C4: 설정 탭
A5: 쓴 개월 수 | B5: =IF(설정!$B$23="","시작일을 넣으십시오",DATEDIF(설정!$B$23,설정!$B$24,"m")+1)
A6: 누적 비용(원) | B6: =IF(ISNUMBER(B5),B5*설정!$B$22,"") | C6: 월 요금 × 개월
A7: 월결제 1년 vs 연결제 차액(원) | B7: =설정!$B$22*12-설정!$B$25 | C7: 연결제로 바꾸면 아끼는 돈
A8: 산군으로 잡힌 설계사무소(곳) | B8: =COUNTIF('3.설계사'!$B$4:$B$303,"?*") | C8: 자동
A9: 그중 한 번이라도 간 곳 | B9: =COUNTIF('3.설계사'!$O$4:$O$303,">0") | C9: 자동
A10: 방문·통화 건수 | B10: =COUNT('4.방문기록'!$A$3:$A$502) | C10: 자동
A11: 설계의뢰 받음 | B11: =COUNTIF('4.방문기록'!$H$3:$H$502,"설계의뢰 받음") | C11: 자동
A12: 도면 받음 | B12: =COUNTIF('4.방문기록'!$H$3:$H$502,"도면 받음") | C12: 자동
A13: 방문 1건당 산군 비용(원) | B13: =IF(AND(ISNUMBER(B6),B10>0),B6/B10,"")
A14: ★ 현장 수(지금 붙여넣은 자료) | B14: =COUNTIF('2.현장'!$AA$2:$AA$1001,"★") | C14: 자동
A17: 유지 판단 기준(3개월 기준 권장)
A18: 기준 | B18: 넣으실 숫자 | C18: 실제 | D18: 통과
A19: 간 설계사무소 최소(곳) | C19: =B9 | D19: =IF(B19="","",IF(C19>=B19,"통과","미달"))
A20: 설계의뢰 받음 최소(건) | C20: =B11 | D20: =IF(B20="","",IF(C20>=B20,"통과","미달"))
A21: 도면 받음 최소(건) | C21: =B12 | D21: =IF(B21="","",IF(C21>=B21,"통과","미달"))
A23: 판정 | B23: =IF(COUNTA(B19:B21)=0,"기준 숫자를 넣으시면 판정합니다",IF(COUNTIF(D19:D21,"미달")=0,"유지","미달 있음 — 해지 또는 조건 변경 검토"))

Sheet 설정
A1: 설정 — 노란 칸만 고치십시오
A3: 항목 | B3: 산군 엑셀의 열 이름(1행 글자 그대로, 없으면 비움) | C3: 찾은 열 번호 | D3: 상태
A4: 주소 ★필수 | B4: 소재지 | C4: =IF(B4="","",IFERROR(MATCH(B4,'1.산군_붙여넣기'!$1:$1,0),"")) | D4: =IF(B4="","안 씀(비움)",IF(C4="","못 찾음 — B칸을 산군 엑셀 1행 글자와 똑같이","정상"))
A5: 건물명 ★필수 | B5: 현장명 | C5: =IF(B5="","",IFERROR(MATCH(B5,'1.산군_붙여넣기'!$1:$1,0),"")) | D5: =IF(B5="","안 씀(비움)",IF(C5="","못 찾음 — B칸을 산군 엑셀 1행 글자와 똑같이","정상"))
A6: 연면적 ★필수 | B6: 연면적㎡ | C6: =IF(B6="","",IFERROR(MATCH(B6,'1.산군_붙여넣기'!$1:$1,0),"")) | D6: =IF(B6="","안 씀(비움)",IF(C6="","못 찾음 — B칸을 산군 엑셀 1행 글자와 똑같이","정상"))
A7: 주용도 ★필수 | B7: 용도 | C7: =IF(B7="","",IFERROR(MATCH(B7,'1.산군_붙여넣기'!$1:$1,0),"")) | D7: =IF(B7="","안 씀(비움)",IF(C7="","못 찾음 — B칸을 산군 엑셀 1행 글자와 똑같이","정상"))
A8: 허가구분 | B8: 구분 | C8: =IF(B8="","",IFERROR(MATCH(B8,'1.산군_붙여넣기'!$1:$1,0),"")) | D8: =IF(B8="","안 씀(비움)",IF(C8="","못 찾음 — B칸을 산군 엑셀 1행 글자와 똑같이","정상"))
A9: 설계사 ★필수 | B9: 건축설계 | C9: =IF(B9="","",IFERROR(MATCH(B9,'1.산군_붙여넣기'!$1:$1,0),"")) | D9: =IF(B9="","안 씀(비움)",IF(C9="","못 찾음 — B칸을 산군 엑셀 1행 글자와 똑같이","정상"))
A10: 시공사 | B10: 열J(미확인) | C10: =IF(B10="","",IFERROR(MATCH(B10,'1.산군_붙여넣기'!$1:$1,0),"")) | D10: =IF(B10="","안 씀(비움)",IF(C10="","못 찾음 — B칸을 산군 엑셀 1행 글자와 똑같이","정상"))
A11: 감리 | C11: =IF(B11="","",IFERROR(MATCH(B11,'1.산군_붙여넣기'!$1:$1,0),"")) | D11: =IF(B11="","안 씀(비움)",IF(C11="","못 찾음 — B칸을 산군 엑셀 1행 글자와 똑같이","정상"))
A12: 건축주 | C12: =IF(B12="","",IFERROR(MATCH(B12,'1.산군_붙여넣기'!$1:$1,0),"")) | D12: =IF(B12="","안 씀(비움)",IF(C12="","못 찾음 — B칸을 산군 엑셀 1행 글자와 똑같이","정상"))
A13: 공사단계 ★필수 | B13: 단계 | C13: =IF(B13="","",IFERROR(MATCH(B13,'1.산군_붙여넣기'!$1:$1,0),"")) | D13: =IF(B13="","안 씀(비움)",IF(C13="","못 찾음 — B칸을 산군 엑셀 1행 글자와 똑같이","정상"))
A14: 허가일 | B14: 날짜1(추정:허가일) | C14: =IF(B14="","",IFERROR(MATCH(B14,'1.산군_붙여넣기'!$1:$1,0),"")) | D14: =IF(B14="","안 씀(비움)",IF(C14="","못 찾음 — B칸을 산군 엑셀 1행 글자와 똑같이","정상"))
A15: 착공일 | B15: 날짜2(추정:착공일) | C15: =IF(B15="","",IFERROR(MATCH(B15,'1.산군_붙여넣기'!$1:$1,0),"")) | D15: =IF(B15="","안 씀(비움)",IF(C15="","못 찾음 — B칸을 산군 엑셀 1행 글자와 똑같이","정상"))
A18: 숫자 입력칸
A19: 연면적 최소(㎡) — 이보다 작으면 ✕ | B19: 1500 | C19: 신규 현장 레이더 숙박 기준(프로님 확정값)
A20: 재방문 간격(일) | B20: 14 | C20: 0번 목록 32 「다녀오신 지 14일」
A21: 이번 주 지역(비우면 전국) — 시·도 첫 단어, 예: 서울특별시 | C21: 5번 탭을 이 지역만 보기
A22: 산군 월 요금(원) | B22: 90000 | C22: 2026-09-27 검색 확인
A23: 산군 사용 시작일 | C23: 넣으시면 6.본전계산이 누적 비용을 냅니다(9/4 통화: 결제 완료 확인)
A24: 오늘 날짜 | B24: =TODAY() | C24: 자동
A25: 산군 연결제 금액(원) | B25: 864000 | C25: 2026-09-27 검색 확인(연 20% 할인)
A26: ★ 연면적 기준(㎡) — 이 이상이고 표류가 아니면 ★ | B26: 4000 | C26: 9/14 캡처 판정(2,596㎡=△, 4,482㎡=★)에서 역산한 추정값 — 고쳐 주십시오
A27: 표류 기준(일) — 허가→착공(착공 없으면 허가→오늘)이 이보다 길면 △ | B27: 1200 | C27: 9/14 캡처 판정 8건과 모두 맞는 경계값(△ 1,295·1,464일 / ★ 1,083·1,096일) — 추정
A28: 착공 「최근」 기준(개월) | B28: 6 | C28: 이 안에 착공한 현장은 아직 기구물 사양을 넣을 여지가 있다고 보고 점수를 줌
A30: 순위 점수 가중치 (5.이번주_갈곳 순서를 정함)
A31: 설계단계 현장 1건 | B31: 10 | C31: Claude 초안값 — 쓰시면서 고쳐 주십시오
A32: 최근 착공 현장 1건 | B32: 6 | C32: Claude 초안값 — 쓰시면서 고쳐 주십시오
A33: 오래된 착공 현장 1건 | B33: 2 | C33: Claude 초안값 — 쓰시면서 고쳐 주십시오
A34: 마감·준공 현장 1건 | B34: 0 | C34: Claude 초안값 — 쓰시면서 고쳐 주십시오
A35: ★ 현장 1건 추가 | B35: 5 | C35: Claude 초안값 — 쓰시면서 고쳐 주십시오
A36: 안 가본 곳 가산 | B36: 30 | C36: Claude 초안값 — 쓰시면서 고쳐 주십시오
A37: 마지막 방문 뒤 1일당(최대 60일) | B37: 0.5 | C37: Claude 초안값 — 쓰시면서 고쳐 주십시오
A38: 최대 연면적 1,000㎡당(최대 20점) | B38: 1 | C38: Claude 초안값 — 쓰시면서 고쳐 주십시오
A39: 7일 안 약속 | B39: 100 | C39: Claude 초안값 — 쓰시면서 고쳐 주십시오
A41: 대상 용도 키워드(주용도·현장명에 이 글자가 있으면 대상) — 10칸
A42: 숙박
A43: 호텔
A44: 리조트
A45: 콘도
...
