Workbook

Sheet 사용법
A1: 시트 3번 「영업판」 v2 (2026-09-27) — 산군 + 설계사 영업 전용
A3: ■ 프로님 손은 1번 : 매주 월요일 산군 엑셀을 받아 「1.산군_붙여넣기」 탭 A1 칸을 누르고 통째로 붙여넣기(전체 덮어쓰기). 여러 조건으로 받으면 아래로 이어 붙여도 됩니다(같은 주소+현장명은 아래 줄이 이김).
A4: → 2.현장(★△✕ 판정) · 3.설계사 · 3b.시공사 · 5.이번주_갈곳 · 7.문안 · 6.본전계산 이 저절로 바뀝니다.
A5: ■ 처음 한 번만 : 「설정」 탭 B4~B15 에 산군 엑셀 1행의 열 이름을 똑같이 적기. 지금은 9/14 산군 화면 캡처의 열 이름입니다. 「0.자가진단」 1번이 「통과」 면 끝.
A6: ■ 지금 1번 탭에 들어 있는 11줄 = 2026-09-14 산군 캡처 실제 자료(드라이브 산군/산군_관심현장 v1). 설계사 이름 2곳은 캡처에서 잘려 「…」 로 끝납니다.
A7: ■ 다녀오시면 : 「4.방문기록」 에 한 줄(날짜·업체·결과). 결과를 「관심 없음」 으로 고르면 갈 곳 목록에서 빠집니다. 설계사·시공사 모두 여기에 적습니다.
A8: ■ 담당자·전화 : 「업체_메모」 에 한 줄. 웹검색으로 찾은 대표전화는 출처와 함께 미리 넣어 두었습니다(확신도 칸 확인).
A9: ■ 현장 뉴스 : 「현장_조사」 탭 = 발주처·시공사·객실 수·최신 상황(웹검색, 출처 포함). 객실 수는 7.문안에 자동으로 들어갑니다.
A10: ■ 전화·메일 문안 : 「7.문안」 B3 에서 업체를 고르면(비우면 5번 1순위) 전화 첫마디·문자·메일·감사 문자가 채워집니다.
A11: ■ 판정 : ✕ = 용도 아님 또는 연면적 미달 / △ = 허가→착공 표류 또는 ★ 기준 미만 / ★ = 나머지. 기준 숫자는 설정 탭.
A12: ■ 누구를 만나나 : 허가·설계 단계 → 설계사무소 / 착공 이후 → 시공사(설계사도 최근 착공이면 점수 있음) / 마감·준공 → 늦음.
A13: ■ 순위 점수 가중치는 전부 「설정」 탭 노란 칸입니다. 노란 칸 = 프로님 입력 / 초록 칸 = 자동(건드리지 않음).
... A15: ■ 바꿀 때는 덮어쓰지 않고 새 판으로 냅니다. 변경 이력은 「0.자가진단」 아래.

Sheet 0.자가진단
A1: 자가진단 — 전부 「통과」 면 정상 (v2)
A3: 번호 | B3: 검사 | C3: 값 | D3: 판정
A4: 1 | B4: 필수 열 6개(주소·현장명·연면적·용도·설계사·단계) 중 찾은 수 | C4: =N(설정!$C$4<>"")+N(설정!$C$5<>"")+N(설정!$C$6<>"")+N(설정!$C$7<>"")+N(설정!$C$9<>"")+N(설정!$C$13<>"") | D4: =IF(C4=6,"통과","실패 — 설정 B4~B15 를 산군 엑셀 1행과 맞추기")
A5: 2 | B5: 붙여넣은 줄 수(1행 제외) | C5: =MAX(COUNTA('1.산군_붙여넣기'!B:B)-1,0) | D5: =IF(C5<=1000,"통과","실패 — 1000줄 넘음, 아래는 안 읽힘")
A6: 3 | B6: 읽은 현장 줄 | C6: =COUNTIF('2.현장'!O2:O1001,TRUE) | D6: =IF(C6=C5,"통과","확인 — 빈 줄·제목줄 섞임")
A7: 4 | B7: 중복 뺀 현장 | C7: =COUNTIF('2.현장'!Q2:Q1001,TRUE) | D7: ="참고"
A8: 5 | B8: ★ + △ + ✕ = 중복 뺀 현장 | C8: =COUNTIF('2.현장'!AA2:AA1001,"★")+COUNTIF('2.현장'!AA2:AA1001,"△")+COUNTIF('2.현장'!AA2:AA1001,"✕") | D8: =IF(C8=C7,"통과","실패")
A9: 6 | B9: 대상(용도·면적 맞음) = ★ + △ | C9: =COUNTIF('2.현장'!T2:T1001,TRUE) | D9: =IF(C9=COUNTIF('2.현장'!AA2:AA1001,"★")+COUNTIF('2.현장'!AA2:AA1001,"△"),"통과","실패")
A10: 7 | B10: 설계사행 + 시공사행 + 늦음 = 대상 | C10: =COUNTIF('2.현장'!U2:U1001,"설계사")+COUNTIF('2.현장'!U2:U1001,"시공사")+COUNTIF('2.현장'!U2:U1001,"늦음") | D10: =IF(C10=C9,"통과","실패 — 설정 단계 행선지 확인")
A11: 8 | B11: 설계사무소 수 = 번호 최댓값 | C11: =COUNTIF('3.설계사'!B4:B303,"?*") | D11: =IF(C11=MAX('2.현장'!W2:W1001),IF(C11<300,"통과","실패 — 300곳 넘음"),"실패")
A12: 9 | B12: 시공사 수 = 번호 최댓값 | C12: =COUNTIF('3b.시공사'!B4:B203,"?*") | D12: =IF(C12=MAX('2.현장'!AD2:AD1001),IF(C12<200,"통과","실패 — 200곳 넘음"),"실패")
A13: 10 | B13: 설계사 이름 빈 대상 현장 | C13: =COUNTIFS('2.현장'!T2:T1001,TRUE,'2.현장'!V2:V1001,"") | D13: =IF(C13=0,"통과","확인 — 산군에 설계사 없는 현장(2.현장 필터)")
A14: 11 | B14: 방문기록 중 목록에 없는 업체 | C14: =SUM('4.방문기록'!J3:J502) | D14: =IF(C14=0,"통과","확인 — 이름이 3·3b번 탭과 다름")
A15: 12 | B15: 점수 가중치 빈칸 | C15: =COUNTBLANK(설정!B31:B39) | D15: =IF(C15=0,"통과","실패 — 설정 가중치 칸을 채우기")
A16: 13 | B16: 잘린 이름(…) 남음 | C16: =COUNTIF('2.현장'!G2:G1001,"*…*") | D16: =IF(C16=0,"통과","알림 — 캡처에서 잘린 설계사 이름. 엑셀 다운로드로 바꾸면 사라짐")
A19: 변경 이력
A20: 날짜 | B20: 판 | C20: 내용 | D20: 이전 값
A21: 2026-09-27 | B21: v1 | C21: 최초 작성 — 11개 탭. 계획서 v1 구조 그대로. [예시] 가짜 7줄. | D21: 없음
A22: 2026-09-27 | B22: v2 | C22: B: 1번 탭 예시 → 9/14 산군 캡처 실제 11줄 / 설정 열 이름 → 캡처 열 이름 | D22: 예시 열 이름(현장주소·건물명·주용도·설계사…)
A23: 2026-09-27 | B23: v2 | C23: B: 순위 점수 고정값 → 설정 탭 가중치 입력칸 9개 / 착공 현장도 설계사 점수(최근 착공 6, 오래된 착공 2) | D23: 설계단계 수×10 + 안가봄 30 + 경과/2 + 면적/1000 (착공 현장은 0점)
A24: 2026-09-27 | B24: v2 | C24: A: ★△✕ 판정 · 3b.시공사 · 현장_조사 · 업체_메모(설계사_메모 확장, 확신도·출처 칸) · 자가진단 13항목 | D24: —
A25: 2026-09-27 | B25: v2 | C25: B: 설계사_메모 → 업체_메모(시공사도 같이) / 방문기록 「설계사무소」 → 「업체」 | D25: 설계사_메모

Sheet 5.이번주_갈곳
A1: ="이번 주 찾아갈 설계사무소 "&COUNT('3.설계사'!U4:U303)&"곳 · 지역: "&IF(설정!$B$21="","전국",설정!$B$21)&" · 기준일 "&TEXT(설정!$B$24,"yyyy-mm-dd")
A2: 순서 : ①7일 안 약속 ②현장점수(설계단계>최근 착공>오래된 착공, ★ 가산) + 안 가본 곳 ③오래 안 간 곳. 관심 없음·최근 방문은 빠짐. 가중치·지역은 설정 탭.
A3: 순위 | B3: 설계사무소 | C3: 왜 가야 하나 | D3: 대표 현장 | E3: 지역 | F3: 최대 연면적 | G3: 객실 수(조사) | H3: 담당자 | I3: 전화 | J3: 전화 첫마디(복사) | K3: _행
A4: =IF(K4="","",1) | B4: =IF(K4="","",INDEX('3.설계사'!$B$4:$B$303,K4)) | C4: =IF(K4="","",IF(INDEX('3.설계사'!$T$4:$T$303,K4)>=설정!$B$39,"약속 "&TEXT(INDEX('3.설계사'!$Q$4:$Q$303,K4),"m/d")&" · ",IF(INDEX('3.설계사'!$O$4:$O$303,K4)="","아직 안 가봄 · ","마지막 방문 "&INDEX('3.설계사'!$P$4:$P$303,K4)&"일 전 · "))&IF(INDEX('3.설계사'!$D$4:$D$303,K4)>0,"설계단계 "&INDEX('3.설계사'!$D$4:$D$303,K4)&"건 ","")&IF(INDEX('3.설계사'!$E$4:$E$303,K4)>0,"착공 "&INDEX('3.설계사'!$E$4:$E$303,K4)&"건 ","")&IF(INDEX('3.설계사'!$F$4:$F$303,K4)>0,"★"&INDEX('3.설계사'!$F$4:$F$303,K4),"")) | D4: =IF(K4="","",INDEX('3.설계사'!$K$4:$K$303,K4)) | E4: =IF(K4="","",INDEX('3.설계사'!$L$4:$L$303,K4)) | F4: =IF(K4="","",INDEX('3.설계사'!$H$4:$H$303,K4)) | G4: =IF(K4="","",IFERROR(IF(VLOOKUP(D4,현장_조사!$A$3:$J$202,5,FALSE)&""="","",VLOOKUP(D4,현장_조사!$A$3:$J$202,5,FALSE)&IF(VLOOKUP(D4,현장_조사!$A$3:$J$202,8,FALSE)="확정",""," ("&VLOOKUP(D4,현장_조사!$A$3:$J$202,8,FALSE)&")")),"")) | H4: =IF(K4="","",INDEX('3.설계사'!$M$4:$M$303,K4)) | I4: =IF(K4="","",INDEX('3.설계사'!$N$4:$N$303,K4)) | J4: =IF(K4="","","한국마이크로닉 배성윤 차장입니다. "&D4&IF(INDEX('3.설계사'!$D$4:$D$303,K4)>0," 설계 진행하고 계신"," 설계하신")&" 걸로 알고 연락드렸습니다. 호텔 객실관리(키센서·온도조절기·조명 제어) 도면과 특기시방서를 무상으로 지원해 드리고 있어서, 이번 주에 10분만 찾아뵈어도 될까요?") | K4: =IFERROR(MATCH(1,'3.설계사'!$U$4:$U$303,0),"")
A5: =IF(K5="","",2) | B5: =IF(K5="","",INDEX('3.설계사'!$B$4:$B$303,K5)) | C5: =IF(K5="","",IF(INDEX('3.설계사'!$T$4:$T$303,K5)>=설정!$B$39,"약속 "&TEXT(INDEX('3.설계사'!$Q$4:$Q$303,K5),"m/d")&" · ",IF(INDEX('3.설계사'!$O$4:$O$303,K5)="","아직 안 가봄 · ","마지막 방문 "&INDEX('3.설계사'!$P$4:$P$303,K5)&"일 전 · "))&IF(INDEX('3.설계사'!$D$4:$D$303,K5)>0,"설계단계 "&INDEX('3.설계사'!$D$4:$D$303,K5)&"건 ","")&IF(INDEX('3.설계사'!$E$4:$E$303,K5)>0,"착공 "&INDEX('3.설계사'!$E$4:$E$303,K5)&"건 ","")&IF(INDEX('3.설계사'!$F$4:$F$303,K5)>0,"★"&INDEX('3.설계사'!$F$4:$F$303,K5),"")) | D5: =IF(K5="","",INDEX('3.설계사'!$K$4:$K$303,K5)) | E5: =IF(K5="","",INDEX('3.설계사'!$L$4:$L$303,K5)) | F5: =IF(K5="","",INDEX('3.설계사'!$H$4:$H$303,K5)) | G5: =IF(K5="","",IFERROR(IF(VLOOKUP(D5,현장_조사!$A$3:$J$202,5,FALSE)&""="","",VLOOKUP(D5,현장_조사!$A$3:$J$202,5,FALSE)&IF(VLOOKUP(D5,현장_조사!$A$3:$J$202,8,FALSE)="확정",""," ("&VLOOKUP(D5,현장_조사!$A$3:$J$202,8,FALSE)&")")),"")) | H5: =IF(K5="","",INDEX('3.설계사'!$M$4:$M$303,K5)) | I5: =IF(K5="","",INDEX('3.설계사'!$N$4:$N$303,K5)) | J5: =IF(K5="","","한국마이크로닉 배성윤 차장입니다. "&D5&IF(INDEX('3.설계사'!$D$4:$D$303,K5)>0," 설계 진행하고 계신"," 설계하신")&" 걸로 알고 연락드렸습니다. 호텔 객실관리(키센서·온도조절기·조명 제어) 도면과 특기시방서를 무상으로 지원해 드리고 있어서, 이번 주에 10분만 찾아뵈어도 될까요?") | K5: =IFERROR(MATCH(2,'3.설계사'!$U$4:$U$303,0),"")
A6: =IF(K6="","",3) | B6: =IF(K6="","",INDEX('3.설계사'!$B$4:$B$303,K6)) | C6: =IF(K6="","",IF(INDEX('3.설계사'!$T$4:$T$303,K6)>=설정!$B$39,"약속 "&TEXT(INDEX('3.설계사'!$Q$4:$Q$303,K6),"m/d")&" · ",IF(INDEX('3.설계사'!$O$4:$O$303,K6)="","아직 안 가봄 · ","마지막 방문 "&INDEX('3.설계사'!$P$4:$P$303,K6)&"일 전 · "))&IF(INDEX('3.설계사'!$D$4:$D$303,K6)>0,"설계단계 "&INDEX('3.설계사'!$D$4:$D$303,K6)&"건 ","")&IF(INDEX('3.설계사'!$E$4:$E$303,K6)>0,"착공 "&INDEX('3.설계사'!$E$4:$E$303,K6)&"건 ","")&IF(INDEX('3.설계사'!$F$4:$F$303,K6)>0,"★"&INDEX('3.설계사'!$F$4:$F$303,K6),"")) | D6: =IF(K6="","",INDEX('3.설계사'!$K$4:$K$303,K6)) | E6: =IF(K6="","",INDEX('3.설계사'!$L$4:$L$303,K6)) | F6: =IF(K6="","",INDEX('3.설계사'!$H$4:$H$303,K6)) | G6: =IF(K6="","",IFERROR(IF(VLOOKUP(D6,현장_조사!$A$3:$J$202,5,FALSE)&""="","",VLOOKUP(D6,현장_조사!$A$3:$J$202,5,FALSE)&IF(VLOOKUP(D6,현장_조사!$A$3:$J$202,8,FALSE)="확정",""," ("&VLOOKUP(D6,현장_조사!$A$3:$J$202,8,FALSE)&")")),"")) | H6: =IF(K6="","",INDEX('3.설계사'!$M$4:$M$303,K6)) | I6: =IF(K6="","",INDEX('3.설계사'!$N$4:$N$303,K6)) | J6: =IF(K6="","","한국마이크로닉 배성윤 차장입니다. "&D6&IF(INDEX('3.설계사'!$D$4:$D$303,K6)>0," 설계 진행하고 계신"," 설계하신")&" 걸로 알고 연락드렸습니다. 호텔 객실관리(키센서·온도조절기·조명 제어) 도면과 특기시방서를 무상으로 지원해 드리고 있어서, 이번 주에 10분만 찾아뵈어도 될까요?") | K6: =IFERROR(MATCH(3,'3.설계사'!$U$4:$U$303,0),"")
A7: =IF(K7="","",4) | B7: =IF(K7="","",INDEX('3.설계사'!$B$4:$B$303,K7)) | C7: =IF(K7="","",IF(INDEX('3.설계사'!$T$4:$T$303,K7)>=설정!$B$39,"약속 "&TEXT(INDEX('3.설계사'!$Q$4:$Q$303,K7),"m/d")&" · ",IF(INDEX('3.설계사'!$O$4:$O$303,K7)="","아직 안 가봄 · ","마지막 방문 "&INDEX('3.설계사'!$P$4:$P$303,K7)&"일 전 · "))&IF(INDEX('3.설계사'!$D$4:$D$303,K7)>0,"설계단계 "&INDEX('3.설계사'!$D$4:$D$303,K7)&"건 ","")&IF(INDEX('3.설계사'!$E$4:$E$303,K7)>0,"착공 "&INDEX('3.설계사'!$E$4:$E$303,K7)&"건 ","")&IF(INDEX('3.설계사'!$F$4:$F$303,K7)>0,"★"&INDEX('3.설계사'!$F$4:$F$303,K7),"")) | D7: =IF(K7="","",INDEX('3.설계사'!$K$4:$K$303,K7)) | E7: =IF(K7="","",INDEX('3.설계사'!$L$4:$L$303,K7)) | F7: =IF(K7="","",INDEX('3.설계사'!$H$4:$H$303,K7)) | G7: =IF(K7="","",IFERROR(IF(VLOOKUP(D7,현장_조사!$A$3:$J$202,5,FALSE)&""="","",VLOOKUP(D7,현장_조사!$A$3:$J$202,5,FALSE)&IF(VLOOKUP(D7,현장_조사!$A$3:$J$202,8,FALSE)="확정",""," ("&VLOOKUP(D7,현장_조사!$A$3:$J$202,8,FALSE)&")")),"")) | H7: =IF(K7="","",INDEX('3.설계사'!$M$4:$M$303,K7)) | I7: =IF(K7="","",INDEX('3.설계사'!$N$4:$N$303,K7)) | J7: =IF(K7="","","한국마이크로닉 배성윤 차장입니다. "&D7&IF(INDEX('3.설계사'!$D$4:$D$303,K7)>0," 설계 진행하고 계신"," 설계하신")&" 걸로 알고 연락드렸습니다. 호텔 객실관리(키센서·온도조절기·조명 제어) 도면과 특기시방서를 무상으로 지원해 드리고 있어서, 이번 주에 10분만 찾아뵈어도 될까요?") | K7: =IFERROR(MATCH(4,'3.설계사'!$U$4:$U$303,0),"")
A8: =IF(K8="","",5) | B8: =IF(K8="","",INDEX('3.설계사'!$B$4:$B$303,K8)) | C8: =IF(K8="","",IF(INDEX('3.설계사'!$T$4:$T$303,K8)>=설정!$B$39,"약속 "&TEXT(INDEX('3.설계사'!$Q$4:$Q$303,K8),"m/d")&" · ",IF(INDEX('3.설계사'!$O$4:$O$303,K8)="","아직 안 가봄 · ","마지막 방문 "&INDEX('3.설계사'!$P$4:$P$303,K8)&"일 전 · "))&IF(INDEX('3.설계사'!$D$4:$D$303,K8)>0,"설계단계 "&INDEX('3.설계사'!$D$4:$D$303,K8)&"건 ","")&IF(INDEX('3.설계사'!$E$4:$E$303,K8)>0,"착공 "&INDEX('3.설계사'!$E$4:$E$303,K8)&"건 ","")&IF(INDEX('3.설계사'!$F$4:$F$303,K8)>0,"★"&INDEX('3.설계사'!$F$4:$F$303,K8),"")) | D8: =IF(K8="","",INDEX('3.설계사'!$K$4:$K$303,K8)) | E8: =IF(K8="","",INDEX('3.설계사'!$L$4:$L$303,K8)) | F8: =IF(K8="","",INDEX('3.설계사'!$H$4:$H$303,K8)) | G8: =IF(K8="","",IFERROR(IF(VLOOKUP(D8,현장_조사!$A$3:$J$202,5,FALSE)&""="","",VLOOKUP(D8,현장_조사!$A$3:$J$202,5,FALSE)&IF(VLOOKUP(D8,현장_조사!$A$3:$J$202,8,FALSE)="확정",""," ("&VLOOKUP(D8,현장_조사!$A$3:$J$202,8,FALSE)&")")),"")) | H8: =IF(K8="","",INDEX('3.설계사'!$M$4:$M$303,K8)) | I8: =IF(K8="","",INDEX('3.설계사'!$N$4:$N$303,K8)) | J8: =IF(K8="","","한국마이크로닉 배성윤 차장입니다. "&D8&IF(INDEX('3.설계사'!$D$4:$D$303,K8)>0," 설계 진행하고 계신"," 설계하신")&" 걸로 알고 연락드렸습니다. 호텔 객실관리(키센서·온도조절기·조명 제어) 도면과 특기시방서를 무상으로 지원해 드리고 있어서, 이번 주에 10분만 찾아뵈어도 될까요?") | K8: =IFERROR(MATCH(5,'3.설계사'!$U$4:$U$303,0),"")
A9: =IF(K9="","",6) | B9: =IF(K9="","",INDEX('3.설계사'!$B$4:$B$303,K9)) | C9: =IF(K9="","",IF(INDEX('3.설계사'!$T$4:$T$303,K9)>=설정!$B$39,"약속 "&TEXT(INDEX('3.설계사'!$Q$4:$Q$303,K9),"m/d")&" · ",IF(INDEX('3.설계사'!$O$4:$O$303,K9)="","아직 안 가봄 · ","마지막 방문 "&INDEX('3.설계사'!$P$4:$P$303,K9)&"일 전 · "))&IF(INDEX('3.설계사'!$D$4:$D$303,K9)>0,"설계단계 "&INDEX('3.설계사'!$D$4:$D$303,K9)&"건 ","")&IF(INDEX('3.설계사'!$E$4:$E$303,K9)>0,"착공 "&INDEX('3.설계사'!$E$4:$E$303,K9)&"건 ","")&IF(INDEX('3.설계사'!$F$4:$F$303,K9)>0,"★"&INDEX('3.설계사'!$F$4:$F$303,K9),"")) | D9: =IF(K9="","",INDEX('3.설계사'!$K$4:$K$303,K9)) | E9: =IF(K9="","",INDEX('3.설계사'!$L$4:$L$303,K9)) | F9: =IF(K9="","",INDEX('3.설계사'!$H$4:$H$303,K9)) | G9: =IF(K9="","",IFERROR(IF(VLOOKUP(D9,현장_조사!$A$3:$J$202,5,FALSE)&""="","",VLOOKUP(D9,현장_조사!$A$3:$J$202,5,FALSE)&IF(VLOOKUP(D9,현장_조사!$A$3:$J$202,8,FALSE)="확정",""," ("&VLOOKUP(D9,현장_조사!$A$3:$J$202,8,FALSE)&")")),"")) | H9: =IF(K9="","",INDEX('3.설계사'!$M$4:$M$303,K9)) | I9: =IF(K9="","",INDEX('3.설계사'!$N$4:$N$303,K9)) | J9: =IF(K9="","","한국마이크로닉 배성윤 차장입니다. "&D9&IF(INDEX('3.설계사'!$D$4:$D$303,K9)>0," 설계 진행하고 계신"," 설계하신")&" 걸로 알고 연락드렸습니다. 호텔 객실관리(키센서·온도조절기·조명 제어) 도면과 특기시방서를 무상으로 지원해 드리고 있어서, 이번 주에 10분만 찾아뵈어도 될까요?") | K9: =IFERROR(MATCH(6,'3.설계사'!$U$4:$U$303,0),"")
A10: =IF(K10="","",7) | B10: =IF(K10="","",INDEX('3.설계사'!$B$4:$B$303,K10)) | C10: =IF(K10="","",IF(INDEX('3.설계사'!$T$4:$T$303,K10)>=설정!$B$39,"약속 "&TEXT(INDEX('3.설계사'!$Q$4:$Q$303,K10),"m/d")&" · ",IF(INDEX('3.설계사'!$O$4:$O$303,K10)="","아직 안 가봄 · ","마지막 방문 "&INDEX('3.설계사'!$P$4:$P$303,K10)&"일 전 · "))&IF(INDEX('3.설계사'!$D$4:$D$303,K10)>0,"설계단계 "&INDEX('3.설계사'!$D$4:$D$303,K10)&"건 ","")&IF(INDEX('3.설계사'!$E$4:$E$303,K10)>0,"착공 "&INDEX('3.설계사'!$E$4:$E$303,K10)&"건 ","")&IF(INDEX('3.설계사'!$F$4:$F$303,K10)>0,"★"&INDEX('3.설계사'!$F$4:$F$303,K10),"")) | D10: =IF(K10="","",INDEX('3.설계사'!$K$4:$K$303,K10)) | E10: =IF(K10="","",INDEX('3.설계사'!$L$4:$L$303,K10)) | F10: =IF(K10="","",INDEX('3.설계사'!$H$4:$H$303,K10)) | G10: =IF(K10="","",IFERROR(IF(VLOOKUP(D10,현장_조사!$A$3:$J$202,5,FALSE)&""="","",VLOOKUP(D10,현장_조사!$A$3:$J$202,5,FALSE)&IF(VLOOKUP(D10,현장_조사!$A$3:$J$202,8,FALSE)="확정",""," ("&VLOOKUP(D10,현장_조사!$A$3:$J$202,8,FALSE)&")")),"")) | H10: =IF(K10="","",INDEX('3.설계사'!$M$4:$M$303,K10)) | I10: =IF(K10="","",INDEX('3.설계사'!$N$4:$N$303,K10)) | J10: =IF(K10="","","한국마이크로닉 배성윤 차장입니다. "&D10&IF(INDEX('3.설계사'!$D$4:$D$303,K10)>0," 설계 진행하고 계신"," 설계하신")&" 걸로 알고 연락드렸습니다. 호텔 객실관리(키센서·온도조절기·조명 제어) 도면과 특기시방서를 무상으로 지원해 드리고 있어서, 이번 주에 10분만 찾아뵈어도 될까요?") | K10: =IFERROR(MATCH(7,'3.설계사'!$U$4:$U$303,0),"")
A11: =IF(K11="","",8) | B11: =IF(K11="","",INDEX('3.설계사'!$B$4:$B$303,K11)) | C11: =IF(K11="","",IF(INDEX('3.설계사'!$T$4:$T$303,K11)>=설정!$B$39,"약속 "&TEXT(INDEX('3.설계사'!$Q$4:$Q$303,K11),"m/d")&" · ",IF(INDEX('3.설계사'!$O$4:$O$303,K11)="","아직 안 가봄 · ","마지막 방문 "&INDEX('3.설계사'!$P$4:$P$303,K11)&"일 전 · "))&IF(INDEX('3.설계사'!$D$4:$D$303,K11)>0,"설계단계 "&INDEX('3.설계사'!$D$4:$D$303,K11)&"건 ","")&IF(INDEX('3.설계사'!$E$4:$E$303,K11)>0,"착공 "&INDEX('3.설계사'!$E$4:$E$303,K11)&"건 ","")&IF(INDEX('3.설계사'!$F$4:$F$303,K11)>0,"★"&INDEX('3.설계사'!$F$4:$F$303,K11),"")) | D11: =IF(K11="","",INDEX('3.설계사'!$K$4:$K$303,K11)) | E11: =IF(K11="","",INDEX('3.설계사'!$L$4:$L$303,K11)) | F11: =IF(K11="","",INDEX('3.설계사'!$H$4:$H$303,K11)) | G11: =IF(K11="","",IFERROR(IF(VLOOKUP(D11,현장_조사!$A$3:$J$202,5,FALSE)&""="","",VLOOKUP(D11,현장_조사!$A$3:$J$202,5,FALSE)&IF(VLOOKUP(D11,현장_조사!$A$3:$J$202,8,FALSE)="확정",""," ("&VLOOKUP(D11,현장_조사!$A$3:$J$202,8,FALSE)&")")),"")) | H11: =IF(K11="","",INDEX('3.설계사'!$M$4:$M$303,K11)) | I11: =IF(K11="","",INDEX('3.설계사'!$N$4:$N$303,K11)) | J11: =IF(K11="","","한국마이크로닉 배성윤 차장입니다. "&D11&IF(INDEX('3.설계사'!$D$4:$D$303,K11)>0," 설계 진행하고 계신"," 설계하신")&" 걸로 알고 연락드렸습니다. 호텔 객실관리(키센서·온도조절기·조명 제어) 도면과 특기시방서를 무상으로 지원해 드리고 있어서, 이번 주에 10분만 찾아뵈어도 될까요?") | K11: =IFERROR(MATCH(8,'3.설계사'!$U$4:$U$303,0),"")
A12: =IF(K12="","",9) | B12: =IF(K12="","",INDEX('3.설계사'!$B$4:$B$303,K12)) | C12: =IF(K12="","",IF(INDEX('3.설계사'!$T$4:$T$303,K12)>=설정!$B$39,"약속 "&TEXT(INDEX('3.설계사'!$Q$4:$Q$303,K12),"m/d")&" · ",IF(INDEX('3.설계사'!$O$4:$O$303,K12)="","아직 안 가봄 · ","마지막 방문 "&INDEX('3.설계사'!$P$4:$P$303,K12)&"일 전 · "))&IF(INDEX('3.설계사'!$D$4:$D$303,K12)>0,"설계단계 "&INDEX('3.설계사'!$D$4:$D$303,K12)&"건 ","")&IF(INDEX('3.설계사'!$E$4:$E$303,K12)>0,"착공 "&INDEX('3.설계사'!$E$4:$E$303,K12)&"건 ","")&IF(INDEX('3.설계사'!$F$4:$F$303,K12)>0,"★"&INDEX('3.설계사'!$F$4:$F$303,K12),"")) | D12: =IF(K12="","",INDEX('3.설계사'!$K$4:$K$303,K12)) | E12: =IF(K12="","",INDEX('3.설계사'!$L$4:$L$303,K12)) | F12: =IF(K12="","",INDEX('3.설계사'!$H$4:$H$303,K12)) | G12: =IF(K12="","",IFERROR(IF(VLOOKUP(D12,현장_조사!$A$3:$J$202,5,FALSE)&""="","",VLOOKUP(D12,현장_조사!$A$3:$J$202,5,FALSE)&IF(VLOOKUP(D12,현장_조사!$A$3:$J$202,8,FALSE)="확정",""," ("&VLOOKUP(D12,현장_조사!$A$3:$J$202,8,FALSE)&")")),"")) | H12: =IF(K12="","",INDEX('3.설계사'!$M$4:$M$303,K12)) | I12: =IF(K12="","",INDEX('3.설계사'!$N$4:$N$303,K12)) | J12: =IF(K12="","","한국마이크로닉 배성윤 차장입니다. "&D12&IF(INDEX('3.설계사'!$D$4:$D$303,K12)>0," 설계 진행하고 계신"," 설계하신")&" 걸로 알고 연락드렸습니다. 호텔 객실관리(키센서·온도조절기·조명 제어) 도면과 특기시방서를 무상으로 지원해 드리고 있어서, 이번 주에 10분만 찾아뵈어도 될까요?") | K12: =IFERROR(MATCH(9,'3.설계사'!$U$4:$U$303,0),"")
A13: =IF(K13="","",10) | B13: =IF(K13="","",INDEX('3.설계사'!$B$4:$B$303,K13)) | C13: =IF(K13="","",IF(INDEX('3.설계사'!$T$4:$T$303,K13)>=설정!$B$39,"약속 "&TEXT(INDEX('3.설계사'!$Q$4:$Q$303,K13),"m/d")&" · ",IF(INDEX('3.설계사'!$O$4:$O$303,K13)="","아직 안 가봄 · ","마지막 방문 "&INDEX('3.설계사'!$P$4:$P$303,K13)&"일 전 · "))&IF(INDEX('3.설계사'!$D$4:$D$303,K13)>0,"설계단계 "&INDEX('3.설계사'!$D$4:$D$303,K13)&"건 ","")&IF(INDEX('3.설계사'!$E$4:$E$303,K13)>0,"착공 "&INDEX('3.설계사'!$E$4:$E$303,K13)&"건 ","")&IF(INDEX('3.설계사'!$F$4:$F$303,K13)>0,"★"&INDEX('3.설계사'!$F$4:$F$303,K13),"")) | D13: =IF(K13="","",INDEX('3.설계사'!$K$4:$K$303,K13)) | E13: =IF(K13="","",INDEX('3.설계사'!$L$4:$L$303,K13)) | F13: =IF(K13="","",INDEX('3.설계사'!$H$4:$H$303,K13)) | G13: =IF(K13="","",IFERROR(IF(VLOOKUP(D13,현장_조사!$A$3:$J$202,5,FALSE)&""="","",VLOOKUP(D13,현장_조사!$A$3:$J$202,5,FALSE)&IF(VLOOKUP(D13,현장_조사!$A$3:$J$202,8,FALSE)="확정",""," ("&VLOOKUP(D13,현장_조사!$A$3:$J$202,8,FALSE)&")")),"")) | H13: =IF(K13="","",INDEX('3.설계사'!$M$4:$M$303,K13)) | I13: =IF(K13="","",INDEX('3.설계사'!$N$4:$N$303,K13)) | J13: =IF(K13="","","한국마이크로닉 배성윤 차장입니다. "&D13&IF(INDEX('3.설계사'!$D$4:$D$303,K13)>0," 설계 진행하고 계신"," 설계하신")&" 걸로 알고 연락드렸습니다. 호텔 객실관리(키센서·온도조절기·조명 제어) 도면과 특기시방서를 무상으로 지원해 드리고 있어서, 이번 주에 10분만 찾아뵈어도 될까요?") | K13: =IFERROR(MATCH(10,'3.설계사'!$U$4:$U$303,0),"")
A14: =IF(K14="","",11) | B14: =IF(K14="","",INDEX('3.설계사'!$B$4:$B$303,K14)) | C14: =IF(K14="","",IF(INDEX('3.설계사'!$T$4:$T$303,K14)>=설정!$B$39,"약속 "&TEXT(INDEX('3.설계사'!$Q$4:$Q$303,K14),"m/d")&" · ",IF(INDEX('3.설계사'!$O$4:$O$303,K14)="","아직 안 가봄 · ","마지막 방문 "&INDEX('3.설계사'!$P$4:$P$303,K14)&"일 전 · "))&IF(INDEX('3.설계사'!$D$4:$D$303,K14)>0,"설계단계 "&INDEX('3.설계사'!$D$4:$D$303,K14)&"건 ","")&IF(INDEX('3.설계사'!$E$4:$E$303,K14)>0,"착공 "&INDEX('3.설계사'!$E$4:$E$303,K14)&"건 ","")&IF(INDEX('3.설계사'!$F$4:$F$303,K14)>0,"★"&INDEX('3.설계사'!$F$4:$F$303,K14),"")) | D14: =IF(K14="","",INDEX('3.설계사'!$K$4:$K$303,K14)) | E14: =IF(K14="","",INDEX('3.설계사'!$L$4:$L$303,K14)) | F14: =IF(K14="","",INDEX('3.설계사'!$H$4:$H$303,K14)) | G14: =IF(K14="","",IFERROR(IF(VLOOKUP(D14,현장_조사!$A$3:$J$202,5,FALSE)&""="","",VLOOKUP(D14,현장_조사!$A$3:$J$202,5,FALSE)&IF(VLOOKUP(D14,현장_조사!$A$3:$J$202,8,FALSE)="확정",""," ("&VLOOKUP(D14,현장_조사!$A$3:$J$202,8,FALSE)&")")),"")) | H14: =IF(K14="","",INDEX('3.설계사'!$M$4:$M$303,K14)) | I14: =IF(K14="","",INDEX('3.설계사'!$N$4:$N$303,K14)) | J14: =IF(K14="","","한국마이크로닉 배성윤 차장입니다. "&D14&IF(INDEX('3.설계사'!$D$4:$D$303,K14)>0," 설계 진행하고 계신"," 설계하신")&" 걸로 알고 연락드렸습니다. 호텔 객실관리(키센서·온도조절기·조명 제어) 도면과 특기시방서를 무상으로 지원해 드리고 있어서, 이번 주에 10분만 찾아뵈어도 될까요?") | K14: =IFERROR(MATCH(11,'3.설계사'!$U$4:$U$303,0),"")
A15: =IF(K15="","",12) | B15: =IF(K15="","",INDEX('3.설계사'!$B$4:$B$303,K15)) | C15: =IF(K15="","",IF(INDEX('3.설계사'!$T$4:$T$303,K15)>=설정!$B$39,"약속 "&TEXT(INDEX('3.설계사'!$Q$4:$Q$303,K15),"m/d")&" · ",IF(INDEX('3.설계사'!$O$4:$O$303,K15)="","아직 안 가봄 · ","마지막 방문 "&INDEX('3.설계사'!$P$4:$P$303,K15)&"일 전 · "))&IF(INDEX('3.설계사'!$D$4:$D$303,K15)>0,"설계단계 "&INDEX('3.설계사'!$D$4:$D$303,K15)&"건 ","")&IF(INDEX('3.설계사'!$E$4:$E$303,K15)>0,"착공 "&INDEX('3.설계사'!$E$4:$E$303,K15)&"건 ","")&IF(INDEX('3.설계사'!$F$4:$F$303,K15)>0,"★"&INDEX('3.설계사'!$F$4:$F$303,K15),"")) | D15: =IF(K15="","",INDEX('3.설계사'!$K$4:$K$303,K15)) | E15: =IF(K15="","",INDEX('3.설계사'!$L$4:$L$303,K15)) | F15: =IF(K15="","",INDEX('3.설계사'!$H$4:$H$303,K15)) | G15: =IF(K15="","",IFERROR(IF(VLOOKUP(D15,현장_조사!$A$3:$J$202,5,FALSE)&""="","",VLOOKUP(D15,현장_조사!$A$3:$J$202,5,FALSE)&IF(VLOOKUP(D15,현장_조사!$A$3:$J$202,8,FALSE)="확정",""," ("&VLOOKUP(D15,현장_조사!$A$3:$J$202,8,FALSE)&")")),"")) | H15: =IF(K15="","",INDEX('3.설계사'!$M$4:$M$303,K15)) | I15: =IF(K15="","",INDEX('3.설계사'!$N$4:$N$303,K15)) | J15: =IF(K15="","","한국마이크로닉 배성윤 차장입니다. "&D15&IF(INDEX('3.설계사'!$D$4:$D$303,K15)>0," 설계 진행하고 계신"," 설계하신")&" 걸로 알고 연락드렸습니다. 호텔 객실관리(키센서·온도조절기·조명 제어) 도면과 특기시방서를 무상으로 지원해 드리고 있어서, 이번 주에 10분만 찾아뵈어도 될까요?") | K15: =IFERROR(MATCH(12,'3.설계사'!$U$4:$U$303,0),"")
A16: =IF(K16="","",13) | B16: =IF(K16="","",INDEX('3.설계사'!$B$4:$B$303,K16)) | C16: =IF(K16="","",IF(INDEX('3.설계사'!$T$4:$T$303,K16)>=설정!$B$39,"약속 "&TEXT(INDEX('3.설계사'!$Q$4:$Q$303,K16),"m/d")&" · ",IF(INDEX('3.설계사'!$O$4:$O$303,K16)="","아직 안 가봄 · ","마지막 방문 "&INDEX('3.설계사'!$P$4:$P$303,K16)&"일 전 · "))&IF(INDEX('3.설계사'!$D$4:$D$303,K16)>0,"설계단계 "&INDEX('3.설계사'!$D$4:$D$303,K16)&"건 ","")&IF(INDEX('3.설계사'!$E$4:$E$303,K16)>0,"착공 "&INDEX('3.설계사'!$E$4:$E$303,K16)&"건 ","")&IF(INDEX('3.설계사'!$F$4:$F$303,K16)>0,"★"&INDEX('3.설계사'!$F$4:$F$303,K16),"")) | D16: =IF(K16="","",INDEX('3.설계사'!$K$4:$K$303,K16)) | E16: =IF(K16="","",INDEX('3.설계사'!$L$4:$L$303,K16)) | F16: =IF(K16="","",INDEX('3.설계사'!$H$4:$H$303,K16)) | G16: =IF(K16="","",IFERROR(IF(VLOOKUP(D16,현장_조사!$A$3:$J$202,5,FALSE)&""="","",VLOOKUP(D16,현장_조사!$A$3:$J$202,5,FALSE)&IF(VLOOKUP(D16,현장_조사!$A$3:$J$202,8,FALSE)="확정",""," ("&VLOOKUP(D16,현장_조사!$A$3:$J$202,8,FALSE)&")")),"")) | H16: =IF(K16="","",INDEX('3.설계사'!$M$4:$M$303,K16)) | I16: =IF(K16="","",INDEX('3.설계사'!$N$4:$N$303,K16)) | J16: =IF(K16="","","한국마이크로닉 배성윤 차장입니다. "&D16&IF(INDEX('3.설계사'!$D$4:$D$303,K16)>0," 설계 진행하고 계신"," 설계하신")&" 걸로 알고 연락드렸습니다. 호텔 객실관리(키센서·온도조절기·조명 제어) 도면과 특기시방서를 무상으로 지원해 드리고 있어서, 이번 주에 10분만 찾아뵈어도 될까요?") | K16: =IFERROR(MATCH(13,'3.설계사'!$U$4:$U$303,0),"")
A17: =IF(K17="","",14) | B17: =IF(K17="","",INDEX('3.설계사'!$B$4:$B$303,K17)) | C17: =IF(K17="","",IF(INDEX('3.설계사'!$T$4:$T$303,K17)>=설정!$B$39,"약속 "&TEXT(INDEX('3.설계사'!$Q$4:$Q$303,K17),"m/d")&" · ",IF(INDEX('3.설계사'!$O$4:$O$303,K17)="","아직 안 가봄 · ","마지막 방문 "&INDEX('3.설계사'!$P$4:$P$303,K17)&"일 전 · "))&IF(INDEX('3.설계사'!$D$4:$D$303,K17)>0,"설계단계 "&INDEX('3.설계사'!$D$4:$D$303,K17)&"건 ","")&IF(INDEX('3.설계사'!$E$4:$E$303,K17)>0,"착공 "&INDEX('3.설계사'!$E$4:$E$303,K17)&"건 ","")&IF(INDEX('3.설계사'!$F$4:$F$303,K17)>0,"★"&INDEX('3.설계사'!$F$4:$F$303,K17),"")) | D17: =IF(K17="","",INDEX('3.설계사'!$K$4:$K$303,K17)) | E17: =IF(K17="","",INDEX('3.설계사'!$L$4:$L$303,K17)) | F17: =IF(K17="","",INDEX('3.설계사'!$H$4:$H$303,K17)) | G17: =IF(K17="","",IFERROR(IF(VLOOKUP(D17,현장_조사!$A$3:$J$202,5,FALSE)&""="","",VLOOKUP(D17,현장_조사!$A$3:$J$202,5,FALSE)&IF(VLOOKUP(D17,현장_조사!$A$3:$J$202,8,FALSE)="확정",""," ("&VLOOKUP(D17,현장_조사!$A$3:$J$202,8,FALSE)&")")),"")) | H17: =IF(K17="","",INDEX('3.설계사'!$M$4:$M$303,K17)) | I17: =IF(K17="","",INDEX('3.설계사'!$N$4:$N$303,K17)) | J17: =IF(K17="","","한국마이크로닉 배성윤 차장입니다. "&D17&IF(INDEX('3.설계사'!$D$4:$D$303,K17)>0," 설계 진행하고 계신"," 설계하신")&" 걸로 알고 연락드렸습니다. 호텔 객실관리(키센서·온도조절기·조명 제어) 도면과 특기시방서를 무상으로 지원해 드리고 있어서, 이번 주에 10분만 찾아뵈어도 될까요?") | K17: =IFERROR(MATCH(14,'3.설계사'!$U$4:$U$303,0),"")
A18: =IF(K18="","",15) | B18: =IF(K18="","",INDEX('3.설계사'!$B$4:$B$303,K18)) | C18: =IF(K18="","",IF(INDEX('3.설계사'!$T$4:$T$303,K18)>=설정!$B$39,"약속 "&TEXT(INDEX('3.설계사'!$Q$4:$Q$303,K18),"m/d")&" · ",IF(INDEX('3.설계사'!$O$4:$O$303,K18)="","아직 안 가봄 · ","마지막 방문 "&INDEX('3.설계사'!$P$4:$P$303,K18)&"일 전 · "))&IF(INDEX('3.설계사'!$D$4:$D$303,K18)>0,"설계단계 "&INDEX('3.설계사'!$D$4:$D$303,K18)&"건 ","")&IF(INDEX('3.설계사'!$E$4:$E$303,K18)>0,"착공 "&INDEX('3.설계사'!$E$4:$E$303,K18)&"건 ","")&IF(INDEX('3.설계사'!$F$4:$F$303,K18)>0,"★"&INDEX('3.설계사'!$F$4:$F$303,K18),"")) | D18: =IF(K18="","",INDEX('3.설계사'!$K$4:$K$303,K18)) | E18: =IF(K18="","",INDEX('3.설계사'!$L$4:$L$303,K18)) | F18: =IF(K18="","",INDEX('3.설계사'!$H$4:$H$303,K18)) | G18: =IF(K18="","",IFERROR(IF(VLOOKUP(D18,현장_조사!$A$3:$J$202,5,FALSE)&""="","",VLOOKUP(D18,현장_조사!$A$3:$J$202,5,FALSE)&IF(VLOOKUP(D18,현장_조사!$A$3:$J$202,8,FALSE)="확정",""," ("&VLOOKUP(D18,현장_조사!$A$3:$J$202,8,FALSE)&")")),"")) | H18: =IF(K18="","",INDEX('3.설계사'!$M$4:$M$303,K18)) | I18: =IF(K18="","",INDEX('3.설계사'!$N$4:$N$303,K18)) | J18: =IF(K18="","","한국마이크로닉 배성윤 차장입니다. "&D18&IF(INDEX('3.설계사'!$D$4:$D$303,K18)>0," 설계 진행하고 계신"," 설계하신")&" 걸로 알고 연락드렸습니다. 호텔 객실관리(키센서·온도조절기·조명 제어) 도면과 특기시방서를 무상으로 지원해 드리고 있어서, 이번 주에 10분만 찾아뵈어도 될까요?") | K18: =IFERROR(MATCH(15,'3.설계사'!$U$4:$U$303,0),"")
A19: =IF(K19="","",16) | B19: =IF(K19="","",INDEX('3.설계사'!$B$4:$B$303,K19)) | C19: =IF(K19="","",IF(INDEX('3.설계사'!$T$4:$T$303,K19)>=설정!$B$39,"약속 "&TEXT(INDEX('3.설계사'!$Q$4:$Q$303,K19),"m/d")&" · ",IF(INDEX('3.설계사'!$O$4:$O$303,K19)="","아직 안 가봄 · ","마지막 방문 "&INDEX('3.설계사'!$P$4:$P$303,K19)&"일 전 · "))&IF(INDEX('3.설계사'!$D$4:$D$303,K19)>0,"설계단계 "&INDEX('3.설계사'!$D$4:$D$303,K19)&"건 ","")&IF(INDEX('3.설계사'!$E$4:$E$303,K19)>0,"착공 "&INDEX('3.설계사'!$E$4:$E$303,K19)&"건 ","")&IF(INDEX('3.설계사'!$F$4:$F$303,K19)>0,"★"&INDEX('3.설계사'!$F$4:$F$303,K19),"")) | D19: =IF(K19="","",INDEX('3.설계사'!$K$4:$K$303,K19)) | E19: =IF(K19="","",INDEX('3.설계사'!$L$4:$L$303,K19)) | F19: =IF(K19="","",INDEX('3.설계사'!$H$4:$H$303,K19)) | G19: =IF(K19="","",IFERROR(IF(VLOOKUP(D19,현장_조사!$A$3:$J$202,5,FALSE)&""="","",VLOOKUP(D19,현장_조사!$A$3:$J$202,5,FALSE)&IF(VLOOKUP(D19,현장_조사!$A$3:$J$202,8,FALSE)="확정",""," ("&VLOOKUP(D19,현장_조사!$A$3:$J$202,8,FALSE)&")")),"")) | H19: =IF(K19="","",INDEX('3.설계사'!$M$4:$M$303,K19)) | I19: =IF(K19="","",INDEX('3.설계사'!$N$4:$N$303,K19)) | J19: =IF(K19="","","한국마이크로닉 배성윤 차장입니다. "&D19&IF(INDEX('3.설계사'!$D$4:$D$303,K19)>0," 설계 진행하고 계신"," 설계하신")&" 걸로 알고 연락드렸습니다. 호텔 객실관리(키센서·온도조절기·조명 제어) 도면과 특기시방서를 무상으로 지원해 드리고 있어서, 이번 주에 10분만 찾아뵈어도 될까요?") | K19: =IFERROR(MATCH(16,'3.설계사'!$U$4:$U$303,0),"")
A20: =IF(K20="","",17) | B20: =IF(K20="","",INDEX('3.설계사'!$B$4:$B$303,K20)) | C20: =IF(K20="","",IF(INDEX('3.설계사'!$T$4:$T$303,K20)>=설정!$B$39,"약속 "&TEXT(INDEX('3.설계사'!$Q$4:$Q$303,K20),"m/d")&" · ",IF(INDEX('3.설계사'!$O$4:$O$303,K20)="","아직 안 가봄 · ","마지막 방문 "&INDEX('3.설계사'!$P$4:$P$303,K20)&"일 전 · "))&IF(INDEX('3.설계사'!$D$4:$D$303,K20)>0,"설계단계 "&INDEX('3.설계사'!$D$4:$D$303,K20)&"건 ","")&IF(INDEX('3.설계사'!$E$4:$E$303,K20)>0,"착공 "&INDEX('3.설계사'!$E$4:$E$303,K20)&"건 ","")&IF(INDEX('3.설계사'!$F$4:$F$303,K20)>0,"★"&INDEX('3.설계사'!$F$4:$F$303,K20),"")) | D20: =IF(K20="","",INDEX('3.설계사'!$K$4:$K$303,K20)) | E20: =IF(K20="","",INDEX('3.설계사'!$L$4:$L$303,K20)) | F20: =IF(K20="","",INDEX('3.설계사'!$H$4:$H$303,K20)) | G20: =IF(K20="","",IFERROR(IF(VLOOKUP(D20,현장_조사!$A$3:$J$202,5,FALSE)&""="","",VLOOKUP(D20,현장_조사!$A$3:$J$202,5,FALSE)&IF(VLOOKUP(D20,현장_조사!$A$3:$J$202,8,FALSE)="확정",""," ("&VLOOKUP(D20,현장_조사!$A$3:$J$202,8,FALSE)&")")),"")) | H20: =IF(K20="","",INDEX('3.설계사'!$M$4:$M$303,K20)) | I20: =IF(K20="","",INDEX('3.설계사'!$N$4:$N$303,K20)) | J20: =IF(K20="","","한국마이크로닉 배성윤 차장입니다. "&D20&IF(INDEX('3.설계사'!$D$4:$D$303,K20)>0," 설계 진행하고 계신"," 설계하신")&" 걸로 알고 연락드렸습니다. 호텔 객실관리(키센서·온도조절기·조명 제어) 도면과 특기시방서를 무상으로 지원해 드리고 있어서, 이번 주에 10분만 찾아뵈어도 될까요?") | K20: =IFERROR(MATCH(17,'3.설계사'!$U$4:$U$303,0),"")
A21: =IF(K21="","",18) | B21: =IF(K21="","",INDEX('3.설계사'!$B$4:$B$303,K21)) | C21: =IF(K21="","",IF(INDEX('3.설계사'!$T$4:$T$303,K21)>=설정!$B$39,"약속 "&TEXT(INDEX('3.설계사'!$Q$4:$Q$303,K21),"m/d")&" · ",IF(INDEX('3.설계사'!$O$4:$O$303,K21)="","아직 안 가봄 · ","마지막 방문 "&INDEX('3.설계사'!$P$4:$P$303,K21)&"일 전 · "))&IF(INDEX('3.설계사'!$D$4:$D$303,K21)>0,"설계단계 "&INDEX('3.설계사'!$D$4:$D$303,K21)&"건 ","")&IF(INDEX('3.설계사'!$E$4:$E$303,K21)>0,"착공 "&INDEX('3.설계사'!$E$4:$E$303,K21)&"건 ","")&IF(INDEX('3.설계사'!$F$4:$F$303,K21)>0,"★"&INDEX('3.설계사'!$F$4:$F$303,K21),"")) | D21: =IF(K21="","",INDEX('3.설계사'!$K$4:$K$303,K21)) | E21: =IF(K21="","",INDEX('3.설계사'!$L$4:$L$303,K21)) | F21: =IF(K21="","",INDEX('3.설계사'!$H$4:$H$303,K21)) | G21: =IF(K21="","",IFERROR(IF(VLOOKUP(D21,현장_조사!$A$3:$J$202,5,FALSE)&""="","",VLOOKUP(D21,현장_조사!$A$3:$J$202,5,FALSE)&IF(VLOOKUP(D21,현장_조사!$A$3:$J$202,8,FALSE)="확정",""," ("&VLOOKUP(D21,현장_조사!$A$3:$J$202,8,FALSE)&")")),"")) | H21: =IF(K21="","",INDEX('3.설계사'!$M$4:$M$303,K21)) | I21: =IF(K21="","",INDEX('3.설계사'!$N$4:$N$303,K21)) | J21: =IF(K21="","","한국마이크로닉 배성윤 차장입니다. "&D21&IF(INDEX('3.설계사'!$D$4:$D$303,K21)>0," 설계 진행하고 계신"," 설계하신")&" 걸로 알고 연락드렸습니다. 호텔 객실관리(키센서·온도조절기·조명 제어) 도면과 특기시방서를 무상으로 지원해 드리고 있어서, 이번 주에 10분만 찾아뵈어도 될까요?") | K21: =IFERROR(MATCH(18,'3.설계사'!$U$4:$U$303,0),"")
A22: =IF(K22="","",19) | B22: =IF(K22="","",INDEX('3.설계사'!$B$4:$B$303,K22)) | C22: =IF(K22="","",IF(INDEX('3.설계사'!$T$4:$T$303,K22)>=설정!$B$39,"약속 "&TEXT(INDEX('3.설계사'!$Q$4:$Q$303,K22),"m/d")&" · ",IF(INDEX('3.설계사'!$O$4:$O$303,K22)="","아직 안 가봄 · ","마지막 방문 "&INDEX('3.설계사'!$P$4:$P$303,K22)&"일 전 · "))&IF(INDEX('3.설계사'!$D$4:$D$303,K22)>0,"설계단계 "&INDEX('3.설계사'!$D$4:$D$303,K22)&"건 ","")&IF(INDEX('3.설계사'!$E$4:$E$303,K22)>0,"착공 "&INDEX('3.설계사'!$E$4:$E$303,K22)&"건 ","")&IF(INDEX('3.설계사'!$F$4:$F$303,K22)>0,"★"&INDEX('3.설계사'!$F$4:$F$303,K22),"")) | D22: =IF(K22="","",INDEX('3.설계사'!$K$4:$K$303,K22)) | E22: =IF(K22="","",INDEX('3.설계사'!$L$4:$L$303,K22)) | F22: =IF(K22="","",INDEX('3.설계사'!$H$4:$H$303,K22)) | G22: =IF(K22="","",IFERROR(IF(VLOOKUP(D22,현장_조사!$A$3:$J$202,5,FALSE)&""="","",VLOOKUP(D22,현장_조사!$A$3:$J$202,5,FALSE)&IF(VLOOKUP(D22,현장_조사!$A$3:$J$202,8,FALSE)="확정",""," ("&VLOOKUP(D22,현장_조사!$A$3:$J$202,8,FALSE)&")")),"")) | H22: =IF(K22="","",INDEX('3.설계사'!$M$4:$M$303,K22)) | I22: =IF(K22="","",INDEX('3.설계사'!$N$4:$N$303,K22)) | J22: =IF(K22="","","한국마이크로닉 배성윤 차장입니다. "&D22&IF(INDEX('3.설계사'!$D$4:$D$303,K22)>0," 설계 진행하고 계신"," 설계하신")&" 걸로 알고 연락드렸습니다. 호텔 객실관리(키센서·온도조절기·조명 제어) 도면과 특기시방서를 무상으로 지원해 드리고 있어서, 이번 주에 10분만 찾아뵈어도 될까요?") | K22: =IFERROR(MATCH(19,'3.설계사'!$U$4:$U$303,0),"")
A23: =IF(K23="","",20) | B23: =IF(K23="","",INDEX('3.설계사'!$B$4:$B$303,K23)) | C23: =IF(K23="","",IF(INDEX('3.설계사'!$T$4:$T$303,K23)>=설정!$B$39,"약속 "&TEXT(INDEX('3.설계사'!$Q$4:$Q$303,K23),"m/d")&" · ",IF(INDEX('3.설계사'!$O$4:$O$303,K23)="","아직 안 가봄 · ","마지막 방문 "&INDEX('3.설계사'!$P$4:$P$303,K23)&"일 전 · "))&IF(INDEX('3.설계사'!$D$4:$D$303,K23)>0,"설계단계 "&INDEX('3.설계사'!$D$4:$D$303,K23)&"건 ","")&IF(INDEX('3.설계사'!$E$4:$E$303,K23)>0,"착공 "&INDEX('3.설계사'!$E$4:$E$303,K23)&"건 ","")&IF(INDEX('3.설계사'!$F$4:$F$303,K23)>0,"★"&INDEX('3.설계사'!$F$4:$F$303,K23),"")) | D23: =IF(K23="","",INDEX('3.설계사'!$K$4:$K$303,K23)) | E23: =IF(K23="","",INDEX('3.설계사'!$L$4:$L$303,K23)) | F23: =IF(K23="","",INDEX('3.설계사'!$H$4:$H$303,K23)) | G23: =IF(K23="","",IFERROR(IF(VLOOKUP(D23,현장_조사!$A$3:$J$202,5,FALSE)&""="","",VLOOKUP(D23,현장_조사!$A$3:$J$202,5,FALSE)&IF(VLOOKUP(D23,현장_조사!$A$3:$J$202,8,FALSE)="확정",""," ("&VLOOKUP(D23,현장_조사!$A$3:$J$202,8,FALSE)&")")),"")) | H23: =IF(K23="","",INDEX('3.설계사'!$M$4:$M$303,K23)) | I23: =IF(K23="","",INDEX('3.설계사'!$N$4:$N$303,K23)) | J23: =IF(K23="","","한국마이크로닉 배성윤 차장입니다. "&D23&IF(INDEX('3.설계사'!$D$4:$D$303,K23)>0," 설계 진행하고 계신"," 설계하신")&" 걸로 알고 연락드렸습니다. 호텔 객실관리(키센서·온도조절기·조명 제어) 도면과 특기시방서를 무상으로 지원해 드리고 있어서, 이번 주에 10분만 찾아뵈어도 될까요?") | K23: =IFERROR(MATCH(20,'3.설계사'!$U$4:$U$303,0),"")
A24: =IF(K24="","",21) | B24: =IF(K24="","",INDEX('3.설계사'!$B$4:$B$303,K24)) | C24: =IF(K24="","",IF(INDEX('3.설계사'!$T$4:$T$303,K24)>=설정!$B$39,"약속 "&TEXT(INDEX('3.설계사'!$Q$4:$Q$303,K24),"m/d")&" · ",IF(INDEX('3.설계사'!$O$4:$O$303,K24)="","아직 안 가봄 · ","마지막 방문 "&INDEX('3.설계사'!$P$4:$P$303,K24)&"일 전 · "))&IF(INDEX('3.설계사'!$D$4:$D$303,K24)>0,"설계단계 "&INDEX('3.설계사'!$D$4:$D$303,K24)&"건 ","")&IF(INDEX('3.설계사'!$E$4:$E$303,K24)>0,"착공 "&INDEX('3.설계사'!$E$4:$E$303,K24)&"건 ","")&IF(INDEX('3.설계사'!$F$4:$F$303,K24)>0,"★"&INDEX('3.설계사'!$F$4:$F$303,K24),"")) | D24: =IF(K24="","",INDEX('3.설계사'!$K$4:$K$303,K24)) | E24: =IF(K24="","",INDEX('3.설계사'!$L$4:$L$303,K24)) | F24: =IF(K24="","",INDEX('3.설계사'!$H$4:$H$303,K24)) | G24: =IF(K24="","",IFERROR(IF(VLOOKUP(D24,현장_조사!$A$3:$J$202,5,FALSE)&""="","",VLOOKUP(D24,현장_조사!$A$3:$J$202,5,FALSE)&IF(VLOOKUP(D24,현장_조사!$A$3:$J$202,8,FALSE)="확정",""," ("&VLOOKUP(D24,현장_조사!$A$3:$J$202,8,FALSE)&")")),"")) | H24: =IF(K24="","",INDEX('3.설계사'!$M$4:$M$303,K24)) | I24: =IF(K24="","",INDEX('3.설계사'!$N$4:$N$303,K24)) | J24: =IF(K24="","","한국마이크로닉 배성윤 차장입니다. "&D24&IF(INDEX('3.설계사'!$D$4:$D$303,K24)>0," 설계 진행하고 계신"," 설계하신")&" 걸로 알고 연락드렸습니다. 호텔 객실관리(키센서·온도조절기·조명 제어) 도면과 특기시방서를 무상으로 지원해 드리고 있어서, 이번 주에 10분만 찾아뵈어도 될까요?") | K24: =IFERROR(MATCH(21,'3.설계사'!$U$4:$U$303,0),"")
A25: =IF(K25="","",22) | B25: =IF(K25="","",INDEX('3.설계사'!$B$4:$B$303,K25)) | C25: =IF(K25="","",IF(INDEX('3.설계사'!$T$4:$T$303,K25)>=설정!$B$39,"약속 "&TEXT(INDEX('3.설계사'!$Q$4:$Q$303,K25),"m/d")&" · ",IF(INDEX('3.설계사'!$O$4:$O$303,K25)="","아직 안 가봄 · ","마지막 방문 "&INDEX('3.설계사'!$P$4:$P$303,K25)&"일 전 · "))&IF(INDEX('3.설계사'!$D$4:$D$303,K25)>0,"설계단계 "&INDEX('3.설계사'!$D$4:$D$303,K25)&"건 ","")&IF(INDEX('3.설계사'!$E$4:$E$303,K25)>0,"착공 "&INDEX('3.설계사'!$E$4:$E$303,K25)&"건 ","")&IF(INDEX('3.설계사'!$F$4:$F$303,K25)>0,"★"&INDEX('3.설계사'!$F$4:$F$303,K25),"")) | D25: =IF(K25="","",INDEX('3.설계사'!$K$4:$K$303,K25)) | E25: =IF(K25="","",INDEX('3.설계사'!$L$4:$L$303,K25)) | F25: =IF(K25="","",INDEX('3.설계사'!$H$4:$H$303,K25)) | G25: =IF(K25="","",IFERROR(IF(VLOOKUP(D25,현장_조사!$A$3:$J$202,5,FALSE)&""="","",VLOOKUP(D25,현장_조사!$A$3:$J$202,5,FALSE)&IF(VLOOKUP(D25,현장_조사!$A$3:$J$202,8,FALSE)="확정",""," ("&VLOOKUP(D25,현장_조사!$A$3:$J$202,8,FALSE)&")")),"")) | H25: =IF(K25="","",INDEX('3.설계사'!$M$4:$M$303,K25)) | I25: =IF(K25="","",INDEX('3.설계사'!$N$4:$N$303,K25)) | J25: =IF(K25="","","한국마이크로닉 배성윤 차장입니다. "&D25&IF(INDEX('3.설계사'!$D$4:$D$303,K25)>0," 설계 진행하고 계신"," 설계하신")&" 걸로 알고 연락드렸습니다. 호텔 객실관리(키센서·온도조절기·조명 제어) 도면과 특기시방서를 무상으로 지원해 드리고 있어서, 이번 주에 10분만 찾아뵈어도 될까요?") | K25: =IFERROR(MATCH(22,'3.설계사'!$U$4:$U$303,0),"")
A26: =IF(K26="","",23) | B26: =IF(K26="","",INDEX('3.설계사'!$B$4:$B$303,K26)) | C26: =IF(K26="","",IF(INDEX('3.설계사'!$T$4:$T$303,K26)>=설정!$B$39,"약속 "&TEXT(INDEX('3.설계사'!$Q$4:$Q$303,K26),"m/d")&" · ",IF(INDEX('3.설계사'!$O$4:$O$303,K26)="","아직 안 가봄 · ","마지막 방문 "&INDEX('3.설계사'!$P$4:$P$303,K26)&"일 전 · "))&IF(INDEX('3.설계사'!$D$4:$D$303,K26)>0,"설계단계 "&INDEX('3.설계사'!$D$4:$D$303,K26)&"건 ","")&IF(INDEX('3.설계사'!$E$4:$E$303,K26)>0,"착공 "&INDEX('3.설계사'!$E$4:$E$303,K26)&"건 ","")&IF(INDEX('3.설계사'!$F$4:$F$303,K26)>0,"★"&INDEX('3.설계사'!$F$4:$F$303,K26),"")) | D26: =IF(K26="","",INDEX('3.설계사'!$K$4:$K$303,K26)) | E26: =IF(K26="","",INDEX('3.설계사'!$L$4:$L$303,K26)) | F26: =IF(K26="","",INDEX('3.설계사'!$H$4:$H$303,K26)) | G26: =IF(K26="","",IFERROR(IF(VLOOKUP(D26,현장_조사!$A$3:$J$202,5,FALSE)&""="","",VLOOKUP(D26,현장_조사!$A$3:$J$202,5,FALSE)&IF(VLOOKUP(D26,현장_조사!$A$3:$J$202,8,FALSE)="확정",""," ("&VLOOKUP(D26,현장_조사!$A$3:$J$202,8,FALSE)&")")),"")) | H26: =IF(K26="","",INDEX('3.설계사'!$M$4:$M$303,K26)) | I26: =IF(K26="","",INDEX('3.설계사'!$N$4:$N$303,K26)) | J26: =IF(K26="","","한국마이크로닉 배성윤 차장입니다. "&D26&IF(INDEX('3.설계사'!$D$4:$D$303,K26)>0," 설계 진행하고 계신"," 설계하신")&" 걸로 알고 연락드렸습니다. 호텔 객실관리(키센서·온도조절기·조명 제어) 도면과 특기시방서를 무상으로 지원해 드리고 있어서, 이번 주에 10분만 찾아뵈어도 될까요?") | K26: =IFERROR(MATCH(23,'3.설계사'!$U$4:$U$303,0),"")
A27: =IF(K27="","",24) | B27: =IF(K27="","",INDEX('3.설계사'!$B$4:$B$303,K27)) | C27: =IF(K27="","",IF(INDEX('3.설계사'!$T$4:$T$303,K27)>=설정!$B$39,"약속 "&TEXT(INDEX('3.설계사'!$Q$4:$Q$303,K27),"m/d")&" · ",IF(INDEX('3.설계사'!$O$4:$O$303,K27)="","아직 안 가봄 · ","마지막 방문 "&INDEX('3.설계사'!$P$4:$P$303,K27)&"일 전 · "))&IF(INDEX('3.설계사'!$D$4:$D$303,K27)>0,"설계단계 "&INDEX('3.설계사'!$D$4:$D$303,K27)&"건 ","")&IF(INDEX('3.설계사'!$E$4:$E$303,K27)>0,"착공 "&INDEX('3.설계사'!$E$4:$E$303,K27)&"건 ","")&IF(INDEX('3.설계사'!$F$4:$F$303,K27)>0,"★"&INDEX('3.설계사'!$F$4:$F$303,K27),"")) | D27: =IF(K27="","",INDEX('3.설계사'!$K$4:$K$303,K27)) | E27: =IF(K27="","",INDEX('3.설계사'!$L$4:$L$303,K27)) | F27: =IF(K27="","",INDEX('3.설계사'!$H$4:$H$303,K27)) | G27: =IF(K27="","",IFERROR(IF(VLOOKUP(D27,현장_조사!$A$3:$J$202,5,FALSE)&""="","",VLOOKUP(D27,현장_조사!$A$3:$J$202,5,FALSE)&IF(VLOOKUP(D27,현장_조사!$A$3:$J$202,8,FALSE)="확정",""," ("&VLOOKUP(D27,현장_조사!$A$3:$J$202,8,FALSE)&")")),"")) | H27: =IF(K27="","",INDEX('3.설계사'!$M$4:$M$303,K27)) | I27: =IF(K27="","",INDEX('3.설계사'!$N$4:$N$303,K27)) | J27: =IF(K27="","","한국마이크로닉 배성윤 차장입니다. "&D27&IF(INDEX('3.설계사'!$D$4:$D$303,K27)>0," 설계 진행하고 계신"," 설계하신")&" 걸로 알고 연락드렸습니다. 호텔 객실관리(키센서·온도조절기·조명 제어) 도면과 특기시방서를 무상으로 지원해 드리고 있어서, 이번 주에 10분만 찾아뵈어도 될까요?") | K27: =IFERROR(MATCH(24,'3.설계사'!$U$4:$U$303,0),"")
A28: =IF(K28="","",25) | B28: =IF(K28="","",INDEX('3.설계사'!$B$4:$B$303,K28)) | C28: =IF(K28="","",IF(INDEX('3.설계사'!$T$4:$T$303,K28)>=설정!$B$39,"약속 "&TEXT(INDEX('3.설계사'!$Q$4:$Q$303,K28),"m/d")&" · ",IF(INDEX('3.설계사'!$O$4:$O$303,K28)="","아직 안 가봄 · ","마지막 방문 "&INDEX('3.설계사'!$P$4:$P$303,K28)&"일 전 · "))&IF(INDEX('3.설계사'!$D$4:$D$303,K28)>0,"설계단계 "&INDEX('3.설계사'!$D$4:$D$303,K28)&"건 ","")&IF(INDEX('3.설계사'!$E$4:$E$303,K28)>0,"착공 "&INDEX('3.설계사'!$E$4:$E$303,K28)&"건 ","")&IF(INDEX('3.설계사'!$F$4:$F$303,K28)>0,"★"&INDEX('3.설계사'!$F$4:$F$303,K28),"")) | D28: =IF(K28="","",INDEX('3.설계사'!$K$4:$K$303,K28)) | E28: =IF(K28="","",INDEX('3.설계사'!$L$4:$L$303,K28)) | F28: =IF(K28="","",INDEX('3.설계사'!$H$4:$H$303,K28)) | G28: =IF(K28="","",IFERROR(IF(VLOOKUP(D28,현장_조사!$A$3:$J$202,5,FALSE)&""="","",VLOOKUP(D28,현장_조사!$A$3:$J$202,5,FALSE)&IF(VLOOKUP(D28,현장_조사!$A$3:$J$202,8,FALSE)="확정",""," ("&VLOOKUP(D28,현장_조사!$A$3:$J$202,8,FALSE)&")")),"")) | H28: =IF(K28="","",INDEX('3.설계사'!$M$4:$M$303,K28)) | I28: =IF(K28="","",INDEX('3.설계사'!$N$4:$N$303,K28)) | J28: =IF(K28="","","한국마이크로닉 배성윤 차장입니다. "&D28&IF(INDEX('3.설계사'!$D$4:$D$303,K28)>0," 설계 진행하고 계신"," 설계하신")&" 걸로 알고 연락드렸습니다. 호텔 객실관리(키센서·온도조절기·조명 제어) 도면과 특기시방서를 무상으로 지원해 드리고 있어서, 이번 주에 10분만 찾아뵈어도 될까요?") | K28: =IFERROR(MATCH(25,'3.설계사'!$U$4:$U$303,0),"")
A29: =IF(K29="","",26) | B29: =IF(K29="","",INDEX('3.설계사'!$B$4:$B$303,K29)) | C29: =IF(K29="","",IF(INDEX('3.설계사'!$T$4:$T$303,K29)>=설정!$B$39,"약속 "&TEXT(INDEX('3.설계사'!$Q$4:$Q$303,K29),"m/d")&" · ",IF(INDEX('3.설계사'!$O$4:$O$303,K29)="","아직 안 가봄 · ","마지막 방문 "&INDEX('3.설계사'!$P$4:$P$303,K29)&"일 전 · "))&IF(INDEX('3.설계사'!$D$4:$D$303,K29)>0,"설계단계 "&INDEX('3.설계사'!$D$4:$D$303,K29)&"건 ","")&IF(INDEX('3.설계사'!$E$4:$E$303,K29)>0,"착공 "&INDEX('3.설계사'!$E$4:$E$303,K29)&"건 ","")&IF(INDEX('3.설계사'!$F$4:$F$303,K29)>0,"★"&INDEX('3.설계사'!$F$4:$F$303,K29),"")) | D29: =IF(K29="","",INDEX('3.설계사'!$K$4:$K$303,K29)) | E29: =IF(K29="","",INDEX('3.설계사'!$L$4:$L$303,K29)) | F29: =IF(K29="","",INDEX('3.설계사'!$H$4:$H$303,K29)) | G29: =IF(K29="","",IFERROR(IF(VLOOKUP(D29,현장_조사!$A$3:$J$202,5,FALSE)&""="","",VLOOKUP(D29,현장_조사!$A$3:$J$202,5,FALSE)&IF(VLOOKUP(D29,현장_조사!$A$3:$J$202,8,FALSE)="확정",""," ("&VLOOKUP(D29,현장_조사!$A$3:$J$202,8,FALSE)&")")),"")) | H29: =IF(K29="","",INDEX('3.설계사'!$M$4:$M$303,K29)) | I29: =IF(K29="","",INDEX('3.설계사'!$N$4:$N$303,K29)) | J29: =IF(K29="","","한국마이크로닉 배성윤 차장입니다. "&D29&IF(INDEX('3.설계사'!$D$4:$D$303,K29)>0," 설계 진행하고 계신"," 설계하신")&" 걸로 알고 연락드렸습니다. 호텔 객실관리(키센서·온도조절기·조명 제어) 도면과 특기시방서를 무상으로 지원해 드리고 있어서, 이번 주에 10분만 찾아뵈어도 될까요?") | K29: =IFERROR(MATCH(26,'3.설계사'!$U$4:$U$303,0),"")
A30: =IF(K30="","",27) | B30: =IF(K30="","",INDEX('3.설계사'!$B$4:$B$303,K30)) | C30: =IF(K30="","",IF(INDEX('3.설계사'!$T$4:$T$303,K30)>=설정!$B$39,"약속 "&TEXT(INDEX('3.설계사'!$Q$4:$Q$303,K30),"m/d")&" · ",IF(INDEX('3.설계사'!$O$4:$O$303,K30)="","아직 안 가봄 · ","마지막 방문 "&INDEX('3.설계사'!$P$4:$P$303,K30)&"일 전 · "))&IF(INDEX('3.설계사'!$D$4:$D$303,K30)>0,"설계단계 "&INDEX('3.설계사'!$D$4:$D$303,K30)&"건 ","")&IF(INDEX('3.설계사'!$E$4:$E$303,K30)>0,"착공 "&INDEX('3.설계사'!$E$4:$E$303,K30)&"건 ","")&IF(INDEX('3.설계사'!$F$4:$F$303,K30)>0,"★"&INDEX('3.설계사'!$F$4:$F$303,K30),"")) | D30: =IF(K30="","",INDEX('3.설계사'!$K$4:$K$303,K30)) | E30: =IF(K30="","",INDEX('3.설계사'!$L$4:$L$303,K30)) | F30: =IF(K30="","",INDEX('3.설계사'!$H$4:$H$303,K30)) | G30: =IF(K30="","",IFERROR(IF(VLOOKUP(D30,현장_조사!$A$3:$J$202,5,FALSE)&""="","",VLOOKUP(D30,현장_조사!$A$3:$J$202,5,FALSE)&IF(VLOOKUP(D30,현장_조사!$A$3:$J$202,8,FALSE)="확정",""," ("&VLOOKUP(D30,현장_조사!$A$3:$J$202,8,FALSE)&")")),"")) | H30: =IF(K30="","",INDEX('3.설계사'!$M$4:$M$303,K30)) | I30: =IF(K30="","",INDEX('3.설계사'!$N$4:$N$303,K30)) | J30: =IF(K30="","","한국마이크로닉 배성윤 차장입니다. "&D30&IF(INDEX('3.설계사'!$D$4:$D$303,K30)>0," 설계 진행하고 계신"," 설계하신")&" 걸로 알고 연락드렸습니다. 호텔 객실관리(키센서·온도조절기·조명 제어) 도면과 특기시방서를 무상으로 지원해 드리고 있어서, 이번 주에 10분만 찾아뵈어도 될까요?") | K30: =IFERROR(MATCH(27,'3.설계사'!$U$4:$U$303,0),"")
A31: =IF(K31="","",28) | B31: =IF(K31="","",INDEX('3.설계사'!$B$4:$B$303,K31)) | C31: =IF(K31="","",IF(INDEX('3.설계사'!$T$4:$T$303,K31)>=설정!$B$39,"약속 "&TEXT(INDEX('3.설계사'!$Q$4:$Q$303,K31),"m/d")&" · ",IF(INDEX('3.설계사'!$O$4:$O$303,K31)="","아직 안 가봄 · ","마지막 방문 "&INDEX('3.설계사'!$P$4:$P$303,K31)&"일 전 · "))&IF(INDEX('3.설계사'!$D$4:$D$303,K31)>0,"설계단계 "&INDEX('3.설계사'!$D$4:$D$303,K31)&"건 ","")&IF(INDEX('3.설계사'!$E$4:$E$303,K31)>0,"착공 "&INDEX('3.설계사'!$E$4:$E$303,K31)&"건 ","")&IF(INDEX('3.설계사'!$F$4:$F$303,K31)>0,"★"&INDEX('3.설계사'!$F$4:$F$303,K31),"")) | D31: =IF(K31="","",INDEX('3.설계사'!$K$4:$K$303,K31)) | E31: =IF(K31="","",INDEX('3.설계사'!$L$4:$L$303,K31)) | F31: =IF(K31="","",INDEX('3.설계사'!$H$4:$H$303,K31)) | G31: =IF(K31="","",IFERROR(IF(VLOOKUP(D31,현장_조사!$A$3:$J$202,5,FALSE)&""="","",VLOOKUP(D31,현장_조사!$A$3:$J$202,5,FALSE)&IF(VLOOKUP(D31,현장_조사!$A$3:$J$202,8,FALSE)="확정",""," ("&VLOOKUP(D31,현장_조사!$A$3:$J$202,8,FALSE)&")")),"")) | H31: =IF(K31="","",INDEX('3.설계사'!$M$4:$M$303,K31)) | I31: =IF(K31="","",INDEX('3.설계사'!$N$4:$N$303,K31)) | J31: =IF(K31="","","한국마이크로닉 배성윤 차장입니다. "&D31&IF(INDEX('3.설계사'!$D$4:$D$303,K31)>0," 설계 진행하고 계신"," 설계하신")&" 걸로 알고 연락드렸습니다. 호텔 객실관리(키센서·온도조절기·조명 제어) 도면과 특기시방서를 무상으로 지원해 드리고 있어서, 이번 주에 10분만 찾아뵈어도 될까요?") | K31: =IFERROR(MATCH(28,'3.설계사'!$U$4:$U$303,0),"")
A32: =IF(K32="","",29) | B32: =IF(K32="","",INDEX('3.설계사'!$B$4:$B$303,K32)) | C32: =IF(K32="","",IF(INDEX('3.설계사'!$T$4:$T$303,K32)>=설정!$B$39,"약속 "&TEXT(INDEX('3.설계사'!$Q$4:$Q$303,K32),"m/d")&" · ",IF(INDEX('3.설계사'!$O$4:$O$303,K32)="","아직 안 가봄 · ","마지막 방문 "&INDEX('3.설계사'!$P$4:$P$303,K32)&"일 전 · "))&IF(INDEX('3.설계사'!$D$4:$D$303,K32)>0,"설계단계 "&INDEX('3.설계사'!$D$4:$D$303,K32)&"건 ","")&IF(INDEX('3.설계사'!$E$4:$E$303,K32)>0,"착공 "&INDEX('3.설계사'!$E$4:$E$303,K32)&"건 ","")&IF(INDEX('3.설계사'!$F$4:$F$303,K32)>0,"★"&INDEX('3.설계사'!$F$4:$F$303,K32),"")) | D32: =IF(K32="","",INDEX('3.설계사'!$K$4:$K$303,K32)) | E32: =IF(K32="","",INDEX('3.설계사'!$L$4:$L$303,K32)) | F32: =IF(K32="","",INDEX('3.설계사'!$H$4:$H$303,K32)) | G32: =IF(K32="","",IFERROR(IF(VLOOKUP(D32,현장_조사!$A$3:$J$202,5,FALSE)&""="","",VLOOKUP(D32,현장_조사!$A$3:$J$202,5,FALSE)&IF(VLOOKUP(D32,현장_조사!$A$3:$J$202,8,FALSE)="확정",""," ("&VLOOKUP(D32,현장_조사!$A$3:$J$202,8,FALSE)&")")),"")) | H32: =IF(K32="","",INDEX('3.설계사'!$M$4:$M$303,K32)) | I32: =IF(K32="","",INDEX('3.설계사'!$N$4:$N$303,K32)) | J32: =IF(K32="","","한국마이크로닉 배성윤 차장입니다. "&D32&IF(INDEX('3.설계사'!$D$4:$D$303,K32)>0," 설계 진행하고 계신"," 설계하신")&" 걸로 알고 연락드렸습니다. 호텔 객실관리(키센서·온도조절기·조명 제어) 도면과 특기시방서를 무상으로 지원해 드리고 있어서, 이번 주에 10분만 찾아뵈어도 될까요?") | K32: =IFERROR(MATCH(29,'3.설계사'!$U$4:$U$303,0),"")
A33: =IF(K33="","",30) | B33: =IF(K33="","",INDEX('3.설계사'!$B$4:$B$303,K33)) | C33: =IF(K33="","",IF(INDEX('3.설계사'!$T$4:$T$303,K33)>=설정!$B$39,"약속 "&TEXT(INDEX('3.설계사'!$Q$4:$Q$303,K33),"m/d")&" · ",IF(INDEX('3.설계사'!$O$4:$O$303,K33)="","아직 안 가봄 · ","마지막 방문 "&INDEX('3.설계사'!$P$4:$P$303,K33)&"일 전 · "))&IF(INDEX('3.설계사'!$D$4:$D$303,K33)>0,"설계단계 "&INDEX('3.설계사'!$D$4:$D$303,K33)&"건 ","")&IF(INDEX('3.설계사'!$E$4:$E$303,K33)>0,"착공 "&INDEX('3.설계사'!$E$4:$E$303,K33)&"건 ","")&IF(INDEX('3.설계사'!$F$4:$F$303,K33)>0,"★"&INDEX('3.설계사'!$F$4:$F$303,K33),"")) | D33: =IF(K33="","",INDEX('3.설계사'!$K$4:$K$303,K33)) | E33: =IF(K33="","",INDEX('3.설계사'!$L$4:$L$303,K33)) | F33: =IF(K33="","",INDEX('3.설계사'!$H$4:$H$303,K33)) | G33: =IF(K33="","",IFERROR(IF(VLOOKUP(D33,현장_조사!$A$3:$J$202,5,FALSE)&""="","",VLOOKUP(D33,현장_조사!$A$3:$J$202,5,FALSE)&IF(VLOOKUP(D33,현장_조사!$A$3:$J$202,8,FALSE)="확정",""," ("&VLOOKUP(D33,현장_조사!$A$3:$J$202,8,FALSE)&")")),"")) | H33: =IF(K33="","",INDEX('3.설계사'!$M$4:$M$303,K33)) | I33: =IF(K33="","",INDEX('3.설계사'!$N$4:$N$303,K33)) | J33: =IF(K33="","","한국마이크로닉 배성윤 차장입니다. "&D33&IF(INDEX('3.설계사'!$D$4:$D$303,K33)>0," 설계 진행하고 계신"," 설계하신")&" 걸로 알고 연락드렸습니다. 호텔 객실관리(키센서·온도조절기·조명 제어) 도면과 특기시방서를 무상으로 지원해 드리고 있어서, 이번 주에 10분만 찾아뵈어도 될까요?") | K33: =IFERROR(MATCH(30,'3.설계사'!$U$4:$U$303,0),"")

Sheet 1.산군_붙여넣기
A1: No | B1: 현장명 | C1: 소재지 | D1: 공종 | E1: 단계 | F1: 날짜1(추정:허가일) | G1: 날짜2(추정:착공일) | H1: 건축설계 | I1: 열J(미확인) | J1: 용도 | K1: 구분 | L1: 연면적㎡ | M1: 구조
A2: 1 | B2: 길상면 선두리 976-7 생활숙박시설 | C2: 인천광역시 강화군 길상면 선두리 976-7 | D2: 건축 | E2: 착공 | F2: 2026-06-23 | G2: 2026-07-02 | J2: 숙박시설 | K2: 신축 | L2: 460 | M2: 경량철골구조
A3: 2 | B3: 범방동 1898-7 생활숙박시설 | C3: 부산광역시 강서구 범방동 1898-7번지 | D3: 건축 | E3: 착공 | F3: 2022-04-15 | G3: 2025-10-31 | J3: 숙박시설 | K3: 신축 | L3: 22409
A4: 3 | B4: 대소면 성본리 115-5 숙박시설 | C4: 충청북도 음성군 대소면 성본리 산115-5 | D4: 건축 | E4: 착공 | F4: 2023-09-14 | G4: 2026-09-14 | H4: 태건축사사무소 | J4: 숙박시설 | K4: 신축 | L4: 2596 | M4: 철근콘크리트구조
A5: 4 | B5: 조양동 1558-3 생활숙박시설 | C5: 강원특별자치도 속초시 조양동 1558-3번지 | D5: 건축 | E5: 착공 | F5: 2023-09-27 | G5: 2026-09-14 | H5: (주)파인드건축사사무소 | J5: 숙박시설 | K5: 신축 | L5: 14868 | M5: 철근콘크리트구조
A6: 5 | B6: 명동2가 95-1 생활숙박시설 신축공사 | C6: 서울특별시 중구 남대문로 64 (명동2가) | D6: 건축 | E6: 착공 | F6: 2023-08-18 | G6: 2026-08-17 | H6: (주)야촌건축사사무소 | I6: (주)시경개발 | J6: 숙박시설 | K6: 신축 | L6: 6095 | M6: 철근콘크리트구조
A7: 6 | B7: 부산시 중구 남포동3가 생활형숙박시설 | C7: 부산광역시 중구 남포길 16 (남포동3가) | D7: 건축 | E7: 착공 | F7: 2023-07-31 | G7: 2026-07-31 | H7: (주)상지이앤에이건축… | I7: (주)평광이앤씨 | J7: 숙박시설 | K7: 신축 | L7: 14453 | M7: 철근콘크리트구조
A8: 7 | B8: 와룡동 37 관광숙박시설 | C8: 서울특별시 종로구 와룡동 37번지 | D8: 건축 | E8: 착공 | F8: 2026-04-01 | G8: 2026-07-30 | H8: 오파드건축연구소 | J8: 숙박시설 | K8: 신축 | L8: 301 | M8: 철근콘크리트구조
A9: 8 | B9: 경서동 경서3구역 11블록 2로트 숙박시설 | C9: 인천광역시 서구 경서동 블록 | D9: 건축 | E9: 착공 | F9: 2022-07-20 | G9: 2026-07-23 | H9: 건축사무소 고강 | J9: 숙박시설 | K9: 신축 | L9: 1995 | M9: 철근콘크리트구조
A10: 9 | B10: 종로5가 193-17,3번지 관광숙박시설 | C10: 서울특별시 종로구 종로 228 (종로5가) | D10: 건축 | E10: 착공 | F10: 2026-01-29 | G10: 2026-07-15 | H10: (주)아이디어키텍… | I10: 태재연구재단 | J10: 숙박시설 | K10: 신축 | L10: 4482 | M10: 철근콘크리트구조
A11: 10 | B11: 부전동 숙박시설 | C11: 부산광역시 부산진구 중앙대로680번가길 | D11: 건축 | E11: 착공 | F11: 2025-10-20 | G11: 2026-07-06 | H11: 이진건축사사무소 | J11: 숙박시설 | K11: 신축 | L11: 2000 | M11: 철근콘크리트구조
A12: 11 | B12: 서면 중방대리 106 일반숙박시설 | C12: 강원특별자치도 홍천군 서면 고두개길 112 | D12: 건축 | E12: 착공 | F12: 2024-08-08 | G12: 2026-06-30 | H12: (주)세움건축사사무소 | J12: 숙박시설 | K12: 신축 | L12: 97 | M12: 일반목구조

Sheet 3.설계사
A1: 설계사무소별 모음 (자동) — 산군 대상 현장을 설계사무소 이름으로 묶음
A2: ="설계사무소 "&COUNTIF(B4:B303,"?*")&"곳 · 대상 현장 "&COUNTIF('2.현장'!T2:T1001,TRUE)&"건 · ★ "&COUNTIFS('2.현장'!AA2:AA1001,"★")&"건"
A3: 번호 | B3: 설계사무소 | C3: 대상 현장 | D3: 설계단계 | E3: 시공단계 | F3: ★ 수 | G3: 현장점수 | H3: 최대 연면적 | I3: 최근 허가일 | J3: 최근 착공일 | K3: 대표 현장 | L3: 지역 | M3: 담당자 | N3: 전화 | O3: 마지막 방문 | P3: 경과일 | Q3: 다음 약속 | R3: 최근 결과 | S3: 상태 | T3: 우선점수 | U3: 순위
A4: =IF(B4="","",1) | B4: =IFERROR(INDEX('2.현장'!$V$2:$V$1001,MATCH(1,'2.현장'!$W$2:$W$1001,0)),"") | C4: =IF(B4="","",COUNTIFS('2.현장'!$V$2:$V$1001,B4,'2.현장'!$T$2:$T$1001,TRUE)) | D4: =IF(B4="","",COUNTIFS('2.현장'!$V$2:$V$1001,B4,'2.현장'!$U$2:$U$1001,"설계사")) | E4: =IF(B4="","",COUNTIFS('2.현장'!$V$2:$V$1001,B4,'2.현장'!$U$2:$U$1001,"시공사")) | F4: =IF(B4="","",COUNTIFS('2.현장'!$V$2:$V$1001,B4,'2.현장'!$T$2:$T$1001,TRUE,'2.현장'!$AA$2:$AA$1001,"★")) | G4: =IF(B4="","",SUMIFS('2.현장'!$AB$2:$AB$1001,'2.현장'!$V$2:$V$1001,B4,'2.현장'!$T$2:$T$1001,TRUE)) | H4: =IF(B4="","",_xlfn.MAXIFS('2.현장'!$D$2:$D$1001,'2.현장'!$V$2:$V$1001,B4,'2.현장'!$T$2:$T$1001,TRUE)) | I4: =IF(B4="","",IF(_xlfn.MAXIFS('2.현장'!$L$2:$L$1001,'2.현장'!$V$2:$V$1001,B4,'2.현장'!$T$2:$T$1001,TRUE)=0,"",_xlfn.MAXIFS('2.현장'!$L$2:$L$1001,'2.현장'!$V$2:$V$1001,B4,'2.현장'!$T$2:$T$1001,TRUE))) | J4: =IF(B4="","",IF(_xlfn.MAXIFS('2.현장'!$M$2:$M$1001,'2.현장'!$V$2:$V$1001,B4,'2.현장'!$T$2:$T$1001,TRUE)=0,"",_xlfn.MAXIFS('2.현장'!$M$2:$M$1001,'2.현장'!$V$2:$V$1001,B4,'2.현장'!$T$2:$T$1001,TRUE))) | K4: =IF(B4="","",IFERROR(INDEX('2.현장'!$C$2:$C$1001,IFERROR(MATCH(B4&"|설계사",'2.현장'!$Z$2:$Z$1001,0),IFERROR(MATCH(B4&"|시공사",'2.현장'!$Z$2:$Z$1001,0),MATCH(B4&"|늦음",'2.현장'!$Z$2:$Z$1001,0)))),"")) | L4: =IF(B4="","",IFERROR(INDEX('2.현장'!$N$2:$N$1001,IFERROR(MATCH(B4&"|설계사",'2.현장'!$Z$2:$Z$1001,0),IFERROR(MATCH(B4&"|시공사",'2.현장'!$Z$2:$Z$1001,0),MATCH(B4&"|늦음",'2.현장'!$Z$2:$Z$1001,0)))),"")) | M4: =IF(B4="","",IFERROR(VLOOKUP(B4,업체_메모!$A$3:$I$302,2,FALSE)&"","")) | N4: =IF(B4="","",IFERROR(VLOOKUP(B4,업체_메모!$A$3:$I$302,4,FALSE)&"","")) | O4: =IF(B4="","",IF(COUNTIF('4.방문기록'!$B$3:$B$502,B4)=0,"",_xlfn.MAXIFS('4.방문기록'!$A$3:$A$502,'4.방문기록'!$B$3:$B$502,B4))) | P4: =IF(O4="","",설정!$B$24-O4) | Q4: =IF(B4="","",IF(_xlfn.MAXIFS('4.방문기록'!$F$3:$F$502,'4.방문기록'!$B$3:$B$502,B4)=0,"",_xlfn.MAXIFS('4.방문기록'!$F$3:$F$502,'4.방문기록'!$B$3:$B$502,B4))) | R4: =IF(O4="","",IFERROR(INDEX('4.방문기록'!$H$3:$H$502,MATCH(B4&"|"&(O4*1),'4.방문기록'!$I$3:$I$502,0))&"","")) | S4: =IF(B4="","",IF(R4="관심 없음","제외",IF(O4="","안 가봄",IF(P4>=설정!$B$20,P4&"일 지남","최근 방문")))) | T4: =IF(B4="","",IF(S4="제외","",IF(AND(설정!$B$21<>"",L4<>설정!$B$21),"",IF(AND(Q4<>"",Q4>N(O4),Q4<=설정!$B$24+7),설정!$B$39+7-(Q4-설정!$B$24),IF(AND(G4>0,OR(S4="안 가봄",RIGHT(S4,2)="지남")),G4+IF(O4="",설정!$B$36,MIN(P4,60)*설정!$B$37)+MIN(N(H4)/1000*설정!$B$38,20),""))))) | U4: =IF(T4="","",COUNTIF(T$4:T$303,">"&T4)+COUNTIF(T$4:T4,T4))
A5: =IF(B5="","",2) | B5: =IFERROR(INDEX('2.현장'!$V$2:$V$1001,MATCH(2,'2.현장'!$W$2:$W$1001,0)),"") | C5: =IF(B5="","",COUNTIFS('2.현장'!$V$2:$V$1001,B5,'2.현장'!$T$2:$T$1001,TRUE)) | D5: =IF(B5="","",COUNTIFS('2.현장'!$V$2:$V$1001,B5,'2.현장'!$U$2:$U$1001,"설계사")) | E5: =IF(B5="","",COUNTIFS('2.현장'!$V$2:$V$1001,B5,'2.현장'!$U$2:$U$1001,"시공사")) | F5: =IF(B5="","",COUNTIFS('2.현장'!$V$2:$V$1001,B5,'2.현장'!$T$2:$T$1001,TRUE,'2.현장'!$AA$2:$AA$1001,"★")) | G5: =IF(B5="","",SUMIFS('2.현장'!$AB$2:$AB$1001,'2.현장'!$V$2:$V$1001,B5,'2.현장'!$T$2:$T$1001,TRUE)) | H5: =IF(B5="","",_xlfn.MAXIFS('2.현장'!$D$2:$D$1001,'2.현장'!$V$2:$V$1001,B5,'2.현장'!$T$2:$T$1001,TRUE)) | I5: =IF(B5="","",IF(_xlfn.MAXIFS('2.현장'!$L$2:$L$1001,'2.현장'!$V$2:$V$1001,B5,'2.현장'!$T$2:$T$1001,TRUE)=0,"",_xlfn.MAXIFS('2.현장'!$L$2:$L$1001,'2.현장'!$V$2:$V$1001,B5,'2.현장'!$T$2:$T$1001,TRUE))) | J5: =IF(B5="","",IF(_xlfn.MAXIFS('2.현장'!$M$2:$M$1001,'2.현장'!$V$2:$V$1001,B5,'2.현장'!$T$2:$T$1001,TRUE)=0,"",_xlfn.MAXIFS('2.현장'!$M$2:$M$1001,'2.현장'!$V$2:$V$1001,B5,'2.현장'!$T$2:$T$1001,TRUE))) | K5: =IF(B5="","",IFERROR(INDEX('2.현장'!$C$2:$C$1001,IFERROR(MATCH(B5&"|설계사",'2.현장'!$Z$2:$Z$1001,0),IFERROR(MATCH(B5&"|시공사",'2.현장'!$Z$2:$Z$1001,0),MATCH(B5&"|늦음",'2.현장'!$Z$2:$Z$1001,0)))),"")) | L5: =IF(B5="","",IFERROR(INDEX('2.현장'!$N$2:$N$1001,IFERROR(MATCH(B5&"|설계사",'2.현장'!$Z$2:$Z$1001,0),IFERROR(MATCH(B5&"|시공사",'2.현장'!$Z$2:$Z$1001,0),MATCH(B5&"|늦음",'2.현장'!$Z$2:$Z$1001,0)))),"")) | M5: =IF(B5="","",IFERROR(VLOOKUP(B5,업체_메모!$A$3:$I$302,2,FALSE)&"","")) | N5: =IF(B5="","",IFERROR(VLOOKUP(B5,업체_메모!$A$3:$I$302,4,FALSE)&"","")) | O5: =IF(B5="","",IF(COUNTIF('4.방문기록'!$B$3:$B$502,B5)=0,"",_xlfn.MAXIFS('4.방문기록'!$A$3:$A$502,'4.방문기록'!$B$3:$B$502,B5))) | P5: =IF(O5="","",설정!$B$24-O5) | Q5: =IF(B5="","",IF(_xlfn.MAXIFS('4.방문기록'!$F$3:$F$502,'4.방문기록'!$B$3:$B$502,B5)=0,"",_xlfn.MAXIFS('4.방문기록'!$F$3:$F$502,'4.방문기록'!$B$3:$B$502,B5))) | R5: =IF(O5="","",IFERROR(INDEX('4.방문기록'!$H$3:$H$502,MATCH(B5&"|"&(O5*1),'4.방문기록'!$I$3:$I$502,0))&"","")) | S5: =IF(B5="","",IF(R5="관심 없음","제외",IF(O5="","안 가봄",IF(P5>=설정!$B$20,P5&"일 지남","최근 방문")))) | T5: =IF(B5="","",IF(S5="제외","",IF(AND(설정!$B$21<>"",L5<>설정!$B$21),"",IF(AND(Q5<>"",Q5>N(O5),Q5<=설정!$B$24+7),설정!$B$39+7-(Q5-설정!$B$24),IF(AND(G5>0,OR(S5="안 가봄",RIGHT(S5,2)="지남")),G5+IF(O5="",설정!$B$36,MIN(P5,60)*설정!$B$37)+MIN(N(H5)/1000*설정!$B$38,20),""))))) | U5: =IF(T5="","",COUNTIF(T$4:T$303,">"&T5)+COUNTIF(T$4:T5,T5))
A6: =IF(B6="","",3) | B6: =IFERROR(INDEX('2.현장'!$V$2:$V$1001,MATCH(3,'2.현장'!$W$2:$W$1001,0)),"") | C6: =IF(B6="","",COUNTIFS('2.현장'!$V$2:$V$1001,B6,'2.현장'!$T$2:$T$1001,TRUE)) | D6: =IF(B6="","",COUNTIFS('2.현장'!$V$2:$V$1001,B6,'2.현장'!$U$2:$U$1001,"설계사")) | E6: =IF(B6="","",COUNTIFS('2.현장'!$V$2:$V$1001,B6,'2.현장'!$U$2:$U$1001,"시공사")) | F6: =IF(B6="","",COUNTIFS('2.현장'!$V$2:$V$1001,B6,'2.현장'!$T$2:$T$1001,TRUE,'2.현장'!$AA$2:$AA$1001,"★")) | G6: =IF(B6="","",SUMIFS('2.현장'!$AB$2:$AB$1001,'2.현장'!$V$2:$V$1001,B6,'2.현장'!$T$2:$T$1001,TRUE)) | H6: =IF(B6="","",_xlfn.MAXIFS('2.현장'!$D$2:$D$1001,'2.현장'!$V$2:$V$1001,B6,'2.현장'!$T$2:$T$1001,TRUE)) | I6: =IF(B6="","",IF(_xlfn.MAXIFS('2.현장'!$L$2:$L$1001,'2.현장'!$V$2:$V$1001,B6,'2.현장'!$T$2:$T$1001,TRUE)=0,"",_xlfn.MAXIFS('2.현장'!$L$2:$L$1001,'2.현장'!$V$2:$V$1001,B6,'2.현장'!$T$2:$T$1001,TRUE))) | J6: =IF(B6="","",IF(_xlfn.MAXIFS('2.현장'!$M$2:$M$1001,'2.현장'!$V$2:$V$1001,B6,'2.현장'!$T$2:$T$1001,TRUE)=0,"",_xlfn.MAXIFS('2.현장'!$M$2:$M$1001,'2.현장'!$V$2:$V$1001,B6,'2.현장'!$T$2:$T$1001,TRUE))) | K6: =IF(B6="","",IFERROR(INDEX('2.현장'!$C$2:$C$1001,IFERROR(MATCH(B6&"|설계사",'2.현장'!$Z$2:$Z$1001,0),IFERROR(MATCH(B6&"|시공사",'2.현장'!$Z$2:$Z$1001,0),MATCH(B6&"|늦음",'2.현장'!$Z$2:$Z$1001,0)))),"")) | L6: =IF(B6="","",IFERROR(INDEX('2.현장'!$N$2:$N$1001,IFERROR(MATCH(B6&"|설계사",'2.현장'!$Z$2:$Z$1001,0),IFERROR(MATCH(B6&"|시공사",'2.현장'!$Z$2:$Z$1001,0),MATCH(B6&"|늦음",'2.현장'!$Z$2:$Z$1001,0)))),"")) | M6: =IF(B6="","",IFERROR(VLOOKUP(B6,업체_메모!$A$3:$I$302,2,FALSE)&"","")) | N6: =IF(B6="","",IFERROR(VLOOKUP(B6,업체_메모!$A$3:$I$302,4,FALSE)&"","")) | O6: =IF(B6="","",IF(COUNTIF('4.방문기록'!$B$3:$B$502,B6)=0,"",_xlfn.MAXIFS('4.방문기록'!$A$3:$A$502,'4.방문기록'!$B$3:$B$502,B6))) | P6: =IF(O6="","",설정!$B$24-O6) | Q6: =IF(B6="","",IF(_xlfn.MAXIFS('4.방문기록'!$F$3:$F$502,'4.방문기록'!$B$3:$B$502,B6)=0,"",_xlfn.MAXIFS('4.방문기록'!$F$3:$F$502,'4.방문기록'!$B$3:$B$502,B6))) | R6: =IF(O6="","",IFERROR(INDEX('4.방문기록'!$H$3:$H$502,MATCH(B6&"|"&(O6*1),'4.방문기록'!$I$3:$I$502,0))&"","")) | S6: =IF(B6="","",IF(R6="관심 없음","제외",IF(O6="","안 가봄",IF(P6>=설정!$B$20,P6&"일 지남","최근 방문")))) | T6: =IF(B6="","",IF(S6="제외","",IF(AND(설정!$B$21<>"",L6<>설정!$B$21),"",IF(AND(Q6<>"",Q6>N(O6),Q6<=설정!$B$24+7),설정!$B$39+7-(Q6-설정!$B$24),IF(AND(G6>0,OR(S6="안 가봄",RIGHT(S6,2)="지남")),G6+IF(O6="",설정!$B$36,MIN(P6,60)*설정!$B$37)+MIN(N(H6)/1000*설정!$B$38,20),""))))) | U6: =IF(T6="","",COUNTIF(T$4:T$303,">"&T6)+COUNTIF(T$4:T6,T6))
A7: =IF(B7="","",4) | B7: =IFERROR(INDEX('2.현장'!$V$2:$V$1001,MATCH(4,'2.현장'!$W$2:$W$1001,0)),"") | C7: =IF(B7="","",COUNTIFS('2.현장'!$V$2:$V$1001,B7,'2.현장'!$T$2:$T$1001,TRUE)) | D7: =IF(B7="","",COUNTIFS('2.현장'!$V$2:$V$1001,B7,'2.현장'!$U$2:$U$1001,"설계사")) | E7: =IF(B7="","",COUNTIFS('2.현장'!$V$2:$V$1001,B7,'2.현장'!$U$2:$U$1001,"시공사")) | F7: =IF(B7="","",COUNTIFS('2.현장'!$V$2:$V$1001,B7,'2.현장'!$T$2:$T$1001,TRUE,'2.현장'!$AA$2:$AA$1001,"★")) | G7: =IF(B7="","",SUMIFS('2.현장'!$AB$2:$AB$1001,'2.현장'!$V$2:$V$1001,B7,'2.현장'!$T$2:$T$1001,TRUE)) | H7: =IF(B7="","",_xlfn.MAXIFS('2.현장'!$D$2:$D$1001,'2.현장'!$V$2:$V$1001,B7,'2.현장'!$T$2:$T$1001,TRUE)) | I7: =IF(B7="","",IF(_xlfn.MAXIFS('2.현장'!$L$2:$L$1001,'2.현장'!$V$2:$V$1001,B7,'2.현장'!$T$2:$T$1001,TRUE)=0,"",_xlfn.MAXIFS('2.현장'!$L$2:$L$1001,'2.현장'!$V$2:$V$1001,B7,'2.현장'!$T$2:$T$1001,TRUE))) | J7: =IF(B7="","",IF(_xlfn.MAXIFS('2.현장'!$M$2:$M$1001,'2.현장'!$V$2:$V$1001,B7,'2.현장'!$T$2:$T$1001,TRUE)=0,"",_xlfn.MAXIFS('2.현장'!$M$2:$M$1001,'2.현장'!$V$2:$V$1001,B7,'2.현장'!$T$2:$T$1001,TRUE))) | K7: =IF(B7="","",IFERROR(INDEX('2.현장'!$C$2:$C$1001,IFERROR(MATCH(B7&"|설계사",'2.현장'!$Z$2:$Z$1001,0),IFERROR(MATCH(B7&"|시공사",'2.현장'!$Z$2:$Z$1001,0),MATCH(B7&"|늦음",'2.현장'!$Z$2:$Z$1001,0)))),"")) | L7: =IF(B7="","",IFERROR(INDEX('2.현장'!$N$2:$N$1001,IFERROR(MATCH(B7&"|설계사",'2.현장'!$Z$2:$Z$1001,0),IFERROR(MATCH(B7&"|시공사",'2.현장'!$Z$2:$Z$1001,0),MATCH(B7&"|늦음",'2.현장'!$Z$2:$Z$1001,0)))),"")) | M7: =IF(B7="","",IFERROR(VLOOKUP(B7,업체_메모!$A$3:$I$302,2,FALSE)&"","")) | N7: =IF(B7="","",IFERROR(VLOOKUP(B7,업체_메모!$A$3:$I$302,4,FALSE)&"","")) | O7: =IF(B7="","",IF(COUNTIF('4.방문기록'!$B$3:$B$502,B7)=0,"",_xlfn.MAXIFS('4.방문기록'!$A$3:$A$502,'4.방문기록'!$B$3:$B$502,B7))) | P7: =IF(O7="","",설정!$B$24-O7) | Q7: =IF(B7="","",IF(_xlfn.MAXIFS('4.방문기록'!$F$3:$F$502,'4.방문기록'!$B$3:$B$502,B7)=0,"",_xlfn.MAXIFS('4.방문기록'!$F$3:$F$502,'4.방문기록'!$B$3:$B$502,B7))) | R7: =IF(O7="","",IFERROR(INDEX('4.방문기록'!$H$3:$H$502,MATCH(B7&"|"&(O7*1),'4.방문기록'!$I$3:$I$502,0))&"","")) | S7: =IF(B7="","",IF(R7="관심 없음","제외",IF(O7="","안 가봄",IF(P7>=설정!$B$20,P7&"일 지남","최근 방문")))) | T7: =IF(B7="","",IF(S7="제외","",IF(AND(설정!$B$21<>"",L7<>설정!$B$21),"",IF(AND(Q7<>"",Q7>N(O7),Q7<=설정!$B$24+7),설정!$B$39+7-(Q7-설정!$B$24),IF(AND(G7>0,OR(S7="안 가봄",RIGHT(S7,2)="지남")),G7+IF(O7="",설정!$B$36,MIN(P7,60)*설정!$B$37)+MIN(N(H7)/1000*설정!$B$38,20),""))))) | U7: =IF(T7="","",COUNTIF(T$4:T$303,">"&T7)+COUNTIF(T$4:T7,T7))
A8: =IF(B8="","",5) | B8: =IFERROR(INDEX('2.현장'!$V$2:$V$1001,MATCH(5,'2.현장'!$W$2:$W$1001,0)),"") | C8: =IF(B8="","",COUNTIFS('2.현장'!$V$2:$V$1001,B8,'2.현장'!$T$2:$T$1001,TRUE)) | D8: =IF(B8="","",COUNTIFS('2.현장'!$V$2:$V$1001,B8,'2.현장'!$U$2:$U$1001,"설계사")) | E8: =IF(B8="","",COUNTIFS('2.현장'!$V$2:$V$1001,B8,'2.현장'!$U$2:$U$1001,"시공사")) | F8: =IF(B8="","",COUNTIFS('2.현장'!$V$2:$V$1001,B8,'2.현장'!$T$2:$T$1001,TRUE,'2.현장'!$AA$2:$AA$1001,"★")) | G8: =IF(B8="","",SUMIFS('2.현장'!$AB$2:$AB$1001,'2.현장'!$V$2:$V$1001,B8,'2.현장'!$T$2:$T$1001,TRUE)) | H8: =IF(B8="","",_xlfn.MAXIFS('2.현장'!$D$2:$D$1001,'2.현장'!$V$2:$V$1001,B8,'2.현장'!$T$2:$T$1001,TRUE)) | I8: =IF(B8="","",IF(_xlfn.MAXIFS('2.현장'!$L$2:$L$1001,'2.현장'!$V$2:$V$1001,B8,'2.현장'!$T$2:$T$1001,TRUE)=0,"",_xlfn.MAXIFS('2.현장'!$L$2:$L$1001,'2.현장'!$V$2:$V$1001,B8,'2.현장'!$T$2:$T$1001,TRUE))) | J8: =IF(B8="","",IF(_xlfn.MAXIFS('2.현장'!$M$2:$M$1001,'2.현장'!$V$2:$V$1001,B8,'2.현장'!$T$2:$T$1001,TRUE)=0,"",_xlfn.MAXIFS('2.현장'!$M$2:$M$1001,'2.현장'!$V$2:$V$1001,B8,'2.현장'!$T$2:$T$1001,TRUE))) | K8: =IF(B8="","",IFERROR(INDEX('2.현장'!$C$2:$C$1001,IFERROR(MATCH(B8&"|설계사",'2.현장'!$Z$2:$Z$1001,0),IFERROR(MATCH(B8&"|시공사",'2.현장'!$Z$2:$Z$1001,0),MATCH(B8&"|늦음",'2.현장'!$Z$2:$Z$1001,0)))),"")) | L8: =IF(B8="","",IFERROR(INDEX('2.현장'!$N$2:$N$1001,IFERROR(MATCH(B8&"|설계사",'2.현장'!$Z$2:$Z$1001,0),IFERROR(MATCH(B8&"|시공사",'2.현장'!$Z$2:$Z$1001,0),MATCH(B8&"|늦음",'2.현장'!$Z$2:$Z$1001,0)))),"")) | M8: =IF(B8="","",IFERROR(VLOOKUP(B8,업체_메모!$A$3:$I$302,2,FALSE)&"","")) | N8: =IF(B8="","",IFERROR(VLOOKUP(B8,업체_메모!$A$3:$I$302,4,FALSE)&"","")) | O8: =IF(B8="","",IF(COUNTIF('4.방문기록'!$B$3:$B$502,B8)=0,"",_xlfn.MAXIFS('4.방문기록'!$A$3:$A$502,'4.방문기록'!$B$3:$B$502,B8))) | P8: =IF(O8="","",설정!$B$24-O8) | Q8: =IF(B8="","",IF(_xlfn.MAXIFS('4.방문기록'!$F$3:$F$502,'4.방문기록'!$B$3:$B$502,B8)=0,"",_xlfn.MAXIFS('4.방문기록'!$F$3:$F$502,'4.방문기록'!$B$3:$B$502,B8))) | R8: =IF(O8="","",IFERROR(INDEX('4.방문기록'!$H$3:$H$502,MATCH(B8&"|"&(O8*1),'4.방문기록'!$I$3:$I$502,0))&"","")) | S8: =IF(B8="","",IF(R8="관심 없음","제외",IF(O8="","안 가봄",IF(P8>=설정!$B$20,P8&"일 지남","최근 방문")))) | T8: =IF(B8="","",IF(S8="제외","",IF(AND(설정!$B$21<>"",L8<>설정!$B$21),"",IF(AND(Q8<>"",Q8>N(O8),Q8<=설정!$B$24+7),설정!$B$39+7-(Q8-설정!$B$24),IF(AND(G8>0,OR(S8="안 가봄",RIGHT(S8,2)="지남")),G8+IF(O8="",설정!$B$36,MIN(P8,60)*설정!$B$37)+MIN(N(H8)/1000*설정!$B$38,20),""))))) | U8: =IF(T8="","",COUNTIF(T$4:T$303,">"&T8)+COUNTIF(T$4:T8,T8))
A9: =IF(B9="","",6) | B9: =IFERROR(INDEX('2.현장'!$V$2:$V$1001,MATCH(6,'2.현장'!$W$2:$W$1001,0)),"") | C9: =IF(B9="","",COUNTIFS('2.현장'!$V$2:$V$1001,B9,'2.현장'!$T$2:$T$1001,TRUE)) | D9: =IF(B9="","",COUNTIFS('2.현장'!$V$2:$V$1001,B9,'2.현장'!$U$2:$U$1001,"설계사")) | E9: =IF(B9="","",COUNTIFS('2.현장'!$V$2:$V$1001,B9,'2.현장'!$U$2:$U$1001,"시공사")) | F9: =IF(B9="","",COUNTIFS('2.현장'!$V$2:$V$1001,B9,'2.현장'!$T$2:$T$1001,TRUE,'2.현장'!$AA$2:$AA$1001,"★")) | G9: =IF(B9="","",SUMIFS('2.현장'!$AB$2:$AB$1001,'2.현장'!$V$2:$V$1001,B9,'2.현장'!$T$2:$T$1001,TRUE)) | H9: =IF(B9="","",_xlfn.MAXIFS('2.현장'!$D$2:$D$1001,'2.현장'!$V$2:$V$1001,B9,'2.현장'!$T$2:$T$1001,TRUE)) | I9: =IF(B9="","",IF(_xlfn.MAXIFS('2.현장'!$L$2:$L$1001,'2.현장'!$V$2:$V$1001,B9,'2.현장'!$T$2:$T$1001,TRUE)=0,"",_xlfn.MAXIFS('2.현장'!$L$2:$L$1001,'2.현장'!$V$2:$V$1001,B9,'2.현장'!$T$2:$T$1001,TRUE))) | J9: =IF(B9="","",IF(_xlfn.MAXIFS('2.현장'!$M$2:$M$1001,'2.현장'!$V$2:$V$1001,B9,'2.현장'!$T$2:$T$1001,TRUE)=0,"",_xlfn.MAXIFS('2.현장'!$M$2:$M$1001,'2.현장'!$V$2:$V$1001,B9,'2.현장'!$T$2:$T$1001,TRUE))) | K9: =IF(B9="","",IFERROR(INDEX('2.현장'!$C$2:$C$1001,IFERROR(MATCH(B9&"|설계사",'2.현장'!$Z$2:$Z$1001,0),IFERROR(MATCH(B9&"|시공사",'2.현장'!$Z$2:$Z$1001,0),MATCH(B9&"|늦음",'2.현장'!$Z$2:$Z$1001,0)))),"")) | L9: =IF(B9="","",IFERROR(INDEX('2.현장'!$N$2:$N$1001,IFERROR(MATCH(B9&"|설계사",'2.현장'!$Z$2:$Z$1001,0),IFERROR(MATCH(B9&"|시공사",'2.현장'!$Z$2:$Z$1001,0),MATCH(B9&"|늦음",'2.현장'!$Z$2:$Z$1001,0)))),"")) | M9: =IF(B9="","",IFERROR(VLOOKUP(B9,업체_메모!$A$3:$I$302,2,FALSE)&"","")) | N9: =IF(B9="","",IFERROR(VLOOKUP(B9,업체_메모!$A$3:$I$302,4,FALSE)&"","")) | O9: =IF(B9="","",IF(COUNTIF('4.방문기록'!$B$3:$B$502,B9)=0,"",_xlfn.MAXIFS('4.방문기록'!$A$3:$A$502,'4.방문기록'!$B$3:$B$502,B9))) | P9: =IF(O9="","",설정!$B$24-O9) | Q9: =IF(B9="","",IF(_xlfn.MAXIFS('4.방문기록'!$F$3:$F$502,'4.방문기록'!$B$3:$B$502,B9)=0,"",_xlfn.MAXIFS('4.방문기록'!$F$3:$F$502,'4.방문기록'!$B$3:$B$502,B9))) | R9: =IF(O9="","",IFERROR(INDEX('4.방문기록'!$H$3:$H$502,MATCH(B9&"|"&(O9*1),'4.방문기록'!$I$3:$I$502,0))&"","")) | S9: =IF(B9="","",IF(R9="관심 없음","제외",IF(O9="","안 가봄",IF(P9>=설정!$B$20,P9&"일 지남","최근 방문")))) | T9: =IF(B9="","",IF(S9="제외","",IF(AND(설정!$B$21<>"",L9<>설정!$B$21),"",IF(AND(Q9<>"",Q9>N(O9),Q9<=설정!$B$24+7),설정!$B$39+7-(Q9-설정!$B$24),IF(AND(G9>0,OR(S9="안 가봄",RIGHT(S9,2)="지남")),G9+IF(O9="",설정!$B$36,MIN(P9,60)*설정!$B$37)+MIN(N(H9)/1000*설정!$B$38,20),""))))) | U9: =IF(T9="","",COUNTIF(T$4:T$303,">"&T9)+COUNTIF(T$4:T9,T9))
