Workbook

Sheet 0.입력칸
A1: 여기 숫자만 넣으시면 「예상 객실수」가 저절로 계산됩니다
A3: 객실 1실당 연면적 (㎡) | C3: ← 여기에 숫자를 넣으십시오 (복도·로비·주차 포함한 값)
A5: 우리 매출 1실당 (원) | C5: ← 여기에 숫자를 넣으시면 「예상 금액」이 나옵니다
A7: ※ 이 두 값은 제가 정하지 않습니다. 차장님이 넣으셔야 1·2번 시트의 빈칸이 채워집니다.

Sheet 1.가야 할 곳(1500㎡↑)
A1: 연면적 1,500㎡ 이상 142곳 — 초록=시공사 정해짐(바로 접촉) / 회색=정보 없음(시·군·구 건축과)
A3: 지역 | B3: 시·군·구 | C3: 현장명 | D3: 착공일 | E3: 경과(개월) | F3: 연면적(㎡) | G3: 예상 객실수 | H3: 예상 금액 | I3: 시공사 유무 | J3: 접촉처 | K3: 설계사 | L3: 감리사 | M3: 건축주 | N3: 허가구분 | O3: 주소
A4: 서울특별시 | B4: 영등포구 | C4: 영등포동3가 5-10 숙박시설 ((주) 영등포중앙기업) | D4: 2025-12-23 | E4: 9 | F4: 13748 | G4: =IF('0.입력칸'!$B$3="","",ROUND(F4/'0.입력칸'!$B$3,0)) | H4: =IF(OR('0.입력칸'!$B$3="",'0.입력칸'!$B$5=""),"",ROUND(G4*'0.입력칸'!$B$5,0)) | I4: 없음 | J4: 설계사 에스브이건축건축사사무소 | K4: 에스브이건축건축사사무소 | M4: (주)영등포중앙기업 | N4: 신축 | O4: 서울특별시 영등포구 영등포로 228 (영등포동3가)
A5: 서울특별시 | B5: 종로구 | C5: 종로5가 193-17 ,3 번지 관광숙박시설 | D5: 2026-07-15 | E5: 2 | F5: 4482 | G5: =IF('0.입력칸'!$B$3="","",ROUND(F5/'0.입력칸'!$B$3,0)) | H5: =IF(OR('0.입력칸'!$B$3="",'0.입력칸'!$B$5=""),"",ROUND(G5*'0.입력칸'!$B$5,0)) | I5: 없음 | J5: 설계사 (주)아이디아키텍츠건축사사무소 | K5: (주)아이디아키텍츠건축사사무소 | M5: 태재연구재단 | N5: 신축 | O5: 서울특별시 종로구 종로 228 (종로5가)
A6: 서울특별시 | B6: 종로구 | C6: 경운동 96-18 관광숙박시설 | D6: 2026-06-24 | E6: 3 | F6: 3642 | G6: =IF('0.입력칸'!$B$3="","",ROUND(F6/'0.입력칸'!$B$3,0)) | H6: =IF(OR('0.입력칸'!$B$3="",'0.입력칸'!$B$5=""),"",ROUND(G6*'0.입력칸'!$B$5,0)) | I6: 있음 | J6: 시공사 희상건설(주) | K6: 제로투엔건축사사무소종합건설(주) | L6: (주)범씨엠건축사사무소 | M6: (주)코람코라이프인프라위탁관리부… | N6: 신축 | O6: 서울특별시 종로구 율곡로 58 (경운동)
A7: 서울특별시 | B7: 중구 | C7: 광희동1가 생활숙박시설 신축공사 | D7: 2026-11-29 | E7: -2 | F7: 8426 | G7: =IF('0.입력칸'!$B$3="","",ROUND(F7/'0.입력칸'!$B$3,0)) | H7: =IF(OR('0.입력칸'!$B$3="",'0.입력칸'!$B$5=""),"",ROUND(G7*'0.입력칸'!$B$5,0)) | I7: 없음 | J7: 설계사 (주)종합건축사사무소도우건축 | K7: (주)종합건축사사무소도우건축 | M7: (주)교보자산신탁 | N7: 신축 | O7: 서울특별시 중구 광희동1가 72-4번지
A8: 서울특별시 | B8: 중구 | C8: 명동2가 95-1 생활숙박시설 신축공사 | D8: 2026-08-17 | E8: 1 | F8: 6095 | G8: =IF('0.입력칸'!$B$3="","",ROUND(F8/'0.입력칸'!$B$3,0)) | H8: =IF(OR('0.입력칸'!$B$3="",'0.입력칸'!$B$5=""),"",ROUND(G8*'0.입력칸'!$B$5,0)) | I8: 없음 | J8: 설계사 (주)야손건축사사무소 | K8: (주)야손건축사사무소 | M8: (주)시경개발 | N8: 신축 | O8: 서울특별시 중구 남대문로 64 (명동2가)
A9: 서울특별시 | B9: 중구 | C9: 광희동2가 40-1번지 외 5필지 일반숙박시설 | D9: 2024-04-15 | E9: 29 | F9: 4530 | G9: =IF('0.입력칸'!$B$3="","",ROUND(F9/'0.입력칸'!$B$3,0)) | H9: =IF(OR('0.입력칸'!$B$3="",'0.입력칸'!$B$5=""),"",ROUND(G9*'0.입력칸'!$B$5,0)) | I9: 있음 | J9: 시공사 도시건축종합건설(주) | K9: 비욘드건축 | L9: 비욘드건축 | M9: 시에이1010(주) | N9: 신축 | O9: 서울특별시 중구 광희동2가 40-1번지
A10: 인천광역시 | B10: 검단구 | C10: 인천 검단신도시 101 역세권 개발사업 C9-2블록 숙박시설 | D10: 2023-06-09 | E10: 39 | F10: 126473 | G10: =IF('0.입력칸'!$B$3="","",ROUND(F10/'0.입력칸'!$B$3,0)) | H10: =IF(OR('0.입력칸'!$B$3="",'0.입력칸'!$B$5=""),"",ROUND(G10*'0.입력칸'!$B$5,0)) | I10: 있음 | J10: 시공사 롯데건설(주) | K10: (주)건축사사무소광장 | L10: (주)정림씨엠건축사사무소 | M10: 넥스트브이시티피에프브이(주) | N10: 신축 | O10: 인천광역시 검단구 원당동 블록
A11: 인천광역시 | B11: 부평구 | C11: 부평동 531-3 오피스텔 및 생활숙박시설 | D11: 2024-12-06 | E11: 21 | F11: 14679 | G11: =IF('0.입력칸'!$B$3="","",ROUND(F11/'0.입력칸'!$B$3,0)) | H11: =IF(OR('0.입력칸'!$B$3="",'0.입력칸'!$B$5=""),"",ROUND(G11*'0.입력칸'!$B$5,0)) | I11: 있음 | J11: 시공사 (주)황산종합건설 | K11: (주)충일건축사사무소 | L11: (주)충일건축사사무소 | N11: 신축 | O11: 인천광역시 부평구 장제로83번길 6 (부평동)
A12: 인천광역시 | B12: 서해구 | C12: 경서동 경서3구역 11블록 2로트 숙박시설 (***) | D12: 2026-07-23 | E12: 2 | F12: 1995 | G12: =IF('0.입력칸'!$B$3="","",ROUND(F12/'0.입력칸'!$B$3,0)) | H12: =IF(OR('0.입력칸'!$B$3="",'0.입력칸'!$B$5=""),"",ROUND(G12*'0.입력칸'!$B$5,0)) | I12: 없음 | J12: 설계사 건축사무소 고강 | K12: 건축사무소 고강 | N12: 신축 | O12: 인천광역시 서해구 경서동 블록
A13: 인천광역시 | B13: 옹진군 | C13: 영흥면 내리 1212-4 숙박시설 | D13: 2022-07-22 | E13: 50 | F13: 1991 | G13: =IF('0.입력칸'!$B$3="","",ROUND(F13/'0.입력칸'!$B$3,0)) | H13: =IF(OR('0.입력칸'!$B$3="",'0.입력칸'!$B$5=""),"",ROUND(G13*'0.입력칸'!$B$5,0)) | I13: 있음 | J13: 시공사 엠에스종합건설(주) | K13: 반달건축사사무소 | L13: 플랜B건축사사무소 | N13: 신축 | O13: 인천광역시 옹진군 영흥면 영흥서로380번길 101-37
A14: 인천광역시 | B14: 중구 | C14: 인천광역시 중구 중산동 1960-10번지 오피스텔 및 생활숙박시설 | D14: 2026-01-12 | E14: 8 | F14: 39880 | G14: =IF('0.입력칸'!$B$3="","",ROUND(F14/'0.입력칸'!$B$3,0)) | H14: =IF(OR('0.입력칸'!$B$3="",'0.입력칸'!$B$5=""),"",ROUND(G14*'0.입력칸'!$B$5,0)) | I14: 없음 | J14: 설계사 (주)기안건축사사무소 | K14: (주)기안건축사사무소 | M14: 우리자산신탁(주) | N14: 신축 | O14: 인천광역시 중구 중산동 1960-10번지
A15: 인천광역시 | B15: 중구 | C15: 인천광역시 중구 중산동 1960-9번지 오피스텔 및 생활숙박시설 | D15: 2026-01-12 | E15: 8 | F15: 36635 | G15: =IF('0.입력칸'!$B$3="","",ROUND(F15/'0.입력칸'!$B$3,0)) | H15: =IF(OR('0.입력칸'!$B$3="",'0.입력칸'!$B$5=""),"",ROUND(G15*'0.입력칸'!$B$5,0)) | I15: 없음 | J15: 설계사 (주)기안건축사사무소 | K15: (주)기안건축사사무소 | M15: 우리자산신탁(주) | N15: 신축 | O15: 인천광역시 중구 중산동 1960-9번지
A16: 인천광역시 | B16: 중구 | C16: 인천광역시 중구 중산동 1960-8번지 오피스텔 및 생활숙박시설 | D16: 2026-01-12 | E16: 8 | F16: 36582 | G16: =IF('0.입력칸'!$B$3="","",ROUND(F16/'0.입력칸'!$B$3,0)) | H16: =IF(OR('0.입력칸'!$B$3="",'0.입력칸'!$B$5=""),"",ROUND(G16*'0.입력칸'!$B$5,0)) | I16: 없음 | J16: 설계사 (주)기안건축사사무소 | K16: (주)기안건축사사무소 | M16: 우리자산신탁(주) | N16: 신축 | O16: 인천광역시 중구 중산동 1960-8번지
A17: 인천광역시 | B17: 중구 | C17: 덕교동 81-3 숙박시설 | D17: 2024-04-22 | E17: 29 | F17: 2689 | G17: =IF('0.입력칸'!$B$3="","",ROUND(F17/'0.입력칸'!$B$3,0)) | H17: =IF(OR('0.입력칸'!$B$3="",'0.입력칸'!$B$5=""),"",ROUND(G17*'0.입력칸'!$B$5,0)) | I17: 없음 | J17: 설계사 (주)충일건축사사무소 | K17: (주)충일건축사사무소 | N17: 신축 | O17: 인천광역시 중구 덕교동 81-3번지
A18: 경기도 | B18: 가평군 | C18: 가평읍 복장리 66-6 숙박시설 (주식회사아아난티) | D18: 2023-03-29 | E18: 42 | F18: 30232 | G18: =IF('0.입력칸'!$B$3="","",ROUND(F18/'0.입력칸'!$B$3,0)) | H18: =IF(OR('0.입력칸'!$B$3="",'0.입력칸'!$B$5=""),"",ROUND(G18*'0.입력칸'!$B$5,0)) | I18: 있음 | J18: 시공사 (주)아난티 | K18: (주)에스케이엠건축사사무소 | L18: (주)이앤건축사사무소 | M18: (주)아난티 | N18: 신축 | O18: 경기도 가평군 가평읍 복장리 66-6번지
A19: 경기도 | B19: 가평군 | C19: 숙박시설-생활숙박시설(관광농원) - 농업회사법인(주)초원관… | D19: 2023-06-23 | E19: 39 | F19: 4235 | G19: =IF('0.입력칸'!$B$3="","",ROUND(F19/'0.입력칸'!$B$3,0)) | H19: =IF(OR('0.입력칸'!$B$3="",'0.입력칸'!$B$5=""),"",ROUND(G19*'0.입력칸'!$B$5,0)) | I19: 있음 | J19: 시공사 (주)인정종합건설 | K19: 기준건축사사무소 | N19: 신축 | O19: 경기도 가평군 조종면 현등사길 55-430
A20: 경기도 | B20: 가평군 | C20: 설악면 위곡리 255 생활형숙박시설 테라스형 변경 | D20: 2025-02-14 | E20: 19 | F20: 2343 | G20: =IF('0.입력칸'!$B$3="","",ROUND(F20/'0.입력칸'!$B$3,0)) | H20: =IF(OR('0.입력칸'!$B$3="",'0.입력칸'!$B$5=""),"",ROUND(G20*'0.입력칸'!$B$5,0)) | I20: 있음 | J20: 시공사 (주)루영건설 | N20: 신축 | O20: 경기도 가평군 설악면 위곡리 256번지
A21: 경기도 | B21: 가평군 | C21: 설악 설곡리 736-4 숙박시설 (***) | D21: 2023-05-11 | E21: 40 | F21: 2137 | G21: =IF('0.입력칸'!$B$3="","",ROUND(F21/'0.입력칸'!$B$3,0)) | H21: =IF(OR('0.입력칸'!$B$3="",'0.입력칸'!$B$5=""),"",ROUND(G21*'0.입력칸'!$B$5,0)) | I21: 있음 | J21: 시공사 (주)청우개발종합건설 | K21: 건축사무소명성 | N21: 신축 | O21: 경기도 가평군 설악면 설곡리 736-4번지
A22: 경기도 | B22: 가평군 | C22: 상면 상동리 370000 숙박시설 (에이피엘시스템(***)) | D22: 2022-11-16 | E22: 46 | F22: 1969 | G22: =IF('0.입력칸'!$B$3="","",ROUND(F22/'0.입력칸'!$B$3,0)) | H22: =IF(OR('0.입력칸'!$B$3="",'0.입력칸'!$B$5=""),"",ROUND(G22*'0.입력칸'!$B$5,0)) | I22: 없음 | J22: 설계사 (주)삼우건축사사무소 | K22: (주)삼우건축사사무소 | L22: (주)예다인건축사사무소 | M22: 에이피엘시스템(주) | N22: 신축 | O22: 경기도 가평군 상면 도야울길 88-33
A23: 경기도 | B23: 가평군 | C23: 상면 임초리 206 숙박시설 (***) | D23: 2022-01-13 | E23: 56 | F23: 1575 | G23: =IF('0.입력칸'!$B$3="","",ROUND(F23/'0.입력칸'!$B$3,0)) | H23: =IF(OR('0.입력칸'!$B$3="",'0.입력칸'!$B$5=""),"",ROUND(G23*'0.입력칸'!$B$5,0)) | I23: 없음 | J23: 설계사 한성건축사사무소 | K23: 한성건축사사무소 | L23: 한성건축사사무소 | N23: 신축 | O23: 경기도 가평군 상면 임초방안골로 119-100
A24: 경기도 | B24: 남양주시 | C24: 별내동 990 생활숙박시설 개발사업 (에스피남양주별내피에프… | D24: 2027-11-13 | E24: -14 | F24: 99547 | G24: =IF('0.입력칸'!$B$3="","",ROUND(F24/'0.입력칸'!$B$3,0)) | H24: =IF(OR('0.입력칸'!$B$3="",'0.입력칸'!$B$5=""),"",ROUND(G24*'0.입력칸'!$B$5,0)) | I24: 없음 | J24: 설계사 (주)정림건축종합건축사사무소 | K24: (주)정림건축종합건축사사무소 | M24: 에스피남양주별내피에프브이(주) | N24: 신축 | O24: 경기도 남양주시 별내동 990번지
A25: 경기도 | B25: 시흥시 | C25: 시화 MTV 거북섬상업 4-1, 4-2블럭 생활숙박시설 | D25: 2025-05-24 | E25: 16 | F25: 109940 | G25: =IF('0.입력칸'!$B$3="","",ROUND(F25/'0.입력칸'!$B$3,0)) | H25: =IF(OR('0.입력칸'!$B$3="",'0.입력칸'!$B$5=""),"",ROUND(G25*'0.입력칸'!$B$5,0)) | I25: 없음 | J25: 설계사 (주)지에이건축사사무소 | K25: (주)지에이건축사사무소 | M25: 신한자산신탁(주) | N25: 신축 | O25: 경기도 시흥시 거북섬로 113 (정왕동)
A26: 경기도 | B26: 시흥시 | C26: 정왕동 시화MT 거북섬 상업 1블록 숙박시설 (케이비부동산신… | D26: 2024-12-20 | E26: 21 | F26: 99409 | G26: =IF('0.입력칸'!$B$3="","",ROUND(F26/'0.입력칸'!$B$3,0)) | H26: =IF(OR('0.입력칸'!$B$3="",'0.입력칸'!$B$5=""),"",ROUND(G26*'0.입력칸'!$B$5,0)) | I26: 없음 | J26: 설계사 (주)정림건축종합건축사사무소 | K26: (주)정림건축종합건축사사무소 | M26: 케이비부동산신탁(주) | N26: 신축 | O26: 경기도 시흥시 정왕동 2723번지
A27: 경기도 | B27: 양평군 | C27: 용문면 마룡리 179-2 관광숙박시설 | D27: 2023-03-30 | E27: 42 | F27: 3569 | G27: =IF('0.입력칸'!$B$3="","",ROUND(F27/'0.입력칸'!$B$3,0)) | H27: =IF(OR('0.입력칸'!$B$3="",'0.입력칸'!$B$5=""),"",ROUND(G27*'0.입력칸'!$B$5,0)) | I27: 있음 | J27: 시공사 (주)태림건설 | K27: (주)크리트건축사사무소 | L27: (주)삼희건축사사무소 | M27: 포인트컨설팅(주) | N27: 신축 | O27: 경기도 양평군 용문면 마룡리 179-2번지
A28: 경기도 | B28: 양평군 | C28: 옥천면 신복리 665-21 숙박시설 (주식회사에이치엔케이투) | D28: 2024-05-20 | E28: 28 | F28: 2146 | G28: =IF('0.입력칸'!$B$3="","",ROUND(F28/'0.입력칸'!$B$3,0)) | H28: =IF(OR('0.입력칸'!$B$3="",'0.입력칸'!$B$5=""),"",ROUND(G28*'0.입력칸'!$B$5,0)) | I28: 있음 | J28: 시공사 (주)아일종합건설 | K28: 더나인건축사사무소(주) | L28: 유에이도시건축사사무소 | M28: (주)에이치엔케이투 | N28: 신축 | O28: 경기도 양평군 옥천면 신복리 665-21번지
A29: 경기도 | B29: 용인시 | C29: 이동읍 화산리 643-16 숙박시설 (***) | D29: 2023-11-23 | E29: 34 | F29: 3586 | G29: =IF('0.입력칸'!$B$3="","",ROUND(F29/'0.입력칸'!$B$3,0)) | H29: =IF(OR('0.입력칸'!$B$3="",'0.입력칸'!$B$5=""),"",ROUND(G29*'0.입력칸'!$B$5,0)) | I29: 있음 | J29: 시공사 (주)이도이엔씨 | K29: (주)혜림건축사사무소 | L29: (주)혜림건축사사무소 | N29: 신축 | O29: 경기도 용인시 처인구 이동읍 화산리 643-16번지
A30: 경기도 | B30: 용인시 | C30: 화산리 숙박시설 신축공사 | D30: 2023-07-10 | E30: 38 | F30: 1510 | G30: =IF('0.입력칸'!$B$3="","",ROUND(F30/'0.입력칸'!$B$3,0)) | H30: =IF(OR('0.입력칸'!$B$3="",'0.입력칸'!$B$5=""),"",ROUND(G30*'0.입력칸'!$B$5,0)) | I30: 있음 | J30: 시공사 (주)아이엠종합건설 | K30: 정음건축사사무소 | L30: 정음건축사사무소 | N30: 신축 | O30: 경기도 용인시 처인구 이동읍 화산리 670-1번지
A31: 경기도 | B31: 파주시 | C31: 대동리 관광숙박시설 | D31: 2023-09-08 | E31: 36 | F31: 4668 | G31: =IF('0.입력칸'!$B$3="","",ROUND(F31/'0.입력칸'!$B$3,0)) | H31: =IF(OR('0.입력칸'!$B$3="",'0.입력칸'!$B$5=""),"",ROUND(G31*'0.입력칸'!$B$5,0)) | I31: 있음 | J31: 시공사 (주)어반씨앤디 | K31: 건축사사무소예담 | L31: 건축사사무소예담 | N31: 신축 | O31: 경기도 파주시 탄현면 새오리로 167-19
A32: 경기도 | B32: 평택시 | C32: 평택시 팽성읍 안정리 169-19 생활숙박시설 | D32: 2024-08-26 | E32: 25 | F32: 5834 | G32: =IF('0.입력칸'!$B$3="","",ROUND(F32/'0.입력칸'!$B$3,0)) | H32: =IF(OR('0.입력칸'!$B$3="",'0.입력칸'!$B$5=""),"",ROUND(G32*'0.입력칸'!$B$5,0)) | I32: 있음 | J32: 시공사 (주)젠건축사사무소 | K32: 빌더스플랜(주) | N32: 신축 | O32: 경기도 평택시 팽성읍 안정리 169-19번지
A33: 경기도 | B33: 평택시 | C33: 신장동 208-22 일반숙박시설 및 근생시설 | D33: 2021-11-19 | E33: 58 | F33: 4962 | G33: =IF('0.입력칸'!$B$3="","",ROUND(F33/'0.입력칸'!$B$3,0)) | H33: =IF(OR('0.입력칸'!$B$3="",'0.입력칸'!$B$5=""),"",ROUND(G33*'0.입력칸'!$B$5,0)) | I33: 있음 | J33: 시공사 (주)지오종합건설 | K33: (주)정헌섭건축사사무소 | L33: (주)정헌섭건축사사무소 | N33: 신축 | O33: 경기도 평택시 신장동 208-22번지
A34: 경기도 | B34: 평택시 | C34: 고덕면 동청리 34-4 숙박시설 | D34: 2021-11-09 | E34: 58 | F34: 1973 | G34: =IF('0.입력칸'!$B$3="","",ROUND(F34/'0.입력칸'!$B$3,0)) | H34: =IF(OR('0.입력칸'!$B$3="",'0.입력칸'!$B$5=""),"",ROUND(G34*'0.입력칸'!$B$5,0)) | I34: 없음 | J34: 설계사 아키원건축사사무소 | K34: 아키원건축사사무소 | N34: 증축 | O34: 경기도 평택시 고덕면 청원로 661-15
A35: 경기도 | B35: 평택시 | C35: 지제동 302-20 숙박시설 (***) | D35: 2024-01-08 | E35: 32 | F35: 1569 | G35: =IF('0.입력칸'!$B$3="","",ROUND(F35/'0.입력칸'!$B$3,0)) | H35: =IF(OR('0.입력칸'!$B$3="",'0.입력칸'!$B$5=""),"",ROUND(G35*'0.입력칸'!$B$5,0)) | I35: 없음 | J35: 설계사 (주)정석건축사사무소 | K35: (주)정석건축사사무소 | N35: 신축 | O35: 경기도 평택시 남북대로 233-25 (지제동)
A36: 경기도 | B36: 포천시 | C36: 영북면 산정리 460 숙박시설-2부지 (주식회사리얼투게더) | D36: 2024-06-30 | E36: 27 | F36: 1676 | G36: =IF('0.입력칸'!$B$3="","",ROUND(F36/'0.입력칸'!$B$3,0)) | H36: =IF(OR('0.입력칸'!$B$3="",'0.입력칸'!$B$5=""),"",ROUND(G36*'0.입력칸'!$B$5,0)) | I36: 없음 | J36: 건축주 (주)리얼투게더 | M36: (주)리얼투게더 | N36: 신축 | O36: 경기도 포천시 영북면 산정리 460번지
A37: 경기도 | B37: 화성시 | C37: 화성병점 복합타운 8BL 생활숙박시설 | D37: 2024-11-29 | E37: 22 | F37: 40550 | G37: =IF('0.입력칸'!$B$3="","",ROUND(F37/'0.입력칸'!$B$3,0)) | H37: =IF(OR('0.입력칸'!$B$3="",'0.입력칸'!$B$5=""),"",ROUND(G37*'0.입력칸'!$B$5,0)) | I37: 없음 | J37: 설계사 (주)종합건축사사무소건원 | K37: (주)종합건축사사무소건원 | M37: (주)원희캐슬병점 | N37: 신축 | O37: 경기도 화성시 진안동 943-3번지
A38: 경기도 | B38: 화성시 | C38: 화성 병점복합타운 숙박시설 | D38: 2024-12-01 | E38: 22 | F38: 29977 | G38: =IF('0.입력칸'!$B$3="","",ROUND(F38/'0.입력칸'!$B$3,0)) | H38: =IF(OR('0.입력칸'!$B$3="",'0.입력칸'!$B$5=""),"",ROUND(G38*'0.입력칸'!$B$5,0)) | I38: 없음 | J38: 설계사 (주)종합건축사사무소건원 | K38: (주)종합건축사사무소건원 | M38: (주)원희캐슬병점 | N38: 신축 | O38: 경기도 화성시 진안동 944-1번지
A39: 경기도 | B39: 화성시 | C39: 제부리 숙박시설 | D39: 2026-12-24 | E39: -3 | F39: 2772 | G39: =IF('0.입력칸'!$B$3="","",ROUND(F39/'0.입력칸'!$B$3,0)) | H39: =IF(OR('0.입력칸'!$B$3="",'0.입력칸'!$B$5=""),"",ROUND(G39*'0.입력칸'!$B$5,0)) | I39: 없음 | J39: 설계사 (주)스페셜파트너건축사사무소 | K39: (주)스페셜파트너건축사사무소 | M39: 이레레저개발(주) | N39: 신축 | O39: 경기도 화성시 서신면 해안길 272
A40: 강원특별자치도 | B40: 강릉시 | C40: 안현동 201-16 관광숙박시설(휴양콘도미니엄) | D40: 2025-12-30 | E40: 9 | F40: 34622 | G40: =IF('0.입력칸'!$B$3="","",ROUND(F40/'0.입력칸'!$B$3,0)) | H40: =IF(OR('0.입력칸'!$B$3="",'0.입력칸'!$B$5=""),"",ROUND(G40*'0.입력칸'!$B$5,0)) | I40: 없음 | J40: 설계사 (주)에스엔비건축사사무소 | K40: (주)에스엔비건축사사무소 | M40: 케이비부동산신탁(주) | N40: 신축 | O40: 강원특별자치도 강릉시 안현동 201-16번지
A41: 강원특별자치도 | B41: 강릉시 | C41: 주문진읍 교항리 171-7 숙박시설 | D41: 2022-04-12 | E41: 53 | F41: 14611 | G41: =IF('0.입력칸'!$B$3="","",ROUND(F41/'0.입력칸'!$B$3,0)) | H41: =IF(OR('0.입력칸'!$B$3="",'0.입력칸'!$B$5=""),"",ROUND(G41*'0.입력칸'!$B$5,0)) | I41: 있음 | J41: 시공사 신화건설(주) | K41: (주)가온아키건축사사무소 | L41: (주)건축사사무소건일종합기술 | N41: 신축 | O41: 강원특별자치도 강릉시 주문진읍 시장길 9
...

Sheet 2.작은 곳(1500㎡미만)
A1: 연면적 1,500㎡ 미만 162곳 — 객실이 적어 우선순위는 낮습니다
A3: 지역 | B3: 시·군·구 | C3: 현장명 | D3: 착공일 | E3: 경과(개월) | F3: 연면적(㎡) | G3: 예상 객실수 | H3: 예상 금액 | I3: 시공사 유무 | J3: 접촉처 | K3: 설계사 | L3: 감리사 | M3: 건축주 | N3: 허가구분 | O3: 주소
A4: 서울특별시 | B4: 성동구 | C4: 성수동2가 299-195 관광숙박시설 | D4: 2026-05-19 | E4: 4 | F4: 757 | G4: =IF('0.입력칸'!$B$3="","",ROUND(F4/'0.입력칸'!$B$3,0)) | H4: =IF(OR('0.입력칸'!$B$3="",'0.입력칸'!$B$5=""),"",ROUND(G4*'0.입력칸'!$B$5,0)) | I4: 있음 | J4: 시공사 신아주종합건설(주) | K4: 고도플루토도시계획건축사사무소(주) | L4: 고도플루토도시계획건축사사무소(주) | N4: 신축 | O4: 서울특별시 성동구 성수동2가 299-195번지
A5: 서울특별시 | B5: 종로구 | C5: 종로구 연건동 관광숙박시설 및 근린생활시설 | D5: 2023-11-20 | E5: 34 | F5: 1331 | G5: =IF('0.입력칸'!$B$3="","",ROUND(F5/'0.입력칸'!$B$3,0)) | H5: =IF(OR('0.입력칸'!$B$3="",'0.입력칸'!$B$5=""),"",ROUND(G5*'0.입력칸'!$B$5,0)) | I5: 있음 | J5: 시공사 (주)범세종합건설 | K5: (주)건축사사무소위즈 | L5: (주)건축사사무소위즈 | M5: (주)케이브홀딩스 | N5: 신축 | O5: 서울특별시 종로구 창경궁로16길 73-4 (연건동)
A6: 서울특별시 | B6: 종로구 | C6: 와룡동 37 관광숙박시설 | D6: 2026-07-30 | E6: 2 | F6: 301 | G6: =IF('0.입력칸'!$B$3="","",ROUND(F6/'0.입력칸'!$B$3,0)) | H6: =IF(OR('0.입력칸'!$B$3="",'0.입력칸'!$B$5=""),"",ROUND(G6*'0.입력칸'!$B$5,0)) | I6: 없음 | J6: 설계사 오파드건축연구소 | K6: 오파드건축연구소 | N6: 신축 | O6: 서울특별시 종로구 와룡동 37번지
A7: 서울특별시 | B7: 중구 | C7: 을지로5가 270-9 생활형숙박시설 | D7: 2025-07-10 | E7: 14 | F7: 1460 | G7: =IF('0.입력칸'!$B$3="","",ROUND(F7/'0.입력칸'!$B$3,0)) | H7: =IF(OR('0.입력칸'!$B$3="",'0.입력칸'!$B$5=""),"",ROUND(G7*'0.입력칸'!$B$5,0)) | I7: 없음 | J7: 설계사 (주)건축사사무소태아건축 | K7: (주)건축사사무소태아건축 | N7: 증축 | O7: 서울특별시 중구 동호로35길 28 (을지로5가)
A8: 서울특별시 | B8: 중구 | C8: 황학동 17700000 숙박시설 (금주영) | D8: 2024-01-13 | E8: 32 | F8: 1131 | G8: =IF('0.입력칸'!$B$3="","",ROUND(F8/'0.입력칸'!$B$3,0)) | H8: =IF(OR('0.입력칸'!$B$3="",'0.입력칸'!$B$5=""),"",ROUND(G8*'0.입력칸'!$B$5,0)) | I8: 없음 | J8: 설계사 예건원건축사사무소 | K8: 예건원건축사사무소 | N8: 신축 | O8: 서울특별시 중구 난계로17길 60-20 (황학동)
A9: 서울특별시 | B9: 중구 | C9: 00숙박시설 | D9: 2026-05-14 | E9: 4 | F9: 825 | G9: =IF('0.입력칸'!$B$3="","",ROUND(F9/'0.입력칸'!$B$3,0)) | H9: =IF(OR('0.입력칸'!$B$3="",'0.입력칸'!$B$5=""),"",ROUND(G9*'0.입력칸'!$B$5,0)) | I9: 있음 | J9: 시공사 금원종합건설(주) | K9: (주)예원종합건축사사무소 | L9: (주)예원종합건축사사무소 | M9: (주)엔티에스개발 | N9: 신축 | O9: 서울특별시 중구 을지로42길 24 (광희동1가)
A10: 인천광역시 | B10: 강화군 | C10: 화도면 내리 2175 숙박시설 (주식회사케이앤에이치강화) | D10: 2023-07-21 | E10: 38 | F10: 530 | G10: =IF('0.입력칸'!$B$3="","",ROUND(F10/'0.입력칸'!$B$3,0)) | H10: =IF(OR('0.입력칸'!$B$3="",'0.입력칸'!$B$5=""),"",ROUND(G10*'0.입력칸'!$B$5,0)) | I10: 있음 | J10: 시공사 장학건설(주) | K10: 태멘건축사사무소 | N10: 신축 | O10: 인천광역시 강화군 화도면 내리 2175번지
A11: 인천광역시 | B11: 강화군 | C11: 길상면 선두리 976-7 생활숙박시설 | D11: 2026-07-02 | E11: 3 | F11: 460 | G11: =IF('0.입력칸'!$B$3="","",ROUND(F11/'0.입력칸'!$B$3,0)) | H11: =IF(OR('0.입력칸'!$B$3="",'0.입력칸'!$B$5=""),"",ROUND(G11*'0.입력칸'!$B$5,0)) | I11: 없음 | J11: (정보 없음 — 시·군·구 건축과) | N11: 신축 | O11: 인천광역시 강화군 길상면 선두리 976-7번지
A12: 인천광역시 | B12: 강화군 | C12: 삼산면 매음리 627-132 생활형숙박시설 | D12: 2024-10-03 | E12: 24 | F12: 399 | G12: =IF('0.입력칸'!$B$3="","",ROUND(F12/'0.입력칸'!$B$3,0)) | H12: =IF(OR('0.입력칸'!$B$3="",'0.입력칸'!$B$5=""),"",ROUND(G12*'0.입력칸'!$B$5,0)) | I12: 없음 | J12: 설계사 종현건축사사무소 | K12: 종현건축사사무소 | N12: 신축 | O12: 인천광역시 강화군 삼산면 매음리 627-132번지
A13: 인천광역시 | B13: 강화군 | C13: 삼산면 매음리 114-211 숙박시설 (***) / A-8 | D13: 2022-04-28 | E13: 53 | F13: 204 | G13: =IF('0.입력칸'!$B$3="","",ROUND(F13/'0.입력칸'!$B$3,0)) | H13: =IF(OR('0.입력칸'!$B$3="",'0.입력칸'!$B$5=""),"",ROUND(G13*'0.입력칸'!$B$5,0)) | I13: 있음 | J13: 시공사 동호건설(주) | K13: 태엔건축사사무소 | L13: 광덕건축사사무소 | N13: 신축 | O13: 인천광역시 강화군 삼산면 매음리 114-211번지
A14: 인천광역시 | B14: 강화군 | C14: 길상면 장흥리 276-57 숙박시설 (원유석) | D14: 2024-06-19 | E14: 27 | F14: 199 | G14: =IF('0.입력칸'!$B$3="","",ROUND(F14/'0.입력칸'!$B$3,0)) | H14: =IF(OR('0.입력칸'!$B$3="",'0.입력칸'!$B$5=""),"",ROUND(G14*'0.입력칸'!$B$5,0)) | I14: 없음 | J14: 설계사 홍건축사사무소 | K14: 홍건축사사무소 | N14: 신축 | O14: 인천광역시 강화군 길상면 장흥리 276-57번지
A15: 인천광역시 | B15: 강화군 | C15: 삼산면 매음리 114-211 숙박시설 (***) / A-9 | D15: 2022-04-28 | E15: 53 | F15: 199 | G15: =IF('0.입력칸'!$B$3="","",ROUND(F15/'0.입력칸'!$B$3,0)) | H15: =IF(OR('0.입력칸'!$B$3="",'0.입력칸'!$B$5=""),"",ROUND(G15*'0.입력칸'!$B$5,0)) | I15: 있음 | J15: 시공사 동호건설(주) | K15: 태엔건축사사무소 | L15: 광덕건축사사무소 | N15: 신축 | O15: 인천광역시 강화군 삼산면 매음리 114-212번지
A16: 인천광역시 | B16: 강화군 | C16: 삼산면 매음리 114-243 숙박시설 (***) | D16: 2021-08-31 | E16: 61 | F16: 99 | G16: =IF('0.입력칸'!$B$3="","",ROUND(F16/'0.입력칸'!$B$3,0)) | H16: =IF(OR('0.입력칸'!$B$3="",'0.입력칸'!$B$5=""),"",ROUND(G16*'0.입력칸'!$B$5,0)) | I16: 없음 | J16: 설계사 건축사사무소알앤비 | K16: 건축사사무소알앤비 | N16: 신축 | O16: 인천광역시 강화군 삼산면 매음리 114-243번지
A17: 인천광역시 | B17: 미추홀구 | C17: 용현동 624-9 숙박시설(수협은행) | D17: 2022-06-24 | E17: 51 | F17: 1358 | G17: =IF('0.입력칸'!$B$3="","",ROUND(F17/'0.입력칸'!$B$3,0)) | H17: =IF(OR('0.입력칸'!$B$3="",'0.입력칸'!$B$5=""),"",ROUND(G17*'0.입력칸'!$B$5,0)) | I17: 없음 | J17: 설계사 (주)미성건축사사무소 | K17: (주)미성건축사사무소 | N17: 증축 | O17: 인천광역시 미추홀구 아암대로53번길 15 (용현동)
A18: 인천광역시 | B18: 옹진군 | C18: 영흥면 선재리 521-90 숙박시설 (***) | D18: 2025-07-24 | E18: 14 | F18: 1212 | G18: =IF('0.입력칸'!$B$3="","",ROUND(F18/'0.입력칸'!$B$3,0)) | H18: =IF(OR('0.입력칸'!$B$3="",'0.입력칸'!$B$5=""),"",ROUND(G18*'0.입력칸'!$B$5,0)) | I18: 없음 | J18: 설계사 (주)미성건축사사무소 | K18: (주)미성건축사사무소 | N18: 신축 | O18: 인천광역시 옹진군 영흥면 선재226번길 107-9
A19: 인천광역시 | B19: 옹진군 | C19: 영흥면 외리 17-32 숙박시설 (***) | D19: 2025-01-09 | E19: 20 | F19: 738 | G19: =IF('0.입력칸'!$B$3="","",ROUND(F19/'0.입력칸'!$B$3,0)) | H19: =IF(OR('0.입력칸'!$B$3="",'0.입력칸'!$B$5=""),"",ROUND(G19*'0.입력칸'!$B$5,0)) | I19: 없음 | J19: 설계사 아침건축사사무소 | K19: 아침건축사사무소 | N19: 신축 | O19: 인천광역시 옹진군 영흥면 외리 17-32번지
A20: 인천광역시 | B20: 옹진군 | C20: 관광숙박시설-호스텔 | D20: 2026-06-02 | E20: 4 | F20: 259 | G20: =IF('0.입력칸'!$B$3="","",ROUND(F20/'0.입력칸'!$B$3,0)) | H20: =IF(OR('0.입력칸'!$B$3="",'0.입력칸'!$B$5=""),"",ROUND(G20*'0.입력칸'!$B$5,0)) | I20: 없음 | J20: 설계사 (주)호누건축사사무소 | K20: (주)호누건축사사무소 | N20: 증축 | O20: 인천광역시 옹진군 영흥면 영흥로643번길 15-1
A21: 인천광역시 | B21: 중구 | C21: 을왕동 762-119 관광숙박시설(호스텔)-이혜석 | D21: 2023-08-28 | E21: 37 | F21: 598 | G21: =IF('0.입력칸'!$B$3="","",ROUND(F21/'0.입력칸'!$B$3,0)) | H21: =IF(OR('0.입력칸'!$B$3="",'0.입력칸'!$B$5=""),"",ROUND(G21*'0.입력칸'!$B$5,0)) | I21: 있음 | J21: 시공사 (주)태원건설 | N21: 대수선 | O21: 인천광역시 중구 용유서로348번길 12 (을왕동, 비치뷰하우스)
A22: 인천광역시 | B22: 중구 | C22: 을왕동 742-12 숙박시설 (***) | D22: 2023-03-24 | E22: 42 | F22: 149 | G22: =IF('0.입력칸'!$B$3="","",ROUND(F22/'0.입력칸'!$B$3,0)) | H22: =IF(OR('0.입력칸'!$B$3="",'0.입력칸'!$B$5=""),"",ROUND(G22*'0.입력칸'!$B$5,0)) | I22: 없음 | J22: 설계사 팀이십일건축사사무소 | K22: 팀이십일건축사사무소 | N22: 증축 | O22: 인천광역시 중구 용유서로302번길 23 (을왕동)
A23: 경기도 | B23: 가평군 | C23: 숙박시설(생활숙박시설) - 주식회사 에이치와이개발 | D23: 2026-04-27 | E23: 5 | F23: 1371 | G23: =IF('0.입력칸'!$B$3="","",ROUND(F23/'0.입력칸'!$B$3,0)) | H23: =IF(OR('0.입력칸'!$B$3="",'0.입력칸'!$B$5=""),"",ROUND(G23*'0.입력칸'!$B$5,0)) | I23: 있음 | J23: 시공사 지건설(주) | N23: 신축 | O23: 경기도 가평군 조종면 운악리 산176-1번지
A24: 경기도 | B24: 가평군 | C24: 조종면 상판리 3790000 숙박시설 (***) | D24: 2024-11-27 | E24: 22 | F24: 1348 | G24: =IF('0.입력칸'!$B$3="","",ROUND(F24/'0.입력칸'!$B$3,0)) | H24: =IF(OR('0.입력칸'!$B$3="",'0.입력칸'!$B$5=""),"",ROUND(G24*'0.입력칸'!$B$5,0)) | I24: 없음 | J24: 설계사 한성건축사사무소 | K24: 한성건축사사무소 | N24: 신축 | O24: 경기도 가평군 조종면 상판리 379번지
A25: 경기도 | B25: 가평군 | C25: 청평면 삼회리 188-1 숙박시설 ((주)이스페이스) | D25: 2023-04-04 | E25: 42 | F25: 1334 | G25: =IF('0.입력칸'!$B$3="","",ROUND(F25/'0.입력칸'!$B$3,0)) | H25: =IF(OR('0.입력칸'!$B$3="",'0.입력칸'!$B$5=""),"",ROUND(G25*'0.입력칸'!$B$5,0)) | I25: 없음 | J25: 설계사 정풍건축사사무소 | K25: 정풍건축사사무소 | N25: 신축 | O25: 경기도 가평군 청평면 삼회리 188-1번지
A26: 경기도 | B26: 가평군 | C26: 북면 백둔리 66 숙박시설 (***) | D26: 2022-11-29 | E26: 46 | F26: 1275 | G26: =IF('0.입력칸'!$B$3="","",ROUND(F26/'0.입력칸'!$B$3,0)) | H26: =IF(OR('0.입력칸'!$B$3="",'0.입력칸'!$B$5=""),"",ROUND(G26*'0.입력칸'!$B$5,0)) | I26: 있음 | J26: 시공사 제이풀건설(주) | K26: (주)케이와이케이건축사사무소 | L26: (주)제이풀씨엠건축사사무소 | N26: 신축 | O26: 경기도 가평군 북면 백둔로133번길 63
A27: 경기도 | B27: 가평군 | C27: 숙박시설(생활숙박) - 정현주 | D27: 2025-06-28 | E27: 15 | F27: 972 | G27: =IF('0.입력칸'!$B$3="","",ROUND(F27/'0.입력칸'!$B$3,0)) | H27: =IF(OR('0.입력칸'!$B$3="",'0.입력칸'!$B$5=""),"",ROUND(G27*'0.입력칸'!$B$5,0)) | I27: 없음 | J27: 설계사 기준건축사사무소 | K27: 기준건축사사무소 | N27: 신축 | O27: 경기도 가평군 청평면 양진길 72
A28: 경기도 | B28: 가평군 | C28: 북면 제령리 557-7 생활형숙박시설 증축공사 | D28: 2026-06-12 | E28: 3 | F28: 942 | G28: =IF('0.입력칸'!$B$3="","",ROUND(F28/'0.입력칸'!$B$3,0)) | H28: =IF(OR('0.입력칸'!$B$3="",'0.입력칸'!$B$5=""),"",ROUND(G28*'0.입력칸'!$B$5,0)) | I28: 없음 | J28: 설계사 알에이케이건축사사무소 | K28: 알에이케이건축사사무소 | N28: 증축 | O28: 경기도 가평군 북면 꽃넘이길 115-47
A29: 경기도 | B29: 가평군 | C29: 가평읍 산유리 67 숙박시설 ((주)호명산힐링타운) | D29: 2024-05-17 | E29: 28 | F29: 849 | G29: =IF('0.입력칸'!$B$3="","",ROUND(F29/'0.입력칸'!$B$3,0)) | H29: =IF(OR('0.입력칸'!$B$3="",'0.입력칸'!$B$5=""),"",ROUND(G29*'0.입력칸'!$B$5,0)) | I29: 없음 | J29: 설계사 건축사사무소태은 | K29: 건축사사무소태은 | N29: 신축 | O29: 경기도 가평군 가평읍 산유리 산 67번지
A30: 경기도 | B30: 가평군 | C30: 청평면 삼회리 470-1 숙박시설 (***) | D30: 2024-04-26 | E30: 29 | F30: 634 | G30: =IF('0.입력칸'!$B$3="","",ROUND(F30/'0.입력칸'!$B$3,0)) | H30: =IF(OR('0.입력칸'!$B$3="",'0.입력칸'!$B$5=""),"",ROUND(G30*'0.입력칸'!$B$5,0)) | I30: 없음 | J30: 설계사 (주)한서건축사사무소 | K30: (주)한서건축사사무소 | N30: 신축 | O30: 경기도 가평군 청평면 삼회리 470-1번지
A31: 경기도 | B31: 가평군 | C31: 상면 행현리 460 숙박시설 (***) | D31: 2024-06-25 | E31: 27 | F31: 609 | G31: =IF('0.입력칸'!$B$3="","",ROUND(F31/'0.입력칸'!$B$3,0)) | H31: =IF(OR('0.입력칸'!$B$3="",'0.입력칸'!$B$5=""),"",ROUND(G31*'0.입력칸'!$B$5,0)) | I31: 없음 | J31: 설계사 기준건축사사무소 | K31: 기준건축사사무소 | N31: 신축 | O31: 경기도 가평군 상면 행현리 460번지
A32: 경기도 | B32: 가평군 | C32: 생활숙박시설 | D32: 2023-04-04 | E32: 42 | F32: 574 | G32: =IF('0.입력칸'!$B$3="","",ROUND(F32/'0.입력칸'!$B$3,0)) | H32: =IF(OR('0.입력칸'!$B$3="",'0.입력칸'!$B$5=""),"",ROUND(G32*'0.입력칸'!$B$5,0)) | I32: 있음 | J32: 시공사 (주)오케이종합건설 | N32: 신축 | O32: 경기도 가평군 조종면 운악청로 238-38
A33: 경기도 | B33: 가평군 | C33: 생활숙박시설 | D33: 2022-08-04 | E33: 50 | F33: 574 | G33: =IF('0.입력칸'!$B$3="","",ROUND(F33/'0.입력칸'!$B$3,0)) | H33: =IF(OR('0.입력칸'!$B$3="",'0.입력칸'!$B$5=""),"",ROUND(G33*'0.입력칸'!$B$5,0)) | I33: 있음 | J33: 시공사 (주)오케이종합건설 | K33: 월드건축사사무소 | L33: 월드건축사사무소 | N33: 신축 | O33: 경기도 가평군 조종면 운악청계로 238-38
A34: 경기도 | B34: 가평군 | C34: 생활숙박시설 | D34: 2022-08-03 | E34: 50 | F34: 574 | G34: =IF('0.입력칸'!$B$3="","",ROUND(F34/'0.입력칸'!$B$3,0)) | H34: =IF(OR('0.입력칸'!$B$3="",'0.입력칸'!$B$5=""),"",ROUND(G34*'0.입력칸'!$B$5,0)) | I34: 있음 | J34: 시공사 (주)오케이종합건설 | K34: 월드건축사사무소 | L34: 월드건축사사무소 | N34: 신축 | O34: 경기도 가평군 조종면 현리 2-5번지
A35: 경기도 | B35: 가평군 | C35: 상면 행현리 322-13 숙박시설 및 근생 | D35: 2021-12-24 | E35: 57 | F35: 506 | G35: =IF('0.입력칸'!$B$3="","",ROUND(F35/'0.입력칸'!$B$3,0)) | H35: =IF(OR('0.입력칸'!$B$3="",'0.입력칸'!$B$5=""),"",ROUND(G35*'0.입력칸'!$B$5,0)) | I35: 없음 | J35: 설계사 아뜰리에노에마 | K35: 아뜰리에노에마 | N35: 증축 | O35: 경기도 가평군 상면 측령로45번길 93-48
A36: 경기도 | B36: 가평군 | C36: 조종면 운악리 162-54 숙박시설 (***)-6 | D36: 2024-01-05 | E36: 32 | F36: 391 | G36: =IF('0.입력칸'!$B$3="","",ROUND(F36/'0.입력칸'!$B$3,0)) | H36: =IF(OR('0.입력칸'!$B$3="",'0.입력칸'!$B$5=""),"",ROUND(G36*'0.입력칸'!$B$5,0)) | I36: 없음 | J36: 설계사 기준건축사사무소 | K36: 기준건축사사무소 | N36: 신축 | O36: 경기도 가평군 조종면 운악리 산 162-54번지
A37: 경기도 | B37: 가평군 | C37: 조종면 운악리 162-56 숙박시설 ((주)운악산에코랜드) -14 | D37: 2023-06-29 | E37: 39 | F37: 353 | G37: =IF('0.입력칸'!$B$3="","",ROUND(F37/'0.입력칸'!$B$3,0)) | H37: =IF(OR('0.입력칸'!$B$3="",'0.입력칸'!$B$5=""),"",ROUND(G37*'0.입력칸'!$B$5,0)) | I37: 없음 | J37: 설계사 기준건축사사무소 | K37: 기준건축사사무소 | N37: 신축 | O37: 경기도 가평군 조종면 운악리 산 162-56번지
A38: 경기도 | B38: 가평군 | C38: 조종면 운악리 419-21 숙박시설 (***) | D38: 2024-09-25 | E38: 24 | F38: 324 | G38: =IF('0.입력칸'!$B$3="","",ROUND(F38/'0.입력칸'!$B$3,0)) | H38: =IF(OR('0.입력칸'!$B$3="",'0.입력칸'!$B$5=""),"",ROUND(G38*'0.입력칸'!$B$5,0)) | I38: 있음 | J38: 시공사 지건설(주) | K38: 기준건축사사무소 | N38: 신축 | O38: 경기도 가평군 조종면 운악리 419-21번지
A39: 경기도 | B39: 가평군 | C39: 상면 상동리 숙박시설 | D39: 2026-04-27 | E39: 5 | F39: 300 | G39: =IF('0.입력칸'!$B$3="","",ROUND(F39/'0.입력칸'!$B$3,0)) | H39: =IF(OR('0.입력칸'!$B$3="",'0.입력칸'!$B$5=""),"",ROUND(G39*'0.입력칸'!$B$5,0)) | I39: 없음 | J39: 설계사 더블유에스엘건축사사무소 | K39: 더블유에스엘건축사사무소 | N39: 신축 | O39: 경기도 가평군 상면 상동리 43-7번지
A40: 경기도 | B40: 가평군 | C40: 숙박시설 (***)-1 | D40: 2024-01-05 | E40: 32 | F40: 295 | G40: =IF('0.입력칸'!$B$3="","",ROUND(F40/'0.입력칸'!$B$3,0)) | H40: =IF(OR('0.입력칸'!$B$3="",'0.입력칸'!$B$5=""),"",ROUND(G40*'0.입력칸'!$B$5,0)) | I40: 없음 | J40: 설계사 기준건축사사무소 | K40: 기준건축사사무소 | N40: 신축 | O40: 경기도 가평군 조종면 운악리 산 162-87번지
A41: 경기도 | B41: 가평군 | C41: 조종면 운악리 162-87 숙박시설 (***)-2 | D41: 2024-01-05 | E41: 32 | F41: 295 | G41: =IF('0.입력칸'!$B$3="","",ROUND(F41/'0.입력칸'!$B$3,0)) | H41: =IF(OR('0.입력칸'!$B$3="",'0.입력칸'!$B$5=""),"",ROUND(G41*'0.입력칸'!$B$5,0)) | I41: 없음 | J41: 설계사 기준건축사사무소 | K41: 기준건축사사무소 | N41: 신축 | O41: 경기도 가평군 조종면 운악리 산 162-87번지
...

Sheet 3.지역별 합계
A1: 지역 | B1: 1500㎡↑ 곳수 | C1: 시공사 정해짐 | D1: 합계 연면적(㎡) | E1: 가장 큰 현장
A2: 서울특별시 | B2: 6 | C2: 2 | D2: 40923 | E2: 영등포동3가 5-10 숙박시설 ((주) 영등포중앙기업)
A3: 인천광역시 | B3: 8 | C3: 3 | D3: 260924 | E3: 인천 검단신도시 101 역세권 개발사업 C9-2블록 숙박시설
A4: 경기도 | B4: 22 | C4: 11 | D4: 456179 | E4: 시화 MTV 거북섬상업 4-1, 4-2블럭 생활숙박시설
A5: 강원특별자치도 | B5: 20 | C5: 5 | D5: 405035 | E5: 낙산 더뷰 컨시어지 호텔 (양양군 강현면 전진리 7-14외 5필지…)
A6: 충청남도 | B6: 15 | C6: 4 | D6: 420853 | E6: 아산배방지구 11BL 생활숙박시설 개발사업
A7: 충청북도 | B7: 6 | C7: 3 | D7: 19786 | E7: 보은읍 죽전리 123-1 생활형 숙박시설
A8: 대전광역시 | B8: 1 | C8: 0 | D8: 6423 | E8: 대전시 동구 정동 생활숙박시설 신축공사
A9: 경상북도 | B9: 11 | C9: 4 | D9: 34952 | E9: 감포읍 대본리 372 숙박시설 (***)
A10: 대구광역시 | B10: 3 | C10: 1 | D10: 14888 | E10: 숙박시설 (주식회사 대산1)
A11: 경상남도 | B11: 14 | C11: 5 | D11: 268222 | E11: 일운면 소동리 19-1 숙박시설 (주식회사 아레포즈거제)
A12: 부산광역시 | B12: 10 | C12: 2 | D12: 184126 | E12: 우동 636-6 숙박시설 (마스턴제107호해운대2피에프브이주식…)
A13: 전라남도 | B13: 11 | C13: 7 | D13: 139491 | E13: 율도동 10000 숙박시설 (주식회사쉼)
... A15: 제주특별자치도 | B15: 5 | C15: 0 | D15: 21848 | E15: 안덕면 서광리 24-8 숙박시설 (람정제주개발 주식회사)
